Workbook
Name _Hlk131856156: Sheet1!#REF!

Sheet About me
A2: TOPIC: ABOUT ME
A3: No | B3: No | C3: ID | D3: Sentence | E3: Type | F3: Link | G3: ID | H3: Copy Google drive to …
B4: 1 | C4: =B4&E4 -> 1Struc | D4: IT’S + ADJ + TO DO SOMETHING /Rất… khi làm gì đó/ | E4: Struc | F4: =IF(G4="","","https://docs.google.com/uc?export=download&id="&G4) | G4: =IFERROR(LEFT(RIGHT(H4,LEN(H4)-32),LEN(RIGHT(H4,LEN(H4)-32))-17),"")
B5: 1.1 | C5: =B5&E5 -> 1.1Viet | D5: Thật tốt khi gặp bạn. | E5: Viet | F5: =IF(G5="","","https://docs.google.com/uc?export=download&id="&G5) | G5: =IFERROR(LEFT(RIGHT(H5,LEN(H5)-32),LEN(RIGHT(H5,LEN(H5)-32))-17),"")
A6: 1 | B6: 1.1 | C6: =B6&E6 -> 1.1Eng | D6: It’s good to see you. | E6: Eng | F6: =IF(G6="","","https://docs.google.com/uc?export=download&id="&G6) | G6: =IFERROR(LEFT(RIGHT(H6,LEN(H6)-32),LEN(RIGHT(H6,LEN(H6)-32))-17),"")
B7: 1.1 | C7: =B7&E7 -> 1.1Phon | D7: ɪts gʊd tu: si: ju: | E7: Phon | F7: =IF(G7="","","https://docs.google.com/uc?export=download&id="&G7) | G7: =IFERROR(LEFT(RIGHT(H7,LEN(H7)-32),LEN(RIGHT(H7,LEN(H7)-32))-17),"")
B8: 1.2 | C8: =B8&E8 -> 1.2Viet | D8: Thật tuyệt khi gặp bạn. | E8: Viet | F8: =IF(G8="","","https://docs.google.com/uc?export=download&id="&G8) | G8: =IFERROR(LEFT(RIGHT(H8,LEN(H8)-32),LEN(RIGHT(H8,LEN(H8)-32))-17),"")
A9: 2 | B9: 1.2 | C9: =B9&E9 -> 1.2Eng | D9: It’s great to see you. | E9: Eng | F9: =IF(G9="","","https://docs.google.com/uc?export=download&id="&G9) | G9: =IFERROR(LEFT(RIGHT(H9,LEN(H9)-32),LEN(RIGHT(H9,LEN(H9)-32))-17),"")
B10: 1.2 | C10: =B10&E10 -> 1.2Phon | D10: ɪts greɪt tu: si: ju: | E10: Phon | F10: =IF(G10="","","https://docs.google.com/uc?export=download&id="&G10) | G10: =IFERROR(LEFT(RIGHT(H10,LEN(H10)-32),LEN(RIGHT(H10,LEN(H10)-32))-17),"")
B11: 1.3 | C11: =B11&E11 -> 1.3Viet | D11: Thật tốt khi biết bạn. | E11: Viet | F11: =IF(G11="","","https://docs.google.com/uc?export=download&id="&G11) | G11: =IFERROR(LEFT(RIGHT(H11,LEN(H11)-32),LEN(RIGHT(H11,LEN(H11)-32))-17),"")
A12: 3 | B12: 1.3 | C12: =B12&E12 -> 1.3Eng | D12: It’s nice to know you. | E12: Eng | F12: =IF(G12="","","https://docs.google.com/uc?export=download&id="&G12) | G12: =IFERROR(LEFT(RIGHT(H12,LEN(H12)-32),LEN(RIGHT(H12,LEN(H12)-32))-17),"")
B13: 1.3 | C13: =B13&E13 -> 1.3Phon | D13: ɪts naɪs tu: noʊ ju: | E13: Phon | F13: =IF(G13="","","https://docs.google.com/uc?export=download&id="&G13) | G13: =IFERROR(LEFT(RIGHT(H13,LEN(H13)-32),LEN(RIGHT(H13,LEN(H13)-32))-17),"")
B14: 1.4 | C14: =B14&E14 -> 1.4Viet | D14: Thật tốt khi gặp lại bạn. | E14: Viet | F14: =IF(G14="","","https://docs.google.com/uc?export=download&id="&G14) | G14: =IFERROR(LEFT(RIGHT(H14,LEN(H14)-32),LEN(RIGHT(H14,LEN(H14)-32))-17),"")
A15: 4 | B15: 1.4 | C15: =B15&E15 -> 1.4Eng | D15: It’s good to meet you again. | E15: Eng | F15: =IF(G15="","","https://docs.google.com/uc?export=download&id="&G15) | G15: =IFERROR(LEFT(RIGHT(H15,LEN(H15)-32),LEN(RIGHT(H15,LEN(H15)-32))-17),"")
B16: 1.4 | C16: =B16&E16 -> 1.4Phon | D16: ɪts gʊd tu: mi:t ju: əˈgɛn | E16: Phon | F16: =IF(G16="","","https://docs.google.com/uc?export=download&id="&G16) | G16: =IFERROR(LEFT(RIGHT(H16,LEN(H16)-32),LEN(RIGHT(H16,LEN(H16)-32))-17),"")
B17: 1.5 | C17: =B17&E17 -> 1.5Viet | D17: Thật tuyệt khi được nói chuyện với bạn. | E17: Viet | F17: =IF(G17="","","https://docs.google.com/uc?export=download&id="&G17) | G17: =IFERROR(LEFT(RIGHT(H17,LEN(H17)-32),LEN(RIGHT(H17,LEN(H17)-32))-17),"")
A18: 5 | B18: 1.5 | C18: =B18&E18 -> 1.5Eng | D18: It’s great to talk to you. | E18: Eng | F18: =IF(G18="","","https://docs.google.com/uc?export=download&id="&G18) | G18: =IFERROR(LEFT(RIGHT(H18,LEN(H18)-32),LEN(RIGHT(H18,LEN(H18)-32))-17),"")
B19: 1.5 | C19: =B19&E19 -> 1.5Phon | D19: ɪts greɪt tu: taːk tu: ju: | E19: Phon | F19: =IF(G19="","","https://docs.google.com/uc?export=download&id="&G19) | G19: =IFERROR(LEFT(RIGHT(H19,LEN(H19)-32),LEN(RIGHT(H19,LEN(H19)-32))-17),"")
B20: 1.6 | C20: =B20&E20 -> 1.6Viet | D20: Rất hân hạnh khi gặp bạn. | E20: Viet | F20: =IF(G20="","","https://docs.google.com/uc?export=download&id="&G20) | G20: =IFERROR(LEFT(RIGHT(H20,LEN(H20)-32),LEN(RIGHT(H20,LEN(H20)-32))-17),"")
A21: 6 | B21: 1.6 | C21: =B21&E21 -> 1.6Eng | D21: It’s a pleasure to meet you. | E21: Eng | F21: =IF(G21="","","https://docs.google.com/uc?export=download&id="&G21) | G21: =IFERROR(LEFT(RIGHT(H21,LEN(H21)-32),LEN(RIGHT(H21,LEN(H21)-32))-17),"")
B22: 1.6 | C22: =B22&E22 -> 1.6Phon | D22: ɪts ə ˈplɛʒər tu: mi:t ju: | E22: Phon | F22: =IF(G22="","","https://docs.google.com/uc?export=download&id="&G22) | G22: =IFERROR(LEFT(RIGHT(H22,LEN(H22)-32),LEN(RIGHT(H22,LEN(H22)-32))-17),"")
B23: 2 | C23: =B23&E23 -> 2Struc | D23: PLEASE ALLOW ME TO INTRODUCE + SOMEONE, SOMEONE’S NAME IS…/Cho phép tôi giới thiệu…/ | E23: Struc | F23: =IF(G23="","","https://docs.google.com/uc?export=download&id="&G23) | G23: =IFERROR(LEFT(RIGHT(H23,LEN(H23)-32),LEN(RIGHT(H23,LEN(H23)-32))-17),"")
B24: 2.1 | C24: =B24&E24 -> 2.1Viet | D24: Cho phép tôi giới thiệu bản thân mình, tên của tôi là Minh. | E24: Viet | F24: =IF(G24="","","https://docs.google.com/uc?export=download&id="&G24) | G24: =IFERROR(LEFT(RIGHT(H24,LEN(H24)-32),LEN(RIGHT(H24,LEN(H24)-32))-17),"")
A25: 7 | B25: 2.1 | C25: =B25&E25 -> 2.1Eng | D25: Please allow me to introduce myself, my name is Minh. | E25: Eng | F25: =IF(G25="","","https://docs.google.com/uc?export=download&id="&G25) | G25: =IFERROR(LEFT(RIGHT(H25,LEN(H25)-32),LEN(RIGHT(H25,LEN(H25)-32))-17),"")
B26: 2.1 | C26: =B26&E26 -> 2.1Phon | D26: pli:z əˈlaʊ mi: tu: ˌɪntrəˈdu:s maɪˈsɛlf maɪ neɪm ɪz Minh | E26: Phon | F26: =IF(G26="","","https://docs.google.com/uc?export=download&id="&G26) | G26: =IFERROR(LEFT(RIGHT(H26,LEN(H26)-32),LEN(RIGHT(H26,LEN(H26)-32))-17),"")
B27: 2.2 | C27: =B27&E27 -> 2.2Viet | D27: Cho phép tôi giới thiệu bản thân mình, tôi là Phương. | E27: Viet | F27: =IF(G27="","","https://docs.google.com/uc?export=download&id="&G27) | G27: =IFERROR(LEFT(RIGHT(H27,LEN(H27)-32),LEN(RIGHT(H27,LEN(H27)-32))-17),"")
A28: 8 | B28: 2.2 | C28: =B28&E28 -> 2.2Eng | D28: Please allow me to introduce myself, I am Phuong. | E28: Eng | F28: =IF(G28="","","https://docs.google.com/uc?export=download&id="&G28) | G28: =IFERROR(LEFT(RIGHT(H28,LEN(H28)-32),LEN(RIGHT(H28,LEN(H28)-32))-17),"")
B29: 2.2 | C29: =B29&E29 -> 2.2Phon | D29: pli:z əˈlaʊ mi: tu: ˌɪntrəˈdu:s maɪˈsɛlf aɪ æm Phuong | E29: Phon | F29: =IF(G29="","","https://docs.google.com/uc?export=download&id="&G29) | G29: =IFERROR(LEFT(RIGHT(H29,LEN(H29)-32),LEN(RIGHT(H29,LEN(H29)-32))-17),"")
B30: 2.3 | C30: =B30&E30 -> 2.3Viet | D30: Cho phép tôi giới thiệu bạn của tôi, tên của cô ấy là Nhung. | E30: Viet | F30: =IF(G30="","","https://docs.google.com/uc?export=download&id="&G30) | G30: =IFERROR(LEFT(RIGHT(H30,LEN(H30)-32),LEN(RIGHT(H30,LEN(H30)-32))-17),"")
A31: 9 | B31: 2.3 | C31: =B31&E31 -> 2.3Eng | D31: Please allow me to introduce my friend, her name is Nhung. | E31: Eng | F31: =IF(G31="","","https://docs.google.com/uc?export=download&id="&G31) | G31: =IFERROR(LEFT(RIGHT(H31,LEN(H31)-32),LEN(RIGHT(H31,LEN(H31)-32))-17),"")
B32: 2.3 | C32: =B32&E32 -> 2.3Phon | D32: pli:z əˈlaʊ mi: tu: ˌɪntrəˈdu:s maɪ frɛnd hɜ:r neɪm ɪz Nhung | E32: Phon | F32: =IF(G32="","","https://docs.google.com/uc?export=download&id="&G32) | G32: =IFERROR(LEFT(RIGHT(H32,LEN(H32)-32),LEN(RIGHT(H32,LEN(H32)-32))-17),"")
B33: 2.4 | C33: =B33&E33 -> 2.4Viet | D33: Cho phép tôi giới thiệu đồng nghiệp của mình, tên anh ấy là Huy. | E33: Viet | F33: =IF(G33="","","https://docs.google.com/uc?export=download&id="&G33) | G33: =IFERROR(LEFT(RIGHT(H33,LEN(H33)-32),LEN(RIGHT(H33,LEN(H33)-32))-17),"")
A34: 10 | B34: 2.4 | C34: =B34&E34 -> 2.4Eng | D34: Please allow me to introduce my co-worker, his name is Huy. | E34: Eng | F34: =IF(G34="","","https://docs.google.com/uc?export=download&id="&G34) | G34: =IFERROR(LEFT(RIGHT(H34,LEN(H34)-32),LEN(RIGHT(H34,LEN(H34)-32))-17),"")
B35: 2.4 | C35: =B35&E35 -> 2.4Phon | D35: pli:z əˈlaʊ mi: tu: ˌɪntrəˈdu:s maɪ koʊ ˈwɜ:rkər hɪz neɪm ɪz Huy | E35: Phon | F35: =IF(G35="","","https://docs.google.com/uc?export=download&id="&G35) | G35: =IFERROR(LEFT(RIGHT(H35,LEN(H35)-32),LEN(RIGHT(H35,LEN(H35)-32))-17),"")
B36: 3 | C36: =B36&E36 -> 3Struc | D36: MY... IS..., YOU CAN CALL ME... IN SHORT /Tên,họ … của tôi là..., bạn có thể gọi tôi là…/ | E36: Struc | F36: =IF(G36="","","https://docs.google.com/uc?export=download&id="&G36) | G36: =IFERROR(LEFT(RIGHT(H36,LEN(H36)-32),LEN(RIGHT(H36,LEN(H36)-32))-17),"")
B37: 3.1 | C37: =B37&E37 -> 3.1Viet | D37: Họ tên tôi là Nguyễn Văn A, bạn có thể gọi tôi là A. | E37: Viet | F37: =IF(G37="","","https://docs.google.com/uc?export=download&id="&G37) | G37: =IFERROR(LEFT(RIGHT(H37,LEN(H37)-32),LEN(RIGHT(H37,LEN(H37)-32))-17),"")
A38: 11 | B38: 3.1 | C38: =B38&E38 -> 3.1Eng | D38: My full name is Nguyen Van A, you can call me A in short. | E38: Eng | F38: =IF(G38="","","https://docs.google.com/uc?export=download&id="&G38) | G38: =IFERROR(LEFT(RIGHT(H38,LEN(H38)-32),LEN(RIGHT(H38,LEN(H38)-32))-17),"")
B39: 3.1 | C39: =B39&E39 -> 3.1Phon | D39: maɪ fʊl neɪm ɪz Nguyen Van A ju: kæn ka:l mi: eɪ ɪn ʃɔ:rt | E39: Phon | F39: =IF(G39="","","https://docs.google.com/uc?export=download&id="&G39) | G39: =IFERROR(LEFT(RIGHT(H39,LEN(H39)-32),LEN(RIGHT(H39,LEN(H39)-32))-17),"")
B40: 3.2 | C40: =B40&E40 -> 3.2Viet | D40: Họ của tôi là Nguyễn, tên của tôi là An, bạn có thể gọi tôi là An nhé! | E40: Viet | F40: =IF(G40="","","https://docs.google.com/uc?export=download&id="&G40) | G40: =IFERROR(LEFT(RIGHT(H40,LEN(H40)-32),LEN(RIGHT(H40,LEN(H40)-32))-17),"")
A41: 12 | B41: 3.2 | C41: =B41&E41 -> 3.2Eng | D41: My last name is Nguyen, my first name is An, you can call me An in short. | E41: Eng | F41: =IF(G41="","","https://docs.google.com/uc?export=download&id="&G41) | G41: =IFERROR(LEFT(RIGHT(H41,LEN(H41)-32),LEN(RIGHT(H41,LEN(H41)-32))-17),"")
...

Sheet Viet
B2: Sentence | C2: Link | D2: ID | E2: Copy Google drive to …
B3: 01-05 | C3: =IF(D3="","","https://docs.google.com/uc?export=download&id="&D3) -> https://docs.google.com/uc?export=download&id=10qlQB8tF1gSzl-Gparsrm3F74hox0hNG | D3: =IFERROR(LEFT(RIGHT(E3,LEN(E3)-32),LEN(RIGHT(E3,LEN(E3)-32))-17),"") -> 10qlQB8tF1gSzl-Gparsrm3F74hox0hNG | E3: https://drive.google.com/file/d/10qlQB8tF1gSzl-Gparsrm3F74hox0hNG/view?usp=sharing
B4: 06-09 | C4: =IF(D4="","","https://docs.google.com/uc?export=download&id="&D4) -> https://docs.google.com/uc?export=download&id=1Vi4ilNsXavOYA4rGbm8nJTp5VFzAs0UV | D4: =IFERROR(LEFT(RIGHT(E4,LEN(E4)-32),LEN(RIGHT(E4,LEN(E4)-32))-17),"") -> 1Vi4ilNsXavOYA4rGbm8nJTp5VFzAs0UV | E4: https://drive.google.com/file/d/1Vi4ilNsXavOYA4rGbm8nJTp5VFzAs0UV/view?usp=sharing
B5: 10-13 | C5: =IF(D5="","","https://docs.google.com/uc?export=download&id="&D5) -> https://docs.google.com/uc?export=download&id=1X9vWN4cPRHgq7tfiAtFUjVab8gEbmf00 | D5: =IFERROR(LEFT(RIGHT(E5,LEN(E5)-32),LEN(RIGHT(E5,LEN(E5)-32))-17),"") -> 1X9vWN4cPRHgq7tfiAtFUjVab8gEbmf00 | E5: https://drive.google.com/file/d/1X9vWN4cPRHgq7tfiAtFUjVab8gEbmf00/view?usp=sharing
B6: 14-17 | C6: =IF(D6="","","https://docs.google.com/uc?export=download&id="&D6) -> https://docs.google.com/uc?export=download&id=1B6EGBHrpPExAP-vSBue6lemxDKWsxGt8 | D6: =IFERROR(LEFT(RIGHT(E6,LEN(E6)-32),LEN(RIGHT(E6,LEN(E6)-32))-17),"") -> 1B6EGBHrpPExAP-vSBue6lemxDKWsxGt8 | E6: https://drive.google.com/file/d/1B6EGBHrpPExAP-vSBue6lemxDKWsxGt8/view?usp=sharing
B7: 18-24 | C7: =IF(D7="","","https://docs.google.com/uc?export=download&id="&D7) -> https://docs.google.com/uc?export=download&id=1kwNhZIe_DzRHthoTyhWJe0j2i5nHyWWU | D7: =IFERROR(LEFT(RIGHT(E7,LEN(E7)-32),LEN(RIGHT(E7,LEN(E7)-32))-17),"") -> 1kwNhZIe_DzRHthoTyhWJe0j2i5nHyWWU | E7: https://drive.google.com/file/d/1kwNhZIe_DzRHthoTyhWJe0j2i5nHyWWU/view?usp=sharing
B8: 01-24 | C8: =IF(D8="","","https://docs.google.com/uc?export=download&id="&D8) -> https://docs.google.com/uc?export=download&id=1q0XTHO24c0hsmHTpb-hu8VS-vP5w5-zT | D8: =IFERROR(LEFT(RIGHT(E8,LEN(E8)-32),LEN(RIGHT(E8,LEN(E8)-32))-17),"") -> 1q0XTHO24c0hsmHTpb-hu8VS-vP5w5-zT | E8: https://drive.google.com/file/d/1q0XTHO24c0hsmHTpb-hu8VS-vP5w5-zT/view?usp=sharing
C9: =IF(D9="","","https://docs.google.com/uc?export=download&id="&D9) | D9: =IFERROR(LEFT(RIGHT(E9,LEN(E9)-32),LEN(RIGHT(E9,LEN(E9)-32))-17),"")
C10: =IF(D10="","","https://docs.google.com/uc?export=download&id="&D10&"""") | D10: =IFERROR(LEFT(RIGHT(E10,LEN(E10)-32),LEN(RIGHT(E10,LEN(E10)-32))-17),"")
C11: =IF(D11="","","https://docs.google.com/uc?export=download&id="&D11&"""") | D11: =IFERROR(LEFT(RIGHT(E11,LEN(E11)-32),LEN(RIGHT(E11,LEN(E11)-32))-17),"")
C12: =IF(D12="","","https://docs.google.com/uc?export=download&id="&D12&"""") | D12: =IFERROR(LEFT(RIGHT(E12,LEN(E12)-32),LEN(RIGHT(E12,LEN(E12)-32))-17),"")
C13: =IF(D13="","","https://docs.google.com/uc?export=download&id="&D13&"""") | D13: =IFERROR(LEFT(RIGHT(E13,LEN(E13)-32),LEN(RIGHT(E13,LEN(E13)-32))-17),"")

Sheet Doc
B1: Link | C1: ID | D1: Copy Google drive to …
A2: MP4 | B2: =IF(C2="","","https://drive.google.com/uc?export=download&id="&C2) -> https://drive.google.com/uc?export=download&id=1yaA5HNAs5jzu20OKyo1SkR34A4jYyxKX | C2: =IFERROR(LEFT(RIGHT(D2,LEN(D2)-32),LEN(RIGHT(D2,LEN(D2)-32))-17),"") -> 1yaA5HNAs5jzu20OKyo1SkR34A4jYyxKX | D2: https://drive.google.com/file/d/1yaA5HNAs5jzu20OKyo1SkR34A4jYyxKX/view?usp=sharing
A3: MP3 | B3: =IF(C3="","","https://docs.google.com/uc?export=download&id="&C3) -> https://docs.google.com/uc?export=download&id=1PocnX9spWHbLaRjmD7yL-UBA2nWHUACi | C3: =IFERROR(LEFT(RIGHT(D3,LEN(D3)-32),LEN(RIGHT(D3,LEN(D3)-32))-17),"") -> 1PocnX9spWHbLaRjmD7yL-UBA2nWHUACi | D3: https://drive.google.com/file/d/1PocnX9spWHbLaRjmD7yL-UBA2nWHUACi/view?usp=sharing
A4: Doc | B4: =IF(C4="","","https://drive.google.com/uc?export=download&id="&C4) -> https://drive.google.com/uc?export=download&id=1KZ01z4pXaLP6Kpue8tVY9GXqoWlHMLXm | C4: =IFERROR(LEFT(RIGHT(D4,LEN(D4)-35),LEN(RIGHT(D4,LEN(D4)-35))-63),"") -> 1KZ01z4pXaLP6Kpue8tVY9GXqoWlHMLXm | D4: https://docs.google.com/document/d/1KZ01z4pXaLP6Kpue8tVY9GXqoWlHMLXm/edit?usp=sharing&ouid=115691797246852180632&rtpof=true&sd=true
A5: Excel | B5: =IF(C5="","","https://drive.google.com/uc?export=download&id="&C5) -> https://drive.google.com/uc?export=download&id=1i2QMI0nI-nZnnUSfRzwDmPv0wE62ZwVp | C5: =IFERROR(LEFT(RIGHT(D5,LEN(D5)-39),LEN(RIGHT(D5,LEN(D5)-39))-63),"") -> 1i2QMI0nI-nZnnUSfRzwDmPv0wE62ZwVp | D5: https://docs.google.com/spreadsheets/d/1i2QMI0nI-nZnnUSfRzwDmPv0wE62ZwVp/edit?usp=sharing&ouid=115691797246852180632&rtpof=true&sd=true
E14: =LEN(D14) -> 0

Sheet Sum
B2: Sentence | C2: Link | D2: ID | E2: Copy Google drive to …
B3: Sum | C3: =IF(D3="","","https://docs.google.com/uc?export=download&id="&D3) -> https://docs.google.com/uc?export=download&id=1fJ1hB_tsAt-bFM29YOwbWqusGHDcgbIZ | D3: =IFERROR(LEFT(RIGHT(E3,LEN(E3)-32),LEN(RIGHT(E3,LEN(E3)-32))-17),"") -> 1fJ1hB_tsAt-bFM29YOwbWqusGHDcgbIZ | E3: https://drive.google.com/file/d/1fJ1hB_tsAt-bFM29YOwbWqusGHDcgbIZ/view?usp=sharing

Sheet Ramdom
B1: From | C1: 95
B2: To | C2: 119
C3: No | D3: No | E3: Viet | F3: Eng
A4: =C1 -> 95 | B4: =IF(A4="","",RANDBETWEEN($C$1,$C$2)) -> 106 | C4: =IFERROR($C$1-1+_xlfn.RANK.EQ(B4,$B$4:$B$130)+COUNTIF(B$4:$B4,B4)-1,"") -> 104 | D4: =IFERROR(VLOOKUP(C4,'About me'!A:B,2,0),"") -> 18.10 | E4: =IFERROR(VLOOKUP(D4&"Viet",'About me'!C:D,2,0),"") -> Hầu hết bạn bè của tôi nói tôi là người hướng ngoại. | F4: =IFERROR(VLOOKUP(D4&"Eng",'About me'!C:D,2,0),"") -> Most of my friends would say I am an extroverted person.
A5: =IFERROR(IF(A4+1>$C$2,"",A4+1),"") -> 96 | B5: =IF(A5="","",RANDBETWEEN($C$1,$C$2)) -> 107 | C5: =IFERROR($C$1-1+_xlfn.RANK.EQ(B5,$B$4:$B$72)+COUNTIF(B$4:$B5,B5)-1,"") -> 102 | D5: =IFERROR(VLOOKUP(C5,'About me'!A:B,2,0),"") -> 18.8 | E5: =IFERROR(VLOOKUP(D5&"Viet",'About me'!C:D,2,0),"") -> Hầu hết bạn bè của tôi nói tôi là người thực tế. | F5: =IFERROR(VLOOKUP(D5&"Eng",'About me'!C:D,2,0),"") -> Most of my friends would say I am a down-to-earth person.
A6: =IFERROR(IF(A5+1>$C$2,"",A5+1),"") -> 97 | B6: =IF(A6="","",RANDBETWEEN($C$1,$C$2)) -> 103 | C6: =IFERROR($C$1-1+_xlfn.RANK.EQ(B6,$B$4:$B$72)+COUNTIF(B$4:$B6,B6)-1,"") -> 109 | D6: =IFERROR(VLOOKUP(C6,'About me'!A:B,2,0),"") -> 19.3 | E6: =IFERROR(VLOOKUP(D6&"Viet",'About me'!C:D,2,0),"") -> Châm ngôn ưa thích của tôi là “Hãy nỗ lực hết mình”. | F6: =IFERROR(VLOOKUP(D6&"Eng",'About me'!C:D,2,0),"") -> My favorite motto is “Do my best”.
A7: =IFERROR(IF(A6+1>$C$2,"",A6+1),"") -> 98 | B7: =IF(A7="","",RANDBETWEEN($C$1,$C$2)) -> 109 | C7: =IFERROR($C$1-1+_xlfn.RANK.EQ(B7,$B$4:$B$72)+COUNTIF(B$4:$B7,B7)-1,"") -> 99 | D7: =IFERROR(VLOOKUP(C7,'About me'!A:B,2,0),"") -> 18.5 | E7: =IFERROR(VLOOKUP(D7&"Viet",'About me'!C:D,2,0),"") -> Hầu hết bạn bè của tôi nói tôi là người dễ xúc động. | F7: =IFERROR(VLOOKUP(D7&"Eng",'About me'!C:D,2,0),"") -> Most of my friends would say I am an emotive person.
A8: =IFERROR(IF(A7+1>$C$2,"",A7+1),"") -> 99 | B8: =IF(A8="","",RANDBETWEEN($C$1,$C$2)) -> 107 | C8: =IFERROR($C$1-1+_xlfn.RANK.EQ(B8,$B$4:$B$72)+COUNTIF(B$4:$B8,B8)-1,"") -> 103 | D8: =IFERROR(VLOOKUP(C8,'About me'!A:B,2,0),"") -> 18.9 | E8: =IFERROR(VLOOKUP(D8&"Viet",'About me'!C:D,2,0),"") -> Hầu hết bạn bè của tôi nói tôi là người hướng nội. | F8: =IFERROR(VLOOKUP(D8&"Eng",'About me'!C:D,2,0),"") -> Most of my friends would say I am an introverted person.
A9: =IFERROR(IF(A8+1>$C$2,"",A8+1),"") -> 100 | B9: =IF(A9="","",RANDBETWEEN($C$1,$C$2)) -> 109 | C9: =IFERROR($C$1-1+_xlfn.RANK.EQ(B9,$B$4:$B$72)+COUNTIF(B$4:$B9,B9)-1,"") -> 100 | D9: =IFERROR(VLOOKUP(C9,'About me'!A:B,2,0),"") -> 18.6 | E9: =IFERROR(VLOOKUP(D9&"Viet",'About me'!C:D,2,0),"") -> Hầu hết bạn bè của tôi nói tôi là người ôn hoà. | F9: =IFERROR(VLOOKUP(D9&"Eng",'About me'!C:D,2,0),"") -> Most of my friends would say I am a mild person.
A10: =IFERROR(IF(A9+1>$C$2,"",A9+1),"") -> 101 | B10: =IF(A10="","",RANDBETWEEN($C$1,$C$2)) -> 98 | C10: =IFERROR($C$1-1+_xlfn.RANK.EQ(B10,$B$4:$B$72)+COUNTIF(B$4:$B10,B10)-1,"") -> 117 | D10: =IFERROR(VLOOKUP(C10,'About me'!A:B,2,0),"") -> 22.1 | E10: =IFERROR(VLOOKUP(D10&"Viet",'About me'!C:D,2,0),"") -> Tôi đã sống ở London được 3 năm. | F10: =IFERROR(VLOOKUP(D10&"Eng",'About me'!C:D,2,0),"") -> I’ve been living in London for 3 years.
A11: =IFERROR(IF(A10+1>$C$2,"",A10+1),"") -> 102 | B11: =IF(A11="","",RANDBETWEEN($C$1,$C$2)) -> 104 | C11: =IFERROR($C$1-1+_xlfn.RANK.EQ(B11,$B$4:$B$72)+COUNTIF(B$4:$B11,B11)-1,"") -> 107 | D11: =IFERROR(VLOOKUP(C11,'About me'!A:B,2,0),"") -> 19.1 | E11: =IFERROR(VLOOKUP(D11&"Viet",'About me'!C:D,2,0),"") -> Châm ngôn ưa thích của tôi là “Không gì là không thể”. | F11: =IFERROR(VLOOKUP(D11&"Eng",'About me'!C:D,2,0),"") -> My favorite motto is “Nothing is impossible”.
A12: =IFERROR(IF(A11+1>$C$2,"",A11+1),"") -> 103 | B12: =IF(A12="","",RANDBETWEEN($C$1,$C$2)) -> 96 | C12: =IFERROR($C$1-1+_xlfn.RANK.EQ(B12,$B$4:$B$72)+COUNTIF(B$4:$B12,B12)-1,"") -> 118 | D12: =IFERROR(VLOOKUP(C12,'About me'!A:B,2,0),"") -> 22.2 | E12: =IFERROR(VLOOKUP(D12&"Viet",'About me'!C:D,2,0),"") -> Tôi đã sống ở Hà Nội được 5 năm. | F12: =IFERROR(VLOOKUP(D12&"Eng",'About me'!C:D,2,0),"") -> I’ve been living in Ha Noi for 5 years.
A13: =IFERROR(IF(A12+1>$C$2,"",A12+1),"") -> 104 | B13: =IF(A13="","",RANDBETWEEN($C$1,$C$2)) -> 105 | C13: =IFERROR($C$1-1+_xlfn.RANK.EQ(B13,$B$4:$B$72)+COUNTIF(B$4:$B13,B13)-1,"") -> 105 | D13: =IFERROR(VLOOKUP(C13,'About me'!A:B,2,0),"") -> 18.11 | E13: =IFERROR(VLOOKUP(D13&"Viet",'About me'!C:D,2,0),"") -> Hầu hết bạn bè của tôi nói tôi là người thận trọng. | F13: =IFERROR(VLOOKUP(D13&"Eng",'About me'!C:D,2,0),"") -> Most of my friends would say I am a cautious person. | J13: 5
A14: =IFERROR(IF(A13+1>$C$2,"",A13+1),"") -> 105 | B14: =IF(A14="","",RANDBETWEEN($C$1,$C$2)) -> 104 | C14: =IFERROR($C$1-1+_xlfn.RANK.EQ(B14,$B$4:$B$72)+COUNTIF(B$4:$B14,B14)-1,"") -> 108 | D14: =IFERROR(VLOOKUP(C14,'About me'!A:B,2,0),"") -> 19.2 | E14: =IFERROR(VLOOKUP(D14&"Viet",'About me'!C:D,2,0),"") -> Châm ngôn ưa thích của tôi là “Hãy hành động”. | F14: =IFERROR(VLOOKUP(D14&"Eng",'About me'!C:D,2,0),"") -> My favorite motto is “Take action”.
A15: =IFERROR(IF(A14+1>$C$2,"",A14+1),"") -> 106 | B15: =IF(A15="","",RANDBETWEEN($C$1,$C$2)) -> 101 | C15: =IFERROR($C$1-1+_xlfn.RANK.EQ(B15,$B$4:$B$72)+COUNTIF(B$4:$B15,B15)-1,"") -> 111 | D15: =IFERROR(VLOOKUP(C15,'About me'!A:B,2,0),"") -> 19.5 | E15: =IFERROR(VLOOKUP(D15&"Viet",'About me'!C:D,2,0),"") -> Châm ngôn ưa thích của tôi là “Cuộc sống là sự lựa chọn”. | F15: =IFERROR(VLOOKUP(D15&"Eng",'About me'!C:D,2,0),"") -> My favorite motto is “Life is a choice”.
A16: =IFERROR(IF(A15+1>$C$2,"",A15+1),"") -> 107 | B16: =IF(A16="","",RANDBETWEEN($C$1,$C$2)) -> 99 | C16: =IFERROR($C$1-1+_xlfn.RANK.EQ(B16,$B$4:$B$72)+COUNTIF(B$4:$B16,B16)-1,"") -> 115 | D16: =IFERROR(VLOOKUP(C16,'About me'!A:B,2,0),"") -> 21.2 | E16: =IFERROR(VLOOKUP(D16&"Viet",'About me'!C:D,2,0),"") -> Tôi đến từ Đà Lạt, nhưng giờ thì tôi sống ở TP. HCM. | F16: =IFERROR(VLOOKUP(D16&"Eng",'About me'!C:D,2,0),"") -> I am originally from Da Lat, but now I’m based in HCM city.
A17: =IFERROR(IF(A16+1>$C$2,"",A16+1),"") -> 108 | B17: =IF(A17="","",RANDBETWEEN($C$1,$C$2)) -> 100 | C17: =IFERROR($C$1-1+_xlfn.RANK.EQ(B17,$B$4:$B$72)+COUNTIF(B$4:$B17,B17)-1,"") -> 114 | D17: =IFERROR(VLOOKUP(C17,'About me'!A:B,2,0),"") -> 21.1 | E17: =IFERROR(VLOOKUP(D17&"Viet",'About me'!C:D,2,0),"") -> Tôi đến từ Hà Nội, nhưng giờ thì tôi sống ở TP. HCM. | F17: =IFERROR(VLOOKUP(D17&"Eng",'About me'!C:D,2,0),"") -> I am originally from Ha Noi, but now I’m based in HCM city.
A18: =IFERROR(IF(A17+1>$C$2,"",A17+1),"") -> 109 | B18: =IF(A18="","",RANDBETWEEN($C$1,$C$2)) -> 113 | C18: =IFERROR($C$1-1+_xlfn.RANK.EQ(B18,$B$4:$B$72)+COUNTIF(B$4:$B18,B18)-1,"") -> 97 | D18: =IFERROR(VLOOKUP(C18,'About me'!A:B,2,0),"") -> 18.3 | E18: =IFERROR(VLOOKUP(D18&"Viet",'About me'!C:D,2,0),"") -> Hầu hết bạn bè của tôi nói tôi là người thân thiện. | F18: =IFERROR(VLOOKUP(D18&"Eng",'About me'!C:D,2,0),"") -> Most of my friends would say I am a friendly person.
A19: =IFERROR(IF(A18+1>$C$2,"",A18+1),"") -> 110 | B19: =IF(A19="","",RANDBETWEEN($C$1,$C$2)) -> 118 | C19: =IFERROR($C$1-1+_xlfn.RANK.EQ(B19,$B$4:$B$72)+COUNTIF(B$4:$B19,B19)-1,"") -> 95 | D19: =IFERROR(VLOOKUP(C19,'About me'!A:B,2,0),"") -> 18.1 | E19: =IFERROR(VLOOKUP(D19&"Viet",'About me'!C:D,2,0),"") -> Hầu hết bạn bè của tôi nói tôi là người năng động. | F19: =IFERROR(VLOOKUP(D19&"Eng",'About me'!C:D,2,0),"") -> Most of my friends would say I am an active person. | J19: njn
A20: =IFERROR(IF(A19+1>$C$2,"",A19+1),"") -> 111 | B20: =IF(A20="","",RANDBETWEEN($C$1,$C$2)) -> 99 | C20: =IFERROR($C$1-1+_xlfn.RANK.EQ(B20,$B$4:$B$72)+COUNTIF(B$4:$B20,B20)-1,"") -> 116 | D20: =IFERROR(VLOOKUP(C20,'About me'!A:B,2,0),"") -> 21.3 | E20: =IFERROR(VLOOKUP(D20&"Viet",'About me'!C:D,2,0),"") -> Tôi đến từ Hà Nội, nhưng giờ thì tôi sống ở TP. Đà Nẵng. | F20: =IFERROR(VLOOKUP(D20&"Eng",'About me'!C:D,2,0),"") -> I am originally from Ha Noi, but now I’m based in Da Nang city.
A21: =IFERROR(IF(A20+1>$C$2,"",A20+1),"") -> 112 | B21: =IF(A21="","",RANDBETWEEN($C$1,$C$2)) -> 96 | C21: =IFERROR($C$1-1+_xlfn.RANK.EQ(B21,$B$4:$B$72)+COUNTIF(B$4:$B21,B21)-1,"") -> 119 | D21: =IFERROR(VLOOKUP(C21,'About me'!A:B,2,0),"") -> 22.3 | E21: =IFERROR(VLOOKUP(D21&"Viet",'About me'!C:D,2,0),"") -> Tôi đã sống ở TP. HCM được 10 năm. | F21: =IFERROR(VLOOKUP(D21&"Eng",'About me'!C:D,2,0),"") -> I’ve been living in HCM city for 10 years.
A22: =IFERROR(IF(A21+1>$C$2,"",A21+1),"") -> 113 | B22: =IF(A22="","",RANDBETWEEN($C$1,$C$2)) -> 101 | C22: =IFERROR($C$1-1+_xlfn.RANK.EQ(B22,$B$4:$B$72)+COUNTIF(B$4:$B22,B22)-1,"") -> 112 | D22: =IFERROR(VLOOKUP(C22,'About me'!A:B,2,0),"") -> 20.1 | E22: =IFERROR(VLOOKUP(D22&"Viet",'About me'!C:D,2,0),"") -> Tôi sinh ra và lớn lên ở Đồng Nai. | F22: =IFERROR(VLOOKUP(D22&"Eng",'About me'!C:D,2,0),"") -> I was born and raised in Dong Nai.
A23: =IFERROR(IF(A22+1>$C$2,"",A22+1),"") -> 114 | B23: =IF(A23="","",RANDBETWEEN($C$1,$C$2)) -> 105 | C23: =IFERROR($C$1-1+_xlfn.RANK.EQ(B23,$B$4:$B$72)+COUNTIF(B$4:$B23,B23)-1,"") -> 106 | D23: =IFERROR(VLOOKUP(C23,'About me'!A:B,2,0),"") -> 18.12 | E23: =IFERROR(VLOOKUP(D23&"Viet",'About me'!C:D,2,0),"") -> Hầu hết bạn bè của tôi nói tôi là người ít nói. | F23: =IFERROR(VLOOKUP(D23&"Eng",'About me'!C:D,2,0),"") -> Most of my friends would say I am a quiet person.
A24: =IFERROR(IF(A23+1>$C$2,"",A23+1),"") -> 115 | B24: =IF(A24="","",RANDBETWEEN($C$1,$C$2)) -> 101 | C24: =IFERROR($C$1-1+_xlfn.RANK.EQ(B24,$B$4:$B$72)+COUNTIF(B$4:$B24,B24)-1,"") -> 113 | D24: =IFERROR(VLOOKUP(C24,'About me'!A:B,2,0),"") -> 20.2 | E24: =IFERROR(VLOOKUP(D24&"Viet",'About me'!C:D,2,0),"") -> Tôi sinh ra và lớn lên ở Lâm Đồng. | F24: =IFERROR(VLOOKUP(D24&"Eng",'About me'!C:D,2,0),"") -> I was born and raised in Lam Dong.
A25: =IFERROR(IF(A24+1>$C$2,"",A24+1),"") -> 116 | B25: =IF(A25="","",RANDBETWEEN($C$1,$C$2)) -> 112 | C25: =IFERROR($C$1-1+_xlfn.RANK.EQ(B25,$B$4:$B$72)+COUNTIF(B$4:$B25,B25)-1,"") -> 98 | D25: =IFERROR(VLOOKUP(C25,'About me'!A:B,2,0),"") -> 18.4 | E25: =IFERROR(VLOOKUP(D25&"Viet",'About me'!C:D,2,0),"") -> Hầu hết bạn bè của tôi nói tôi là người hiền hậu. | F25: =IFERROR(VLOOKUP(D25&"Eng",'About me'!C:D,2,0),"") -> Most of my friends would say I am a gentle person.
A26: =IFERROR(IF(A25+1>$C$2,"",A25+1),"") -> 117 | B26: =IF(A26="","",RANDBETWEEN($C$1,$C$2)) -> 103 | C26: =IFERROR($C$1-1+_xlfn.RANK.EQ(B26,$B$4:$B$72)+COUNTIF(B$4:$B26,B26)-1,"") -> 110 | D26: =IFERROR(VLOOKUP(C26,'About me'!A:B,2,0),"") -> 19.4 | E26: =IFERROR(VLOOKUP(D26&"Viet",'About me'!C:D,2,0),"") -> Châm ngôn ưa thích của tôi là “Không bao giờ bỏ cuộc”. | F26: =IFERROR(VLOOKUP(D26&"Eng",'About me'!C:D,2,0),"") -> My favorite motto is “Never give up”.
A27: =IFERROR(IF(A26+1>$C$2,"",A26+1),"") -> 118 | B27: =IF(A27="","",RANDBETWEEN($C$1,$C$2)) -> 108 | C27: =IFERROR($C$1-1+_xlfn.RANK.EQ(B27,$B$4:$B$72)+COUNTIF(B$4:$B27,B27)-1,"") -> 101 | D27: =IFERROR(VLOOKUP(C27,'About me'!A:B,2,0),"") -> 18.7 | E27: =IFERROR(VLOOKUP(D27&"Viet",'About me'!C:D,2,0),"") -> Hầu hết bạn bè của tôi nói tôi là người lạc quan. | F27: =IFERROR(VLOOKUP(D27&"Eng",'About me'!C:D,2,0),"") -> Most of my friends would say I am an optimistic person.
A28: =IFERROR(IF(A27+1>$C$2,"",A27+1),"") -> 119 | B28: =IF(A28="","",RANDBETWEEN($C$1,$C$2)) -> 116 | C28: =IFERROR($C$1-1+_xlfn.RANK.EQ(B28,$B$4:$B$72)+COUNTIF(B$4:$B28,B28)-1,"") -> 96 | D28: =IFERROR(VLOOKUP(C28,'About me'!A:B,2,0),"") -> 18.2 | E28: =IFERROR(VLOOKUP(D28&"Viet",'About me'!C:D,2,0),"") -> Hầu hết bạn bè của tôi nói tôi là người nhút nhát. | F28: =IFERROR(VLOOKUP(D28&"Eng",'About me'!C:D,2,0),"") -> Most of my friends would say I am a shy person.
A29: =IFERROR(IF(A28+1>$C$2,"",A28+1),"") | B29: =IF(A29="","",RANDBETWEEN($C$1,$C$2)) | C29: =IFERROR($C$1-1+_xlfn.RANK.EQ(B29,$B$4:$B$72)+COUNTIF(B$4:$B29,B29)-1,"") | D29: =IFERROR(VLOOKUP(C29,'About me'!A:B,2,0),"") | E29: =IFERROR(VLOOKUP(D29&"Viet",'About me'!C:D,2,0),"") | F29: =IFERROR(VLOOKUP(D29&"Eng",'About me'!C:D,2,0),"")
A30: =IFERROR(IF(A29+1>$C$2,"",A29+1),"") | B30: =IF(A30="","",RANDBETWEEN($C$1,$C$2)) | C30: =IFERROR($C$1-1+_xlfn.RANK.EQ(B30,$B$4:$B$72)+COUNTIF(B$4:$B30,B30)-1,"") | D30: =IFERROR(VLOOKUP(C30,'About me'!A:B,2,0),"") | E30: =IFERROR(VLOOKUP(D30&"Viet",'About me'!C:D,2,0),"") | F30: =IFERROR(VLOOKUP(D30&"Eng",'About me'!C:D,2,0),"")
A31: =IFERROR(IF(A30+1>$C$2,"",A30+1),"") | B31: =IF(A31="","",RANDBETWEEN($C$1,$C$2)) | C31: =IFERROR($C$1-1+_xlfn.RANK.EQ(B31,$B$4:$B$72)+COUNTIF(B$4:$B31,B31)-1,"") | D31: =IFERROR(VLOOKUP(C31,'About me'!A:B,2,0),"") | E31: =IFERROR(VLOOKUP(D31&"Viet",'About me'!C:D,2,0),"") | F31: =IFERROR(VLOOKUP(D31&"Eng",'About me'!C:D,2,0),"")
... A72: =IFERROR(IF(A71+1>$C$2,"",A71+1),"") | B72: =IF(A72="","",RANDBETWEEN($C$1,$C$2)) | C72: =IFERROR($C$1-1+_xlfn.RANK.EQ(B72,$B$4:$B$72)+COUNTIF(B$4:$B72,B72)-1,"") | D72: =IFERROR(VLOOKUP(C72,'About me'!A:B,2,0),"") | E72: =IFERROR(VLOOKUP(D72&"Viet",'About me'!C:D,2,0),"") | F72: =IFERROR(VLOOKUP(D72&"Eng",'About me'!C:D,2,0),"")
A73: =IFERROR(IF(A72+1>$C$2,"",A72+1),"") | B73: =IF(A73="","",RANDBETWEEN($C$1,$C$2)) | C73: =IFERROR($C$1-1+_xlfn.RANK.EQ(B73,$B$4:$B$72)+COUNTIF(B$4:$B73,B73)-1,"") | D73: =IFERROR(VLOOKUP(C73,'About me'!A:B,2,0),"")
A74: =IFERROR(IF(A73+1>$C$2,"",A73+1),"") | B74: =IF(A74="","",RANDBETWEEN($C$1,$C$2)) | C74: =IFERROR($C$1-1+_xlfn.RANK.EQ(B74,$B$4:$B$72)+COUNTIF(B$4:$B74,B74)-1,"") | D74: =IFERROR(VLOOKUP(C74,'About me'!A:B,2,0),"")
A75: =IFERROR(IF(A74+1>$C$2,"",A74+1),"") | B75: =IF(A75="","",RANDBETWEEN($C$1,$C$2)) | C75: =IFERROR($C$1-1+_xlfn.RANK.EQ(B75,$B$4:$B$72)+COUNTIF(B$4:$B75,B75)-1,"") | D75: =IFERROR(VLOOKUP(C75,'About me'!A:B,2,0),"")
A76: =IFERROR(IF(A75+1>$C$2,"",A75+1),"") | B76: =IF(A76="","",RANDBETWEEN($C$1,$C$2)) | C76: =IFERROR($C$1-1+_xlfn.RANK.EQ(B76,$B$4:$B$72)+COUNTIF(B$4:$B76,B76)-1,"") | D76: =IFERROR(VLOOKUP(C76,'About me'!A:B,2,0),"")
A77: =IFERROR(IF(A76+1>$C$2,"",A76+1),"") | B77: =IF(A77="","",RANDBETWEEN($C$1,$C$2)) | C77: =IFERROR($C$1-1+_xlfn.RANK.EQ(B77,$B$4:$B$72)+COUNTIF(B$4:$B77,B77)-1,"") | D77: =IFERROR(VLOOKUP(C77,'About me'!A:B,2,0),"")
A78: =IFERROR(IF(A77+1>$C$2,"",A77+1),"") | B78: =IF(A78="","",RANDBETWEEN($C$1,$C$2)) | C78: =IFERROR($C$1-1+_xlfn.RANK.EQ(B78,$B$4:$B$72)+COUNTIF(B$4:$B78,B78)-1,"") | D78: =IFERROR(VLOOKUP(C78,'About me'!A:B,2,0),"")
A79: =IFERROR(IF(A78+1>$C$2,"",A78+1),"") | B79: =IF(A79="","",RANDBETWEEN($C$1,$C$2)) | C79: =IFERROR($C$1-1+_xlfn.RANK.EQ(B79,$B$4:$B$72)+COUNTIF(B$4:$B79,B79)-1,"") | D79: =IFERROR(VLOOKUP(C79,'About me'!A:B,2,0),"")
A80: =IFERROR(IF(A79+1>$C$2,"",A79+1),"") | B80: =IF(A80="","",RANDBETWEEN($C$1,$C$2)) | C80: =IFERROR($C$1-1+_xlfn.RANK.EQ(B80,$B$4:$B$72)+COUNTIF(B$4:$B80,B80)-1,"") | D80: =IFERROR(VLOOKUP(C80,'About me'!A:B,2,0),"")
...

Sheet Sheet1
