Workbook

Sheet Anger
B2: TOPIC: ANGER
A3: No | B3: No | C3: ID | D3: Sentence | E3: Type | F3: Link | G3: ID | H3: Copy Google drive to …
B4: 1 | C4: 1Struc | D4: S + TO BE SO MAD AT + SOMEONE /Nổi giận/nổi điên với ai đó…/ | E4: Struc
B5: 1.1 | C5: 1.1Viet | D5: Hiện giờ tôi đang rất giận bạn. | E5: Viet | G5: =IFERROR(LEFT(RIGHT(H5,LEN(H5)-32),LEN(RIGHT(H5,LEN(H5)-32))-17),"")
A6: 1 | B6: 1.1 | C6: 1.1Eng | D6: I’m so mad at you right now. | E6: Eng | F6: https://docs.google.com/uc?export=download&id=1-ajtbCeUQXHx9GEHjoFMkU2clNh7XW_P | G6: =IFERROR(LEFT(RIGHT(H6,LEN(H6)-32),LEN(RIGHT(H6,LEN(H6)-32))-17),"")
B7: 1.1 | C7: 1.1Phon | D7: aɪm soʊ mæd æt ju: raɪt naʊ | E7: Phon | G7: =IFERROR(LEFT(RIGHT(H7,LEN(H7)-32),LEN(RIGHT(H7,LEN(H7)-32))-17),"")
B8: 1.2 | C8: 1.2Viet | D8: Anh ấy nổi giận với cô ấy. | E8: Viet | G8: =IFERROR(LEFT(RIGHT(H8,LEN(H8)-32),LEN(RIGHT(H8,LEN(H8)-32))-17),"")
A9: 2 | B9: 1.2 | C9: 1.2Eng | D9: He is so mad at her. | E9: Eng | F9: https://docs.google.com/uc?export=download&id=10gXMNgd1mYXzzOu6WlJuQMY8kh1GgQLo | G9: =IFERROR(LEFT(RIGHT(H9,LEN(H9)-32),LEN(RIGHT(H9,LEN(H9)-32))-17),"")
B10: 1.2 | C10: 1.2Phon | D10: hi: ɪz soʊ mæd æt hɜ:r | E10: Phon | G10: =IFERROR(LEFT(RIGHT(H10,LEN(H10)-32),LEN(RIGHT(H10,LEN(H10)-32))-17),"")
B11: 1.3 | C11: 1.3Viet | D11: Tôi rất giận cô ấy. | E11: Viet | G11: =IFERROR(LEFT(RIGHT(H11,LEN(H11)-32),LEN(RIGHT(H11,LEN(H11)-32))-17),"")
A12: 3 | B12: 1.3 | C12: 1.3Eng | D12: I am so mad at her. | E12: Eng | F12: https://docs.google.com/uc?export=download&id=13ndrDVWCNHoZUGo8I9eO3sP3DRFSIRCz | G12: =IFERROR(LEFT(RIGHT(H12,LEN(H12)-32),LEN(RIGHT(H12,LEN(H12)-32))-17),"")
B13: 1.3 | C13: 1.3Phon | D13: aɪ æm soʊ mæd æt hɜ:r | E13: Phon | G13: =IFERROR(LEFT(RIGHT(H13,LEN(H13)-32),LEN(RIGHT(H13,LEN(H13)-32))-17),"")
B14: 1.4 | C14: 1.4Viet | D14: Mẹ tôi nổi giận với tôi. | E14: Viet | G14: =IFERROR(LEFT(RIGHT(H14,LEN(H14)-32),LEN(RIGHT(H14,LEN(H14)-32))-17),"")
A15: 4 | B15: 1.4 | C15: 1.4Eng | D15: My mom is so mad at me. | E15: Eng | F15: https://docs.google.com/uc?export=download&id=1cp9AwpnTjbDDMNQSLUfYp_HDLjn_mQg5 | G15: =IFERROR(LEFT(RIGHT(H15,LEN(H15)-32),LEN(RIGHT(H15,LEN(H15)-32))-17),"")
B16: 1.4 | C16: 1.4Phon | D16: maɪ ma:m ɪz soʊ mæd æt mi: | E16: Phon | G16: =IFERROR(LEFT(RIGHT(H16,LEN(H16)-32),LEN(RIGHT(H16,LEN(H16)-32))-17),"")
B17: 2 | C17: 2Struc | D17: S1 + TO BE GOING TO BE + TÍNH TỪ WHEN S1 FINDS OUT WHAT HAPPENED /Ai đó sẽ... khi phát hiện chuyện đã xảy ra/ | E17: Struc | G17: =IFERROR(LEFT(RIGHT(H17,LEN(H17)-32),LEN(RIGHT(H17,LEN(H17)-32))-17),"")
B18: 2.1 | C18: 2.1Viet | D18: Mẹ của bạn sẽ nổi giận khi bà ấy phát hiện chuyện đã xảy ra. | E18: Viet | G18: =IFERROR(LEFT(RIGHT(H18,LEN(H18)-32),LEN(RIGHT(H18,LEN(H18)-32))-17),"")
A19: 5 | B19: 2.1 | C19: 2.1Eng | D19: Your mom is going to be furious when she finds out what happened. | E19: Eng | F19: https://docs.google.com/uc?export=download&id=1WcQSGY7PYWiqAhjbizdVGF5UFhSXhzUG | G19: =IFERROR(LEFT(RIGHT(H19,LEN(H19)-32),LEN(RIGHT(H19,LEN(H19)-32))-17),"")
B20: 2.1 | C20: 2.1Phon | D20: jʊr ma:m ɪz ˈgoʊɪŋ tu: bi: ˈfjʊriəs wɛn ʃi: faɪndz aʊt wʌt ˈhæpənd | E20: Phon | G20: =IFERROR(LEFT(RIGHT(H20,LEN(H20)-32),LEN(RIGHT(H20,LEN(H20)-32))-17),"")
B21: 2.2 | C21: 2.2Viet | D21: Anh ấy sẽ buồn khi anh ấy phát hiện chuyện đã xảy ra. | E21: Viet | G21: =IFERROR(LEFT(RIGHT(H21,LEN(H21)-32),LEN(RIGHT(H21,LEN(H21)-32))-17),"")
A22: 6 | B22: 2.2 | C22: 2.2Eng | D22: He is going to be upset when he finds out what happened. | E22: Eng | F22: https://docs.google.com/uc?export=download&id=1AqJeMqtujwHOo6O4biI_ypOx87W7cw8b | G22: =IFERROR(LEFT(RIGHT(H22,LEN(H22)-32),LEN(RIGHT(H22,LEN(H22)-32))-17),"")
B23: 2.2 | C23: 2.2Phon | D23: hi: ɪz ˈgoʊɪŋ tu: bi: ʌpˈset wɛn hi: faɪndz aʊt wʌt ˈhæpənd | E23: Phon | G23: =IFERROR(LEFT(RIGHT(H23,LEN(H23)-32),LEN(RIGHT(H23,LEN(H23)-32))-17),"")
B24: 2.3 | C24: 2.3Viet | D24: Bạn sẽ nổi giận khi bạn phát hiện chuyện đã xảy ra. | E24: Viet | G24: =IFERROR(LEFT(RIGHT(H24,LEN(H24)-32),LEN(RIGHT(H24,LEN(H24)-32))-17),"")
A25: 7 | B25: 2.3 | C25: 2.3Eng | D25: You are going to be furious when you find out what happened. | E25: Eng | F25: https://docs.google.com/uc?export=download&id=1DfkD12QTNOSkC2S5jEKAjqqjtUZHGmcs | G25: =IFERROR(LEFT(RIGHT(H25,LEN(H25)-32),LEN(RIGHT(H25,LEN(H25)-32))-17),"")
B26: 2.3 | C26: 2.3Phon | D26: ju: a:r ˈgoʊɪŋ tu: bi: ˈfjʊriəs wɛn ju: faɪnd aʊt wʌt ˈhæpənd | E26: Phon | G26: =IFERROR(LEFT(RIGHT(H26,LEN(H26)-32),LEN(RIGHT(H26,LEN(H26)-32))-17),"")
B27: 3 | C27: 3Struc | D27: S + NEED TO BETTER CONTROL S’S TEMPER /Cần kiềm chế tính khí/ | E27: Struc | G27: =IFERROR(LEFT(RIGHT(H27,LEN(H27)-32),LEN(RIGHT(H27,LEN(H27)-32))-17),"")
B28: 3.1 | C28: 3.1Viet | D28: Tôi cần kiềm chế tính khí của mình nhiều hơn. | E28: Viet | G28: =IFERROR(LEFT(RIGHT(H28,LEN(H28)-32),LEN(RIGHT(H28,LEN(H28)-32))-17),"")
A29: 8 | B29: 3.1 | C29: 3.1Eng | D29: I need to better control my temper. | E29: Eng | F29: https://docs.google.com/uc?export=download&id=1OJJMQjui7NiMn5YPFzxTPVR0lacZ3TS4 | G29: =IFERROR(LEFT(RIGHT(H29,LEN(H29)-32),LEN(RIGHT(H29,LEN(H29)-32))-17),"")
B30: 3.1 | C30: 3.1Phon | D30: aɪ ni:d tu: ˈbɛtər kənˈtroʊl maɪ ˈtɛmpər | E30: Phon | G30: =IFERROR(LEFT(RIGHT(H30,LEN(H30)-32),LEN(RIGHT(H30,LEN(H30)-32))-17),"")
B31: 3.2 | C31: 3.2Viet | D31: Bạn nên kiềm chế tính khí của bạn nhiều hơn. | E31: Viet | G31: =IFERROR(LEFT(RIGHT(H31,LEN(H31)-32),LEN(RIGHT(H31,LEN(H31)-32))-17),"")
A32: 9 | B32: 3.2 | C32: 3.2Eng | D32: You need to better control your temper. | E32: Eng | F32: https://docs.google.com/uc?export=download&id=14g_Nn4aDOkoedZL_SLFdPzZd0q0zRcIg | G32: =IFERROR(LEFT(RIGHT(H32,LEN(H32)-32),LEN(RIGHT(H32,LEN(H32)-32))-17),"")
B33: 3.2 | C33: 3.2Phon | D33: ju: ni:d tu: ˈbɛtər kənˈtroʊl jʊr ˈtɛmpər | E33: Phon | G33: =IFERROR(LEFT(RIGHT(H33,LEN(H33)-32),LEN(RIGHT(H33,LEN(H33)-32))-17),"")
B34: 3.3 | C34: 3.3Viet | D34: Anh ấy cần kiềm chế tính khí của ảnh nhiều hơn. | E34: Viet | G34: =IFERROR(LEFT(RIGHT(H34,LEN(H34)-32),LEN(RIGHT(H34,LEN(H34)-32))-17),"")
A35: 10 | B35: 3.3 | C35: 3.3Eng | D35: He needs to better control his temper. | E35: Eng | F35: https://docs.google.com/uc?export=download&id=1VXbIm_rp2K2_-3gv_0uGwXLWTaga9m8e | G35: =IFERROR(LEFT(RIGHT(H35,LEN(H35)-32),LEN(RIGHT(H35,LEN(H35)-32))-17),"")
B36: 3.3 | C36: 3.3Phon | D36: hi: ni:dz tu: ˈbɛtər kənˈtroʊl hɪz ˈtɛmpər | E36: Phon | G36: =IFERROR(LEFT(RIGHT(H36,LEN(H36)-32),LEN(RIGHT(H36,LEN(H36)-32))-17),"")
B37: 4 | C37: 4Struc | D37: IT WON’T HELP ANYTHING IF + S GET ANGRY /Không giải quyết được gì cả nếu nổi giận/ | E37: Struc | G37: =IFERROR(LEFT(RIGHT(H37,LEN(H37)-32),LEN(RIGHT(H37,LEN(H37)-32))-17),"")
B38: 4.1 | C38: 4.1Viet | D38: Nếu anh nổi giận thì nó không giải quyết được gì cả. | E38: Viet | G38: =IFERROR(LEFT(RIGHT(H38,LEN(H38)-32),LEN(RIGHT(H38,LEN(H38)-32))-17),"")
A39: 11 | B39: 4.1 | C39: 4.1Eng | D39: It won’t help anything if you get angry. | E39: Eng | F39: https://docs.google.com/uc?export=download&id=1Z2tcV1F8ffVNbKdYizR67rfLfllc0HDi | G39: =IFERROR(LEFT(RIGHT(H39,LEN(H39)-32),LEN(RIGHT(H39,LEN(H39)-32))-17),"")
B40: 4.1 | C40: 4.1Phon | D40: ɪt woʊnt hɛlp ˈɛniθɪŋ ɪf ju: gɛt ˈæŋgri | E40: Phon | G40: =IFERROR(LEFT(RIGHT(H40,LEN(H40)-32),LEN(RIGHT(H40,LEN(H40)-32))-17),"")
B41: 4.2 | C41: 4.2Viet | D41: Nếu tôi nổi giận thì nó không giải quyết được gì cả. | E41: Viet | G41: =IFERROR(LEFT(RIGHT(H41,LEN(H41)-32),LEN(RIGHT(H41,LEN(H41)-32))-17),"")
...

Sheet Viet
B2: Sentence | C2: Link | D2: ID | E2: Copy Google drive to …
B3: 01-05 | C3: =IF(D3="","","https://docs.google.com/uc?export=download&id="&D3) -> https://docs.google.com/uc?export=download&id=1m6o0grLZpRv8NcYs-9Kyle81Amc2DeiQ | D3: =IFERROR(LEFT(RIGHT(E3,LEN(E3)-32),LEN(RIGHT(E3,LEN(E3)-32))-17),"") -> 1m6o0grLZpRv8NcYs-9Kyle81Amc2DeiQ | E3: https://drive.google.com/file/d/1m6o0grLZpRv8NcYs-9Kyle81Amc2DeiQ/view?usp=sharing
B4: 06-09 | C4: =IF(D4="","","https://docs.google.com/uc?export=download&id="&D4) -> https://docs.google.com/uc?export=download&id=1vKerznEEx67IeMZZhGUSLRClr-1NUrYi | D4: =IFERROR(LEFT(RIGHT(E4,LEN(E4)-32),LEN(RIGHT(E4,LEN(E4)-32))-17),"") -> 1vKerznEEx67IeMZZhGUSLRClr-1NUrYi | E4: https://drive.google.com/file/d/1vKerznEEx67IeMZZhGUSLRClr-1NUrYi/view?usp=sharing
B5: 01-09 | C5: =IF(D5="","","https://docs.google.com/uc?export=download&id="&D5) -> https://docs.google.com/uc?export=download&id=1vZkcKg7dYr3kJFlQuAhRDvjM3ZfFfqaf | D5: =IFERROR(LEFT(RIGHT(E5,LEN(E5)-32),LEN(RIGHT(E5,LEN(E5)-32))-17),"") -> 1vZkcKg7dYr3kJFlQuAhRDvjM3ZfFfqaf | E5: https://drive.google.com/file/d/1vZkcKg7dYr3kJFlQuAhRDvjM3ZfFfqaf/view?usp=sharing

Sheet Sum
B2: Sentence | C2: Link | D2: ID | E2: Copy Google drive to …
B3: Woman | C3: =IF(D3="","","https://docs.google.com/uc?export=download&id="&D3) -> https://docs.google.com/uc?export=download&id=1oOAe_Uo5RVjuOwL7odyMUqbjcIay_4zG | D3: =IFERROR(LEFT(RIGHT(E3,LEN(E3)-32),LEN(RIGHT(E3,LEN(E3)-32))-17),"") -> 1oOAe_Uo5RVjuOwL7odyMUqbjcIay_4zG | E3: https://drive.google.com/file/d/1oOAe_Uo5RVjuOwL7odyMUqbjcIay_4zG/view?usp=sharing
B4: Man | C4: =IF(D4="","","https://docs.google.com/uc?export=download&id="&D4) -> https://docs.google.com/uc?export=download&id=1ZOHF8mv3TaDXUIYFR-yYUxcctLB4VrG8 | D4: =IFERROR(LEFT(RIGHT(E4,LEN(E4)-32),LEN(RIGHT(E4,LEN(E4)-32))-17),"") -> 1ZOHF8mv3TaDXUIYFR-yYUxcctLB4VrG8 | E4: https://drive.google.com/file/d/1ZOHF8mv3TaDXUIYFR-yYUxcctLB4VrG8/view?usp=sharing

Sheet Ramdom
B1: From | C1: 17
B2: To | C2: 28
C3: No | D3: No | E3: Viet | F3: Eng
A4: =C1 -> 17 | B4: =IF(A4="","",RANDBETWEEN($C$1,$C$2)) -> 26 | C4: =IFERROR($C$1-1+_xlfn.RANK.EQ(B4,$B$4:$B$31)+COUNTIF(B$4:$B4,B4)-1,"") -> 20 | D4: =IFERROR(VLOOKUP(C4,Anger!A:B,2,0),"") -> 7.1 | E4: =IFERROR(VLOOKUP(D4&"Viet",Anger!C:D,2,0),"") -> Tôi đã quá giận nên không kịp suy nghĩ đúng đắn. | F4: =IFERROR(VLOOKUP(D4&"Eng",Anger!C:D,2,0),"") -> I was simply too mad to think straight.
A5: =IFERROR(IF(A4+1>$C$2,"",A4+1),"") -> 18 | B5: =IF(A5="","",RANDBETWEEN($C$1,$C$2)) -> 22 | C5: =IFERROR($C$1-1+_xlfn.RANK.EQ(B5,$B$4:$B$31)+COUNTIF(B$4:$B5,B5)-1,"") -> 25 | D5: =IFERROR(VLOOKUP(C5,Anger!A:B,2,0),"") -> 8.3 | E5: =IFERROR(VLOOKUP(D5&"Viet",Anger!C:D,2,0),"") -> Có lẽ tôi sẽ không chấm dứt mối quan hệ bạn bè với anh, nhưng tôi vẫn phải nói hết cho nhẹ người. | F5: =IFERROR(VLOOKUP(D5&"Eng",Anger!C:D,2,0),"") -> Maybe I won’t stop being friend with you, but I’m still going to tell you what I think about you.
A6: =IFERROR(IF(A5+1>$C$2,"",A5+1),"") -> 19 | B6: =IF(A6="","",RANDBETWEEN($C$1,$C$2)) -> 21 | C6: =IFERROR($C$1-1+_xlfn.RANK.EQ(B6,$B$4:$B$31)+COUNTIF(B$4:$B6,B6)-1,"") -> 28 | D6: =IFERROR(VLOOKUP(C6,Anger!A:B,2,0),"") -> 9.3 | E6: =IFERROR(VLOOKUP(D6&"Viet",Anger!C:D,2,0),"") -> Tôi không hiểu sao bạn có thể thiếu suy nghĩ vậy. | F6: =IFERROR(VLOOKUP(D6&"Eng",Anger!C:D,2,0),"") -> I don’t understand how you can be so thoughtless. | K6: l
A7: =IFERROR(IF(A6+1>$C$2,"",A6+1),"") -> 20 | B7: =IF(A7="","",RANDBETWEEN($C$1,$C$2)) -> 27 | C7: =IFERROR($C$1-1+_xlfn.RANK.EQ(B7,$B$4:$B$31)+COUNTIF(B$4:$B7,B7)-1,"") -> 17 | D7: =IFERROR(VLOOKUP(C7,Anger!A:B,2,0),"") -> 6.1 | E7: =IFERROR(VLOOKUP(D7&"Viet",Anger!C:D,2,0),"") -> Anh ta biết là tôi rất ghét bị cho leo cây. | F7: =IFERROR(VLOOKUP(D7&"Eng",Anger!C:D,2,0),"") -> He knows how much I hate being stood up.
A8: =IFERROR(IF(A7+1>$C$2,"",A7+1),"") -> 21 | B8: =IF(A8="","",RANDBETWEEN($C$1,$C$2)) -> 22 | C8: =IFERROR($C$1-1+_xlfn.RANK.EQ(B8,$B$4:$B$31)+COUNTIF(B$4:$B8,B8)-1,"") -> 26 | D8: =IFERROR(VLOOKUP(C8,Anger!A:B,2,0),"") -> 9.1 | E8: =IFERROR(VLOOKUP(D8&"Viet",Anger!C:D,2,0),"") -> Tôi không hiểu làm sao mà cô ấy lại có thể vô trách nhiệm đến như vậy. | F8: =IFERROR(VLOOKUP(D8&"Eng",Anger!C:D,2,0),"") -> I don’t understand how she can be so irresponsible.
A9: =IFERROR(IF(A8+1>$C$2,"",A8+1),"") -> 22 | B9: =IF(A9="","",RANDBETWEEN($C$1,$C$2)) -> 24 | C9: =IFERROR($C$1-1+_xlfn.RANK.EQ(B9,$B$4:$B$31)+COUNTIF(B$4:$B9,B9)-1,"") -> 23 | D9: =IFERROR(VLOOKUP(C9,Anger!A:B,2,0),"") -> 8.1 | E9: =IFERROR(VLOOKUP(D9&"Viet",Anger!C:D,2,0),"") -> Có lẽ tôi sẽ không chấm dứt mối quan hệ bạn bè với anh ấy, nhưng tôi vẫn phải mắng cho anh ta một trận. | F9: =IFERROR(VLOOKUP(D9&"Eng",Anger!C:D,2,0),"") -> Maybe I won’t stop being friend with him, but I’m still going to tell him off.
A10: =IFERROR(IF(A9+1>$C$2,"",A9+1),"") -> 23 | B10: =IF(A10="","",RANDBETWEEN($C$1,$C$2)) -> 25 | C10: =IFERROR($C$1-1+_xlfn.RANK.EQ(B10,$B$4:$B$31)+COUNTIF(B$4:$B10,B10)-1,"") -> 22 | D10: =IFERROR(VLOOKUP(C10,Anger!A:B,2,0),"") -> 7.3 | E10: =IFERROR(VLOOKUP(D10&"Viet",Anger!C:D,2,0),"") -> Tôi đã quá giận nên không kịp suy nghĩ hợp lý. | F10: =IFERROR(VLOOKUP(D10&"Eng",Anger!C:D,2,0),"") -> I was simply too mad to think sensibly.
A11: =IFERROR(IF(A10+1>$C$2,"",A10+1),"") -> 24 | B11: =IF(A11="","",RANDBETWEEN($C$1,$C$2)) -> 24 | C11: =IFERROR($C$1-1+_xlfn.RANK.EQ(B11,$B$4:$B$31)+COUNTIF(B$4:$B11,B11)-1,"") -> 24 | D11: =IFERROR(VLOOKUP(C11,Anger!A:B,2,0),"") -> 8.2 | E11: =IFERROR(VLOOKUP(D11&"Viet",Anger!C:D,2,0),"") -> Có lẽ tôi sẽ không chấm dứt mối quan hệ bạn bè với cô ấy, nhưng tôi vẫn phải nói cho cổ biết suy nghĩ của tôi về cổ. | F11: =IFERROR(VLOOKUP(D11&"Eng",Anger!C:D,2,0),"") -> Maybe I won’t stop being friend with her, but I’m still going to tell her what I think about her. | H11: l
A12: =IFERROR(IF(A11+1>$C$2,"",A11+1),"") -> 25 | B12: =IF(A12="","",RANDBETWEEN($C$1,$C$2)) -> 22 | C12: =IFERROR($C$1-1+_xlfn.RANK.EQ(B12,$B$4:$B$31)+COUNTIF(B$4:$B12,B12)-1,"") -> 27 | D12: =IFERROR(VLOOKUP(C12,Anger!A:B,2,0),"") -> 9.2 | E12: =IFERROR(VLOOKUP(D12&"Viet",Anger!C:D,2,0),"") -> Tôi không hiểu làm sao mà anh ấy lại có thể bất cẩn đến như vậy. | F12: =IFERROR(VLOOKUP(D12&"Eng",Anger!C:D,2,0),"") -> I don’t understand how he can be so careless.
A13: =IFERROR(IF(A12+1>$C$2,"",A12+1),"") -> 26 | B13: =IF(A13="","",RANDBETWEEN($C$1,$C$2)) -> 27 | C13: =IFERROR($C$1-1+_xlfn.RANK.EQ(B13,$B$4:$B$31)+COUNTIF(B$4:$B13,B13)-1,"") -> 18 | D13: =IFERROR(VLOOKUP(C13,Anger!A:B,2,0),"") -> 6.2 | E13: =IFERROR(VLOOKUP(D13&"Viet",Anger!C:D,2,0),"") -> Bạn biết là tôi rất ghét bị chờ lâu. | F13: =IFERROR(VLOOKUP(D13&"Eng",Anger!C:D,2,0),"") -> You know how much I hate being kept waiting.
A14: =IFERROR(IF(A13+1>$C$2,"",A13+1),"") -> 27 | B14: =IF(A14="","",RANDBETWEEN($C$1,$C$2)) -> 26 | C14: =IFERROR($C$1-1+_xlfn.RANK.EQ(B14,$B$4:$B$31)+COUNTIF(B$4:$B14,B14)-1,"") -> 21 | D14: =IFERROR(VLOOKUP(C14,Anger!A:B,2,0),"") -> 7.2 | E14: =IFERROR(VLOOKUP(D14&"Viet",Anger!C:D,2,0),"") -> Tôi đã quá giận nên không kịp suy nghĩ rõ ràng. | F14: =IFERROR(VLOOKUP(D14&"Eng",Anger!C:D,2,0),"") -> I was simply too mad to think clearly. | L14: k
A15: =IFERROR(IF(A14+1>$C$2,"",A14+1),"") -> 28 | B15: =IF(A15="","",RANDBETWEEN($C$1,$C$2)) -> 27 | C15: =IFERROR($C$1-1+_xlfn.RANK.EQ(B15,$B$4:$B$31)+COUNTIF(B$4:$B15,B15)-1,"") -> 19 | D15: =IFERROR(VLOOKUP(C15,Anger!A:B,2,0),"") -> 6.3 | E15: =IFERROR(VLOOKUP(D15&"Viet",Anger!C:D,2,0),"") -> Tôi biết là anh rất ghét bị phí thời giờ. | F15: =IFERROR(VLOOKUP(D15&"Eng",Anger!C:D,2,0),"") -> I know how much you hate having your time wasted.
A16: =IFERROR(IF(A15+1>$C$2,"",A15+1),"") | B16: =IF(A16="","",RANDBETWEEN($C$1,$C$2)) | C16: =IFERROR($C$1-1+_xlfn.RANK.EQ(B16,$B$4:$B$31)+COUNTIF(B$4:$B16,B16)-1,"") | D16: =IFERROR(VLOOKUP(C16,Anger!A:B,2,0),"") | E16: =IFERROR(VLOOKUP(D16&"Viet",Anger!C:D,2,0),"") | F16: =IFERROR(VLOOKUP(D16&"Eng",Anger!C:D,2,0),"")
A17: =IFERROR(IF(A16+1>$C$2,"",A16+1),"") | B17: =IF(A17="","",RANDBETWEEN($C$1,$C$2)) | C17: =IFERROR($C$1-1+_xlfn.RANK.EQ(B17,$B$4:$B$31)+COUNTIF(B$4:$B17,B17)-1,"") | D17: =IFERROR(VLOOKUP(C17,Anger!A:B,2,0),"") | E17: =IFERROR(VLOOKUP(D17&"Viet",Anger!C:D,2,0),"") | F17: =IFERROR(VLOOKUP(D17&"Eng",Anger!C:D,2,0),"") | I17: k
A18: =IFERROR(IF(A17+1>$C$2,"",A17+1),"") | B18: =IF(A18="","",RANDBETWEEN($C$1,$C$2)) | C18: =IFERROR($C$1-1+_xlfn.RANK.EQ(B18,$B$4:$B$31)+COUNTIF(B$4:$B18,B18)-1,"") | D18: =IFERROR(VLOOKUP(C18,Anger!A:B,2,0),"") | E18: =IFERROR(VLOOKUP(D18&"Viet",Anger!C:D,2,0),"") | F18: =IFERROR(VLOOKUP(D18&"Eng",Anger!C:D,2,0),"") | I18: ;l | L18: j
A19: =IFERROR(IF(A18+1>$C$2,"",A18+1),"") | B19: =IF(A19="","",RANDBETWEEN($C$1,$C$2)) | C19: =IFERROR($C$1-1+_xlfn.RANK.EQ(B19,$B$4:$B$31)+COUNTIF(B$4:$B19,B19)-1,"") | D19: =IFERROR(VLOOKUP(C19,Anger!A:B,2,0),"") | E19: =IFERROR(VLOOKUP(D19&"Viet",Anger!C:D,2,0),"") | F19: =IFERROR(VLOOKUP(D19&"Eng",Anger!C:D,2,0),"")
A20: =IFERROR(IF(A19+1>$C$2,"",A19+1),"") | B20: =IF(A20="","",RANDBETWEEN($C$1,$C$2)) | C20: =IFERROR($C$1-1+_xlfn.RANK.EQ(B20,$B$4:$B$31)+COUNTIF(B$4:$B20,B20)-1,"") | D20: =IFERROR(VLOOKUP(C20,Anger!A:B,2,0),"") | E20: =IFERROR(VLOOKUP(D20&"Viet",Anger!C:D,2,0),"") | F20: =IFERROR(VLOOKUP(D20&"Eng",Anger!C:D,2,0),"")
A21: =IFERROR(IF(A20+1>$C$2,"",A20+1),"") | B21: =IF(A21="","",RANDBETWEEN($C$1,$C$2)) | C21: =IFERROR($C$1-1+_xlfn.RANK.EQ(B21,$B$4:$B$31)+COUNTIF(B$4:$B21,B21)-1,"") | D21: =IFERROR(VLOOKUP(C21,Anger!A:B,2,0),"") | E21: =IFERROR(VLOOKUP(D21&"Viet",Anger!C:D,2,0),"") | F21: =IFERROR(VLOOKUP(D21&"Eng",Anger!C:D,2,0),"") | M21: j
A22: =IFERROR(IF(A21+1>$C$2,"",A21+1),"") | B22: =IF(A22="","",RANDBETWEEN($C$1,$C$2)) | C22: =IFERROR($C$1-1+_xlfn.RANK.EQ(B22,$B$4:$B$31)+COUNTIF(B$4:$B22,B22)-1,"") | D22: =IFERROR(VLOOKUP(C22,Anger!A:B,2,0),"") | E22: =IFERROR(VLOOKUP(D22&"Viet",Anger!C:D,2,0),"") | F22: =IFERROR(VLOOKUP(D22&"Eng",Anger!C:D,2,0),"")
A23: =IFERROR(IF(A22+1>$C$2,"",A22+1),"") | B23: =IF(A23="","",RANDBETWEEN($C$1,$C$2)) | C23: =IFERROR($C$1-1+_xlfn.RANK.EQ(B23,$B$4:$B$31)+COUNTIF(B$4:$B23,B23)-1,"") | D23: =IFERROR(VLOOKUP(C23,Anger!A:B,2,0),"") | E23: =IFERROR(VLOOKUP(D23&"Viet",Anger!C:D,2,0),"") | F23: =IFERROR(VLOOKUP(D23&"Eng",Anger!C:D,2,0),"")
A24: =IFERROR(IF(A23+1>$C$2,"",A23+1),"") | B24: =IF(A24="","",RANDBETWEEN($C$1,$C$2)) | C24: =IFERROR($C$1-1+_xlfn.RANK.EQ(B24,$B$4:$B$31)+COUNTIF(B$4:$B24,B24)-1,"") | D24: =IFERROR(VLOOKUP(C24,Anger!A:B,2,0),"") | E24: =IFERROR(VLOOKUP(D24&"Viet",Anger!C:D,2,0),"") | F24: =IFERROR(VLOOKUP(D24&"Eng",Anger!C:D,2,0),"")
A25: =IFERROR(IF(A24+1>$C$2,"",A24+1),"") | B25: =IF(A25="","",RANDBETWEEN($C$1,$C$2)) | C25: =IFERROR($C$1-1+_xlfn.RANK.EQ(B25,$B$4:$B$31)+COUNTIF(B$4:$B25,B25)-1,"") | D25: =IFERROR(VLOOKUP(C25,Anger!A:B,2,0),"") | E25: =IFERROR(VLOOKUP(D25&"Viet",Anger!C:D,2,0),"") | F25: =IFERROR(VLOOKUP(D25&"Eng",Anger!C:D,2,0),"")
A26: =IFERROR(IF(A25+1>$C$2,"",A25+1),"") | B26: =IF(A26="","",RANDBETWEEN($C$1,$C$2)) | C26: =IFERROR($C$1-1+_xlfn.RANK.EQ(B26,$B$4:$B$31)+COUNTIF(B$4:$B26,B26)-1,"") | D26: =IFERROR(VLOOKUP(C26,Anger!A:B,2,0),"") | E26: =IFERROR(VLOOKUP(D26&"Viet",Anger!C:D,2,0),"") | F26: =IFERROR(VLOOKUP(D26&"Eng",Anger!C:D,2,0),"")
A27: =IFERROR(IF(A26+1>$C$2,"",A26+1),"") | B27: =IF(A27="","",RANDBETWEEN($C$1,$C$2)) | C27: =IFERROR($C$1-1+_xlfn.RANK.EQ(B27,$B$4:$B$31)+COUNTIF(B$4:$B27,B27)-1,"") | D27: =IFERROR(VLOOKUP(C27,Anger!A:B,2,0),"") | E27: =IFERROR(VLOOKUP(D27&"Viet",Anger!C:D,2,0),"") | F27: =IFERROR(VLOOKUP(D27&"Eng",Anger!C:D,2,0),"")
A28: =IFERROR(IF(A27+1>$C$2,"",A27+1),"") | B28: =IF(A28="","",RANDBETWEEN($C$1,$C$2)) | C28: =IFERROR($C$1-1+_xlfn.RANK.EQ(B28,$B$4:$B$31)+COUNTIF(B$4:$B28,B28)-1,"") | D28: =IFERROR(VLOOKUP(C28,Anger!A:B,2,0),"") | E28: =IFERROR(VLOOKUP(D28&"Viet",Anger!C:D,2,0),"") | F28: =IFERROR(VLOOKUP(D28&"Eng",Anger!C:D,2,0),"")
A29: =IFERROR(IF(A28+1>$C$2,"",A28+1),"") | B29: =IF(A29="","",RANDBETWEEN($C$1,$C$2)) | C29: =IFERROR($C$1-1+_xlfn.RANK.EQ(B29,$B$4:$B$31)+COUNTIF(B$4:$B29,B29)-1,"") | D29: =IFERROR(VLOOKUP(C29,Anger!A:B,2,0),"") | E29: =IFERROR(VLOOKUP(D29&"Viet",Anger!C:D,2,0),"") | F29: =IFERROR(VLOOKUP(D29&"Eng",Anger!C:D,2,0),"")
A30: =IFERROR(IF(A29+1>$C$2,"",A29+1),"") | B30: =IF(A30="","",RANDBETWEEN($C$1,$C$2)) | C30: =IFERROR($C$1-1+_xlfn.RANK.EQ(B30,$B$4:$B$31)+COUNTIF(B$4:$B30,B30)-1,"") | D30: =IFERROR(VLOOKUP(C30,Anger!A:B,2,0),"") | E30: =IFERROR(VLOOKUP(D30&"Viet",Anger!C:D,2,0),"") | F30: =IFERROR(VLOOKUP(D30&"Eng",Anger!C:D,2,0),"")
A31: =IFERROR(IF(A30+1>$C$2,"",A30+1),"") | B31: =IF(A31="","",RANDBETWEEN($C$1,$C$2)) | C31: =IFERROR($C$1-1+_xlfn.RANK.EQ(B31,$B$4:$B$31)+COUNTIF(B$4:$B31,B31)-1,"") | D31: =IFERROR(VLOOKUP(C31,Anger!A:B,2,0),"") | E31: =IFERROR(VLOOKUP(D31&"Viet",Anger!C:D,2,0),"") | F31: =IFERROR(VLOOKUP(D31&"Eng",Anger!C:D,2,0),"")
A32: =IFERROR(IF(A31+1>$C$2,"",A31+1),"") | B32: =IF(A32="","",RANDBETWEEN($C$1,$C$2)) | C32: =IFERROR($C$1-1+_xlfn.RANK.EQ(B32,$B$4:$B$101)+COUNTIF(B$4:$B32,B32)-1,"") | D32: =IFERROR(VLOOKUP(C32,Anger!A:B,2,0),"") | E32: =IFERROR(VLOOKUP(D32&"Viet",Anger!C:D,2,0),"") | F32: =IFERROR(VLOOKUP(D32&"Eng",Anger!C:D,2,0),"")
A33: =IFERROR(IF(A32+1>$C$2,"",A32+1),"") | B33: =IF(A33="","",RANDBETWEEN($C$1,$C$2)) | C33: =IFERROR($C$1-1+_xlfn.RANK.EQ(B33,$B$4:$B$101)+COUNTIF(B$4:$B33,B33)-1,"") | D33: =IFERROR(VLOOKUP(C33,Anger!A:B,2,0),"") | E33: =IFERROR(VLOOKUP(D33&"Viet",Anger!C:D,2,0),"") | F33: =IFERROR(VLOOKUP(D33&"Eng",Anger!C:D,2,0),"")
A34: =IFERROR(IF(A33+1>$C$2,"",A33+1),"") | B34: =IF(A34="","",RANDBETWEEN($C$1,$C$2)) | C34: =IFERROR($C$1-1+_xlfn.RANK.EQ(B34,$B$4:$B$101)+COUNTIF(B$4:$B34,B34)-1,"") | D34: =IFERROR(VLOOKUP(C34,Anger!A:B,2,0),"") | E34: =IFERROR(VLOOKUP(D34&"Viet",Anger!C:D,2,0),"") | F34: =IFERROR(VLOOKUP(D34&"Eng",Anger!C:D,2,0),"")
A35: =IFERROR(IF(A34+1>$C$2,"",A34+1),"") | B35: =IF(A35="","",RANDBETWEEN($C$1,$C$2)) | C35: =IFERROR($C$1-1+_xlfn.RANK.EQ(B35,$B$4:$B$101)+COUNTIF(B$4:$B35,B35)-1,"") | D35: =IFERROR(VLOOKUP(C35,Anger!A:B,2,0),"") | E35: =IFERROR(VLOOKUP(D35&"Viet",Anger!C:D,2,0),"") | F35: =IFERROR(VLOOKUP(D35&"Eng",Anger!C:D,2,0),"")
A36: =IFERROR(IF(A35+1>$C$2,"",A35+1),"") | B36: =IF(A36="","",RANDBETWEEN($C$1,$C$2)) | C36: =IFERROR($C$1-1+_xlfn.RANK.EQ(B36,$B$4:$B$101)+COUNTIF(B$4:$B36,B36)-1,"") | D36: =IFERROR(VLOOKUP(C36,Anger!A:B,2,0),"") | E36: =IFERROR(VLOOKUP(D36&"Viet",Anger!C:D,2,0),"") | F36: =IFERROR(VLOOKUP(D36&"Eng",Anger!C:D,2,0),"")
A37: =IFERROR(IF(A36+1>$C$2,"",A36+1),"") | B37: =IF(A37="","",RANDBETWEEN($C$1,$C$2)) | C37: =IFERROR($C$1-1+_xlfn.RANK.EQ(B37,$B$4:$B$101)+COUNTIF(B$4:$B37,B37)-1,"") | D37: =IFERROR(VLOOKUP(C37,Anger!A:B,2,0),"") | E37: =IFERROR(VLOOKUP(D37&"Viet",Anger!C:D,2,0),"") | F37: =IFERROR(VLOOKUP(D37&"Eng",Anger!C:D,2,0),"")
A38: =IFERROR(IF(A37+1>$C$2,"",A37+1),"") | B38: =IF(A38="","",RANDBETWEEN($C$1,$C$2)) | C38: =IFERROR($C$1-1+_xlfn.RANK.EQ(B38,$B$4:$B$101)+COUNTIF(B$4:$B38,B38)-1,"") | D38: =IFERROR(VLOOKUP(C38,Anger!A:B,2,0),"") | E38: =IFERROR(VLOOKUP(D38&"Viet",Anger!C:D,2,0),"") | F38: =IFERROR(VLOOKUP(D38&"Eng",Anger!C:D,2,0),"")
A39: =IFERROR(IF(A38+1>$C$2,"",A38+1),"") | B39: =IF(A39="","",RANDBETWEEN($C$1,$C$2)) | C39: =IFERROR($C$1-1+_xlfn.RANK.EQ(B39,$B$4:$B$101)+COUNTIF(B$4:$B39,B39)-1,"") | D39: =IFERROR(VLOOKUP(C39,Anger!A:B,2,0),"") | E39: =IFERROR(VLOOKUP(D39&"Viet",Anger!C:D,2,0),"") | F39: =IFERROR(VLOOKUP(D39&"Eng",Anger!C:D,2,0),"")
A40: =IFERROR(IF(A39+1>$C$2,"",A39+1),"") | B40: =IF(A40="","",RANDBETWEEN($C$1,$C$2)) | C40: =IFERROR($C$1-1+_xlfn.RANK.EQ(B40,$B$4:$B$101)+COUNTIF(B$4:$B40,B40)-1,"") | D40: =IFERROR(VLOOKUP(C40,Anger!A:B,2,0),"") | E40: =IFERROR(VLOOKUP(D40&"Viet",Anger!C:D,2,0),"") | F40: =IFERROR(VLOOKUP(D40&"Eng",Anger!C:D,2,0),"")
...

Sheet Sheet1
