Workbook

Sheet At Home
B2: TOPIC: AT HOME
A3: No | B3: No | C3: ID | D3: Sentence | E3: Type | F3: Link | G3: ID | H3: Copy Google drive to …
B4: 1 | C4: =B4&E4 -> 1Struc | D4: S + SHOULD GET IN THE HABIT OF... /Ai đó nên tập thói quen.../ | E4: Struc | F4: =IF(G4="","","https://docs.google.com/uc?export=download&id="&G4)
B5: 1.1 | C5: =B5&E5 -> 1.1Viet | D5: Chúng ta nên tập thói quen đi ngủ sớm. | E5: Viet | F5: =IF(G5="","","https://docs.google.com/uc?export=download&id="&G5) | G5: =IFERROR(LEFT(RIGHT(H5,LEN(H5)-32),LEN(RIGHT(H5,LEN(H5)-32))-17),"")
A6: 1 | B6: 1.1 | C6: =B6&E6 -> 1.1Eng | D6: We should get in the habit of going to bed early. | E6: Eng | F6: =IF(G6="","","https://docs.google.com/uc?export=download&id="&G6) -> https://docs.google.com/uc?export=download&id=1EUEwBv_Azfhs7iLZkzMl4yHtAOMLZyVX | G6: =IFERROR(LEFT(RIGHT(H6,LEN(H6)-32),LEN(RIGHT(H6,LEN(H6)-32))-17),"") -> 1EUEwBv_Azfhs7iLZkzMl4yHtAOMLZyVX | H6: https://drive.google.com/file/d/1EUEwBv_Azfhs7iLZkzMl4yHtAOMLZyVX/view?usp=sharing
B7: 1.1 | C7: =B7&E7 -> 1.1Phon | D7: wi: ʃʊd gɛt ɪn ðə ˈhæbɪt ʌv ˈgoʊɪŋ tu: bɛd ˈɜ:rli | E7: Phon | F7: =IF(G7="","","https://docs.google.com/uc?export=download&id="&G7) | G7: =IFERROR(LEFT(RIGHT(H7,LEN(H7)-32),LEN(RIGHT(H7,LEN(H7)-32))-17),"")
B8: 1.2 | C8: =B8&E8 -> 1.2Viet | D8: Bạn nên tập thói quen ăn ít đường lại. | E8: Viet | F8: =IF(G8="","","https://docs.google.com/uc?export=download&id="&G8) | G8: =IFERROR(LEFT(RIGHT(H8,LEN(H8)-32),LEN(RIGHT(H8,LEN(H8)-32))-17),"")
A9: 2 | B9: 1.2 | C9: =B9&E9 -> 1.2Eng | D9: You should get in the habit of eating less sugar. | E9: Eng | F9: =IF(G9="","","https://docs.google.com/uc?export=download&id="&G9) -> https://docs.google.com/uc?export=download&id=1MlqjNq8kQ94dYJweu5oPBrFx0I93Yyeo | G9: =IFERROR(LEFT(RIGHT(H9,LEN(H9)-32),LEN(RIGHT(H9,LEN(H9)-32))-17),"") -> 1MlqjNq8kQ94dYJweu5oPBrFx0I93Yyeo | H9: https://drive.google.com/file/d/1MlqjNq8kQ94dYJweu5oPBrFx0I93Yyeo/view?usp=sharing
B10: 1.2 | C10: =B10&E10 -> 1.2Phon | D10: ju: ʃʊd gɛt ɪn ðə ˈhæbɪt ʌv ˈi:tɪŋ lɛs ˈʃʊgər | E10: Phon | F10: =IF(G10="","","https://docs.google.com/uc?export=download&id="&G10) | G10: =IFERROR(LEFT(RIGHT(H10,LEN(H10)-32),LEN(RIGHT(H10,LEN(H10)-32))-17),"")
B11: 1.3 | C11: =B11&E11 -> 1.3Viet | D11: Bạn nên tập thói quen ăn nhiều rau hơn. | E11: Viet | F11: =IF(G11="","","https://docs.google.com/uc?export=download&id="&G11) | G11: =IFERROR(LEFT(RIGHT(H11,LEN(H11)-32),LEN(RIGHT(H11,LEN(H11)-32))-17),"")
A12: 3 | B12: 1.3 | C12: =B12&E12 -> 1.3Eng | D12: You should get in the habit of eating more vegetables. | E12: Eng | F12: =IF(G12="","","https://docs.google.com/uc?export=download&id="&G12) -> https://docs.google.com/uc?export=download&id=1SeIJlTweNW1_IyLqcY34YuKkzysG0g4j | G12: =IFERROR(LEFT(RIGHT(H12,LEN(H12)-32),LEN(RIGHT(H12,LEN(H12)-32))-17),"") -> 1SeIJlTweNW1_IyLqcY34YuKkzysG0g4j | H12: https://drive.google.com/file/d/1SeIJlTweNW1_IyLqcY34YuKkzysG0g4j/view?usp=sharing
B13: 1.3 | C13: =B13&E13 -> 1.3Phon | D13: ju: ʃʊd gɛt ɪn ðə ˈhæbɪt ʌv ˈi:tɪŋ mɔ:r ˈvɛʤtəbəlz | E13: Phon | F13: =IF(G13="","","https://docs.google.com/uc?export=download&id="&G13) | G13: =IFERROR(LEFT(RIGHT(H13,LEN(H13)-32),LEN(RIGHT(H13,LEN(H13)-32))-17),"")
B14: 1.4 | C14: =B14&E14 -> 1.4Viet | D14: Bạn nên tập thói quen uống hai lít nước mỗi ngày. | E14: Viet | F14: =IF(G14="","","https://docs.google.com/uc?export=download&id="&G14) | G14: =IFERROR(LEFT(RIGHT(H14,LEN(H14)-32),LEN(RIGHT(H14,LEN(H14)-32))-17),"")
A15: 4 | B15: 1.4 | C15: =B15&E15 -> 1.4Eng | D15: You should get in the habit of drinking two liters of water a day. | E15: Eng | F15: =IF(G15="","","https://docs.google.com/uc?export=download&id="&G15) -> https://docs.google.com/uc?export=download&id=1cpT1V0nph64P_jIEXen2_Elf_6juUjLu | G15: =IFERROR(LEFT(RIGHT(H15,LEN(H15)-32),LEN(RIGHT(H15,LEN(H15)-32))-17),"") -> 1cpT1V0nph64P_jIEXen2_Elf_6juUjLu | H15: https://drive.google.com/file/d/1cpT1V0nph64P_jIEXen2_Elf_6juUjLu/view?usp=sharing
B16: 1.4 | C16: =B16&E16 -> 1.4Phon | D16: ju: ʃʊd gɛt ɪn ðə ˈhæbɪt ʌv ˈdrɪŋkɪŋ tu: ˈli:tərz ʌv ˈwa:tər ə deɪ | E16: Phon | F16: =IF(G16="","","https://docs.google.com/uc?export=download&id="&G16) | G16: =IFERROR(LEFT(RIGHT(H16,LEN(H16)-32),LEN(RIGHT(H16,LEN(H16)-32))-17),"")
B17: 1.5 | C17: =B17&E17 -> 1.5Viet | D17: Bạn nên tập thói quen đọc sách mỗi ngày. | E17: Viet | F17: =IF(G17="","","https://docs.google.com/uc?export=download&id="&G17) | G17: =IFERROR(LEFT(RIGHT(H17,LEN(H17)-32),LEN(RIGHT(H17,LEN(H17)-32))-17),"")
A18: 5 | B18: 1.5 | C18: =B18&E18 -> 1.5Eng | D18: You should get in the habit of reading book everyday. | E18: Eng | F18: =IF(G18="","","https://docs.google.com/uc?export=download&id="&G18) -> https://docs.google.com/uc?export=download&id=1kwClC1wSsTrVRfYVZv91B7GQmqUKo0n- | G18: =IFERROR(LEFT(RIGHT(H18,LEN(H18)-32),LEN(RIGHT(H18,LEN(H18)-32))-17),"") -> 1kwClC1wSsTrVRfYVZv91B7GQmqUKo0n- | H18: https://drive.google.com/file/d/1kwClC1wSsTrVRfYVZv91B7GQmqUKo0n-/view?usp=sharing
B19: 1.5 | C19: =B19&E19 -> 1.5Phon | D19: ju: ʃʊd gɛt ɪn ðə ˈhæbɪt ʌv ˈriːdɪŋ bʊk ˈevrideɪ | E19: Phon | F19: =IF(G19="","","https://docs.google.com/uc?export=download&id="&G19) | G19: =IFERROR(LEFT(RIGHT(H19,LEN(H19)-32),LEN(RIGHT(H19,LEN(H19)-32))-17),"")
B20: 2 | C20: =B20&E20 -> 2Struc | D20: YOU CAN... WHEN YOU... /Bạn có thể... khi bạn…/ | E20: Struc | F20: =IF(G20="","","https://docs.google.com/uc?export=download&id="&G20) | G20: =IFERROR(LEFT(RIGHT(H20,LEN(H20)-32),LEN(RIGHT(H20,LEN(H20)-32))-17),"")
B21: 2.1 | C21: =B21&E21 -> 2.1Viet | D21: Bạn có thể thấy tốt hơn khi bạn ngủ ngon giấc. | E21: Viet | F21: =IF(G21="","","https://docs.google.com/uc?export=download&id="&G21) | G21: =IFERROR(LEFT(RIGHT(H21,LEN(H21)-32),LEN(RIGHT(H21,LEN(H21)-32))-17),"")
A22: 6 | B22: 2.1 | C22: =B22&E22 -> 2.1Eng | D22: You can feel better when you sleep well. | E22: Eng | F22: =IF(G22="","","https://docs.google.com/uc?export=download&id="&G22) -> https://docs.google.com/uc?export=download&id=190CxmSvCqUXTiJB0vKpvTSxHOfd9-ugK | G22: =IFERROR(LEFT(RIGHT(H22,LEN(H22)-32),LEN(RIGHT(H22,LEN(H22)-32))-17),"") -> 190CxmSvCqUXTiJB0vKpvTSxHOfd9-ugK | H22: https://drive.google.com/file/d/190CxmSvCqUXTiJB0vKpvTSxHOfd9-ugK/view?usp=sharing
B23: 2.1 | C23: =B23&E23 -> 2.1Phon | D23: ju: kæn fi:l ˈbɛtər wɛn ju: sli:p wɛl | E23: Phon | F23: =IF(G23="","","https://docs.google.com/uc?export=download&id="&G23) | G23: =IFERROR(LEFT(RIGHT(H23,LEN(H23)-32),LEN(RIGHT(H23,LEN(H23)-32))-17),"")
B24: 2.2 | C24: =B24&E24 -> 2.2Viet | D24: Bạn có thể tập trung tốt hơn khi bạn ngủ đủ giấc. | E24: Viet | F24: =IF(G24="","","https://docs.google.com/uc?export=download&id="&G24) | G24: =IFERROR(LEFT(RIGHT(H24,LEN(H24)-32),LEN(RIGHT(H24,LEN(H24)-32))-17),"")
A25: 7 | B25: 2.2 | C25: =B25&E25 -> 2.2Eng | D25: You can focus better when you get enough sleep. | E25: Eng | F25: =IF(G25="","","https://docs.google.com/uc?export=download&id="&G25) -> https://docs.google.com/uc?export=download&id=1q_VEFhV42JL3iG1YDJz2lFtdk8gHcSM1 | G25: =IFERROR(LEFT(RIGHT(H25,LEN(H25)-32),LEN(RIGHT(H25,LEN(H25)-32))-17),"") -> 1q_VEFhV42JL3iG1YDJz2lFtdk8gHcSM1 | H25: https://drive.google.com/file/d/1q_VEFhV42JL3iG1YDJz2lFtdk8gHcSM1/view?usp=sharing
B26: 2.2 | C26: =B26&E26 -> 2.2Phon | D26: ju: kæn ˈfoʊkəs ˈbɛtər wɛn ju: gɛt ɪˈnʌf sli:p | E26: Phon | F26: =IF(G26="","","https://docs.google.com/uc?export=download&id="&G26) | G26: =IFERROR(LEFT(RIGHT(H26,LEN(H26)-32),LEN(RIGHT(H26,LEN(H26)-32))-17),"")
B27: 2.3 | C27: =B27&E27 -> 2.3Viet | D27: Da bạn sẽ đẹp hơn khi bạn ngủ 8 tiếng mỗi đêm. | E27: Viet | F27: =IF(G27="","","https://docs.google.com/uc?export=download&id="&G27) | G27: =IFERROR(LEFT(RIGHT(H27,LEN(H27)-32),LEN(RIGHT(H27,LEN(H27)-32))-17),"")
A28: 8 | B28: 2.3 | C28: =B28&E28 -> 2.3Eng | D28: Your skin looks better when you sleep eight hours a night. | E28: Eng | F28: =IF(G28="","","https://docs.google.com/uc?export=download&id="&G28) -> https://docs.google.com/uc?export=download&id=1M2C3kZJPCE9ds51Hc3PJD4T-S7qxjRZI | G28: =IFERROR(LEFT(RIGHT(H28,LEN(H28)-32),LEN(RIGHT(H28,LEN(H28)-32))-17),"") -> 1M2C3kZJPCE9ds51Hc3PJD4T-S7qxjRZI | H28: https://drive.google.com/file/d/1M2C3kZJPCE9ds51Hc3PJD4T-S7qxjRZI/view?usp=sharing
B29: 2.3 | C29: =B29&E29 -> 2.3Phon | D29: jʊr skɪn lʊks ˈbɛtər wɛn ju: sli:p eɪt ˈaʊərz ə naɪt | E29: Phon | F29: =IF(G29="","","https://docs.google.com/uc?export=download&id="&G29) | G29: =IFERROR(LEFT(RIGHT(H29,LEN(H29)-32),LEN(RIGHT(H29,LEN(H29)-32))-17),"")
B30: 2.4 | C30: =B30&E30 -> 2.4Viet | D30: Bạn có thể thấy khoẻ hơn khi bạn tập thể dục đều đặn. | E30: Viet | F30: =IF(G30="","","https://docs.google.com/uc?export=download&id="&G30) | G30: =IFERROR(LEFT(RIGHT(H30,LEN(H30)-32),LEN(RIGHT(H30,LEN(H30)-32))-17),"")
A31: 9 | B31: 2.4 | C31: =B31&E31 -> 2.4Eng | D31: You can feel better when you exercise regularly. | E31: Eng | F31: =IF(G31="","","https://docs.google.com/uc?export=download&id="&G31) -> https://docs.google.com/uc?export=download&id=1p15eoz1B0og3wMHeNX6siiPbbGv3-ep9 | G31: =IFERROR(LEFT(RIGHT(H31,LEN(H31)-32),LEN(RIGHT(H31,LEN(H31)-32))-17),"") -> 1p15eoz1B0og3wMHeNX6siiPbbGv3-ep9 | H31: https://drive.google.com/file/d/1p15eoz1B0og3wMHeNX6siiPbbGv3-ep9/view?usp=sharing
B32: 2.4 | C32: =B32&E32 -> 2.4Phon | D32: ju: kæn fi:l ˈbɛtər wɛn ju: ˈɛksərsaɪz ˈrɛgjələrli | E32: Phon | F32: =IF(G32="","","https://docs.google.com/uc?export=download&id="&G32) | G32: =IFERROR(LEFT(RIGHT(H32,LEN(H32)-32),LEN(RIGHT(H32,LEN(H32)-32))-17),"")
B33: 2.5 | C33: =B33&E33 -> 2.5Viet | D33: Công việc của bạn sẽ kém đi khi bạn không ngủ đủ giấc. | E33: Viet | F33: =IF(G33="","","https://docs.google.com/uc?export=download&id="&G33) | G33: =IFERROR(LEFT(RIGHT(H33,LEN(H33)-32),LEN(RIGHT(H33,LEN(H33)-32))-17),"")
A34: 10 | B34: 2.5 | C34: =B34&E34 -> 2.5Eng | D34: Your work can suffer when you don’t get enough sleep. | E34: Eng | F34: =IF(G34="","","https://docs.google.com/uc?export=download&id="&G34) -> https://docs.google.com/uc?export=download&id=16HD5I-PAnqXzU1yCAmvjIZY0TD8LMUPi | G34: =IFERROR(LEFT(RIGHT(H34,LEN(H34)-32),LEN(RIGHT(H34,LEN(H34)-32))-17),"") -> 16HD5I-PAnqXzU1yCAmvjIZY0TD8LMUPi | H34: https://drive.google.com/file/d/16HD5I-PAnqXzU1yCAmvjIZY0TD8LMUPi/view?usp=sharing
B35: 2.5 | C35: =B35&E35 -> 2.5Phon | D35: jʊr wɜ:rk kæn ˈsʌfər wɛn ju: doʊnt gɛt ɪˈnʌf sli:p | E35: Phon | F35: =IF(G35="","","https://docs.google.com/uc?export=download&id="&G35) | G35: =IFERROR(LEFT(RIGHT(H35,LEN(H35)-32),LEN(RIGHT(H35,LEN(H35)-32))-17),"")
B36: 3 | C36: =B36&E36 -> 3Struc | D36: ….NAG SOMEONE... /…cằn nhằn ai đó.../ | E36: Struc | F36: =IF(G36="","","https://docs.google.com/uc?export=download&id="&G36) | G36: =IFERROR(LEFT(RIGHT(H36,LEN(H36)-32),LEN(RIGHT(H36,LEN(H36)-32))-17),"")
B37: 3.1 | C37: =B37&E37 -> 3.1Viet | D37: Ba mẹ cứ cằn nhằn tôi miếc. | E37: Viet | F37: =IF(G37="","","https://docs.google.com/uc?export=download&id="&G37) | G37: =IFERROR(LEFT(RIGHT(H37,LEN(H37)-32),LEN(RIGHT(H37,LEN(H37)-32))-17),"")
A38: 11 | B38: 3.1 | C38: =B38&E38 -> 3.1Eng | D38: My parents nag me all the time. | E38: Eng | F38: =IF(G38="","","https://docs.google.com/uc?export=download&id="&G38) -> https://docs.google.com/uc?export=download&id=1OX5ZhzBSYvhsYQ453S2zeXUDeqdL6GXK | G38: =IFERROR(LEFT(RIGHT(H38,LEN(H38)-32),LEN(RIGHT(H38,LEN(H38)-32))-17),"") -> 1OX5ZhzBSYvhsYQ453S2zeXUDeqdL6GXK | H38: https://drive.google.com/file/d/1OX5ZhzBSYvhsYQ453S2zeXUDeqdL6GXK/view?usp=sharing
B39: 3.1 | C39: =B39&E39 -> 3.1Phon | D39: maɪ ˈpɛrənts næg mi: a:l ðə taɪm | E39: Phon | F39: =IF(G39="","","https://docs.google.com/uc?export=download&id="&G39) | G39: =IFERROR(LEFT(RIGHT(H39,LEN(H39)-32),LEN(RIGHT(H39,LEN(H39)-32))-17),"")
B40: 3.2 | C40: =B40&E40 -> 3.2Viet | D40: Anh chỉ mong em đừng cằn nhằn nữa. | E40: Viet | F40: =IF(G40="","","https://docs.google.com/uc?export=download&id="&G40) | G40: =IFERROR(LEFT(RIGHT(H40,LEN(H40)-32),LEN(RIGHT(H40,LEN(H40)-32))-17),"")
A41: 12 | B41: 3.2 | C41: =B41&E41 -> 3.2Eng | D41: I wish you’d stop nagging. | E41: Eng | F41: =IF(G41="","","https://docs.google.com/uc?export=download&id="&G41) -> https://docs.google.com/uc?export=download&id=1md-VahdksxLlOJsQCZZAwT8bZBs21_JB | G41: =IFERROR(LEFT(RIGHT(H41,LEN(H41)-32),LEN(RIGHT(H41,LEN(H41)-32))-17),"") -> 1md-VahdksxLlOJsQCZZAwT8bZBs21_JB | H41: https://drive.google.com/file/d/1md-VahdksxLlOJsQCZZAwT8bZBs21_JB/view?usp=sharing
...

Sheet Viet
B2: Sentence | C2: Link | D2: ID | E2: Copy Google drive to …
B3: 01-05 | C3: =IF(D3="","","https://docs.google.com/uc?export=download&id="&D3) -> https://docs.google.com/uc?export=download&id=1LKgh_q2mt_AZMy1WT6LYZlYzAit_8BdL | D3: =IFERROR(LEFT(RIGHT(E3,LEN(E3)-32),LEN(RIGHT(E3,LEN(E3)-32))-17),"") -> 1LKgh_q2mt_AZMy1WT6LYZlYzAit_8BdL | E3: https://drive.google.com/file/d/1LKgh_q2mt_AZMy1WT6LYZlYzAit_8BdL/view?usp=sharing
B4: 06-09 | C4: =IF(D4="","","https://docs.google.com/uc?export=download&id="&D4) -> https://docs.google.com/uc?export=download&id=1DSjExOEA3oqHmLgEnME5-urB9iOR9874 | D4: =IFERROR(LEFT(RIGHT(E4,LEN(E4)-32),LEN(RIGHT(E4,LEN(E4)-32))-17),"") -> 1DSjExOEA3oqHmLgEnME5-urB9iOR9874 | E4: https://drive.google.com/file/d/1DSjExOEA3oqHmLgEnME5-urB9iOR9874/view?usp=sharing
B5: 01-09 | C5: =IF(D5="","","https://docs.google.com/uc?export=download&id="&D5) -> https://docs.google.com/uc?export=download&id=1v-P7zZ-ycJFQSn_ZrN3BGTr1nQda6NeA | D5: =IFERROR(LEFT(RIGHT(E5,LEN(E5)-32),LEN(RIGHT(E5,LEN(E5)-32))-17),"") -> 1v-P7zZ-ycJFQSn_ZrN3BGTr1nQda6NeA | E5: https://drive.google.com/file/d/1v-P7zZ-ycJFQSn_ZrN3BGTr1nQda6NeA/view?usp=sharing
C6: =IF(D6="","","https://docs.google.com/uc?export=download&id="&D6) | D6: =IFERROR(LEFT(RIGHT(E6,LEN(E6)-32),LEN(RIGHT(E6,LEN(E6)-32))-17),"")
C7: =IF(D7="","","https://docs.google.com/uc?export=download&id="&D7) | D7: =IFERROR(LEFT(RIGHT(E7,LEN(E7)-32),LEN(RIGHT(E7,LEN(E7)-32))-17),"")

Sheet Sum
B2: Sentence | C2: Link | D2: ID | E2: Copy Google drive to …
B3: Woman | C3: =IF(D3="","","https://docs.google.com/uc?export=download&id="&D3) | D3: =IFERROR(LEFT(RIGHT(E3,LEN(E3)-32),LEN(RIGHT(E3,LEN(E3)-32))-17),"")
B4: Man | C4: =IF(D4="","","https://docs.google.com/uc?export=download&id="&D4) | D4: =IFERROR(LEFT(RIGHT(E4,LEN(E4)-32),LEN(RIGHT(E4,LEN(E4)-32))-17),"")

Sheet Ramdom
B1: From | C1: 23
B2: To | C2: 37
C3: No | D3: No | E3: Viet | F3: Eng
A4: =C1 -> 23 | B4: =IF(A4="","",RANDBETWEEN($C$1,$C$2)) -> 23 | C4: =IFERROR($C$1-1+_xlfn.RANK.EQ(B4,$B$4:$B$40)+COUNTIF(B$4:$B4,B4)-1,"") -> 37 | D4: =IFERROR(VLOOKUP(C4,'At Home'!A:B,2,0),"") -> 9.3 | E4: =IFERROR(VLOOKUP(D4&"Viet",'At Home'!C:D,2,0),"") -> Dường như anh có vẻ cáu giận, có chuyện gì hả? | F4: =IFERROR(VLOOKUP(D4&"Eng",'At Home'!C:D,2,0),"") -> You seem angry, has something happened?
A5: =IFERROR(IF(A4+1>$C$2,"",A4+1),"") -> 24 | B5: =IF(A5="","",RANDBETWEEN($C$1,$C$2)) -> 33 | C5: =IFERROR($C$1-1+_xlfn.RANK.EQ(B5,$B$4:$B$40)+COUNTIF(B$4:$B5,B5)-1,"") -> 27 | D5: =IFERROR(VLOOKUP(C5,'At Home'!A:B,2,0),"") -> 7.1 | E5: =IFERROR(VLOOKUP(D5&"Viet",'At Home'!C:D,2,0),"") -> Em có muốn thử ăn hàng rong không? | F5: =IFERROR(VLOOKUP(D5&"Eng",'At Home'!C:D,2,0),"") -> Do you feel like trying some vendor food?
A6: =IFERROR(IF(A5+1>$C$2,"",A5+1),"") -> 25 | B6: =IF(A6="","",RANDBETWEEN($C$1,$C$2)) -> 25 | C6: =IFERROR($C$1-1+_xlfn.RANK.EQ(B6,$B$4:$B$40)+COUNTIF(B$4:$B6,B6)-1,"") -> 33 | D6: =IFERROR(VLOOKUP(C6,'At Home'!A:B,2,0),"") -> 8.3 | E6: =IFERROR(VLOOKUP(D6&"Viet",'At Home'!C:D,2,0),"") -> Anh còn bụng cho bữa tối không? | F6: =IFERROR(VLOOKUP(D6&"Eng",'At Home'!C:D,2,0),"") -> Do you still have room for dinner?
A7: =IFERROR(IF(A6+1>$C$2,"",A6+1),"") -> 26 | B7: =IF(A7="","",RANDBETWEEN($C$1,$C$2)) -> 34 | C7: =IFERROR($C$1-1+_xlfn.RANK.EQ(B7,$B$4:$B$40)+COUNTIF(B$4:$B7,B7)-1,"") -> 26 | D7: =IFERROR(VLOOKUP(C7,'At Home'!A:B,2,0),"") -> 6.4 | E7: =IFERROR(VLOOKUP(D7&"Viet",'At Home'!C:D,2,0),"") -> Anh ấy không muốn đi ra ngoài vào tối nay. | F7: =IFERROR(VLOOKUP(D7&"Eng",'At Home'!C:D,2,0),"") -> He doesn’t feel like going out tonight.
A8: =IFERROR(IF(A7+1>$C$2,"",A7+1),"") -> 27 | B8: =IF(A8="","",RANDBETWEEN($C$1,$C$2)) -> 31 | C8: =IFERROR($C$1-1+_xlfn.RANK.EQ(B8,$B$4:$B$40)+COUNTIF(B$4:$B8,B8)-1,"") -> 28 | D8: =IFERROR(VLOOKUP(C8,'At Home'!A:B,2,0),"") -> 7.2 | E8: =IFERROR(VLOOKUP(D8&"Viet",'At Home'!C:D,2,0),"") -> Anh có muốn thử cái gì đó mới không? | F8: =IFERROR(VLOOKUP(D8&"Eng",'At Home'!C:D,2,0),"") -> Do you feel like trying something new?
A9: =IFERROR(IF(A8+1>$C$2,"",A8+1),"") -> 28 | B9: =IF(A9="","",RANDBETWEEN($C$1,$C$2)) -> 26 | C9: =IFERROR($C$1-1+_xlfn.RANK.EQ(B9,$B$4:$B$40)+COUNTIF(B$4:$B9,B9)-1,"") -> 31 | D9: =IFERROR(VLOOKUP(C9,'At Home'!A:B,2,0),"") -> 8.1 | E9: =IFERROR(VLOOKUP(D9&"Viet",'At Home'!C:D,2,0),"") -> Con vẫn còn bụng để ăn mấy miếng gà rút xương. | F9: =IFERROR(VLOOKUP(D9&"Eng",'At Home'!C:D,2,0),"") -> I still have room for chicken nuggets.
A10: =IFERROR(IF(A9+1>$C$2,"",A9+1),"") -> 29 | B10: =IF(A10="","",RANDBETWEEN($C$1,$C$2)) -> 27 | C10: =IFERROR($C$1-1+_xlfn.RANK.EQ(B10,$B$4:$B$40)+COUNTIF(B$4:$B10,B10)-1,"") -> 30 | D10: =IFERROR(VLOOKUP(C10,'At Home'!A:B,2,0),"") -> 7.4 | E10: =IFERROR(VLOOKUP(D10&"Viet",'At Home'!C:D,2,0),"") -> Em có muốn thử món khác không? | F10: =IFERROR(VLOOKUP(D10&"Eng",'At Home'!C:D,2,0),"") -> Do you feel like trying different dish?
A11: =IFERROR(IF(A10+1>$C$2,"",A10+1),"") -> 30 | B11: =IF(A11="","",RANDBETWEEN($C$1,$C$2)) -> 35 | C11: =IFERROR($C$1-1+_xlfn.RANK.EQ(B11,$B$4:$B$40)+COUNTIF(B$4:$B11,B11)-1,"") -> 25 | D11: =IFERROR(VLOOKUP(C11,'At Home'!A:B,2,0),"") -> 6.3 | E11: =IFERROR(VLOOKUP(D11&"Viet",'At Home'!C:D,2,0),"") -> Tối nay em không muốn ăn. | F11: =IFERROR(VLOOKUP(D11&"Eng",'At Home'!C:D,2,0),"") -> I don’t feel like eating tonight.
A12: =IFERROR(IF(A11+1>$C$2,"",A11+1),"") -> 31 | B12: =IF(A12="","",RANDBETWEEN($C$1,$C$2)) -> 37 | C12: =IFERROR($C$1-1+_xlfn.RANK.EQ(B12,$B$4:$B$40)+COUNTIF(B$4:$B12,B12)-1,"") -> 23 | D12: =IFERROR(VLOOKUP(C12,'At Home'!A:B,2,0),"") -> 6.1 | E12: =IFERROR(VLOOKUP(D12&"Viet",'At Home'!C:D,2,0),"") -> Tối nay em không muốn nấu ăn. | F12: =IFERROR(VLOOKUP(D12&"Eng",'At Home'!C:D,2,0),"") -> I don’t feel like cooking tonight.
A13: =IFERROR(IF(A12+1>$C$2,"",A12+1),"") -> 32 | B13: =IF(A13="","",RANDBETWEEN($C$1,$C$2)) -> 36 | C13: =IFERROR($C$1-1+_xlfn.RANK.EQ(B13,$B$4:$B$40)+COUNTIF(B$4:$B13,B13)-1,"") -> 24 | D13: =IFERROR(VLOOKUP(C13,'At Home'!A:B,2,0),"") -> 6.2 | E13: =IFERROR(VLOOKUP(D13&"Viet",'At Home'!C:D,2,0),"") -> Hôm nay em không muốn làm gì cả. | F13: =IFERROR(VLOOKUP(D13&"Eng",'At Home'!C:D,2,0),"") -> I don’t feel like doing anything today.
A14: =IFERROR(IF(A13+1>$C$2,"",A13+1),"") -> 33 | B14: =IF(A14="","",RANDBETWEEN($C$1,$C$2)) -> 26 | C14: =IFERROR($C$1-1+_xlfn.RANK.EQ(B14,$B$4:$B$40)+COUNTIF(B$4:$B14,B14)-1,"") -> 32 | D14: =IFERROR(VLOOKUP(C14,'At Home'!A:B,2,0),"") -> 8.2 | E14: =IFERROR(VLOOKUP(D14&"Viet",'At Home'!C:D,2,0),"") -> Em vẫn còn bụng cho bữa trưa. | F14: =IFERROR(VLOOKUP(D14&"Eng",'At Home'!C:D,2,0),"") -> I still have room for lunch.
A15: =IFERROR(IF(A14+1>$C$2,"",A14+1),"") -> 34 | B15: =IF(A15="","",RANDBETWEEN($C$1,$C$2)) -> 24 | C15: =IFERROR($C$1-1+_xlfn.RANK.EQ(B15,$B$4:$B$40)+COUNTIF(B$4:$B15,B15)-1,"") -> 34 | D15: =IFERROR(VLOOKUP(C15,'At Home'!A:B,2,0),"") -> 8.4 | E15: =IFERROR(VLOOKUP(D15&"Viet",'At Home'!C:D,2,0),"") -> Tôi no rồi, nhưng vẫn còn bụng cho khoai tây chiên. | F15: =IFERROR(VLOOKUP(D15&"Eng",'At Home'!C:D,2,0),"") -> I’m full but I still have room for chips. | K15: 4
A16: =IFERROR(IF(A15+1>$C$2,"",A15+1),"") -> 35 | B16: =IF(A16="","",RANDBETWEEN($C$1,$C$2)) -> 24 | C16: =IFERROR($C$1-1+_xlfn.RANK.EQ(B16,$B$4:$B$40)+COUNTIF(B$4:$B16,B16)-1,"") -> 35 | D16: =IFERROR(VLOOKUP(C16,'At Home'!A:B,2,0),"") -> 9.1 | E16: =IFERROR(VLOOKUP(D16&"Viet",'At Home'!C:D,2,0),"") -> Dường như anh có vẻ đau buồn, có chuyện gì sao? | F16: =IFERROR(VLOOKUP(D16&"Eng",'At Home'!C:D,2,0),"") -> You seem upset, has something happened?
A17: =IFERROR(IF(A16+1>$C$2,"",A16+1),"") -> 36 | B17: =IF(A17="","",RANDBETWEEN($C$1,$C$2)) -> 24 | C17: =IFERROR($C$1-1+_xlfn.RANK.EQ(B17,$B$4:$B$40)+COUNTIF(B$4:$B17,B17)-1,"") -> 36 | D17: =IFERROR(VLOOKUP(C17,'At Home'!A:B,2,0),"") -> 9.2 | E17: =IFERROR(VLOOKUP(D17&"Viet",'At Home'!C:D,2,0),"") -> Dường như anh lo lắng, có chuyện gì sao? | F17: =IFERROR(VLOOKUP(D17&"Eng",'At Home'!C:D,2,0),"") -> You seem agitated, has something happened? | L17: 4
A18: =IFERROR(IF(A17+1>$C$2,"",A17+1),"") -> 37 | B18: =IF(A18="","",RANDBETWEEN($C$1,$C$2)) -> 30 | C18: =IFERROR($C$1-1+_xlfn.RANK.EQ(B18,$B$4:$B$40)+COUNTIF(B$4:$B18,B18)-1,"") -> 29 | D18: =IFERROR(VLOOKUP(C18,'At Home'!A:B,2,0),"") -> 7.3 | E18: =IFERROR(VLOOKUP(D18&"Viet",'At Home'!C:D,2,0),"") -> Bạn có muốn thử màu khác không? | F18: =IFERROR(VLOOKUP(D18&"Eng",'At Home'!C:D,2,0),"") -> Do you feel like trying different color? | M18: k
A19: =IFERROR(IF(A18+1>$C$2,"",A18+1),"") | B19: =IF(A19="","",RANDBETWEEN($C$1,$C$2)) | C19: =IFERROR($C$1-1+_xlfn.RANK.EQ(B19,$B$4:$B$40)+COUNTIF(B$4:$B19,B19)-1,"") | D19: =IFERROR(VLOOKUP(C19,'At Home'!A:B,2,0),"") | E19: =IFERROR(VLOOKUP(D19&"Viet",'At Home'!C:D,2,0),"") | F19: =IFERROR(VLOOKUP(D19&"Eng",'At Home'!C:D,2,0),"") | L19: p
A20: =IFERROR(IF(A19+1>$C$2,"",A19+1),"") | B20: =IF(A20="","",RANDBETWEEN($C$1,$C$2)) | C20: =IFERROR($C$1-1+_xlfn.RANK.EQ(B20,$B$4:$B$40)+COUNTIF(B$4:$B20,B20)-1,"") | D20: =IFERROR(VLOOKUP(C20,'At Home'!A:B,2,0),"") | E20: =IFERROR(VLOOKUP(D20&"Viet",'At Home'!C:D,2,0),"") | F20: =IFERROR(VLOOKUP(D20&"Eng",'At Home'!C:D,2,0),"")
A21: =IFERROR(IF(A20+1>$C$2,"",A20+1),"") | B21: =IF(A21="","",RANDBETWEEN($C$1,$C$2)) | C21: =IFERROR($C$1-1+_xlfn.RANK.EQ(B21,$B$4:$B$40)+COUNTIF(B$4:$B21,B21)-1,"") | D21: =IFERROR(VLOOKUP(C21,'At Home'!A:B,2,0),"") | E21: =IFERROR(VLOOKUP(D21&"Viet",'At Home'!C:D,2,0),"") | F21: =IFERROR(VLOOKUP(D21&"Eng",'At Home'!C:D,2,0),"")
A22: =IFERROR(IF(A21+1>$C$2,"",A21+1),"") | B22: =IF(A22="","",RANDBETWEEN($C$1,$C$2)) | C22: =IFERROR($C$1-1+_xlfn.RANK.EQ(B22,$B$4:$B$40)+COUNTIF(B$4:$B22,B22)-1,"") | D22: =IFERROR(VLOOKUP(C22,'At Home'!A:B,2,0),"") | E22: =IFERROR(VLOOKUP(D22&"Viet",'At Home'!C:D,2,0),"") | F22: =IFERROR(VLOOKUP(D22&"Eng",'At Home'!C:D,2,0),"")
A23: =IFERROR(IF(A22+1>$C$2,"",A22+1),"") | B23: =IF(A23="","",RANDBETWEEN($C$1,$C$2)) | C23: =IFERROR($C$1-1+_xlfn.RANK.EQ(B23,$B$4:$B$40)+COUNTIF(B$4:$B23,B23)-1,"") | D23: =IFERROR(VLOOKUP(C23,'At Home'!A:B,2,0),"") | E23: =IFERROR(VLOOKUP(D23&"Viet",'At Home'!C:D,2,0),"") | F23: =IFERROR(VLOOKUP(D23&"Eng",'At Home'!C:D,2,0),"")
A24: =IFERROR(IF(A23+1>$C$2,"",A23+1),"") | B24: =IF(A24="","",RANDBETWEEN($C$1,$C$2)) | C24: =IFERROR($C$1-1+_xlfn.RANK.EQ(B24,$B$4:$B$40)+COUNTIF(B$4:$B24,B24)-1,"") | D24: =IFERROR(VLOOKUP(C24,'At Home'!A:B,2,0),"") | E24: =IFERROR(VLOOKUP(D24&"Viet",'At Home'!C:D,2,0),"") | F24: =IFERROR(VLOOKUP(D24&"Eng",'At Home'!C:D,2,0),"")
A25: =IFERROR(IF(A24+1>$C$2,"",A24+1),"") | B25: =IF(A25="","",RANDBETWEEN($C$1,$C$2)) | C25: =IFERROR($C$1-1+_xlfn.RANK.EQ(B25,$B$4:$B$40)+COUNTIF(B$4:$B25,B25)-1,"") | D25: =IFERROR(VLOOKUP(C25,'At Home'!A:B,2,0),"") | E25: =IFERROR(VLOOKUP(D25&"Viet",'At Home'!C:D,2,0),"") | F25: =IFERROR(VLOOKUP(D25&"Eng",'At Home'!C:D,2,0),"")
A26: =IFERROR(IF(A25+1>$C$2,"",A25+1),"") | B26: =IF(A26="","",RANDBETWEEN($C$1,$C$2)) | C26: =IFERROR($C$1-1+_xlfn.RANK.EQ(B26,$B$4:$B$40)+COUNTIF(B$4:$B26,B26)-1,"") | D26: =IFERROR(VLOOKUP(C26,'At Home'!A:B,2,0),"") | E26: =IFERROR(VLOOKUP(D26&"Viet",'At Home'!C:D,2,0),"") | F26: =IFERROR(VLOOKUP(D26&"Eng",'At Home'!C:D,2,0),"")
A27: =IFERROR(IF(A26+1>$C$2,"",A26+1),"") | B27: =IF(A27="","",RANDBETWEEN($C$1,$C$2)) | C27: =IFERROR($C$1-1+_xlfn.RANK.EQ(B27,$B$4:$B$40)+COUNTIF(B$4:$B27,B27)-1,"") | D27: =IFERROR(VLOOKUP(C27,'At Home'!A:B,2,0),"") | E27: =IFERROR(VLOOKUP(D27&"Viet",'At Home'!C:D,2,0),"") | F27: =IFERROR(VLOOKUP(D27&"Eng",'At Home'!C:D,2,0),"")
A28: =IFERROR(IF(A27+1>$C$2,"",A27+1),"") | B28: =IF(A28="","",RANDBETWEEN($C$1,$C$2)) | C28: =IFERROR($C$1-1+_xlfn.RANK.EQ(B28,$B$4:$B$40)+COUNTIF(B$4:$B28,B28)-1,"") | D28: =IFERROR(VLOOKUP(C28,'At Home'!A:B,2,0),"") | E28: =IFERROR(VLOOKUP(D28&"Viet",'At Home'!C:D,2,0),"") | F28: =IFERROR(VLOOKUP(D28&"Eng",'At Home'!C:D,2,0),"")
A29: =IFERROR(IF(A28+1>$C$2,"",A28+1),"") | B29: =IF(A29="","",RANDBETWEEN($C$1,$C$2)) | C29: =IFERROR($C$1-1+_xlfn.RANK.EQ(B29,$B$4:$B$40)+COUNTIF(B$4:$B29,B29)-1,"") | D29: =IFERROR(VLOOKUP(C29,'At Home'!A:B,2,0),"") | E29: =IFERROR(VLOOKUP(D29&"Viet",'At Home'!C:D,2,0),"") | F29: =IFERROR(VLOOKUP(D29&"Eng",'At Home'!C:D,2,0),"")
A30: =IFERROR(IF(A29+1>$C$2,"",A29+1),"") | B30: =IF(A30="","",RANDBETWEEN($C$1,$C$2)) | C30: =IFERROR($C$1-1+_xlfn.RANK.EQ(B30,$B$4:$B$40)+COUNTIF(B$4:$B30,B30)-1,"") | D30: =IFERROR(VLOOKUP(C30,'At Home'!A:B,2,0),"") | E30: =IFERROR(VLOOKUP(D30&"Viet",'At Home'!C:D,2,0),"") | F30: =IFERROR(VLOOKUP(D30&"Eng",'At Home'!C:D,2,0),"")
A31: =IFERROR(IF(A30+1>$C$2,"",A30+1),"") | B31: =IF(A31="","",RANDBETWEEN($C$1,$C$2)) | C31: =IFERROR($C$1-1+_xlfn.RANK.EQ(B31,$B$4:$B$40)+COUNTIF(B$4:$B31,B31)-1,"") | D31: =IFERROR(VLOOKUP(C31,'At Home'!A:B,2,0),"") | E31: =IFERROR(VLOOKUP(D31&"Viet",'At Home'!C:D,2,0),"") | F31: =IFERROR(VLOOKUP(D31&"Eng",'At Home'!C:D,2,0),"")
... A72: =IFERROR(IF(A71+1>$C$2,"",A71+1),"") | B72: =IF(A72="","",RANDBETWEEN($C$1,$C$2)) | C72: =IFERROR($C$1-1+_xlfn.RANK.EQ(B72,$B$4:$B$40)+COUNTIF(B$4:$B72,B72)-1,"") | D72: =IFERROR(VLOOKUP(C72,'At Home'!A:B,2,0),"") | E72: =IFERROR(VLOOKUP(D72&"Viet",'At Home'!C:D,2,0),"") | F72: =IFERROR(VLOOKUP(D72&"Eng",'At Home'!C:D,2,0),"")
A73: =IFERROR(IF(A72+1>$C$2,"",A72+1),"") | B73: =IF(A73="","",RANDBETWEEN($C$1,$C$2)) | C73: =IFERROR($C$1-1+_xlfn.RANK.EQ(B73,$B$4:$B$40)+COUNTIF(B$4:$B73,B73)-1,"") | D73: =IFERROR(VLOOKUP(C73,'At Home'!A:B,2,0),"")
A74: =IFERROR(IF(A73+1>$C$2,"",A73+1),"") | B74: =IF(A74="","",RANDBETWEEN($C$1,$C$2)) | C74: =IFERROR($C$1-1+_xlfn.RANK.EQ(B74,$B$4:$B$40)+COUNTIF(B$4:$B74,B74)-1,"") | D74: =IFERROR(VLOOKUP(C74,'At Home'!A:B,2,0),"")
A75: =IFERROR(IF(A74+1>$C$2,"",A74+1),"") | B75: =IF(A75="","",RANDBETWEEN($C$1,$C$2)) | C75: =IFERROR($C$1-1+_xlfn.RANK.EQ(B75,$B$4:$B$40)+COUNTIF(B$4:$B75,B75)-1,"") | D75: =IFERROR(VLOOKUP(C75,'At Home'!A:B,2,0),"")
A76: =IFERROR(IF(A75+1>$C$2,"",A75+1),"") | B76: =IF(A76="","",RANDBETWEEN($C$1,$C$2)) | C76: =IFERROR($C$1-1+_xlfn.RANK.EQ(B76,$B$4:$B$40)+COUNTIF(B$4:$B76,B76)-1,"") | D76: =IFERROR(VLOOKUP(C76,'At Home'!A:B,2,0),"")
A77: =IFERROR(IF(A76+1>$C$2,"",A76+1),"") | B77: =IF(A77="","",RANDBETWEEN($C$1,$C$2)) | C77: =IFERROR($C$1-1+_xlfn.RANK.EQ(B77,$B$4:$B$40)+COUNTIF(B$4:$B77,B77)-1,"") | D77: =IFERROR(VLOOKUP(C77,'At Home'!A:B,2,0),"")
A78: =IFERROR(IF(A77+1>$C$2,"",A77+1),"") | B78: =IF(A78="","",RANDBETWEEN($C$1,$C$2)) | C78: =IFERROR($C$1-1+_xlfn.RANK.EQ(B78,$B$4:$B$40)+COUNTIF(B$4:$B78,B78)-1,"") | D78: =IFERROR(VLOOKUP(C78,'At Home'!A:B,2,0),"")
A79: =IFERROR(IF(A78+1>$C$2,"",A78+1),"") | B79: =IF(A79="","",RANDBETWEEN($C$1,$C$2)) | C79: =IFERROR($C$1-1+_xlfn.RANK.EQ(B79,$B$4:$B$40)+COUNTIF(B$4:$B79,B79)-1,"") | D79: =IFERROR(VLOOKUP(C79,'At Home'!A:B,2,0),"")
A80: =IFERROR(IF(A79+1>$C$2,"",A79+1),"") | B80: =IF(A80="","",RANDBETWEEN($C$1,$C$2)) | C80: =IFERROR($C$1-1+_xlfn.RANK.EQ(B80,$B$4:$B$40)+COUNTIF(B$4:$B80,B80)-1,"") | D80: =IFERROR(VLOOKUP(C80,'At Home'!A:B,2,0),"")
...

Sheet Sheet1

Sheet Sheet2
