Workbook

Sheet Declarative sentences
B2: TOPIC: DECLARATIVE SENTENCES
A3: No | B3: No | C3: ID | D3: Sentence | E3: Type | F3: Link | G3: ID | H3: Copy Google drive to …
B4: 1 | C4: 1Struc | D4: I’M GOING TO... /Tôi sẽ... / | E4: Struc | F4: =IF(G4="","","https://docs.google.com/uc?export=download&id="&G4)
B5: 1.1 | C5: 1.1Viet | D5: Tôi sẽ đi tắm. | E5: Viet | F5: =IF(G5="","","https://docs.google.com/uc?export=download&id="&G5) | G5: =IFERROR(LEFT(RIGHT(H5,LEN(H5)-32),LEN(RIGHT(H5,LEN(H5)-32))-17),"")
A6: 1 | B6: 1.1 | C6: 1.1Anh | D6: I’m going to take a shower. | E6: Eng | F6: =IF(G6="","","https://docs.google.com/uc?export=download&id="&G6) | G6: =IFERROR(LEFT(RIGHT(H6,LEN(H6)-32),LEN(RIGHT(H6,LEN(H6)-32))-17),"")
B7: 1.1 | C7: 1.1Phon | D7: aɪm ˈgoʊɪŋ tu: teɪk ə ˈʃaʊər | E7: Phon | F7: =IF(G7="","","https://docs.google.com/uc?export=download&id="&G7) | G7: =IFERROR(LEFT(RIGHT(H7,LEN(H7)-32),LEN(RIGHT(H7,LEN(H7)-32))-17),"")
B8: 1.2 | C8: 1.2Viet | D8: Tôi sẽ chợp mắt một chút. | E8: Viet | F8: =IF(G8="","","https://docs.google.com/uc?export=download&id="&G8) | G8: =IFERROR(LEFT(RIGHT(H8,LEN(H8)-32),LEN(RIGHT(H8,LEN(H8)-32))-17),"")
A9: 2 | B9: 1.2 | C9: 1.2Anh | D9: I’m going to take a quick nap. | E9: Eng | F9: =IF(G9="","","https://docs.google.com/uc?export=download&id="&G9) | G9: =IFERROR(LEFT(RIGHT(H9,LEN(H9)-32),LEN(RIGHT(H9,LEN(H9)-32))-17),"")
B10: 1.2 | C10: 1.2Phon | D10: aɪm ˈgoʊɪŋ tu: teɪk ə kwɪk næp | E10: Phon | F10: =IF(G10="","","https://docs.google.com/uc?export=download&id="&G10) | G10: =IFERROR(LEFT(RIGHT(H10,LEN(H10)-32),LEN(RIGHT(H10,LEN(H10)-32))-17),"")
B11: 1.3 | C11: 1.3Viet | D11: Tôi sẽ đi tìm chứng cứ. | E11: Viet | F11: =IF(G11="","","https://docs.google.com/uc?export=download&id="&G11) | G11: =IFERROR(LEFT(RIGHT(H11,LEN(H11)-32),LEN(RIGHT(H11,LEN(H11)-32))-17),"")
A12: 3 | B12: 1.3 | C12: 1.3Anh | D12: I’m going to find some evidence. | E12: Eng | F12: =IF(G12="","","https://docs.google.com/uc?export=download&id="&G12) | G12: =IFERROR(LEFT(RIGHT(H12,LEN(H12)-32),LEN(RIGHT(H12,LEN(H12)-32))-17),"")
B13: 1.3 | C13: 1.3Phon | D13: aɪm ˈgoʊɪŋ tu: faɪnd sʌm ˈɛvədəns | E13: Phon | F13: =IF(G13="","","https://docs.google.com/uc?export=download&id="&G13) | G13: =IFERROR(LEFT(RIGHT(H13,LEN(H13)-32),LEN(RIGHT(H13,LEN(H13)-32))-17),"")
B14: 1.4 | C14: 1.4Viet | D14: Tôi sẽ không tranh cãi với cậu. | E14: Viet | F14: =IF(G14="","","https://docs.google.com/uc?export=download&id="&G14) | G14: =IFERROR(LEFT(RIGHT(H14,LEN(H14)-32),LEN(RIGHT(H14,LEN(H14)-32))-17),"")
A15: 4 | B15: 1.4 | C15: 1.4Anh | D15: I’m not going to argue with you. | E15: Eng | F15: =IF(G15="","","https://docs.google.com/uc?export=download&id="&G15) | G15: =IFERROR(LEFT(RIGHT(H15,LEN(H15)-32),LEN(RIGHT(H15,LEN(H15)-32))-17),"")
B16: 1.4 | C16: 1.4Phon | D16: aɪm na:t ˈgoʊɪŋ tu: ˈa:rgju: wɪð ju: | E16: Phon | F16: =IF(G16="","","https://docs.google.com/uc?export=download&id="&G16) | G16: =IFERROR(LEFT(RIGHT(H16,LEN(H16)-32),LEN(RIGHT(H16,LEN(H16)-32))-17),"")
B17: 1.5 | C17: 1.5Viet | D17: Tôi sẽ không tỏ ra lịch sự với anh ấy. | E17: Viet | F17: =IF(G17="","","https://docs.google.com/uc?export=download&id="&G17) | G17: =IFERROR(LEFT(RIGHT(H17,LEN(H17)-32),LEN(RIGHT(H17,LEN(H17)-32))-17),"")
A18: 5 | B18: 1.5 | C18: 1.5Anh | D18: I’m not going to be polite to him. | E18: Eng | F18: =IF(G18="","","https://docs.google.com/uc?export=download&id="&G18) | G18: =IFERROR(LEFT(RIGHT(H18,LEN(H18)-32),LEN(RIGHT(H18,LEN(H18)-32))-17),"")
B19: 1.5 | C19: 1.5Phon | D19: aɪm na:t ˈgoʊɪŋ tu: bi: pəˈlaɪt tu: hɪm | E19: Phon | F19: =IF(G19="","","https://docs.google.com/uc?export=download&id="&G19) | G19: =IFERROR(LEFT(RIGHT(H19,LEN(H19)-32),LEN(RIGHT(H19,LEN(H19)-32))-17),"")
B20: 1.6 | C20: 1.6Viet | D20: Tôi sẽ không phản bội cậu. | E20: Viet | F20: =IF(G20="","","https://docs.google.com/uc?export=download&id="&G20) | G20: =IFERROR(LEFT(RIGHT(H20,LEN(H20)-32),LEN(RIGHT(H20,LEN(H20)-32))-17),"")
A21: 6 | B21: 1.6 | C21: 1.6Anh | D21: I’m not going to betray you. | E21: Eng | F21: =IF(G21="","","https://docs.google.com/uc?export=download&id="&G21) | G21: =IFERROR(LEFT(RIGHT(H21,LEN(H21)-32),LEN(RIGHT(H21,LEN(H21)-32))-17),"")
B22: 1.6 | C22: 1.6Phon | D22: aɪm na:t ˈgoʊɪŋ tu: bɪˈtreɪ ju: | E22: Phon | F22: =IF(G22="","","https://docs.google.com/uc?export=download&id="&G22) | G22: =IFERROR(LEFT(RIGHT(H22,LEN(H22)-32),LEN(RIGHT(H22,LEN(H22)-32))-17),"")
B23: 1.7 | C23: 1.7Viet | D23: Cậu sẽ ổn khi không có cô ấy chứ? | E23: Viet | F23: =IF(G23="","","https://docs.google.com/uc?export=download&id="&G23) | G23: =IFERROR(LEFT(RIGHT(H23,LEN(H23)-32),LEN(RIGHT(H23,LEN(H23)-32))-17),"")
A24: 7 | B24: 1.7 | C24: 1.7Anh | D24: Are you going to be ok without her? | E24: Eng | F24: =IF(G24="","","https://docs.google.com/uc?export=download&id="&G24) | G24: =IFERROR(LEFT(RIGHT(H24,LEN(H24)-32),LEN(RIGHT(H24,LEN(H24)-32))-17),"")
B25: 1.7 | C25: 1.7Phon | D25: a:r ju: ˈgoʊɪŋ tu: bi: oʊˈkeɪ wɪˈðaʊt hɜ:r | E25: Phon | F25: =IF(G25="","","https://docs.google.com/uc?export=download&id="&G25) | G25: =IFERROR(LEFT(RIGHT(H25,LEN(H25)-32),LEN(RIGHT(H25,LEN(H25)-32))-17),"")
B26: 1.8 | C26: 1.8Viet | D26: Cậu có định đi chơi với cô ấy không? | E26: Viet | F26: =IF(G26="","","https://docs.google.com/uc?export=download&id="&G26) | G26: =IFERROR(LEFT(RIGHT(H26,LEN(H26)-32),LEN(RIGHT(H26,LEN(H26)-32))-17),"")
A27: 8 | B27: 1.8 | C27: 1.8Anh | D27: Are you going to go out with her? | E27: Eng | F27: =IF(G27="","","https://docs.google.com/uc?export=download&id="&G27) | G27: =IFERROR(LEFT(RIGHT(H27,LEN(H27)-32),LEN(RIGHT(H27,LEN(H27)-32))-17),"")
B28: 1.8 | C28: 1.8Phon | D28: a:r ju: ˈgoʊɪŋ tu: goʊ aʊt wɪð hɜ:r | E28: Phon | F28: =IF(G28="","","https://docs.google.com/uc?export=download&id="&G28) | G28: =IFERROR(LEFT(RIGHT(H28,LEN(H28)-32),LEN(RIGHT(H28,LEN(H28)-32))-17),"")
B29: 1.9 | C29: 1.9Viet | D29: Cậu có định lát nữa quay lại văn phòng không? | E29: Viet | F29: =IF(G29="","","https://docs.google.com/uc?export=download&id="&G29) | G29: =IFERROR(LEFT(RIGHT(H29,LEN(H29)-32),LEN(RIGHT(H29,LEN(H29)-32))-17),"")
A30: 9 | B30: 1.9 | C30: 1.9Anh | D30: Are you going to be back in the office later? | E30: Eng | F30: =IF(G30="","","https://docs.google.com/uc?export=download&id="&G30) | G30: =IFERROR(LEFT(RIGHT(H30,LEN(H30)-32),LEN(RIGHT(H30,LEN(H30)-32))-17),"")
B31: 1.9 | C31: 1.9Phon | D31: a:r ju: ˈgoʊɪŋ tu: bi: bæk ɪn ði: ˈa:fɪs ˈleɪtər | E31: Phon | F31: =IF(G31="","","https://docs.google.com/uc?export=download&id="&G31) | G31: =IFERROR(LEFT(RIGHT(H31,LEN(H31)-32),LEN(RIGHT(H31,LEN(H31)-32))-17),"")
B32: 2 | C32: 2Struc | D32: I WILL... /Tôi sẽ.../ | E32: Struc | F32: =IF(G32="","","https://docs.google.com/uc?export=download&id="&G32) | G32: =IFERROR(LEFT(RIGHT(H32,LEN(H32)-32),LEN(RIGHT(H32,LEN(H32)-32))-17),"")
B33: 2.1 | C33: 2.1Viet | D33: Tôi sẽ kể cho cậu chuyện này. | E33: Viet | F33: =IF(G33="","","https://docs.google.com/uc?export=download&id="&G33) | G33: =IFERROR(LEFT(RIGHT(H33,LEN(H33)-32),LEN(RIGHT(H33,LEN(H33)-32))-17),"")
A34: 10 | B34: 2.1 | C34: 2.1Anh | D34: I will tell you this. | E34: Eng | F34: =IF(G34="","","https://docs.google.com/uc?export=download&id="&G34) | G34: =IFERROR(LEFT(RIGHT(H34,LEN(H34)-32),LEN(RIGHT(H34,LEN(H34)-32))-17),"")
B35: 2.1 | C35: 2.1Phon | D35: aɪ wɪl tɛl ju: ðɪs | E35: Phon | F35: =IF(G35="","","https://docs.google.com/uc?export=download&id="&G35) | G35: =IFERROR(LEFT(RIGHT(H35,LEN(H35)-32),LEN(RIGHT(H35,LEN(H35)-32))-17),"")
B36: 2.2 | C36: 2.2Viet | D36: Tôi sẽ thay đổi kiểu tóc. | E36: Viet | F36: =IF(G36="","","https://docs.google.com/uc?export=download&id="&G36) | G36: =IFERROR(LEFT(RIGHT(H36,LEN(H36)-32),LEN(RIGHT(H36,LEN(H36)-32))-17),"")
A37: 11 | B37: 2.2 | C37: 2.2Anh | D37: I will change my hairstyle. | E37: Eng | F37: =IF(G37="","","https://docs.google.com/uc?export=download&id="&G37) | G37: =IFERROR(LEFT(RIGHT(H37,LEN(H37)-32),LEN(RIGHT(H37,LEN(H37)-32))-17),"")
B38: 2.2 | C38: 2.2Phon | D38: aɪ wɪl ʧeɪnʤ maɪ ˈhɛrstaɪl | E38: Phon | F38: =IF(G38="","","https://docs.google.com/uc?export=download&id="&G38) | G38: =IFERROR(LEFT(RIGHT(H38,LEN(H38)-32),LEN(RIGHT(H38,LEN(H38)-32))-17),"")
B39: 2.3 | C39: 2.3Viet | D39: Tôi sẽ giữ bí mật. | E39: Viet | F39: =IF(G39="","","https://docs.google.com/uc?export=download&id="&G39) | G39: =IFERROR(LEFT(RIGHT(H39,LEN(H39)-32),LEN(RIGHT(H39,LEN(H39)-32))-17),"")
A40: 12 | B40: 2.3 | C40: 2.3Anh | D40: I will keep it secret. | E40: Eng | F40: =IF(G40="","","https://docs.google.com/uc?export=download&id="&G40) | G40: =IFERROR(LEFT(RIGHT(H40,LEN(H40)-32),LEN(RIGHT(H40,LEN(H40)-32))-17),"")
B41: 2.3 | C41: 2.3Phon | D41: aɪ wɪl ki:p ɪt ˈsi:krət | E41: Phon | F41: =IF(G41="","","https://docs.google.com/uc?export=download&id="&G41) | G41: =IFERROR(LEFT(RIGHT(H41,LEN(H41)-32),LEN(RIGHT(H41,LEN(H41)-32))-17),"")
...

Sheet Viet
B2: Sentence | C2: Link | D2: ID | E2: Copy Google drive to …
B3: 01-05 | C3: =IF(D3="","","https://docs.google.com/uc?export=download&id="&D3) | D3: =IFERROR(LEFT(RIGHT(E3,LEN(E3)-32),LEN(RIGHT(E3,LEN(E3)-32))-17),"")
B4: 06-09 | C4: =IF(D4="","","https://docs.google.com/uc?export=download&id="&D4) | D4: =IFERROR(LEFT(RIGHT(E4,LEN(E4)-32),LEN(RIGHT(E4,LEN(E4)-32))-17),"")
C5: =IF(D5="","","https://docs.google.com/uc?export=download&id="&D5) | D5: =IFERROR(LEFT(RIGHT(E5,LEN(E5)-32),LEN(RIGHT(E5,LEN(E5)-32))-17),"")
C6: =IF(D6="","","https://docs.google.com/uc?export=download&id="&D6) | D6: =IFERROR(LEFT(RIGHT(E6,LEN(E6)-32),LEN(RIGHT(E6,LEN(E6)-32))-17),"")
C7: =IF(D7="","","https://docs.google.com/uc?export=download&id="&D7) | D7: =IFERROR(LEFT(RIGHT(E7,LEN(E7)-32),LEN(RIGHT(E7,LEN(E7)-32))-17),"")

Sheet Sum
B2: Sentence | C2: Link | D2: ID | E2: Copy Google drive to …
B3: Woman | C3: =IF(D3="","","https://docs.google.com/uc?export=download&id="&D3) | D3: =IFERROR(LEFT(RIGHT(E3,LEN(E3)-32),LEN(RIGHT(E3,LEN(E3)-32))-17),"")
B4: Man | C4: =IF(D4="","","https://docs.google.com/uc?export=download&id="&D4) | D4: =IFERROR(LEFT(RIGHT(E4,LEN(E4)-32),LEN(RIGHT(E4,LEN(E4)-32))-17),"")

Sheet Ramdom
B1: From | C1: 1
B2: To | C2: 10
C3: No | D3: No | E3: Viet | F3: Eng
A4: =C1 -> 1 | B4: =IF(A4="","",RANDBETWEEN($C$1,$C$2)) -> 4 | C4: =IFERROR($C$1-1+_xlfn.RANK.EQ(B4,$B$4:$B$134)+COUNTIF(B$4:$B4,B4)-1,"") -> 6 | D4: =IFERROR(VLOOKUP(C4,'Declarative sentences'!A:B,2,0),"") -> 1.6 | E4: =IFERROR(VLOOKUP(D4&"Viet",'Declarative sentences'!C:D,2,0),"") -> Tôi sẽ không phản bội cậu. | F4: =IFERROR(VLOOKUP(D4&"Eng",'Declarative sentences'!C:D,2,0),"")
A5: =IFERROR(IF(A4+1>$C$2,"",A4+1),"") -> 2 | B5: =IF(A5="","",RANDBETWEEN($C$1,$C$2)) -> 5 | C5: =IFERROR($C$1-1+_xlfn.RANK.EQ(B5,$B$4:$B$40)+COUNTIF(B$4:$B5,B5)-1,"") -> 4 | D5: =IFERROR(VLOOKUP(C5,'Declarative sentences'!A:B,2,0),"") -> 1.4 | E5: =IFERROR(VLOOKUP(D5&"Viet",'Declarative sentences'!C:D,2,0),"") -> Tôi sẽ không tranh cãi với cậu. | F5: =IFERROR(VLOOKUP(D5&"Eng",'Declarative sentences'!C:D,2,0),"")
A6: =IFERROR(IF(A5+1>$C$2,"",A5+1),"") -> 3 | B6: =IF(A6="","",RANDBETWEEN($C$1,$C$2)) -> 6 | C6: =IFERROR($C$1-1+_xlfn.RANK.EQ(B6,$B$4:$B$40)+COUNTIF(B$4:$B6,B6)-1,"") -> 3 | D6: =IFERROR(VLOOKUP(C6,'Declarative sentences'!A:B,2,0),"") -> 1.3 | E6: =IFERROR(VLOOKUP(D6&"Viet",'Declarative sentences'!C:D,2,0),"") -> Tôi sẽ đi tìm chứng cứ. | F6: =IFERROR(VLOOKUP(D6&"Eng",'Declarative sentences'!C:D,2,0),"")
A7: =IFERROR(IF(A6+1>$C$2,"",A6+1),"") -> 4 | B7: =IF(A7="","",RANDBETWEEN($C$1,$C$2)) -> 9 | C7: =IFERROR($C$1-1+_xlfn.RANK.EQ(B7,$B$4:$B$40)+COUNTIF(B$4:$B7,B7)-1,"") -> 1 | D7: =IFERROR(VLOOKUP(C7,'Declarative sentences'!A:B,2,0),"") -> 1.1 | E7: =IFERROR(VLOOKUP(D7&"Viet",'Declarative sentences'!C:D,2,0),"") -> Tôi sẽ đi tắm. | F7: =IFERROR(VLOOKUP(D7&"Eng",'Declarative sentences'!C:D,2,0),"")
A8: =IFERROR(IF(A7+1>$C$2,"",A7+1),"") -> 5 | B8: =IF(A8="","",RANDBETWEEN($C$1,$C$2)) -> 7 | C8: =IFERROR($C$1-1+_xlfn.RANK.EQ(B8,$B$4:$B$40)+COUNTIF(B$4:$B8,B8)-1,"") -> 2 | D8: =IFERROR(VLOOKUP(C8,'Declarative sentences'!A:B,2,0),"") -> 1.2 | E8: =IFERROR(VLOOKUP(D8&"Viet",'Declarative sentences'!C:D,2,0),"") -> Tôi sẽ chợp mắt một chút. | F8: =IFERROR(VLOOKUP(D8&"Eng",'Declarative sentences'!C:D,2,0),"")
A9: =IFERROR(IF(A8+1>$C$2,"",A8+1),"") -> 6 | B9: =IF(A9="","",RANDBETWEEN($C$1,$C$2)) -> 4 | C9: =IFERROR($C$1-1+_xlfn.RANK.EQ(B9,$B$4:$B$40)+COUNTIF(B$4:$B9,B9)-1,"") -> 7 | D9: =IFERROR(VLOOKUP(C9,'Declarative sentences'!A:B,2,0),"") -> 1.7 | E9: =IFERROR(VLOOKUP(D9&"Viet",'Declarative sentences'!C:D,2,0),"") -> Cậu sẽ ổn khi không có cô ấy chứ? | F9: =IFERROR(VLOOKUP(D9&"Eng",'Declarative sentences'!C:D,2,0),"")
A10: =IFERROR(IF(A9+1>$C$2,"",A9+1),"") -> 7 | B10: =IF(A10="","",RANDBETWEEN($C$1,$C$2)) -> 5 | C10: =IFERROR($C$1-1+_xlfn.RANK.EQ(B10,$B$4:$B$40)+COUNTIF(B$4:$B10,B10)-1,"") -> 5 | D10: =IFERROR(VLOOKUP(C10,'Declarative sentences'!A:B,2,0),"") -> 1.5 | E10: =IFERROR(VLOOKUP(D10&"Viet",'Declarative sentences'!C:D,2,0),"") -> Tôi sẽ không tỏ ra lịch sự với anh ấy. | F10: =IFERROR(VLOOKUP(D10&"Eng",'Declarative sentences'!C:D,2,0),"")
A11: =IFERROR(IF(A10+1>$C$2,"",A10+1),"") -> 8 | B11: =IF(A11="","",RANDBETWEEN($C$1,$C$2)) -> 1 | C11: =IFERROR($C$1-1+_xlfn.RANK.EQ(B11,$B$4:$B$40)+COUNTIF(B$4:$B11,B11)-1,"") -> 10 | D11: =IFERROR(VLOOKUP(C11,'Declarative sentences'!A:B,2,0),"") -> 2.1 | E11: =IFERROR(VLOOKUP(D11&"Viet",'Declarative sentences'!C:D,2,0),"") -> Tôi sẽ kể cho cậu chuyện này. | F11: =IFERROR(VLOOKUP(D11&"Eng",'Declarative sentences'!C:D,2,0),"")
A12: =IFERROR(IF(A11+1>$C$2,"",A11+1),"") -> 9 | B12: =IF(A12="","",RANDBETWEEN($C$1,$C$2)) -> 4 | C12: =IFERROR($C$1-1+_xlfn.RANK.EQ(B12,$B$4:$B$40)+COUNTIF(B$4:$B12,B12)-1,"") -> 8 | D12: =IFERROR(VLOOKUP(C12,'Declarative sentences'!A:B,2,0),"") -> 1.8 | E12: =IFERROR(VLOOKUP(D12&"Viet",'Declarative sentences'!C:D,2,0),"") -> Cậu có định đi chơi với cô ấy không? | F12: =IFERROR(VLOOKUP(D12&"Eng",'Declarative sentences'!C:D,2,0),"")
A13: =IFERROR(IF(A12+1>$C$2,"",A12+1),"") -> 10 | B13: =IF(A13="","",RANDBETWEEN($C$1,$C$2)) -> 4 | C13: =IFERROR($C$1-1+_xlfn.RANK.EQ(B13,$B$4:$B$40)+COUNTIF(B$4:$B13,B13)-1,"") -> 9 | D13: =IFERROR(VLOOKUP(C13,'Declarative sentences'!A:B,2,0),"") -> 1.9 | E13: =IFERROR(VLOOKUP(D13&"Viet",'Declarative sentences'!C:D,2,0),"") -> Cậu có định lát nữa quay lại văn phòng không? | F13: =IFERROR(VLOOKUP(D13&"Eng",'Declarative sentences'!C:D,2,0),"")
A14: =IFERROR(IF(A13+1>$C$2,"",A13+1),"") | B14: =IF(A14="","",RANDBETWEEN($C$1,$C$2)) | C14: =IFERROR($C$1-1+_xlfn.RANK.EQ(B14,$B$4:$B$40)+COUNTIF(B$4:$B14,B14)-1,"") | D14: =IFERROR(VLOOKUP(C14,'Declarative sentences'!A:B,2,0),"") | E14: =IFERROR(VLOOKUP(D14&"Viet",'Declarative sentences'!C:D,2,0),"") | F14: =IFERROR(VLOOKUP(D14&"Eng",'Declarative sentences'!C:D,2,0),"")
A15: =IFERROR(IF(A14+1>$C$2,"",A14+1),"") | B15: =IF(A15="","",RANDBETWEEN($C$1,$C$2)) | C15: =IFERROR($C$1-1+_xlfn.RANK.EQ(B15,$B$4:$B$40)+COUNTIF(B$4:$B15,B15)-1,"") | D15: =IFERROR(VLOOKUP(C15,'Declarative sentences'!A:B,2,0),"") | E15: =IFERROR(VLOOKUP(D15&"Viet",'Declarative sentences'!C:D,2,0),"") | F15: =IFERROR(VLOOKUP(D15&"Eng",'Declarative sentences'!C:D,2,0),"")
A16: =IFERROR(IF(A15+1>$C$2,"",A15+1),"") | B16: =IF(A16="","",RANDBETWEEN($C$1,$C$2)) | C16: =IFERROR($C$1-1+_xlfn.RANK.EQ(B16,$B$4:$B$40)+COUNTIF(B$4:$B16,B16)-1,"") | D16: =IFERROR(VLOOKUP(C16,'Declarative sentences'!A:B,2,0),"") | E16: =IFERROR(VLOOKUP(D16&"Viet",'Declarative sentences'!C:D,2,0),"") | F16: =IFERROR(VLOOKUP(D16&"Eng",'Declarative sentences'!C:D,2,0),"")
A17: =IFERROR(IF(A16+1>$C$2,"",A16+1),"") | B17: =IF(A17="","",RANDBETWEEN($C$1,$C$2)) | C17: =IFERROR($C$1-1+_xlfn.RANK.EQ(B17,$B$4:$B$40)+COUNTIF(B$4:$B17,B17)-1,"") | D17: =IFERROR(VLOOKUP(C17,'Declarative sentences'!A:B,2,0),"") | E17: =IFERROR(VLOOKUP(D17&"Viet",'Declarative sentences'!C:D,2,0),"") | F17: =IFERROR(VLOOKUP(D17&"Eng",'Declarative sentences'!C:D,2,0),"") | L17: 4
A18: =IFERROR(IF(A17+1>$C$2,"",A17+1),"") | B18: =IF(A18="","",RANDBETWEEN($C$1,$C$2)) | C18: =IFERROR($C$1-1+_xlfn.RANK.EQ(B18,$B$4:$B$40)+COUNTIF(B$4:$B18,B18)-1,"") | D18: =IFERROR(VLOOKUP(C18,'Declarative sentences'!A:B,2,0),"") | E18: =IFERROR(VLOOKUP(D18&"Viet",'Declarative sentences'!C:D,2,0),"") | F18: =IFERROR(VLOOKUP(D18&"Eng",'Declarative sentences'!C:D,2,0),"")
A19: =IFERROR(IF(A18+1>$C$2,"",A18+1),"") | B19: =IF(A19="","",RANDBETWEEN($C$1,$C$2)) | C19: =IFERROR($C$1-1+_xlfn.RANK.EQ(B19,$B$4:$B$40)+COUNTIF(B$4:$B19,B19)-1,"") | D19: =IFERROR(VLOOKUP(C19,'Declarative sentences'!A:B,2,0),"") | E19: =IFERROR(VLOOKUP(D19&"Viet",'Declarative sentences'!C:D,2,0),"") | F19: =IFERROR(VLOOKUP(D19&"Eng",'Declarative sentences'!C:D,2,0),"") | L19: p
A20: =IFERROR(IF(A19+1>$C$2,"",A19+1),"") | B20: =IF(A20="","",RANDBETWEEN($C$1,$C$2)) | C20: =IFERROR($C$1-1+_xlfn.RANK.EQ(B20,$B$4:$B$40)+COUNTIF(B$4:$B20,B20)-1,"") | D20: =IFERROR(VLOOKUP(C20,'Declarative sentences'!A:B,2,0),"") | E20: =IFERROR(VLOOKUP(D20&"Viet",'Declarative sentences'!C:D,2,0),"") | F20: =IFERROR(VLOOKUP(D20&"Eng",'Declarative sentences'!C:D,2,0),"")
A21: =IFERROR(IF(A20+1>$C$2,"",A20+1),"") | B21: =IF(A21="","",RANDBETWEEN($C$1,$C$2)) | C21: =IFERROR($C$1-1+_xlfn.RANK.EQ(B21,$B$4:$B$40)+COUNTIF(B$4:$B21,B21)-1,"") | D21: =IFERROR(VLOOKUP(C21,'Declarative sentences'!A:B,2,0),"") | E21: =IFERROR(VLOOKUP(D21&"Viet",'Declarative sentences'!C:D,2,0),"") | F21: =IFERROR(VLOOKUP(D21&"Eng",'Declarative sentences'!C:D,2,0),"")
A22: =IFERROR(IF(A21+1>$C$2,"",A21+1),"") | B22: =IF(A22="","",RANDBETWEEN($C$1,$C$2)) | C22: =IFERROR($C$1-1+_xlfn.RANK.EQ(B22,$B$4:$B$40)+COUNTIF(B$4:$B22,B22)-1,"") | D22: =IFERROR(VLOOKUP(C22,'Declarative sentences'!A:B,2,0),"") | E22: =IFERROR(VLOOKUP(D22&"Viet",'Declarative sentences'!C:D,2,0),"") | F22: =IFERROR(VLOOKUP(D22&"Eng",'Declarative sentences'!C:D,2,0),"")
A23: =IFERROR(IF(A22+1>$C$2,"",A22+1),"") | B23: =IF(A23="","",RANDBETWEEN($C$1,$C$2)) | C23: =IFERROR($C$1-1+_xlfn.RANK.EQ(B23,$B$4:$B$40)+COUNTIF(B$4:$B23,B23)-1,"") | D23: =IFERROR(VLOOKUP(C23,'Declarative sentences'!A:B,2,0),"") | E23: =IFERROR(VLOOKUP(D23&"Viet",'Declarative sentences'!C:D,2,0),"") | F23: =IFERROR(VLOOKUP(D23&"Eng",'Declarative sentences'!C:D,2,0),"")
A24: =IFERROR(IF(A23+1>$C$2,"",A23+1),"") | B24: =IF(A24="","",RANDBETWEEN($C$1,$C$2)) | C24: =IFERROR($C$1-1+_xlfn.RANK.EQ(B24,$B$4:$B$40)+COUNTIF(B$4:$B24,B24)-1,"") | D24: =IFERROR(VLOOKUP(C24,'Declarative sentences'!A:B,2,0),"") | E24: =IFERROR(VLOOKUP(D24&"Viet",'Declarative sentences'!C:D,2,0),"") | F24: =IFERROR(VLOOKUP(D24&"Eng",'Declarative sentences'!C:D,2,0),"")
A25: =IFERROR(IF(A24+1>$C$2,"",A24+1),"") | B25: =IF(A25="","",RANDBETWEEN($C$1,$C$2)) | C25: =IFERROR($C$1-1+_xlfn.RANK.EQ(B25,$B$4:$B$40)+COUNTIF(B$4:$B25,B25)-1,"") | D25: =IFERROR(VLOOKUP(C25,'Declarative sentences'!A:B,2,0),"") | E25: =IFERROR(VLOOKUP(D25&"Viet",'Declarative sentences'!C:D,2,0),"") | F25: =IFERROR(VLOOKUP(D25&"Eng",'Declarative sentences'!C:D,2,0),"")
A26: =IFERROR(IF(A25+1>$C$2,"",A25+1),"") | B26: =IF(A26="","",RANDBETWEEN($C$1,$C$2)) | C26: =IFERROR($C$1-1+_xlfn.RANK.EQ(B26,$B$4:$B$40)+COUNTIF(B$4:$B26,B26)-1,"") | D26: =IFERROR(VLOOKUP(C26,'Declarative sentences'!A:B,2,0),"") | E26: =IFERROR(VLOOKUP(D26&"Viet",'Declarative sentences'!C:D,2,0),"") | F26: =IFERROR(VLOOKUP(D26&"Eng",'Declarative sentences'!C:D,2,0),"")
A27: =IFERROR(IF(A26+1>$C$2,"",A26+1),"") | B27: =IF(A27="","",RANDBETWEEN($C$1,$C$2)) | C27: =IFERROR($C$1-1+_xlfn.RANK.EQ(B27,$B$4:$B$40)+COUNTIF(B$4:$B27,B27)-1,"") | D27: =IFERROR(VLOOKUP(C27,'Declarative sentences'!A:B,2,0),"") | E27: =IFERROR(VLOOKUP(D27&"Viet",'Declarative sentences'!C:D,2,0),"") | F27: =IFERROR(VLOOKUP(D27&"Eng",'Declarative sentences'!C:D,2,0),"")
A28: =IFERROR(IF(A27+1>$C$2,"",A27+1),"") | B28: =IF(A28="","",RANDBETWEEN($C$1,$C$2)) | C28: =IFERROR($C$1-1+_xlfn.RANK.EQ(B28,$B$4:$B$40)+COUNTIF(B$4:$B28,B28)-1,"") | D28: =IFERROR(VLOOKUP(C28,'Declarative sentences'!A:B,2,0),"") | E28: =IFERROR(VLOOKUP(D28&"Viet",'Declarative sentences'!C:D,2,0),"") | F28: =IFERROR(VLOOKUP(D28&"Eng",'Declarative sentences'!C:D,2,0),"")
A29: =IFERROR(IF(A28+1>$C$2,"",A28+1),"") | B29: =IF(A29="","",RANDBETWEEN($C$1,$C$2)) | C29: =IFERROR($C$1-1+_xlfn.RANK.EQ(B29,$B$4:$B$40)+COUNTIF(B$4:$B29,B29)-1,"") | D29: =IFERROR(VLOOKUP(C29,'Declarative sentences'!A:B,2,0),"") | E29: =IFERROR(VLOOKUP(D29&"Viet",'Declarative sentences'!C:D,2,0),"") | F29: =IFERROR(VLOOKUP(D29&"Eng",'Declarative sentences'!C:D,2,0),"")
A30: =IFERROR(IF(A29+1>$C$2,"",A29+1),"") | B30: =IF(A30="","",RANDBETWEEN($C$1,$C$2)) | C30: =IFERROR($C$1-1+_xlfn.RANK.EQ(B30,$B$4:$B$40)+COUNTIF(B$4:$B30,B30)-1,"") | D30: =IFERROR(VLOOKUP(C30,'Declarative sentences'!A:B,2,0),"") | E30: =IFERROR(VLOOKUP(D30&"Viet",'Declarative sentences'!C:D,2,0),"") | F30: =IFERROR(VLOOKUP(D30&"Eng",'Declarative sentences'!C:D,2,0),"")
A31: =IFERROR(IF(A30+1>$C$2,"",A30+1),"") | B31: =IF(A31="","",RANDBETWEEN($C$1,$C$2)) | C31: =IFERROR($C$1-1+_xlfn.RANK.EQ(B31,$B$4:$B$40)+COUNTIF(B$4:$B31,B31)-1,"") | D31: =IFERROR(VLOOKUP(C31,'Declarative sentences'!A:B,2,0),"") | E31: =IFERROR(VLOOKUP(D31&"Viet",'Declarative sentences'!C:D,2,0),"") | F31: =IFERROR(VLOOKUP(D31&"Eng",'Declarative sentences'!C:D,2,0),"")
... A72: =IFERROR(IF(A71+1>$C$2,"",A71+1),"") | B72: =IF(A72="","",RANDBETWEEN($C$1,$C$2)) | C72: =IFERROR($C$1-1+_xlfn.RANK.EQ(B72,$B$4:$B$40)+COUNTIF(B$4:$B72,B72)-1,"") | D72: =IFERROR(VLOOKUP(C72,'Declarative sentences'!A:B,2,0),"") | E72: =IFERROR(VLOOKUP(D72&"Viet",'Declarative sentences'!C:D,2,0),"") | F72: =IFERROR(VLOOKUP(D72&"Eng",'Declarative sentences'!C:D,2,0),"")
A73: =IFERROR(IF(A72+1>$C$2,"",A72+1),"") | B73: =IF(A73="","",RANDBETWEEN($C$1,$C$2)) | C73: =IFERROR($C$1-1+_xlfn.RANK.EQ(B73,$B$4:$B$40)+COUNTIF(B$4:$B73,B73)-1,"") | D73: =IFERROR(VLOOKUP(C73,'Declarative sentences'!A:B,2,0),"")
A74: =IFERROR(IF(A73+1>$C$2,"",A73+1),"") | B74: =IF(A74="","",RANDBETWEEN($C$1,$C$2)) | C74: =IFERROR($C$1-1+_xlfn.RANK.EQ(B74,$B$4:$B$40)+COUNTIF(B$4:$B74,B74)-1,"") | D74: =IFERROR(VLOOKUP(C74,'Declarative sentences'!A:B,2,0),"")
A75: =IFERROR(IF(A74+1>$C$2,"",A74+1),"") | B75: =IF(A75="","",RANDBETWEEN($C$1,$C$2)) | C75: =IFERROR($C$1-1+_xlfn.RANK.EQ(B75,$B$4:$B$40)+COUNTIF(B$4:$B75,B75)-1,"") | D75: =IFERROR(VLOOKUP(C75,'Declarative sentences'!A:B,2,0),"")
A76: =IFERROR(IF(A75+1>$C$2,"",A75+1),"") | B76: =IF(A76="","",RANDBETWEEN($C$1,$C$2)) | C76: =IFERROR($C$1-1+_xlfn.RANK.EQ(B76,$B$4:$B$40)+COUNTIF(B$4:$B76,B76)-1,"") | D76: =IFERROR(VLOOKUP(C76,'Declarative sentences'!A:B,2,0),"")
A77: =IFERROR(IF(A76+1>$C$2,"",A76+1),"") | B77: =IF(A77="","",RANDBETWEEN($C$1,$C$2)) | C77: =IFERROR($C$1-1+_xlfn.RANK.EQ(B77,$B$4:$B$40)+COUNTIF(B$4:$B77,B77)-1,"") | D77: =IFERROR(VLOOKUP(C77,'Declarative sentences'!A:B,2,0),"")
A78: =IFERROR(IF(A77+1>$C$2,"",A77+1),"") | B78: =IF(A78="","",RANDBETWEEN($C$1,$C$2)) | C78: =IFERROR($C$1-1+_xlfn.RANK.EQ(B78,$B$4:$B$40)+COUNTIF(B$4:$B78,B78)-1,"") | D78: =IFERROR(VLOOKUP(C78,'Declarative sentences'!A:B,2,0),"")
A79: =IFERROR(IF(A78+1>$C$2,"",A78+1),"") | B79: =IF(A79="","",RANDBETWEEN($C$1,$C$2)) | C79: =IFERROR($C$1-1+_xlfn.RANK.EQ(B79,$B$4:$B$40)+COUNTIF(B$4:$B79,B79)-1,"") | D79: =IFERROR(VLOOKUP(C79,'Declarative sentences'!A:B,2,0),"")
A80: =IFERROR(IF(A79+1>$C$2,"",A79+1),"") | B80: =IF(A80="","",RANDBETWEEN($C$1,$C$2)) | C80: =IFERROR($C$1-1+_xlfn.RANK.EQ(B80,$B$4:$B$40)+COUNTIF(B$4:$B80,B80)-1,"") | D80: =IFERROR(VLOOKUP(C80,'Declarative sentences'!A:B,2,0),"")
...

Sheet Sheet1
C1: dfdfsd | D1: dxasdas
A2: 1 | B2: =A2&D2 -> 1Struc | C2: 1. I’M GOING TO... /Tôi sẽ... / | D2: Struc | E2: =C2 -> 1. I’M GOING TO... /Tôi sẽ... /
A3: 1.1 | B3: =A3&D3 -> 1.1Viet | C3: Tôi sẽ đi tắm. | D3: Viet | E3: =A3&". "&C3 -> 1.1. Tôi sẽ đi tắm.
A4: 1.1 | B4: =A4&D4 -> 1.1Anh | C4: I’m going to take a shower. | D4: Anh | E4: =C4 -> I’m going to take a shower.
A5: 1.1 | B5: =A5&D5 -> 1.1Phon | C5: aɪm ˈgoʊɪŋ tu: teɪk ə ˈʃaʊər | D5: Phon | E5: =C5 -> aɪm ˈgoʊɪŋ tu: teɪk ə ˈʃaʊər
A6: 1.2 | B6: =A6&D6 -> 1.2Viet | C6: Tôi sẽ chợp mắt một chút. | D6: Viet | E6: =A6&". "&C6 -> 1.2. Tôi sẽ chợp mắt một chút.
A7: 1.2 | B7: =A7&D7 -> 1.2Anh | C7: I’m going to take a quick nap. | D7: Anh | E7: =C7 -> I’m going to take a quick nap.
A8: 1.2 | B8: =A8&D8 -> 1.2Phon | C8: aɪm ˈgoʊɪŋ tu: teɪk ə kwɪk næp | D8: Phon | E8: =C8 -> aɪm ˈgoʊɪŋ tu: teɪk ə kwɪk næp
A9: 1.3 | B9: =A9&D9 -> 1.3Viet | C9: Tôi sẽ đi tìm chứng cứ. | D9: Viet | E9: =A9&". "&C9 -> 1.3. Tôi sẽ đi tìm chứng cứ.
A10: 1.3 | B10: =A10&D10 -> 1.3Anh | C10: I’m going to find some evidence. | D10: Anh | E10: =C10 -> I’m going to find some evidence.
A11: 1.3 | B11: =A11&D11 -> 1.3Phon | C11: aɪm ˈgoʊɪŋ tu: faɪnd sʌm ˈɛvədəns | D11: Phon | E11: =C11 -> aɪm ˈgoʊɪŋ tu: faɪnd sʌm ˈɛvədəns
A12: 1.4 | B12: =A12&D12 -> 1.4Viet | C12: Tôi sẽ không tranh cãi với cậu. | D12: Viet | E12: =A12&". "&C12 -> 1.4. Tôi sẽ không tranh cãi với cậu.
A13: 1.4 | B13: =A13&D13 -> 1.4Anh | C13: I’m not going to argue with you. | D13: Anh | E13: =C13 -> I’m not going to argue with you.
A14: 1.4 | B14: =A14&D14 -> 1.4Phon | C14: aɪm na:t ˈgoʊɪŋ tu: ˈa:rgju: wɪð ju: | D14: Phon | E14: =C14 -> aɪm na:t ˈgoʊɪŋ tu: ˈa:rgju: wɪð ju:
A15: 1.5 | B15: =A15&D15 -> 1.5Viet | C15: Tôi sẽ không tỏ ra lịch sự với anh ấy. | D15: Viet | E15: =A15&". "&C15 -> 1.5. Tôi sẽ không tỏ ra lịch sự với anh ấy.
A16: 1.5 | B16: =A16&D16 -> 1.5Anh | C16: I’m not going to be polite to him. | D16: Anh | E16: =C16 -> I’m not going to be polite to him.
A17: 1.5 | B17: =A17&D17 -> 1.5Phon | C17: aɪm na:t ˈgoʊɪŋ tu: bi: pəˈlaɪt tu: hɪm | D17: Phon | E17: =C17 -> aɪm na:t ˈgoʊɪŋ tu: bi: pəˈlaɪt tu: hɪm
A18: 1.6 | B18: =A18&D18 -> 1.6Viet | C18: Tôi sẽ không phản bội cậu. | D18: Viet | E18: =A18&". "&C18 -> 1.6. Tôi sẽ không phản bội cậu.
A19: 1.6 | B19: =A19&D19 -> 1.6Anh | C19: I’m not going to betray you. | D19: Anh | E19: =C19 -> I’m not going to betray you.
A20: 1.6 | B20: =A20&D20 -> 1.6Phon | C20: aɪm na:t ˈgoʊɪŋ tu: bɪˈtreɪ ju: | D20: Phon | E20: =C20 -> aɪm na:t ˈgoʊɪŋ tu: bɪˈtreɪ ju:
A21: 1.7 | B21: =A21&D21 -> 1.7Viet | C21: Cậu sẽ ổn khi không có cô ấy chứ? | D21: Viet | E21: =A21&". "&C21 -> 1.7. Cậu sẽ ổn khi không có cô ấy chứ?
A22: 1.7 | B22: =A22&D22 -> 1.7Anh | C22: Are you going to be ok without her? | D22: Anh | E22: =C22 -> Are you going to be ok without her?
A23: 1.7 | B23: =A23&D23 -> 1.7Phon | C23: a:r ju: ˈgoʊɪŋ tu: bi: oʊˈkeɪ wɪˈðaʊt hɜ:r | D23: Phon | E23: =C23 -> a:r ju: ˈgoʊɪŋ tu: bi: oʊˈkeɪ wɪˈðaʊt hɜ:r
A24: 1.8 | B24: =A24&D24 -> 1.8Viet | C24: Cậu có định đi chơi với cô ấy không? | D24: Viet | E24: =A24&". "&C24 -> 1.8. Cậu có định đi chơi với cô ấy không?
A25: 1.8 | B25: =A25&D25 -> 1.8Anh | C25: Are you going to go out with her? | D25: Anh | E25: =C25 -> Are you going to go out with her?
A26: 1.8 | B26: =A26&D26 -> 1.8Phon | C26: a:r ju: ˈgoʊɪŋ tu: goʊ aʊt wɪð hɜ:r | D26: Phon | E26: =C26 -> a:r ju: ˈgoʊɪŋ tu: goʊ aʊt wɪð hɜ:r
A27: 1.9 | B27: =A27&D27 -> 1.9Viet | C27: Cậu có định lát nữa quay lại văn phòng không? | D27: Viet | E27: =A27&". "&C27 -> 1.9. Cậu có định lát nữa quay lại văn phòng không?
A28: 1.9 | B28: =A28&D28 -> 1.9Anh | C28: Are you going to be back in the office later? | D28: Anh | E28: =C28 -> Are you going to be back in the office later?
A29: 1.9 | B29: =A29&D29 -> 1.9Phon | C29: a:r ju: ˈgoʊɪŋ tu: bi: bæk ɪn ði: ˈa:fɪs ˈleɪtər | D29: Phon | E29: =C29 -> a:r ju: ˈgoʊɪŋ tu: bi: bæk ɪn ði: ˈa:fɪs ˈleɪtər
A30: 2 | B30: =A30&D30 -> 2Struc | C30: 2. I WILL... /Tôi sẽ.../ | D30: Struc | E30: =C30 -> 2. I WILL... /Tôi sẽ.../
A31: 2.1 | B31: =A31&D31 -> 2.1Viet | C31: Tôi sẽ kể cho cậu chuyện này. | D31: Viet | E31: =A31&". "&C31 -> 2.1. Tôi sẽ kể cho cậu chuyện này.
A32: 2.1 | B32: =A32&D32 -> 2.1Anh | C32: I will tell you this. | D32: Anh | E32: =C32 -> I will tell you this.
A33: 2.1 | B33: =A33&D33 -> 2.1Phon | C33: aɪ wɪl tɛl ju: ðɪs | D33: Phon | E33: =C33 -> aɪ wɪl tɛl ju: ðɪs
A34: 2.2 | B34: =A34&D34 -> 2.2Viet | C34: Tôi sẽ thay đổi kiểu tóc. | D34: Viet | E34: =A34&". "&C34 -> 2.2. Tôi sẽ thay đổi kiểu tóc.
A35: 2.2 | B35: =A35&D35 -> 2.2Anh | C35: I will change my hairstyle. | D35: Anh | E35: =C35 -> I will change my hairstyle.
A36: 2.2 | B36: =A36&D36 -> 2.2Phon | C36: aɪ wɪl ʧeɪnʤ maɪ ˈhɛrstaɪl | D36: Phon | E36: =C36 -> aɪ wɪl ʧeɪnʤ maɪ ˈhɛrstaɪl
A37: 2.3 | B37: =A37&D37 -> 2.3Viet | C37: Tôi sẽ giữ bí mật. | D37: Viet | E37: =A37&". "&C37 -> 2.3. Tôi sẽ giữ bí mật.
A38: 2.3 | B38: =A38&D38 -> 2.3Anh | C38: I will keep it secret. | D38: Anh | E38: =C38 -> I will keep it secret.
A39: 2.3 | B39: =A39&D39 -> 2.3Phon | C39: aɪ wɪl ki:p ɪt ˈsi:krət | D39: Phon | E39: =C39 -> aɪ wɪl ki:p ɪt ˈsi:krət
A40: 2.4 | B40: =A40&D40 -> 2.4Viet | C40: Tôi sẽ không lặp lại chuyện đó. | D40: Viet | E40: =A40&". "&C40 -> 2.4. Tôi sẽ không lặp lại chuyện đó.
...

Sheet Sheet2
