Workbook

Sheet Discussion
B2: TOPIC: DISCUSSION
A3: No | B3: No | C3: ID | D3: Sentence | E3: Type | F3: Link | G3: ID | H3: Copy Google drive to …
B4: 1 | C4: 1Struc | D4: I WANT TO ASK YOU ABOUT… /Tôi muốn hỏi anh về… của anh gần đây/ | E4: Struc | F4: =IF(G4="","","https://docs.google.com/uc?export=download&id="&G4)
B5: 1.1 | C5: 1.1Viet | D5: Tôi muốn hỏi anh về doanh số của anh gần đây. | E5: Viet | F5: =IF(G5="","","https://docs.google.com/uc?export=download&id="&G5) | G5: =IFERROR(LEFT(RIGHT(H5,LEN(H5)-32),LEN(RIGHT(H5,LEN(H5)-32))-17),"")
A6: 1 | B6: 1.1 | C6: 1.1Eng | D6: I want to ask you about your sales lately. | E6: Eng | F6: =IF(G6="","","https://docs.google.com/uc?export=download&id="&G6) -> https://docs.google.com/uc?export=download&id=1P_3DcEQ_tML-h9z38KjK-NDy4UA1ALzf | G6: =IFERROR(LEFT(RIGHT(H6,LEN(H6)-32),LEN(RIGHT(H6,LEN(H6)-32))-17),"") -> 1P_3DcEQ_tML-h9z38KjK-NDy4UA1ALzf | H6: https://drive.google.com/file/d/1P_3DcEQ_tML-h9z38KjK-NDy4UA1ALzf/view?usp=sharing
B7: 1.1 | C7: 1.1Phon | D7: aɪ waːnt tu: æsk ju: əˈbaʊt jʊr seɪlz ˈleɪtli | E7: Phon | F7: =IF(G7="","","https://docs.google.com/uc?export=download&id="&G7) | G7: =IFERROR(LEFT(RIGHT(H7,LEN(H7)-32),LEN(RIGHT(H7,LEN(H7)-32))-17),"")
B8: 1.2 | C8: 1.2Viet | D8: Tôi muốn hỏi anh về lợi nhuận của anh gần đây. | E8: Viet | F8: =IF(G8="","","https://docs.google.com/uc?export=download&id="&G8) | G8: =IFERROR(LEFT(RIGHT(H8,LEN(H8)-32),LEN(RIGHT(H8,LEN(H8)-32))-17),"")
A9: 2 | B9: 1.2 | C9: 1.2Eng | D9: I want to ask you about your profits lately. | E9: Eng | F9: =IF(G9="","","https://docs.google.com/uc?export=download&id="&G9) -> https://docs.google.com/uc?export=download&id=1piF9LqgfYhwzXUhx5XI_CjxC6UZkY-hS | G9: =IFERROR(LEFT(RIGHT(H9,LEN(H9)-32),LEN(RIGHT(H9,LEN(H9)-32))-17),"") -> 1piF9LqgfYhwzXUhx5XI_CjxC6UZkY-hS | H9: https://drive.google.com/file/d/1piF9LqgfYhwzXUhx5XI_CjxC6UZkY-hS/view?usp=sharing
B10: 1.2 | C10: 1.2Phon | D10: aɪ waːnt tu: æsk ju: əˈbaʊt jʊr ˈpraːfɪts ˈleɪtli | E10: Phon | F10: =IF(G10="","","https://docs.google.com/uc?export=download&id="&G10) | G10: =IFERROR(LEFT(RIGHT(H10,LEN(H10)-32),LEN(RIGHT(H10,LEN(H10)-32))-17),"")
B11: 1.3 | C11: 1.3Viet | D11: Tôi muốn hỏi anh về hiệu suất công việc của anh gần đây. | E11: Viet | F11: =IF(G11="","","https://docs.google.com/uc?export=download&id="&G11) | G11: =IFERROR(LEFT(RIGHT(H11,LEN(H11)-32),LEN(RIGHT(H11,LEN(H11)-32))-17),"")
A12: 3 | B12: 1.3 | C12: 1.3Eng | D12: I want to ask you about your work performance lately. | E12: Eng | F12: =IF(G12="","","https://docs.google.com/uc?export=download&id="&G12) -> https://docs.google.com/uc?export=download&id=1hPvzcbxB0_UkQp9yqh7CSyhv-tpqcuU8 | G12: =IFERROR(LEFT(RIGHT(H12,LEN(H12)-32),LEN(RIGHT(H12,LEN(H12)-32))-17),"") -> 1hPvzcbxB0_UkQp9yqh7CSyhv-tpqcuU8 | H12: https://drive.google.com/file/d/1hPvzcbxB0_UkQp9yqh7CSyhv-tpqcuU8/view?usp=sharing
B13: 1.3 | C13: 1.3Phon | D13: aɪ waːnt tu: æsk ju: əˈbaʊt jʊr wɜ:rk pərˈfɔːməns ˈleɪtli | E13: Phon | F13: =IF(G13="","","https://docs.google.com/uc?export=download&id="&G13) | G13: =IFERROR(LEFT(RIGHT(H13,LEN(H13)-32),LEN(RIGHT(H13,LEN(H13)-32))-17),"")
B14: 1.4 | C14: 1.4Viet | D14: Tôi muốn hỏi anh về việc kinh doanh của anh gần đây. | E14: Viet | F14: =IF(G14="","","https://docs.google.com/uc?export=download&id="&G14) | G14: =IFERROR(LEFT(RIGHT(H14,LEN(H14)-32),LEN(RIGHT(H14,LEN(H14)-32))-17),"")
A15: 4 | B15: 1.4 | C15: 1.4Eng | D15: I want to ask you about your business lately. | E15: Eng | F15: =IF(G15="","","https://docs.google.com/uc?export=download&id="&G15) -> https://docs.google.com/uc?export=download&id=1xeVzc9P4a_ROIQ_QweAcbX-7LIFy-9PR | G15: =IFERROR(LEFT(RIGHT(H15,LEN(H15)-32),LEN(RIGHT(H15,LEN(H15)-32))-17),"") -> 1xeVzc9P4a_ROIQ_QweAcbX-7LIFy-9PR | H15: https://drive.google.com/file/d/1xeVzc9P4a_ROIQ_QweAcbX-7LIFy-9PR/view?usp=sharing
B16: 1.4 | C16: 1.4Phon | D16: aɪ waːnt tu: æsk ju: əˈbaʊt jʊr ˈbɪznɪs ˈleɪtli | E16: Phon | F16: =IF(G16="","","https://docs.google.com/uc?export=download&id="&G16) | G16: =IFERROR(LEFT(RIGHT(H16,LEN(H16)-32),LEN(RIGHT(H16,LEN(H16)-32))-17),"")
B17: 1.5 | C17: 1.5Viet | D17: Tôi hi vọng ông có thể gửi cho tôi các thông tin liên quan. | E17: Viet | F17: =IF(G17="","","https://docs.google.com/uc?export=download&id="&G17) | G17: =IFERROR(LEFT(RIGHT(H17,LEN(H17)-32),LEN(RIGHT(H17,LEN(H17)-32))-17),"")
A18: 5 | B18: 1.5 | C18: 1.5Eng | D18: I want to ask you to kindly send me the related information. | E18: Eng | F18: =IF(G18="","","https://docs.google.com/uc?export=download&id="&G18) -> https://docs.google.com/uc?export=download&id=1p22GOupLd9sCRmMQjEz1AhVDxQ649Tv_ | G18: =IFERROR(LEFT(RIGHT(H18,LEN(H18)-32),LEN(RIGHT(H18,LEN(H18)-32))-17),"") -> 1p22GOupLd9sCRmMQjEz1AhVDxQ649Tv_ | H18: https://drive.google.com/file/d/1p22GOupLd9sCRmMQjEz1AhVDxQ649Tv_/view?usp=sharing
B19: 1.5 | C19: 1.5Phon | D19: aɪ waːnt tu: æsk ju: tu: ˈkaɪndli send miː ðə rɪˈleɪtɪd ˌɪnfərˈmeɪʃən | E19: Phon | F19: =IF(G19="","","https://docs.google.com/uc?export=download&id="&G19) | G19: =IFERROR(LEFT(RIGHT(H19,LEN(H19)-32),LEN(RIGHT(H19,LEN(H19)-32))-17),"")
B20: 2 | C20: 2Struc | D20: WE’D LIKE TO DISCUSS… /Chúng tôi muốn thảo luận về.../ | E20: Struc | F20: =IF(G20="","","https://docs.google.com/uc?export=download&id="&G20) | G20: =IFERROR(LEFT(RIGHT(H20,LEN(H20)-32),LEN(RIGHT(H20,LEN(H20)-32))-17),"")
B21: 2.1 | C21: 2.1Viet | D21: Chúng tôi muốn thảo luận về mức giá mà ông đưa ra. | E21: Viet | F21: =IF(G21="","","https://docs.google.com/uc?export=download&id="&G21) | G21: =IFERROR(LEFT(RIGHT(H21,LEN(H21)-32),LEN(RIGHT(H21,LEN(H21)-32))-17),"")
A22: 6 | B22: 2.1 | C22: 2.1Eng | D22: We’d like to discuss the price you quoted. | E22: Eng | F22: =IF(G22="","","https://docs.google.com/uc?export=download&id="&G22) -> https://docs.google.com/uc?export=download&id=1BkY4PdvGJeqU4m_T_QQxaFhDGHa5rT8K | G22: =IFERROR(LEFT(RIGHT(H22,LEN(H22)-32),LEN(RIGHT(H22,LEN(H22)-32))-17),"") -> 1BkY4PdvGJeqU4m_T_QQxaFhDGHa5rT8K | H22: https://drive.google.com/file/d/1BkY4PdvGJeqU4m_T_QQxaFhDGHa5rT8K/view?usp=sharing
B23: 2.1 | C23: 2.1Phon | D23: wi:d laɪk tu: dɪˈskʌs ðə praɪs ju: ˈkwoʊtɪd | E23: Phon | F23: =IF(G23="","","https://docs.google.com/uc?export=download&id="&G23) | G23: =IFERROR(LEFT(RIGHT(H23,LEN(H23)-32),LEN(RIGHT(H23,LEN(H23)-32))-17),"")
B24: 2.2 | C24: 2.2Viet | D24: Chúng tôi muốn thảo luận về các điều khoản và điều kiện chi trả. | E24: Viet | F24: =IF(G24="","","https://docs.google.com/uc?export=download&id="&G24) | G24: =IFERROR(LEFT(RIGHT(H24,LEN(H24)-32),LEN(RIGHT(H24,LEN(H24)-32))-17),"")
A25: 7 | B25: 2.2 | C25: 2.2Eng | D25: We’d like to discuss the terms and conditions of payment. | E25: Eng | F25: =IF(G25="","","https://docs.google.com/uc?export=download&id="&G25) -> https://docs.google.com/uc?export=download&id=1hgubR1vMD65CSeEH7gKfKDn4rlIEmeHy | G25: =IFERROR(LEFT(RIGHT(H25,LEN(H25)-32),LEN(RIGHT(H25,LEN(H25)-32))-17),"") -> 1hgubR1vMD65CSeEH7gKfKDn4rlIEmeHy | H25: https://drive.google.com/file/d/1hgubR1vMD65CSeEH7gKfKDn4rlIEmeHy/view?usp=sharing
B26: 2.2 | C26: 2.2Phon | D26: wi:d laɪk tu: dɪˈskʌs ðə tɜːrmz ænd kənˈdɪʃənz ʌv ˈpeɪmənt | E26: Phon | F26: =IF(G26="","","https://docs.google.com/uc?export=download&id="&G26) | G26: =IFERROR(LEFT(RIGHT(H26,LEN(H26)-32),LEN(RIGHT(H26,LEN(H26)-32))-17),"")
B27: 2.3 | C27: 2.3Viet | D27: Chúng tôi muốn thảo luận về khoản tiền được giảm nếu thanh toán sớm. | E27: Viet | F27: =IF(G27="","","https://docs.google.com/uc?export=download&id="&G27) | G27: =IFERROR(LEFT(RIGHT(H27,LEN(H27)-32),LEN(RIGHT(H27,LEN(H27)-32))-17),"")
A28: 8 | B28: 2.3 | C28: 2.3Eng | D28: We’d like to discuss the discount on early settlement. | E28: Eng | F28: =IF(G28="","","https://docs.google.com/uc?export=download&id="&G28) -> https://docs.google.com/uc?export=download&id=1jRgso7_BUtOijcQup2wDBHfbqfIi1VXh | G28: =IFERROR(LEFT(RIGHT(H28,LEN(H28)-32),LEN(RIGHT(H28,LEN(H28)-32))-17),"") -> 1jRgso7_BUtOijcQup2wDBHfbqfIi1VXh | H28: https://drive.google.com/file/d/1jRgso7_BUtOijcQup2wDBHfbqfIi1VXh/view?usp=sharing
B29: 2.3 | C29: 2.3Phon | D29: wi:d laɪk tu: dɪˈskʌs ðə ˈdɪskaʊnt aːn ˈɜ:rli ˈsetəlmənt | E29: Phon | F29: =IF(G29="","","https://docs.google.com/uc?export=download&id="&G29) | G29: =IFERROR(LEFT(RIGHT(H29,LEN(H29)-32),LEN(RIGHT(H29,LEN(H29)-32))-17),"")
B30: 2.4 | C30: 2.4Viet | D30: Chúng tôi muốn thảo luận về cơ hội này nhiều hơn. | E30: Viet | F30: =IF(G30="","","https://docs.google.com/uc?export=download&id="&G30) | G30: =IFERROR(LEFT(RIGHT(H30,LEN(H30)-32),LEN(RIGHT(H30,LEN(H30)-32))-17),"")
A31: 9 | B31: 2.4 | C31: 2.4Eng | D31: We’d like to discuss this opportunity further. | E31: Eng | F31: =IF(G31="","","https://docs.google.com/uc?export=download&id="&G31) -> https://docs.google.com/uc?export=download&id=17ifgTufzlA8Eo-ohgkzuH189DnsKlEEe | G31: =IFERROR(LEFT(RIGHT(H31,LEN(H31)-32),LEN(RIGHT(H31,LEN(H31)-32))-17),"") -> 17ifgTufzlA8Eo-ohgkzuH189DnsKlEEe | H31: https://drive.google.com/file/d/17ifgTufzlA8Eo-ohgkzuH189DnsKlEEe/view?usp=sharing
B32: 2.4 | C32: 2.4Phon | D32: wi:d laɪk tu: dɪˈskʌs ðɪs ˌaːpərˈtuːnəti ˈfɜːrðər | E32: Phon | F32: =IF(G32="","","https://docs.google.com/uc?export=download&id="&G32) | G32: =IFERROR(LEFT(RIGHT(H32,LEN(H32)-32),LEN(RIGHT(H32,LEN(H32)-32))-17),"")
B33: 2.5 | C33: 2.5Viet | D33: Chúng tôi muốn thảo luận chi tiết hơn. | E33: Viet | F33: =IF(G33="","","https://docs.google.com/uc?export=download&id="&G33) | G33: =IFERROR(LEFT(RIGHT(H33,LEN(H33)-32),LEN(RIGHT(H33,LEN(H33)-32))-17),"")
A34: 10 | B34: 2.5 | C34: 2.5Eng | D34: We’d like to discuss in more detail. | E34: Eng | F34: =IF(G34="","","https://docs.google.com/uc?export=download&id="&G34) -> https://docs.google.com/uc?export=download&id=1mwul5IpSIZvG_axjaFvRkd6WG40Zcbcb | G34: =IFERROR(LEFT(RIGHT(H34,LEN(H34)-32),LEN(RIGHT(H34,LEN(H34)-32))-17),"") -> 1mwul5IpSIZvG_axjaFvRkd6WG40Zcbcb | H34: https://drive.google.com/file/d/1mwul5IpSIZvG_axjaFvRkd6WG40Zcbcb/view?usp=sharing
B35: 2.5 | C35: 2.5Phon | D35: wi:d laɪk tu: dɪˈskʌs ɪn mɔːr ˈdiːteɪl | E35: Phon | F35: =IF(G35="","","https://docs.google.com/uc?export=download&id="&G35) | G35: =IFERROR(LEFT(RIGHT(H35,LEN(H35)-32),LEN(RIGHT(H35,LEN(H35)-32))-17),"")
B36: 3 | C36: 3Struc | D36: I WOULD LIKE TO... /Tôi muốn…/ | E36: Struc | F36: =IF(G36="","","https://docs.google.com/uc?export=download&id="&G36) | G36: =IFERROR(LEFT(RIGHT(H36,LEN(H36)-32),LEN(RIGHT(H36,LEN(H36)-32))-17),"")
B37: 3.1 | C37: 3.1Viet | D37: Tôi muốn mọi việc được tiến hành. | E37: Viet | F37: =IF(G37="","","https://docs.google.com/uc?export=download&id="&G37) | G37: =IFERROR(LEFT(RIGHT(H37,LEN(H37)-32),LEN(RIGHT(H37,LEN(H37)-32))-17),"")
A38: 11 | B38: 3.1 | C38: 3.1Eng | D38: I would like to get things under way. | E38: Eng | F38: =IF(G38="","","https://docs.google.com/uc?export=download&id="&G38) -> https://docs.google.com/uc?export=download&id=1mt5TWOihD0jpSFeE0AQVHUGOnNtg9KXw | G38: =IFERROR(LEFT(RIGHT(H38,LEN(H38)-32),LEN(RIGHT(H38,LEN(H38)-32))-17),"") -> 1mt5TWOihD0jpSFeE0AQVHUGOnNtg9KXw | H38: https://drive.google.com/file/d/1mt5TWOihD0jpSFeE0AQVHUGOnNtg9KXw/view?usp=sharing
B39: 3.1 | C39: 3.1Phon | D39: aɪ wʊd laɪk tu: get θɪŋz ˈʌndər weɪ | E39: Phon | F39: =IF(G39="","","https://docs.google.com/uc?export=download&id="&G39) | G39: =IFERROR(LEFT(RIGHT(H39,LEN(H39)-32),LEN(RIGHT(H39,LEN(H39)-32))-17),"")
B40: 3.2 | C40: 3.2Viet | D40: Tôi muốn xác nhận lại mục đích của cuộc họp này. | E40: Viet | F40: =IF(G40="","","https://docs.google.com/uc?export=download&id="&G40) | G40: =IFERROR(LEFT(RIGHT(H40,LEN(H40)-32),LEN(RIGHT(H40,LEN(H40)-32))-17),"")
A41: 12 | B41: 3.2 | C41: 3.2Eng | D41: I would like to confirm the purpose of this meeting. | E41: Eng | F41: =IF(G41="","","https://docs.google.com/uc?export=download&id="&G41) -> https://docs.google.com/uc?export=download&id=1egSrW5SoJbQ2nFRfw3KlTnPxsGd5lIAz | G41: =IFERROR(LEFT(RIGHT(H41,LEN(H41)-32),LEN(RIGHT(H41,LEN(H41)-32))-17),"") -> 1egSrW5SoJbQ2nFRfw3KlTnPxsGd5lIAz | H41: https://drive.google.com/file/d/1egSrW5SoJbQ2nFRfw3KlTnPxsGd5lIAz/view?usp=sharing
...

Sheet Viet
B2: Sentence | C2: Link | D2: ID | E2: Copy Google drive to …
B3: 01-05 | C3: =IF(D3="","","https://docs.google.com/uc?export=download&id="&D3) -> https://docs.google.com/uc?export=download&id=1lkh8jcr85LICTsksDQ7_BYnUQl3gOyAV | D3: =IFERROR(LEFT(RIGHT(E3,LEN(E3)-32),LEN(RIGHT(E3,LEN(E3)-32))-17),"") -> 1lkh8jcr85LICTsksDQ7_BYnUQl3gOyAV | E3: https://drive.google.com/file/d/1lkh8jcr85LICTsksDQ7_BYnUQl3gOyAV/view?usp=sharing
C4: =IF(D4="","","https://docs.google.com/uc?export=download&id="&D4) | D4: =IFERROR(LEFT(RIGHT(E4,LEN(E4)-32),LEN(RIGHT(E4,LEN(E4)-32))-17),"")
C5: =IF(D5="","","https://docs.google.com/uc?export=download&id="&D5) | D5: =IFERROR(LEFT(RIGHT(E5,LEN(E5)-32),LEN(RIGHT(E5,LEN(E5)-32))-17),"")
C6: =IF(D6="","","https://docs.google.com/uc?export=download&id="&D6) | D6: =IFERROR(LEFT(RIGHT(E6,LEN(E6)-32),LEN(RIGHT(E6,LEN(E6)-32))-17),"")
C7: =IF(D7="","","https://docs.google.com/uc?export=download&id="&D7) | D7: =IFERROR(LEFT(RIGHT(E7,LEN(E7)-32),LEN(RIGHT(E7,LEN(E7)-32))-17),"")

Sheet Sum
B2: Sentence | C2: Link | D2: ID | E2: Copy Google drive to …
B3: Woman | C3: =IF(D3="","","https://docs.google.com/uc?export=download&id="&D3) | D3: =IFERROR(LEFT(RIGHT(E3,LEN(E3)-32),LEN(RIGHT(E3,LEN(E3)-32))-17),"")
B4: Man | C4: =IF(D4="","","https://docs.google.com/uc?export=download&id="&D4) | D4: =IFERROR(LEFT(RIGHT(E4,LEN(E4)-32),LEN(RIGHT(E4,LEN(E4)-32))-17),"")

Sheet Ramdom
B1: From | C1: 1
B2: To | C2: 37
C3: No | D3: No | E3: Viet | F3: Eng
A4: =C1 -> 1 | B4: =IF(A4="","",RANDBETWEEN($C$1,$C$2)) -> 18 | C4: =IFERROR($C$1-1+_xlfn.RANK.EQ(B4,$B$4:$B$40)+COUNTIF(B$4:$B4,B4)-1,"") -> 24 | D4: =IFERROR(VLOOKUP(C4,Discussion!A:B,2,0),"") -> 4.1 | E4: =IFERROR(VLOOKUP(D4&"Viet",Discussion!C:D,2,0),"") -> Bạn có thể trình bày một lần nữa cho tôi không? | F4: =IFERROR(VLOOKUP(D4&"Eng",Discussion!C:D,2,0),"") -> Could you run that by me one more time?
A5: =IFERROR(IF(A4+1>$C$2,"",A4+1),"") -> 2 | B5: =IF(A5="","",RANDBETWEEN($C$1,$C$2)) -> 20 | C5: =IFERROR($C$1-1+_xlfn.RANK.EQ(B5,$B$4:$B$40)+COUNTIF(B$4:$B5,B5)-1,"") -> 22 | D5: =IFERROR(VLOOKUP(C5,Discussion!A:B,2,0),"") -> 3.12 | E5: =IFERROR(VLOOKUP(D5&"Viet",Discussion!C:D,2,0),"") -> Tôi muốn thử. | F5: =IFERROR(VLOOKUP(D5&"Eng",Discussion!C:D,2,0),"") -> I would like to try.
A6: =IFERROR(IF(A5+1>$C$2,"",A5+1),"") -> 3 | B6: =IF(A6="","",RANDBETWEEN($C$1,$C$2)) -> 10 | C6: =IFERROR($C$1-1+_xlfn.RANK.EQ(B6,$B$4:$B$40)+COUNTIF(B$4:$B6,B6)-1,"") -> 28 | D6: =IFERROR(VLOOKUP(C6,Discussion!A:B,2,0),"") -> 4.5 | E6: =IFERROR(VLOOKUP(D6&"Viet",Discussion!C:D,2,0),"") -> Ông có thể cho tôi xem ca ta lô và tài liệu cập nhật tới hiện tại không? | F6: =IFERROR(VLOOKUP(D6&"Eng",Discussion!C:D,2,0),"") -> Could you show me up-to-date catalogues and documents?
A7: =IFERROR(IF(A6+1>$C$2,"",A6+1),"") -> 4 | B7: =IF(A7="","",RANDBETWEEN($C$1,$C$2)) -> 30 | C7: =IFERROR($C$1-1+_xlfn.RANK.EQ(B7,$B$4:$B$40)+COUNTIF(B$4:$B7,B7)-1,"") -> 9 | D7: =IFERROR(VLOOKUP(C7,Discussion!A:B,2,0),"") -> 2.4 | E7: =IFERROR(VLOOKUP(D7&"Viet",Discussion!C:D,2,0),"") -> Chúng tôi muốn thảo luận về cơ hội này nhiều hơn. | F7: =IFERROR(VLOOKUP(D7&"Eng",Discussion!C:D,2,0),"") -> We’d like to discuss this opportunity further.
A8: =IFERROR(IF(A7+1>$C$2,"",A7+1),"") -> 5 | B8: =IF(A8="","",RANDBETWEEN($C$1,$C$2)) -> 36 | C8: =IFERROR($C$1-1+_xlfn.RANK.EQ(B8,$B$4:$B$40)+COUNTIF(B$4:$B8,B8)-1,"") -> 1 | D8: =IFERROR(VLOOKUP(C8,Discussion!A:B,2,0),"") -> 1.1 | E8: =IFERROR(VLOOKUP(D8&"Viet",Discussion!C:D,2,0),"") -> Tôi muốn hỏi anh về doanh số của anh gần đây. | F8: =IFERROR(VLOOKUP(D8&"Eng",Discussion!C:D,2,0),"") -> I want to ask you about your sales lately.
A9: =IFERROR(IF(A8+1>$C$2,"",A8+1),"") -> 6 | B9: =IF(A9="","",RANDBETWEEN($C$1,$C$2)) -> 28 | C9: =IFERROR($C$1-1+_xlfn.RANK.EQ(B9,$B$4:$B$40)+COUNTIF(B$4:$B9,B9)-1,"") -> 12 | D9: =IFERROR(VLOOKUP(C9,Discussion!A:B,2,0),"") -> 3.2 | E9: =IFERROR(VLOOKUP(D9&"Viet",Discussion!C:D,2,0),"") -> Tôi muốn xác nhận lại mục đích của cuộc họp này. | F9: =IFERROR(VLOOKUP(D9&"Eng",Discussion!C:D,2,0),"") -> I would like to confirm the purpose of this meeting.
A10: =IFERROR(IF(A9+1>$C$2,"",A9+1),"") -> 7 | B10: =IF(A10="","",RANDBETWEEN($C$1,$C$2)) -> 30 | C10: =IFERROR($C$1-1+_xlfn.RANK.EQ(B10,$B$4:$B$40)+COUNTIF(B$4:$B10,B10)-1,"") -> 10 | D10: =IFERROR(VLOOKUP(C10,Discussion!A:B,2,0),"") -> 2.5 | E10: =IFERROR(VLOOKUP(D10&"Viet",Discussion!C:D,2,0),"") -> Chúng tôi muốn thảo luận chi tiết hơn. | F10: =IFERROR(VLOOKUP(D10&"Eng",Discussion!C:D,2,0),"") -> We’d like to discuss in more detail.
A11: =IFERROR(IF(A10+1>$C$2,"",A10+1),"") -> 8 | B11: =IF(A11="","",RANDBETWEEN($C$1,$C$2)) -> 33 | C11: =IFERROR($C$1-1+_xlfn.RANK.EQ(B11,$B$4:$B$40)+COUNTIF(B$4:$B11,B11)-1,"") -> 6 | D11: =IFERROR(VLOOKUP(C11,Discussion!A:B,2,0),"") -> 2.1 | E11: =IFERROR(VLOOKUP(D11&"Viet",Discussion!C:D,2,0),"") -> Chúng tôi muốn thảo luận về mức giá mà ông đưa ra. | F11: =IFERROR(VLOOKUP(D11&"Eng",Discussion!C:D,2,0),"") -> We’d like to discuss the price you quoted.
A12: =IFERROR(IF(A11+1>$C$2,"",A11+1),"") -> 9 | B12: =IF(A12="","",RANDBETWEEN($C$1,$C$2)) -> 27 | C12: =IFERROR($C$1-1+_xlfn.RANK.EQ(B12,$B$4:$B$40)+COUNTIF(B$4:$B12,B12)-1,"") -> 14 | D12: =IFERROR(VLOOKUP(C12,Discussion!A:B,2,0),"") -> 3.4 | E12: =IFERROR(VLOOKUP(D12&"Viet",Discussion!C:D,2,0),"") -> Tôi muốn đánh dấu một số điểm để thảo luận. | F12: =IFERROR(VLOOKUP(D12&"Eng",Discussion!C:D,2,0),"") -> I would like to flag a number of points for discussion.
A13: =IFERROR(IF(A12+1>$C$2,"",A12+1),"") -> 10 | B13: =IF(A13="","",RANDBETWEEN($C$1,$C$2)) -> 11 | C13: =IFERROR($C$1-1+_xlfn.RANK.EQ(B13,$B$4:$B$40)+COUNTIF(B$4:$B13,B13)-1,"") -> 26 | D13: =IFERROR(VLOOKUP(C13,Discussion!A:B,2,0),"") -> 4.3 | E13: =IFERROR(VLOOKUP(D13&"Viet",Discussion!C:D,2,0),"") -> Bạn giải thích cho tôi với? | F13: =IFERROR(VLOOKUP(D13&"Eng",Discussion!C:D,2,0),"") -> Could you explain to me?
A14: =IFERROR(IF(A13+1>$C$2,"",A13+1),"") -> 11 | B14: =IF(A14="","",RANDBETWEEN($C$1,$C$2)) -> 22 | C14: =IFERROR($C$1-1+_xlfn.RANK.EQ(B14,$B$4:$B$40)+COUNTIF(B$4:$B14,B14)-1,"") -> 20 | D14: =IFERROR(VLOOKUP(C14,Discussion!A:B,2,0),"") -> 3.10 | E14: =IFERROR(VLOOKUP(D14&"Viet",Discussion!C:D,2,0),"") -> Tôi xin được tiếp tục. | F14: =IFERROR(VLOOKUP(D14&"Eng",Discussion!C:D,2,0),"") -> I would like to move on.
A15: =IFERROR(IF(A14+1>$C$2,"",A14+1),"") -> 12 | B15: =IF(A15="","",RANDBETWEEN($C$1,$C$2)) -> 7 | C15: =IFERROR($C$1-1+_xlfn.RANK.EQ(B15,$B$4:$B$40)+COUNTIF(B$4:$B15,B15)-1,"") -> 29 | D15: =IFERROR(VLOOKUP(C15,Discussion!A:B,2,0),"") -> 4.6 | E15: =IFERROR(VLOOKUP(D15&"Viet",Discussion!C:D,2,0),"") -> Anh có thể bắt đầu được chưa? | F15: =IFERROR(VLOOKUP(D15&"Eng",Discussion!C:D,2,0),"") -> Could you start things off?
A16: =IFERROR(IF(A15+1>$C$2,"",A15+1),"") -> 13 | B16: =IF(A16="","",RANDBETWEEN($C$1,$C$2)) -> 36 | C16: =IFERROR($C$1-1+_xlfn.RANK.EQ(B16,$B$4:$B$40)+COUNTIF(B$4:$B16,B16)-1,"") -> 2 | D16: =IFERROR(VLOOKUP(C16,Discussion!A:B,2,0),"") -> 1.2 | E16: =IFERROR(VLOOKUP(D16&"Viet",Discussion!C:D,2,0),"") -> Tôi muốn hỏi anh về lợi nhuận của anh gần đây. | F16: =IFERROR(VLOOKUP(D16&"Eng",Discussion!C:D,2,0),"") -> I want to ask you about your profits lately.
... A72: =IFERROR(IF(A71+1>$C$2,"",A71+1),"") | B72: =IF(A72="","",RANDBETWEEN($C$1,$C$2)) | C72: =IFERROR($C$1-1+_xlfn.RANK.EQ(B72,$B$4:$B$40)+COUNTIF(B$4:$B72,B72)-1,"") | D72: =IFERROR(VLOOKUP(C72,Discussion!A:B,2,0),"") | E72: =IFERROR(VLOOKUP(D72&"Viet",Discussion!C:D,2,0),"") | F72: =IFERROR(VLOOKUP(D72&"Eng",Discussion!C:D,2,0),"")
A73: =IFERROR(IF(A72+1>$C$2,"",A72+1),"") | B73: =IF(A73="","",RANDBETWEEN($C$1,$C$2)) | C73: =IFERROR($C$1-1+_xlfn.RANK.EQ(B73,$B$4:$B$40)+COUNTIF(B$4:$B73,B73)-1,"") | D73: =IFERROR(VLOOKUP(C73,Discussion!A:B,2,0),"")
A74: =IFERROR(IF(A73+1>$C$2,"",A73+1),"") | B74: =IF(A74="","",RANDBETWEEN($C$1,$C$2)) | C74: =IFERROR($C$1-1+_xlfn.RANK.EQ(B74,$B$4:$B$40)+COUNTIF(B$4:$B74,B74)-1,"") | D74: =IFERROR(VLOOKUP(C74,Discussion!A:B,2,0),"")
A75: =IFERROR(IF(A74+1>$C$2,"",A74+1),"") | B75: =IF(A75="","",RANDBETWEEN($C$1,$C$2)) | C75: =IFERROR($C$1-1+_xlfn.RANK.EQ(B75,$B$4:$B$40)+COUNTIF(B$4:$B75,B75)-1,"") | D75: =IFERROR(VLOOKUP(C75,Discussion!A:B,2,0),"")
A76: =IFERROR(IF(A75+1>$C$2,"",A75+1),"") | B76: =IF(A76="","",RANDBETWEEN($C$1,$C$2)) | C76: =IFERROR($C$1-1+_xlfn.RANK.EQ(B76,$B$4:$B$40)+COUNTIF(B$4:$B76,B76)-1,"") | D76: =IFERROR(VLOOKUP(C76,Discussion!A:B,2,0),"")
A77: =IFERROR(IF(A76+1>$C$2,"",A76+1),"") | B77: =IF(A77="","",RANDBETWEEN($C$1,$C$2)) | C77: =IFERROR($C$1-1+_xlfn.RANK.EQ(B77,$B$4:$B$40)+COUNTIF(B$4:$B77,B77)-1,"") | D77: =IFERROR(VLOOKUP(C77,Discussion!A:B,2,0),"")
A78: =IFERROR(IF(A77+1>$C$2,"",A77+1),"") | B78: =IF(A78="","",RANDBETWEEN($C$1,$C$2)) | C78: =IFERROR($C$1-1+_xlfn.RANK.EQ(B78,$B$4:$B$40)+COUNTIF(B$4:$B78,B78)-1,"") | D78: =IFERROR(VLOOKUP(C78,Discussion!A:B,2,0),"")
A79: =IFERROR(IF(A78+1>$C$2,"",A78+1),"") | B79: =IF(A79="","",RANDBETWEEN($C$1,$C$2)) | C79: =IFERROR($C$1-1+_xlfn.RANK.EQ(B79,$B$4:$B$40)+COUNTIF(B$4:$B79,B79)-1,"") | D79: =IFERROR(VLOOKUP(C79,Discussion!A:B,2,0),"")
A80: =IFERROR(IF(A79+1>$C$2,"",A79+1),"") | B80: =IF(A80="","",RANDBETWEEN($C$1,$C$2)) | C80: =IFERROR($C$1-1+_xlfn.RANK.EQ(B80,$B$4:$B$40)+COUNTIF(B$4:$B80,B80)-1,"") | D80: =IFERROR(VLOOKUP(C80,Discussion!A:B,2,0),"")
A81: =IFERROR(IF(A80+1>$C$2,"",A80+1),"") | B81: =IF(A81="","",RANDBETWEEN($C$1,$C$2)) | C81: =IFERROR($C$1-1+_xlfn.RANK.EQ(B81,$B$4:$B$40)+COUNTIF(B$4:$B81,B81)-1,"") | D81: =IFERROR(VLOOKUP(C81,Discussion!A:B,2,0),"")
A82: =IFERROR(IF(A81+1>$C$2,"",A81+1),"") | B82: =IF(A82="","",RANDBETWEEN($C$1,$C$2)) | C82: =IFERROR($C$1-1+_xlfn.RANK.EQ(B82,$B$4:$B$40)+COUNTIF(B$4:$B82,B82)-1,"") | D82: =IFERROR(VLOOKUP(C82,Discussion!A:B,2,0),"")
A83: =IFERROR(IF(A82+1>$C$2,"",A82+1),"") | B83: =IF(A83="","",RANDBETWEEN($C$1,$C$2)) | C83: =IFERROR($C$1-1+_xlfn.RANK.EQ(B83,$B$4:$B$40)+COUNTIF(B$4:$B83,B83)-1,"") | D83: =IFERROR(VLOOKUP(C83,Discussion!A:B,2,0),"")
A84: =IFERROR(IF(A83+1>$C$2,"",A83+1),"") | B84: =IF(A84="","",RANDBETWEEN($C$1,$C$2)) | C84: =IFERROR($C$1-1+_xlfn.RANK.EQ(B84,$B$4:$B$40)+COUNTIF(B$4:$B84,B84)-1,"") | D84: =IFERROR(VLOOKUP(C84,Discussion!A:B,2,0),"")
... A142: =IFERROR(IF(A141+1>$C$2,"",A141+1),"") | B142: =IF(A142="","",RANDBETWEEN($C$1,$C$2)) | C142: =IFERROR($C$1-1+_xlfn.RANK.EQ(B142,$B$4:$B$40)+COUNTIF(B$4:$B142,B142)-1,"") | D142: =IFERROR(VLOOKUP(C142,Discussion!A:B,2,0),"")
A143: =IFERROR(IF(A142+1>$C$2,"",A142+1),"") | B143: =IF(A143="","",RANDBETWEEN($C$1,$C$2))
A144: =IFERROR(IF(A143+1>$C$2,"",A143+1),"") | B144: =IF(A144="","",RANDBETWEEN($C$1,$C$2))
A145: =IFERROR(IF(A144+1>$C$2,"",A144+1),"") | B145: =IF(A145="","",RANDBETWEEN($C$1,$C$2))
A146: =IFERROR(IF(A145+1>$C$2,"",A145+1),"") | B146: =IF(A146="","",RANDBETWEEN($C$1,$C$2))
A147: =IFERROR(IF(A146+1>$C$2,"",A146+1),"") | B147: =IF(A147="","",RANDBETWEEN($C$1,$C$2))
A148: =IFERROR(IF(A147+1>$C$2,"",A147+1),"") | B148: =IF(A148="","",RANDBETWEEN($C$1,$C$2))
A149: =IFERROR(IF(A148+1>$C$2,"",A148+1),"") | B149: =IF(A149="","",RANDBETWEEN($C$1,$C$2))
A150: =IFERROR(IF(A149+1>$C$2,"",A149+1),"") | B150: =IF(A150="","",RANDBETWEEN($C$1,$C$2))
A151: =IFERROR(IF(A150+1>$C$2,"",A150+1),"") | B151: =IF(A151="","",RANDBETWEEN($C$1,$C$2))
A152: =IFERROR(IF(A151+1>$C$2,"",A151+1),"") | B152: =IF(A152="","",RANDBETWEEN($C$1,$C$2))
...

Sheet Sheet1

Sheet Sheet2
