Workbook

Sheet Expressing opinions
B2: TOPIC: EXPRESSING OPINIONS
A3: No | B3: No | C3: ID | D3: Sentence | E3: Type | F3: Link | G3: ID | H3: Copy Google drive to …
B4: 1 | C4: 1Struc | D4: I THINK... /Tôi nghĩ là.../ | E4: Struc | F4: =IF(G4="","","https://docs.google.com/uc?export=download&id="&G4)
B5: 1.1 | C5: 1.1Viet | D5: Tôi nghĩ là nó ngầu đấy. | E5: Viet | F5: =IF(G5="","","https://docs.google.com/uc?export=download&id="&G5) | G5: =IFERROR(LEFT(RIGHT(H5,LEN(H5)-32),LEN(RIGHT(H5,LEN(H5)-32))-17),"")
A6: 1 | B6: 1.1 | C6: 1.1Eng | D6: I think it is cool. | E6: Eng | F6: =IF(G6="","","https://docs.google.com/uc?export=download&id="&G6) | G6: =IFERROR(LEFT(RIGHT(H6,LEN(H6)-32),LEN(RIGHT(H6,LEN(H6)-32))-17),"")
B7: 1.1 | C7: 1.1Phon | D7: aɪ θɪŋk ɪt ɪz ku:l | E7: Phon | F7: =IF(G7="","","https://docs.google.com/uc?export=download&id="&G7) | G7: =IFERROR(LEFT(RIGHT(H7,LEN(H7)-32),LEN(RIGHT(H7,LEN(H7)-32))-17),"")
B8: 1.2 | C8: 1.2Viet | D8: Tôi nghĩ đó là một ý kiến hay. | E8: Viet | F8: =IF(G8="","","https://docs.google.com/uc?export=download&id="&G8) | G8: =IFERROR(LEFT(RIGHT(H8,LEN(H8)-32),LEN(RIGHT(H8,LEN(H8)-32))-17),"")
A9: 2 | B9: 1.2 | C9: 1.2Eng | D9: I think it is a good idea. | E9: Eng | F9: =IF(G9="","","https://docs.google.com/uc?export=download&id="&G9) | G9: =IFERROR(LEFT(RIGHT(H9,LEN(H9)-32),LEN(RIGHT(H9,LEN(H9)-32))-17),"")
B10: 1.2 | C10: 1.2Phon | D10: aɪ θɪŋk ɪt ɪz ə gʊd aɪˈdi:ə | E10: Phon | F10: =IF(G10="","","https://docs.google.com/uc?export=download&id="&G10) | G10: =IFERROR(LEFT(RIGHT(H10,LEN(H10)-32),LEN(RIGHT(H10,LEN(H10)-32))-17),"")
B11: 1.3 | C11: 1.3Viet | D11: Tôi nghĩ điều đó hợp lí. | E11: Viet | F11: =IF(G11="","","https://docs.google.com/uc?export=download&id="&G11) | G11: =IFERROR(LEFT(RIGHT(H11,LEN(H11)-32),LEN(RIGHT(H11,LEN(H11)-32))-17),"")
A12: 3 | B12: 1.3 | C12: 1.3Eng | D12: I think it makes sense. | E12: Eng | F12: =IF(G12="","","https://docs.google.com/uc?export=download&id="&G12) | G12: =IFERROR(LEFT(RIGHT(H12,LEN(H12)-32),LEN(RIGHT(H12,LEN(H12)-32))-17),"")
B13: 1.3 | C13: 1.3Phon | D13: aɪ θɪŋk ɪt meɪks sɛns | E13: Phon | F13: =IF(G13="","","https://docs.google.com/uc?export=download&id="&G13) | G13: =IFERROR(LEFT(RIGHT(H13,LEN(H13)-32),LEN(RIGHT(H13,LEN(H13)-32))-17),"")
B14: 1.4 | C14: 1.4Viet | D14: Tôi nghĩ là cậu đúng. | E14: Viet | F14: =IF(G14="","","https://docs.google.com/uc?export=download&id="&G14) | G14: =IFERROR(LEFT(RIGHT(H14,LEN(H14)-32),LEN(RIGHT(H14,LEN(H14)-32))-17),"")
A15: 4 | B15: 1.4 | C15: 1.4Eng | D15: I think you are right. | E15: Eng | F15: =IF(G15="","","https://docs.google.com/uc?export=download&id="&G15) | G15: =IFERROR(LEFT(RIGHT(H15,LEN(H15)-32),LEN(RIGHT(H15,LEN(H15)-32))-17),"")
B16: 1.4 | C16: 1.4Phon | D16: aɪ θɪŋk ju: a:r raɪt | E16: Phon | F16: =IF(G16="","","https://docs.google.com/uc?export=download&id="&G16) | G16: =IFERROR(LEFT(RIGHT(H16,LEN(H16)-32),LEN(RIGHT(H16,LEN(H16)-32))-17),"")
B17: 1.5 | C17: 1.5Viet | D17: Tôi nghĩ là họ hiểu lầm chúng ta. | E17: Viet | F17: =IF(G17="","","https://docs.google.com/uc?export=download&id="&G17) | G17: =IFERROR(LEFT(RIGHT(H17,LEN(H17)-32),LEN(RIGHT(H17,LEN(H17)-32))-17),"")
A18: 5 | B18: 1.5 | C18: 1.5Eng | D18: I think they got us wrong. | E18: Eng | F18: =IF(G18="","","https://docs.google.com/uc?export=download&id="&G18) | G18: =IFERROR(LEFT(RIGHT(H18,LEN(H18)-32),LEN(RIGHT(H18,LEN(H18)-32))-17),"")
B19: 1.5 | C19: 1.5Phon | D19: aɪ θɪŋk ðeɪ ga:t ʌs rɔ:ŋ | E19: Phon | F19: =IF(G19="","","https://docs.google.com/uc?export=download&id="&G19) | G19: =IFERROR(LEFT(RIGHT(H19,LEN(H19)-32),LEN(RIGHT(H19,LEN(H19)-32))-17),"")
B20: 2 | C20: 2Struc | D20: I DON’T THINK... /Tôi không nghĩ là.../ | E20: Struc | F20: =IF(G20="","","https://docs.google.com/uc?export=download&id="&G20) | G20: =IFERROR(LEFT(RIGHT(H20,LEN(H20)-32),LEN(RIGHT(H20,LEN(H20)-32))-17),"")
B21: 2.1 | C21: 2.1Viet | D21: Tôi không nghĩ là nó đáng. | E21: Viet | F21: =IF(G21="","","https://docs.google.com/uc?export=download&id="&G21) | G21: =IFERROR(LEFT(RIGHT(H21,LEN(H21)-32),LEN(RIGHT(H21,LEN(H21)-32))-17),"")
A22: 6 | B22: 2.1 | C22: 2.1Eng | D22: I don’t think it is worthy. | E22: Eng | F22: =IF(G22="","","https://docs.google.com/uc?export=download&id="&G22) | G22: =IFERROR(LEFT(RIGHT(H22,LEN(H22)-32),LEN(RIGHT(H22,LEN(H22)-32))-17),"")
B23: 2.1 | C23: 2.1Phon | D23: aɪ doʊnt θɪŋk ɪt ɪz ˈwɜ:rði | E23: Phon | F23: =IF(G23="","","https://docs.google.com/uc?export=download&id="&G23) | G23: =IFERROR(LEFT(RIGHT(H23,LEN(H23)-32),LEN(RIGHT(H23,LEN(H23)-32))-17),"")
B24: 2.2 | C24: 2.2Viet | D24: Tôi không nghĩ anh ta chân thành. | E24: Viet | F24: =IF(G24="","","https://docs.google.com/uc?export=download&id="&G24) | G24: =IFERROR(LEFT(RIGHT(H24,LEN(H24)-32),LEN(RIGHT(H24,LEN(H24)-32))-17),"")
A25: 7 | B25: 2.2 | C25: 2.2Eng | D25: I don’t think he is honest. | E25: Eng | F25: =IF(G25="","","https://docs.google.com/uc?export=download&id="&G25) | G25: =IFERROR(LEFT(RIGHT(H25,LEN(H25)-32),LEN(RIGHT(H25,LEN(H25)-32))-17),"")
B26: 2.2 | C26: 2.2Phon | D26: aɪ doʊnt θɪŋk hi: ɪz ˈaːnɪst | E26: Phon | F26: =IF(G26="","","https://docs.google.com/uc?export=download&id="&G26) | G26: =IFERROR(LEFT(RIGHT(H26,LEN(H26)-32),LEN(RIGHT(H26,LEN(H26)-32))-17),"")
B27: 2.3 | C27: 2.3Viet | D27: Tôi không nghĩ cô ta xứng đáng với nó. | E27: Viet | F27: =IF(G27="","","https://docs.google.com/uc?export=download&id="&G27) | G27: =IFERROR(LEFT(RIGHT(H27,LEN(H27)-32),LEN(RIGHT(H27,LEN(H27)-32))-17),"")
A28: 8 | B28: 2.3 | C28: 2.3Eng | D28: I don’t think she deserves it. | E28: Eng | F28: =IF(G28="","","https://docs.google.com/uc?export=download&id="&G28) | G28: =IFERROR(LEFT(RIGHT(H28,LEN(H28)-32),LEN(RIGHT(H28,LEN(H28)-32))-17),"")
B29: 2.3 | C29: 2.3Phon | D29: aɪ doʊnt θɪŋk ʃi: dɪˈzɜ:rvz ɪt | E29: Phon | F29: =IF(G29="","","https://docs.google.com/uc?export=download&id="&G29) | G29: =IFERROR(LEFT(RIGHT(H29,LEN(H29)-32),LEN(RIGHT(H29,LEN(H29)-32))-17),"")
B30: 2.4 | C30: 2.4Viet | D30: Tôi không nghĩ cậu sẽ thích mấy món ăn này. | E30: Viet | F30: =IF(G30="","","https://docs.google.com/uc?export=download&id="&G30) | G30: =IFERROR(LEFT(RIGHT(H30,LEN(H30)-32),LEN(RIGHT(H30,LEN(H30)-32))-17),"")
A31: 9 | B31: 2.4 | C31: 2.4Eng | D31: I don’t think you will like the food. | E31: Eng | F31: =IF(G31="","","https://docs.google.com/uc?export=download&id="&G31) | G31: =IFERROR(LEFT(RIGHT(H31,LEN(H31)-32),LEN(RIGHT(H31,LEN(H31)-32))-17),"")
B32: 2.4 | C32: 2.4Phon | D32: aɪ doʊnt θɪŋk ju: wɪl laɪk ðə fu:d | E32: Phon | F32: =IF(G32="","","https://docs.google.com/uc?export=download&id="&G32) | G32: =IFERROR(LEFT(RIGHT(H32,LEN(H32)-32),LEN(RIGHT(H32,LEN(H32)-32))-17),"")
B33: 3 | C33: 3Struc | D33: I THOUGHT… /Tôi tưởng là…/ | E33: Struc | F33: =IF(G33="","","https://docs.google.com/uc?export=download&id="&G33) | G33: =IFERROR(LEFT(RIGHT(H33,LEN(H33)-32),LEN(RIGHT(H33,LEN(H33)-32))-17),"")
B34: 3.1 | C34: 3.1Viet | D34: Tôi tưởng đó là lời nói dối. | E34: Viet | F34: =IF(G34="","","https://docs.google.com/uc?export=download&id="&G34) | G34: =IFERROR(LEFT(RIGHT(H34,LEN(H34)-32),LEN(RIGHT(H34,LEN(H34)-32))-17),"")
A35: 10 | B35: 3.1 | C35: 3.1Eng | D35: I thought it was a lie. | E35: Eng | F35: =IF(G35="","","https://docs.google.com/uc?export=download&id="&G35) | G35: =IFERROR(LEFT(RIGHT(H35,LEN(H35)-32),LEN(RIGHT(H35,LEN(H35)-32))-17),"")
B36: 3.1 | C36: 3.1Phon | D36: aɪ θɔ:t ɪt wʌz ə laɪ | E36: Phon | F36: =IF(G36="","","https://docs.google.com/uc?export=download&id="&G36) | G36: =IFERROR(LEFT(RIGHT(H36,LEN(H36)-32),LEN(RIGHT(H36,LEN(H36)-32))-17),"")
B37: 3.2 | C37: 3.2Viet | D37: Tôi đã nghĩ đó là một ý tưởng ngớ ngẩn. | E37: Viet | F37: =IF(G37="","","https://docs.google.com/uc?export=download&id="&G37) | G37: =IFERROR(LEFT(RIGHT(H37,LEN(H37)-32),LEN(RIGHT(H37,LEN(H37)-32))-17),"")
A38: 11 | B38: 3.2 | C38: 3.2Eng | D38: I thought it was a stupid idea. | E38: Eng | F38: =IF(G38="","","https://docs.google.com/uc?export=download&id="&G38) | G38: =IFERROR(LEFT(RIGHT(H38,LEN(H38)-32),LEN(RIGHT(H38,LEN(H38)-32))-17),"")
B39: 3.2 | C39: 3.2Phon | D39: aɪ θɔ:t ɪt wʌz ə ˈstuːpɪd aɪˈdi:ə | E39: Phon | F39: =IF(G39="","","https://docs.google.com/uc?export=download&id="&G39) | G39: =IFERROR(LEFT(RIGHT(H39,LEN(H39)-32),LEN(RIGHT(H39,LEN(H39)-32))-17),"")
B40: 3.3 | C40: 3.3Viet | D40: Tôi đã nghĩ là nó có thể chấp nhận được. | E40: Viet | F40: =IF(G40="","","https://docs.google.com/uc?export=download&id="&G40) | G40: =IFERROR(LEFT(RIGHT(H40,LEN(H40)-32),LEN(RIGHT(H40,LEN(H40)-32))-17),"")
A41: 12 | B41: 3.3 | C41: 3.3Eng | D41: I thought it was acceptable. | E41: Eng | F41: =IF(G41="","","https://docs.google.com/uc?export=download&id="&G41) | G41: =IFERROR(LEFT(RIGHT(H41,LEN(H41)-32),LEN(RIGHT(H41,LEN(H41)-32))-17),"")
...

Sheet Viet
B2: Sentence | C2: Link | D2: ID | E2: Copy Google drive to …
B3: 01-05 | C3: =IF(D3="","","https://docs.google.com/uc?export=download&id="&D3) | D3: =IFERROR(LEFT(RIGHT(E3,LEN(E3)-32),LEN(RIGHT(E3,LEN(E3)-32))-17),"")
B4: 06-10 | C4: =IF(D4="","","https://docs.google.com/uc?export=download&id="&D4) | D4: =IFERROR(LEFT(RIGHT(E4,LEN(E4)-32),LEN(RIGHT(E4,LEN(E4)-32))-17),"")
B5: 11-15 | C5: =IF(D5="","","https://docs.google.com/uc?export=download&id="&D5) | D5: =IFERROR(LEFT(RIGHT(E5,LEN(E5)-32),LEN(RIGHT(E5,LEN(E5)-32))-17),"")
B6: 16-23 | C6: =IF(D6="","","https://docs.google.com/uc?export=download&id="&D6) | D6: =IFERROR(LEFT(RIGHT(E6,LEN(E6)-32),LEN(RIGHT(E6,LEN(E6)-32))-17),"")
C7: =IF(D7="","","https://docs.google.com/uc?export=download&id="&D7) | D7: =IFERROR(LEFT(RIGHT(E7,LEN(E7)-32),LEN(RIGHT(E7,LEN(E7)-32))-17),"")

Sheet Sum
B2: Sentence | C2: Link | D2: ID | E2: Copy Google drive to …
B3: Woman | C3: =IF(D3="","","https://docs.google.com/uc?export=download&id="&D3) | D3: =IFERROR(LEFT(RIGHT(E3,LEN(E3)-32),LEN(RIGHT(E3,LEN(E3)-32))-17),"")
B4: Man | C4: =IF(D4="","","https://docs.google.com/uc?export=download&id="&D4) | D4: =IFERROR(LEFT(RIGHT(E4,LEN(E4)-32),LEN(RIGHT(E4,LEN(E4)-32))-17),"")

Sheet Ramdom
B1: From | C1: 1
B2: To | C2: 10
C3: No | D3: No | E3: Viet | F3: Eng
A4: =C1 -> 1 | B4: =IF(A4="","",RANDBETWEEN($C$1,$C$2)) -> 10 | C4: =IFERROR($C$1-1+_xlfn.RANK.EQ(B4,$B$4:$B$166)+COUNTIF(B$4:$B4,B4)-1,"") -> 1 | D4: =IFERROR(VLOOKUP(C4,'Expressing opinions'!A:B,2,0),"") -> 1.1 | E4: =IFERROR(VLOOKUP(D4&"Viet",'Expressing opinions'!C:D,2,0),"") -> Tôi nghĩ là nó ngầu đấy. | F4: =IFERROR(VLOOKUP(D4&"Eng",'Expressing opinions'!C:D,2,0),"") -> I think it is cool.
A5: =IFERROR(IF(A4+1>$C$2,"",A4+1),"") -> 2 | B5: =IF(A5="","",RANDBETWEEN($C$1,$C$2)) -> 5 | C5: =IFERROR($C$1-1+_xlfn.RANK.EQ(B5,$B$4:$B$166)+COUNTIF(B$4:$B5,B5)-1,"") -> 6 | D5: =IFERROR(VLOOKUP(C5,'Expressing opinions'!A:B,2,0),"") -> 2.1 | E5: =IFERROR(VLOOKUP(D5&"Viet",'Expressing opinions'!C:D,2,0),"") -> Tôi không nghĩ là nó đáng. | F5: =IFERROR(VLOOKUP(D5&"Eng",'Expressing opinions'!C:D,2,0),"") -> I don’t think it is worthy.
A6: =IFERROR(IF(A5+1>$C$2,"",A5+1),"") -> 3 | B6: =IF(A6="","",RANDBETWEEN($C$1,$C$2)) -> 2 | C6: =IFERROR($C$1-1+_xlfn.RANK.EQ(B6,$B$4:$B$166)+COUNTIF(B$4:$B6,B6)-1,"") -> 10 | D6: =IFERROR(VLOOKUP(C6,'Expressing opinions'!A:B,2,0),"") -> 3.1 | E6: =IFERROR(VLOOKUP(D6&"Viet",'Expressing opinions'!C:D,2,0),"") -> Tôi tưởng đó là lời nói dối. | F6: =IFERROR(VLOOKUP(D6&"Eng",'Expressing opinions'!C:D,2,0),"") -> I thought it was a lie.
A7: =IFERROR(IF(A6+1>$C$2,"",A6+1),"") -> 4 | B7: =IF(A7="","",RANDBETWEEN($C$1,$C$2)) -> 9 | C7: =IFERROR($C$1-1+_xlfn.RANK.EQ(B7,$B$4:$B$166)+COUNTIF(B$4:$B7,B7)-1,"") -> 3 | D7: =IFERROR(VLOOKUP(C7,'Expressing opinions'!A:B,2,0),"") -> 1.3 | E7: =IFERROR(VLOOKUP(D7&"Viet",'Expressing opinions'!C:D,2,0),"") -> Tôi nghĩ điều đó hợp lí. | F7: =IFERROR(VLOOKUP(D7&"Eng",'Expressing opinions'!C:D,2,0),"") -> I think it makes sense.
A8: =IFERROR(IF(A7+1>$C$2,"",A7+1),"") -> 5 | B8: =IF(A8="","",RANDBETWEEN($C$1,$C$2)) -> 10 | C8: =IFERROR($C$1-1+_xlfn.RANK.EQ(B8,$B$4:$B$166)+COUNTIF(B$4:$B8,B8)-1,"") -> 2 | D8: =IFERROR(VLOOKUP(C8,'Expressing opinions'!A:B,2,0),"") -> 1.2 | E8: =IFERROR(VLOOKUP(D8&"Viet",'Expressing opinions'!C:D,2,0),"") -> Tôi nghĩ đó là một ý kiến hay. | F8: =IFERROR(VLOOKUP(D8&"Eng",'Expressing opinions'!C:D,2,0),"") -> I think it is a good idea.
A9: =IFERROR(IF(A8+1>$C$2,"",A8+1),"") -> 6 | B9: =IF(A9="","",RANDBETWEEN($C$1,$C$2)) -> 8 | C9: =IFERROR($C$1-1+_xlfn.RANK.EQ(B9,$B$4:$B$166)+COUNTIF(B$4:$B9,B9)-1,"") -> 5 | D9: =IFERROR(VLOOKUP(C9,'Expressing opinions'!A:B,2,0),"") -> 1.5 | E9: =IFERROR(VLOOKUP(D9&"Viet",'Expressing opinions'!C:D,2,0),"") -> Tôi nghĩ là họ hiểu lầm chúng ta. | F9: =IFERROR(VLOOKUP(D9&"Eng",'Expressing opinions'!C:D,2,0),"") -> I think they got us wrong.
A10: =IFERROR(IF(A9+1>$C$2,"",A9+1),"") -> 7 | B10: =IF(A10="","",RANDBETWEEN($C$1,$C$2)) -> 3 | C10: =IFERROR($C$1-1+_xlfn.RANK.EQ(B10,$B$4:$B$166)+COUNTIF(B$4:$B10,B10)-1,"") -> 9 | D10: =IFERROR(VLOOKUP(C10,'Expressing opinions'!A:B,2,0),"") -> 2.4 | E10: =IFERROR(VLOOKUP(D10&"Viet",'Expressing opinions'!C:D,2,0),"") -> Tôi không nghĩ cậu sẽ thích mấy món ăn này. | F10: =IFERROR(VLOOKUP(D10&"Eng",'Expressing opinions'!C:D,2,0),"") -> I don’t think you will like the food.
A11: =IFERROR(IF(A10+1>$C$2,"",A10+1),"") -> 8 | B11: =IF(A11="","",RANDBETWEEN($C$1,$C$2)) -> 9 | C11: =IFERROR($C$1-1+_xlfn.RANK.EQ(B11,$B$4:$B$166)+COUNTIF(B$4:$B11,B11)-1,"") -> 4 | D11: =IFERROR(VLOOKUP(C11,'Expressing opinions'!A:B,2,0),"") -> 1.4 | E11: =IFERROR(VLOOKUP(D11&"Viet",'Expressing opinions'!C:D,2,0),"") -> Tôi nghĩ là cậu đúng. | F11: =IFERROR(VLOOKUP(D11&"Eng",'Expressing opinions'!C:D,2,0),"") -> I think you are right.
A12: =IFERROR(IF(A11+1>$C$2,"",A11+1),"") -> 9 | B12: =IF(A12="","",RANDBETWEEN($C$1,$C$2)) -> 4 | C12: =IFERROR($C$1-1+_xlfn.RANK.EQ(B12,$B$4:$B$166)+COUNTIF(B$4:$B12,B12)-1,"") -> 7 | D12: =IFERROR(VLOOKUP(C12,'Expressing opinions'!A:B,2,0),"") -> 2.2 | E12: =IFERROR(VLOOKUP(D12&"Viet",'Expressing opinions'!C:D,2,0),"") -> Tôi không nghĩ anh ta chân thành. | F12: =IFERROR(VLOOKUP(D12&"Eng",'Expressing opinions'!C:D,2,0),"") -> I don’t think he is honest.
A13: =IFERROR(IF(A12+1>$C$2,"",A12+1),"") -> 10 | B13: =IF(A13="","",RANDBETWEEN($C$1,$C$2)) -> 4 | C13: =IFERROR($C$1-1+_xlfn.RANK.EQ(B13,$B$4:$B$166)+COUNTIF(B$4:$B13,B13)-1,"") -> 8 | D13: =IFERROR(VLOOKUP(C13,'Expressing opinions'!A:B,2,0),"") -> 2.3 | E13: =IFERROR(VLOOKUP(D13&"Viet",'Expressing opinions'!C:D,2,0),"") -> Tôi không nghĩ cô ta xứng đáng với nó. | F13: =IFERROR(VLOOKUP(D13&"Eng",'Expressing opinions'!C:D,2,0),"") -> I don’t think she deserves it.
A14: =IFERROR(IF(A13+1>$C$2,"",A13+1),"") | B14: =IF(A14="","",RANDBETWEEN($C$1,$C$2)) | C14: =IFERROR($C$1-1+_xlfn.RANK.EQ(B14,$B$4:$B$166)+COUNTIF(B$4:$B14,B14)-1,"") | D14: =IFERROR(VLOOKUP(C14,'Expressing opinions'!A:B,2,0),"") | E14: =IFERROR(VLOOKUP(D14&"Viet",'Expressing opinions'!C:D,2,0),"") | F14: =IFERROR(VLOOKUP(D14&"Eng",'Expressing opinions'!C:D,2,0),"")
A15: =IFERROR(IF(A14+1>$C$2,"",A14+1),"") | B15: =IF(A15="","",RANDBETWEEN($C$1,$C$2)) | C15: =IFERROR($C$1-1+_xlfn.RANK.EQ(B15,$B$4:$B$166)+COUNTIF(B$4:$B15,B15)-1,"") | D15: =IFERROR(VLOOKUP(C15,'Expressing opinions'!A:B,2,0),"") | E15: =IFERROR(VLOOKUP(D15&"Viet",'Expressing opinions'!C:D,2,0),"") | F15: =IFERROR(VLOOKUP(D15&"Eng",'Expressing opinions'!C:D,2,0),"")
A16: =IFERROR(IF(A15+1>$C$2,"",A15+1),"") | B16: =IF(A16="","",RANDBETWEEN($C$1,$C$2)) | C16: =IFERROR($C$1-1+_xlfn.RANK.EQ(B16,$B$4:$B$166)+COUNTIF(B$4:$B16,B16)-1,"") | D16: =IFERROR(VLOOKUP(C16,'Expressing opinions'!A:B,2,0),"") | E16: =IFERROR(VLOOKUP(D16&"Viet",'Expressing opinions'!C:D,2,0),"") | F16: =IFERROR(VLOOKUP(D16&"Eng",'Expressing opinions'!C:D,2,0),"")
A17: =IFERROR(IF(A16+1>$C$2,"",A16+1),"") | B17: =IF(A17="","",RANDBETWEEN($C$1,$C$2)) | C17: =IFERROR($C$1-1+_xlfn.RANK.EQ(B17,$B$4:$B$166)+COUNTIF(B$4:$B17,B17)-1,"") | D17: =IFERROR(VLOOKUP(C17,'Expressing opinions'!A:B,2,0),"") | E17: =IFERROR(VLOOKUP(D17&"Viet",'Expressing opinions'!C:D,2,0),"") | F17: =IFERROR(VLOOKUP(D17&"Eng",'Expressing opinions'!C:D,2,0),"") | L17: 4
A18: =IFERROR(IF(A17+1>$C$2,"",A17+1),"") | B18: =IF(A18="","",RANDBETWEEN($C$1,$C$2)) | C18: =IFERROR($C$1-1+_xlfn.RANK.EQ(B18,$B$4:$B$166)+COUNTIF(B$4:$B18,B18)-1,"") | D18: =IFERROR(VLOOKUP(C18,'Expressing opinions'!A:B,2,0),"") | E18: =IFERROR(VLOOKUP(D18&"Viet",'Expressing opinions'!C:D,2,0),"") | F18: =IFERROR(VLOOKUP(D18&"Eng",'Expressing opinions'!C:D,2,0),"")
A19: =IFERROR(IF(A18+1>$C$2,"",A18+1),"") | B19: =IF(A19="","",RANDBETWEEN($C$1,$C$2)) | C19: =IFERROR($C$1-1+_xlfn.RANK.EQ(B19,$B$4:$B$166)+COUNTIF(B$4:$B19,B19)-1,"") | D19: =IFERROR(VLOOKUP(C19,'Expressing opinions'!A:B,2,0),"") | E19: =IFERROR(VLOOKUP(D19&"Viet",'Expressing opinions'!C:D,2,0),"") | F19: =IFERROR(VLOOKUP(D19&"Eng",'Expressing opinions'!C:D,2,0),"") | L19: p
A20: =IFERROR(IF(A19+1>$C$2,"",A19+1),"") | B20: =IF(A20="","",RANDBETWEEN($C$1,$C$2)) | C20: =IFERROR($C$1-1+_xlfn.RANK.EQ(B20,$B$4:$B$166)+COUNTIF(B$4:$B20,B20)-1,"") | D20: =IFERROR(VLOOKUP(C20,'Expressing opinions'!A:B,2,0),"") | E20: =IFERROR(VLOOKUP(D20&"Viet",'Expressing opinions'!C:D,2,0),"") | F20: =IFERROR(VLOOKUP(D20&"Eng",'Expressing opinions'!C:D,2,0),"")
A21: =IFERROR(IF(A20+1>$C$2,"",A20+1),"") | B21: =IF(A21="","",RANDBETWEEN($C$1,$C$2)) | C21: =IFERROR($C$1-1+_xlfn.RANK.EQ(B21,$B$4:$B$166)+COUNTIF(B$4:$B21,B21)-1,"") | D21: =IFERROR(VLOOKUP(C21,'Expressing opinions'!A:B,2,0),"") | E21: =IFERROR(VLOOKUP(D21&"Viet",'Expressing opinions'!C:D,2,0),"") | F21: =IFERROR(VLOOKUP(D21&"Eng",'Expressing opinions'!C:D,2,0),"")
A22: =IFERROR(IF(A21+1>$C$2,"",A21+1),"") | B22: =IF(A22="","",RANDBETWEEN($C$1,$C$2)) | C22: =IFERROR($C$1-1+_xlfn.RANK.EQ(B22,$B$4:$B$166)+COUNTIF(B$4:$B22,B22)-1,"") | D22: =IFERROR(VLOOKUP(C22,'Expressing opinions'!A:B,2,0),"") | E22: =IFERROR(VLOOKUP(D22&"Viet",'Expressing opinions'!C:D,2,0),"") | F22: =IFERROR(VLOOKUP(D22&"Eng",'Expressing opinions'!C:D,2,0),"")
A23: =IFERROR(IF(A22+1>$C$2,"",A22+1),"") | B23: =IF(A23="","",RANDBETWEEN($C$1,$C$2)) | C23: =IFERROR($C$1-1+_xlfn.RANK.EQ(B23,$B$4:$B$166)+COUNTIF(B$4:$B23,B23)-1,"") | D23: =IFERROR(VLOOKUP(C23,'Expressing opinions'!A:B,2,0),"") | E23: =IFERROR(VLOOKUP(D23&"Viet",'Expressing opinions'!C:D,2,0),"") | F23: =IFERROR(VLOOKUP(D23&"Eng",'Expressing opinions'!C:D,2,0),"")
A24: =IFERROR(IF(A23+1>$C$2,"",A23+1),"") | B24: =IF(A24="","",RANDBETWEEN($C$1,$C$2)) | C24: =IFERROR($C$1-1+_xlfn.RANK.EQ(B24,$B$4:$B$166)+COUNTIF(B$4:$B24,B24)-1,"") | D24: =IFERROR(VLOOKUP(C24,'Expressing opinions'!A:B,2,0),"") | E24: =IFERROR(VLOOKUP(D24&"Viet",'Expressing opinions'!C:D,2,0),"") | F24: =IFERROR(VLOOKUP(D24&"Eng",'Expressing opinions'!C:D,2,0),"")
A25: =IFERROR(IF(A24+1>$C$2,"",A24+1),"") | B25: =IF(A25="","",RANDBETWEEN($C$1,$C$2)) | C25: =IFERROR($C$1-1+_xlfn.RANK.EQ(B25,$B$4:$B$166)+COUNTIF(B$4:$B25,B25)-1,"") | D25: =IFERROR(VLOOKUP(C25,'Expressing opinions'!A:B,2,0),"") | E25: =IFERROR(VLOOKUP(D25&"Viet",'Expressing opinions'!C:D,2,0),"") | F25: =IFERROR(VLOOKUP(D25&"Eng",'Expressing opinions'!C:D,2,0),"")
A26: =IFERROR(IF(A25+1>$C$2,"",A25+1),"") | B26: =IF(A26="","",RANDBETWEEN($C$1,$C$2)) | C26: =IFERROR($C$1-1+_xlfn.RANK.EQ(B26,$B$4:$B$166)+COUNTIF(B$4:$B26,B26)-1,"") | D26: =IFERROR(VLOOKUP(C26,'Expressing opinions'!A:B,2,0),"") | E26: =IFERROR(VLOOKUP(D26&"Viet",'Expressing opinions'!C:D,2,0),"") | F26: =IFERROR(VLOOKUP(D26&"Eng",'Expressing opinions'!C:D,2,0),"")
A27: =IFERROR(IF(A26+1>$C$2,"",A26+1),"") | B27: =IF(A27="","",RANDBETWEEN($C$1,$C$2)) | C27: =IFERROR($C$1-1+_xlfn.RANK.EQ(B27,$B$4:$B$166)+COUNTIF(B$4:$B27,B27)-1,"") | D27: =IFERROR(VLOOKUP(C27,'Expressing opinions'!A:B,2,0),"") | E27: =IFERROR(VLOOKUP(D27&"Viet",'Expressing opinions'!C:D,2,0),"") | F27: =IFERROR(VLOOKUP(D27&"Eng",'Expressing opinions'!C:D,2,0),"")
A28: =IFERROR(IF(A27+1>$C$2,"",A27+1),"") | B28: =IF(A28="","",RANDBETWEEN($C$1,$C$2)) | C28: =IFERROR($C$1-1+_xlfn.RANK.EQ(B28,$B$4:$B$166)+COUNTIF(B$4:$B28,B28)-1,"") | D28: =IFERROR(VLOOKUP(C28,'Expressing opinions'!A:B,2,0),"") | E28: =IFERROR(VLOOKUP(D28&"Viet",'Expressing opinions'!C:D,2,0),"") | F28: =IFERROR(VLOOKUP(D28&"Eng",'Expressing opinions'!C:D,2,0),"")
A29: =IFERROR(IF(A28+1>$C$2,"",A28+1),"") | B29: =IF(A29="","",RANDBETWEEN($C$1,$C$2)) | C29: =IFERROR($C$1-1+_xlfn.RANK.EQ(B29,$B$4:$B$166)+COUNTIF(B$4:$B29,B29)-1,"") | D29: =IFERROR(VLOOKUP(C29,'Expressing opinions'!A:B,2,0),"") | E29: =IFERROR(VLOOKUP(D29&"Viet",'Expressing opinions'!C:D,2,0),"") | F29: =IFERROR(VLOOKUP(D29&"Eng",'Expressing opinions'!C:D,2,0),"")
A30: =IFERROR(IF(A29+1>$C$2,"",A29+1),"") | B30: =IF(A30="","",RANDBETWEEN($C$1,$C$2)) | C30: =IFERROR($C$1-1+_xlfn.RANK.EQ(B30,$B$4:$B$166)+COUNTIF(B$4:$B30,B30)-1,"") | D30: =IFERROR(VLOOKUP(C30,'Expressing opinions'!A:B,2,0),"") | E30: =IFERROR(VLOOKUP(D30&"Viet",'Expressing opinions'!C:D,2,0),"") | F30: =IFERROR(VLOOKUP(D30&"Eng",'Expressing opinions'!C:D,2,0),"")
A31: =IFERROR(IF(A30+1>$C$2,"",A30+1),"") | B31: =IF(A31="","",RANDBETWEEN($C$1,$C$2)) | C31: =IFERROR($C$1-1+_xlfn.RANK.EQ(B31,$B$4:$B$166)+COUNTIF(B$4:$B31,B31)-1,"") | D31: =IFERROR(VLOOKUP(C31,'Expressing opinions'!A:B,2,0),"") | E31: =IFERROR(VLOOKUP(D31&"Viet",'Expressing opinions'!C:D,2,0),"") | F31: =IFERROR(VLOOKUP(D31&"Eng",'Expressing opinions'!C:D,2,0),"")
... A72: =IFERROR(IF(A71+1>$C$2,"",A71+1),"") | B72: =IF(A72="","",RANDBETWEEN($C$1,$C$2)) | C72: =IFERROR($C$1-1+_xlfn.RANK.EQ(B72,$B$4:$B$166)+COUNTIF(B$4:$B72,B72)-1,"") | D72: =IFERROR(VLOOKUP(C72,'Expressing opinions'!A:B,2,0),"") | E72: =IFERROR(VLOOKUP(D72&"Viet",'Expressing opinions'!C:D,2,0),"") | F72: =IFERROR(VLOOKUP(D72&"Eng",'Expressing opinions'!C:D,2,0),"")
A73: =IFERROR(IF(A72+1>$C$2,"",A72+1),"") | B73: =IF(A73="","",RANDBETWEEN($C$1,$C$2)) | C73: =IFERROR($C$1-1+_xlfn.RANK.EQ(B73,$B$4:$B$166)+COUNTIF(B$4:$B73,B73)-1,"") | D73: =IFERROR(VLOOKUP(C73,'Expressing opinions'!A:B,2,0),"")
A74: =IFERROR(IF(A73+1>$C$2,"",A73+1),"") | B74: =IF(A74="","",RANDBETWEEN($C$1,$C$2)) | C74: =IFERROR($C$1-1+_xlfn.RANK.EQ(B74,$B$4:$B$166)+COUNTIF(B$4:$B74,B74)-1,"") | D74: =IFERROR(VLOOKUP(C74,'Expressing opinions'!A:B,2,0),"")
A75: =IFERROR(IF(A74+1>$C$2,"",A74+1),"") | B75: =IF(A75="","",RANDBETWEEN($C$1,$C$2)) | C75: =IFERROR($C$1-1+_xlfn.RANK.EQ(B75,$B$4:$B$166)+COUNTIF(B$4:$B75,B75)-1,"") | D75: =IFERROR(VLOOKUP(C75,'Expressing opinions'!A:B,2,0),"")
A76: =IFERROR(IF(A75+1>$C$2,"",A75+1),"") | B76: =IF(A76="","",RANDBETWEEN($C$1,$C$2)) | C76: =IFERROR($C$1-1+_xlfn.RANK.EQ(B76,$B$4:$B$166)+COUNTIF(B$4:$B76,B76)-1,"") | D76: =IFERROR(VLOOKUP(C76,'Expressing opinions'!A:B,2,0),"")
A77: =IFERROR(IF(A76+1>$C$2,"",A76+1),"") | B77: =IF(A77="","",RANDBETWEEN($C$1,$C$2)) | C77: =IFERROR($C$1-1+_xlfn.RANK.EQ(B77,$B$4:$B$166)+COUNTIF(B$4:$B77,B77)-1,"") | D77: =IFERROR(VLOOKUP(C77,'Expressing opinions'!A:B,2,0),"")
A78: =IFERROR(IF(A77+1>$C$2,"",A77+1),"") | B78: =IF(A78="","",RANDBETWEEN($C$1,$C$2)) | C78: =IFERROR($C$1-1+_xlfn.RANK.EQ(B78,$B$4:$B$166)+COUNTIF(B$4:$B78,B78)-1,"") | D78: =IFERROR(VLOOKUP(C78,'Expressing opinions'!A:B,2,0),"")
A79: =IFERROR(IF(A78+1>$C$2,"",A78+1),"") | B79: =IF(A79="","",RANDBETWEEN($C$1,$C$2)) | C79: =IFERROR($C$1-1+_xlfn.RANK.EQ(B79,$B$4:$B$166)+COUNTIF(B$4:$B79,B79)-1,"") | D79: =IFERROR(VLOOKUP(C79,'Expressing opinions'!A:B,2,0),"")
A80: =IFERROR(IF(A79+1>$C$2,"",A79+1),"") | B80: =IF(A80="","",RANDBETWEEN($C$1,$C$2)) | C80: =IFERROR($C$1-1+_xlfn.RANK.EQ(B80,$B$4:$B$166)+COUNTIF(B$4:$B80,B80)-1,"") | D80: =IFERROR(VLOOKUP(C80,'Expressing opinions'!A:B,2,0),"")
...

Sheet Sheet1

Sheet Sheet2
