Workbook

Sheet Feeling
B2: TOPIC: FEELING
B3: No | C3: ID | D3: Sentence | E3: Type | F3: Link | G3: ID | H3: Copy Google drive to …
B4: 1 | C4: =B4&E4 -> 1Struc | D4: I FEEL … /tôi cảm thấy/ | E4: Struc | F4: =IF(G4="","","https://docs.google.com/uc?export=download&id="&G4) | G4: =IFERROR(LEFT(RIGHT(H4,LEN(H4)-32),LEN(RIGHT(H4,LEN(H4)-32))-17),"")
B5: 1.1 | C5: =B5&E5 -> 1.1Viet | D5: Tôi thấy thoải mái. | E5: Viet | F5: =IF(G5="","","https://docs.google.com/uc?export=download&id="&G5) | G5: =IFERROR(LEFT(RIGHT(H5,LEN(H5)-32),LEN(RIGHT(H5,LEN(H5)-32))-17),"")
A6: 1 | B6: 1.1 | C6: =B6&E6 -> 1.1Eng | D6: I feel comfortable. | E6: Eng | F6: =IF(G6="","","https://docs.google.com/uc?export=download&id="&G6) -> https://docs.google.com/uc?export=download&id=1mxLQYIr-tiS1nbHo5twOoje77OqnWmP_ | G6: =IFERROR(LEFT(RIGHT(H6,LEN(H6)-32),LEN(RIGHT(H6,LEN(H6)-32))-17),"") -> 1mxLQYIr-tiS1nbHo5twOoje77OqnWmP_ | H6: https://drive.google.com/file/d/1mxLQYIr-tiS1nbHo5twOoje77OqnWmP_/view?usp=sharing
B7: 1.1 | C7: =B7&E7 -> 1.1Phon | D7: aɪ fil ˈkʌmfərtəbəl. | E7: Phon | F7: =IF(G7="","","https://docs.google.com/uc?export=download&id="&G7) | G7: =IFERROR(LEFT(RIGHT(H7,LEN(H7)-32),LEN(RIGHT(H7,LEN(H7)-32))-17),"")
B8: 1.2 | C8: =B8&E8 -> 1.2Viet | D8: Tôi thấy sảng khoái. | E8: Viet | F8: =IF(G8="","","https://docs.google.com/uc?export=download&id="&G8) | G8: =IFERROR(LEFT(RIGHT(H8,LEN(H8)-32),LEN(RIGHT(H8,LEN(H8)-32))-17),"")
A9: 2 | B9: 1.2 | C9: =B9&E9 -> 1.2Eng | D9: I feel refreshed. | E9: Eng | F9: =IF(G9="","","https://docs.google.com/uc?export=download&id="&G9) -> https://docs.google.com/uc?export=download&id=1Aj0KIwUmaxBnWv7uFYF-KIwgB6Xq5k16 | G9: =IFERROR(LEFT(RIGHT(H9,LEN(H9)-32),LEN(RIGHT(H9,LEN(H9)-32))-17),"") -> 1Aj0KIwUmaxBnWv7uFYF-KIwgB6Xq5k16 | H9: https://drive.google.com/file/d/1Aj0KIwUmaxBnWv7uFYF-KIwgB6Xq5k16/view?usp=sharing
B10: 1.2 | C10: =B10&E10 -> 1.2Phon | D10: aɪ fil riˈfrɛʃt. | E10: Phon | F10: =IF(G10="","","https://docs.google.com/uc?export=download&id="&G10) | G10: =IFERROR(LEFT(RIGHT(H10,LEN(H10)-32),LEN(RIGHT(H10,LEN(H10)-32))-17),"")
B11: 1.3 | C11: =B11&E11 -> 1.3Viet | D11: Tôi thấy khá hơn rồi. | E11: Viet | F11: =IF(G11="","","https://docs.google.com/uc?export=download&id="&G11) | G11: =IFERROR(LEFT(RIGHT(H11,LEN(H11)-32),LEN(RIGHT(H11,LEN(H11)-32))-17),"")
A12: 3 | B12: 1.3 | C12: =B12&E12 -> 1.3Eng | D12: I feel better. | E12: Eng | F12: =IF(G12="","","https://docs.google.com/uc?export=download&id="&G12) -> https://docs.google.com/uc?export=download&id=1RBiFUBsSV4LgrGy3DdbMy1jZpwsiyfw8 | G12: =IFERROR(LEFT(RIGHT(H12,LEN(H12)-32),LEN(RIGHT(H12,LEN(H12)-32))-17),"") -> 1RBiFUBsSV4LgrGy3DdbMy1jZpwsiyfw8 | H12: https://drive.google.com/file/d/1RBiFUBsSV4LgrGy3DdbMy1jZpwsiyfw8/view?usp=sharing
B13: 1.3 | C13: =B13&E13 -> 1.3Phon | D13: aɪ fil ˈbɛtər. | E13: Phon | F13: =IF(G13="","","https://docs.google.com/uc?export=download&id="&G13) | G13: =IFERROR(LEFT(RIGHT(H13,LEN(H13)-32),LEN(RIGHT(H13,LEN(H13)-32))-17),"")
B14: 1.4 | C14: =B14&E14 -> 1.4Viet | D14: Tôi thấy căng thẳng. | E14: Viet | F14: =IF(G14="","","https://docs.google.com/uc?export=download&id="&G14) | G14: =IFERROR(LEFT(RIGHT(H14,LEN(H14)-32),LEN(RIGHT(H14,LEN(H14)-32))-17),"")
A15: 4 | B15: 1.4 | C15: =B15&E15 -> 1.4Eng | D15: I feel stressed. | E15: Eng | F15: =IF(G15="","","https://docs.google.com/uc?export=download&id="&G15) -> https://docs.google.com/uc?export=download&id=1Wmy8zAD64rZN7IpgkgbDdup0dvvz1bhI | G15: =IFERROR(LEFT(RIGHT(H15,LEN(H15)-32),LEN(RIGHT(H15,LEN(H15)-32))-17),"") -> 1Wmy8zAD64rZN7IpgkgbDdup0dvvz1bhI | H15: https://drive.google.com/file/d/1Wmy8zAD64rZN7IpgkgbDdup0dvvz1bhI/view?usp=sharing
B16: 1.4 | C16: =B16&E16 -> 1.4Phon | D16: aɪ fil strɛst. | E16: Phon | F16: =IF(G16="","","https://docs.google.com/uc?export=download&id="&G16) | G16: =IFERROR(LEFT(RIGHT(H16,LEN(H16)-32),LEN(RIGHT(H16,LEN(H16)-32))-17),"")
B17: 1.5 | C17: =B17&E17 -> 1.5Viet | D17: Tôi thấy lo lắng. | E17: Viet | F17: =IF(G17="","","https://docs.google.com/uc?export=download&id="&G17) | G17: =IFERROR(LEFT(RIGHT(H17,LEN(H17)-32),LEN(RIGHT(H17,LEN(H17)-32))-17),"")
A18: 5 | B18: 1.5 | C18: =B18&E18 -> 1.5Eng | D18: I feel nervous. | E18: Eng | F18: =IF(G18="","","https://docs.google.com/uc?export=download&id="&G18) -> https://docs.google.com/uc?export=download&id=1W3QjRPpslSjmddSTTTu4R7k3skQyYrka | G18: =IFERROR(LEFT(RIGHT(H18,LEN(H18)-32),LEN(RIGHT(H18,LEN(H18)-32))-17),"") -> 1W3QjRPpslSjmddSTTTu4R7k3skQyYrka | H18: https://drive.google.com/file/d/1W3QjRPpslSjmddSTTTu4R7k3skQyYrka/view?usp=sharing
B19: 1.5 | C19: =B19&E19 -> 1.5Phon | D19: aɪ fil ˈnɜrvəs. | E19: Phon | F19: =IF(G19="","","https://docs.google.com/uc?export=download&id="&G19) | G19: =IFERROR(LEFT(RIGHT(H19,LEN(H19)-32),LEN(RIGHT(H19,LEN(H19)-32))-17),"")
B20: 1.6 | C20: =B20&E20 -> 1.6Viet | D20: Tôi thấy mệt mỏi. | E20: Viet | F20: =IF(G20="","","https://docs.google.com/uc?export=download&id="&G20) | G20: =IFERROR(LEFT(RIGHT(H20,LEN(H20)-32),LEN(RIGHT(H20,LEN(H20)-32))-17),"")
A21: 6 | B21: 1.6 | C21: =B21&E21 -> 1.6Eng | D21: I feel tired. | E21: Eng | F21: =IF(G21="","","https://docs.google.com/uc?export=download&id="&G21) -> https://docs.google.com/uc?export=download&id=1T9C3mQJpMMTGGUc1Pa6-z6SkTpMjQ9Ov | G21: =IFERROR(LEFT(RIGHT(H21,LEN(H21)-32),LEN(RIGHT(H21,LEN(H21)-32))-17),"") -> 1T9C3mQJpMMTGGUc1Pa6-z6SkTpMjQ9Ov | H21: https://drive.google.com/file/d/1T9C3mQJpMMTGGUc1Pa6-z6SkTpMjQ9Ov/view?usp=sharing
B22: 1.6 | C22: =B22&E22 -> 1.6Phon | D22: aɪ fil ˈtaɪərd. | E22: Phon | F22: =IF(G22="","","https://docs.google.com/uc?export=download&id="&G22) | G22: =IFERROR(LEFT(RIGHT(H22,LEN(H22)-32),LEN(RIGHT(H22,LEN(H22)-32))-17),"")
B23: 1.7 | C23: =B23&E23 -> 1.7Viet | D23: Tôi thấy như tôi đang nằm mơ vậy. | E23: Viet | F23: =IF(G23="","","https://docs.google.com/uc?export=download&id="&G23) | G23: =IFERROR(LEFT(RIGHT(H23,LEN(H23)-32),LEN(RIGHT(H23,LEN(H23)-32))-17),"")
A24: 7 | B24: 1.7 | C24: =B24&E24 -> 1.7Eng | D24: I feel like I’m in a dream. | E24: Eng | F24: =IF(G24="","","https://docs.google.com/uc?export=download&id="&G24) -> https://docs.google.com/uc?export=download&id=1ibpzWN7H0Ha2-Gz1vjTv6MKK8r9-3CKV | G24: =IFERROR(LEFT(RIGHT(H24,LEN(H24)-32),LEN(RIGHT(H24,LEN(H24)-32))-17),"") -> 1ibpzWN7H0Ha2-Gz1vjTv6MKK8r9-3CKV | H24: https://drive.google.com/file/d/1ibpzWN7H0Ha2-Gz1vjTv6MKK8r9-3CKV/view?usp=sharing
B25: 1.7 | C25: =B25&E25 -> 1.7Phon | D25: aɪ fil laɪk aɪm ɪn ə drim. | E25: Phon | F25: =IF(G25="","","https://docs.google.com/uc?export=download&id="&G25) | G25: =IFERROR(LEFT(RIGHT(H25,LEN(H25)-32),LEN(RIGHT(H25,LEN(H25)-32))-17),"")
B26: 1.8 | C26: =B26&E26 -> 1.8Viet | D26: Tôi thấy xấu hổ. | E26: Viet | F26: =IF(G26="","","https://docs.google.com/uc?export=download&id="&G26) | G26: =IFERROR(LEFT(RIGHT(H26,LEN(H26)-32),LEN(RIGHT(H26,LEN(H26)-32))-17),"")
A27: 8 | B27: 1.8 | C27: =B27&E27 -> 1.8Eng | D27: I feel embarrassed. | E27: Eng | F27: =IF(G27="","","https://docs.google.com/uc?export=download&id="&G27) -> https://docs.google.com/uc?export=download&id=1tuJQu6Dek4OVsFDRUJrFHmViHuQ73SX8 | G27: =IFERROR(LEFT(RIGHT(H27,LEN(H27)-32),LEN(RIGHT(H27,LEN(H27)-32))-17),"") -> 1tuJQu6Dek4OVsFDRUJrFHmViHuQ73SX8 | H27: https://drive.google.com/file/d/1tuJQu6Dek4OVsFDRUJrFHmViHuQ73SX8/view?usp=sharing
B28: 1.8 | C28: =B28&E28 -> 1.8Phon | D28: aɪ fil ɪmˈbɛrəst. | E28: Phon | F28: =IF(G28="","","https://docs.google.com/uc?export=download&id="&G28) | G28: =IFERROR(LEFT(RIGHT(H28,LEN(H28)-32),LEN(RIGHT(H28,LEN(H28)-32))-17),"")
B29: 1.9 | C29: =B29&E29 -> 1.9Viet | D29: Tôi thấy mình có vẻ đã thua cuộc rồi. | E29: Viet | F29: =IF(G29="","","https://docs.google.com/uc?export=download&id="&G29) | G29: =IFERROR(LEFT(RIGHT(H29,LEN(H29)-32),LEN(RIGHT(H29,LEN(H29)-32))-17),"")
A30: 9 | B30: 1.9 | C30: =B30&E30 -> 1.9Eng | D30: I feel like I lost the game. | E30: Eng | F30: =IF(G30="","","https://docs.google.com/uc?export=download&id="&G30) -> https://docs.google.com/uc?export=download&id=1EyeXtM1F2MDnlHgJHdajf_sHiMQWN9xI | G30: =IFERROR(LEFT(RIGHT(H30,LEN(H30)-32),LEN(RIGHT(H30,LEN(H30)-32))-17),"") -> 1EyeXtM1F2MDnlHgJHdajf_sHiMQWN9xI | H30: https://drive.google.com/file/d/1EyeXtM1F2MDnlHgJHdajf_sHiMQWN9xI/view?usp=sharing
B31: 1.9 | C31: =B31&E31 -> 1.9Phon | D31: aɪ fil laɪk aɪ lɔst ðə ɡeɪm. | E31: Phon | F31: =IF(G31="","","https://docs.google.com/uc?export=download&id="&G31) | G31: =IFERROR(LEFT(RIGHT(H31,LEN(H31)-32),LEN(RIGHT(H31,LEN(H31)-32))-17),"")
B32: 1.10 | C32: =B32&E32 -> 1.10Viet | D32: Tôi cảm thấy như đang ở nhà vậy. | E32: Viet | F32: =IF(G32="","","https://docs.google.com/uc?export=download&id="&G32) | G32: =IFERROR(LEFT(RIGHT(H32,LEN(H32)-32),LEN(RIGHT(H32,LEN(H32)-32))-17),"")
A33: 10 | B33: 1.10 | C33: =B33&E33 -> 1.10Eng | D33: I feel like I am home. | E33: Eng | F33: =IF(G33="","","https://docs.google.com/uc?export=download&id="&G33) -> https://docs.google.com/uc?export=download&id=1SJ5gTOJYbZZbV7JzR1PRuumdsksd2max | G33: =IFERROR(LEFT(RIGHT(H33,LEN(H33)-32),LEN(RIGHT(H33,LEN(H33)-32))-17),"") -> 1SJ5gTOJYbZZbV7JzR1PRuumdsksd2max | H33: https://drive.google.com/file/d/1SJ5gTOJYbZZbV7JzR1PRuumdsksd2max/view?usp=sharing
B34: 1.10 | C34: =B34&E34 -> 1.10Phon | D34: aɪ fil laɪk aɪ əm hoʊm. | E34: Phon | F34: =IF(G34="","","https://docs.google.com/uc?export=download&id="&G34) | G34: =IFERROR(LEFT(RIGHT(H34,LEN(H34)-32),LEN(RIGHT(H34,LEN(H34)-32))-17),"")
B35: 2 | C35: =B35&E35 -> 2Struc | D35: WHEN I …, I… /khi…, tôi…/ | E35: Struc | F35: =IF(G35="","","https://docs.google.com/uc?export=download&id="&G35) | G35: =IFERROR(LEFT(RIGHT(H35,LEN(H35)-32),LEN(RIGHT(H35,LEN(H35)-32))-17),"")
B36: 2.1 | C36: =B36&E36 -> 2.1Viet | D36: Khi cảm thấy chán nản, tôi đi xem ca nhạc. | E36: Viet | F36: =IF(G36="","","https://docs.google.com/uc?export=download&id="&G36) | G36: =IFERROR(LEFT(RIGHT(H36,LEN(H36)-32),LEN(RIGHT(H36,LEN(H36)-32))-17),"")
A37: 11 | B37: 2.1 | C37: =B37&E37 -> 2.1Eng | D37: When I am depressed, I go to concerts. | E37: Eng | F37: =IF(G37="","","https://docs.google.com/uc?export=download&id="&G37) -> https://docs.google.com/uc?export=download&id=1zWSx63P4LowVT119ZmcY4L2y9ZoiXmIz | G37: =IFERROR(LEFT(RIGHT(H37,LEN(H37)-32),LEN(RIGHT(H37,LEN(H37)-32))-17),"") -> 1zWSx63P4LowVT119ZmcY4L2y9ZoiXmIz | H37: https://drive.google.com/file/d/1zWSx63P4LowVT119ZmcY4L2y9ZoiXmIz/view?usp=sharing
B38: 2.1 | C38: =B38&E38 -> 2.1Phon | D38: wɛn aɪ əm dɪˈprɛst, aɪ ɡoʊ tə ˈkɑnsərts. | E38: Phon | F38: =IF(G38="","","https://docs.google.com/uc?export=download&id="&G38) | G38: =IFERROR(LEFT(RIGHT(H38,LEN(H38)-32),LEN(RIGHT(H38,LEN(H38)-32))-17),"")
B39: 2.2 | C39: =B39&E39 -> 2.2Viet | D39: Khi gặp gỡ bạn bè, tôi thường đi xem phim cùng họ. | E39: Viet | F39: =IF(G39="","","https://docs.google.com/uc?export=download&id="&G39) | G39: =IFERROR(LEFT(RIGHT(H39,LEN(H39)-32),LEN(RIGHT(H39,LEN(H39)-32))-17),"")
A40: 12 | B40: 2.2 | C40: =B40&E40 -> 2.2Eng | D40: When I meet my friends, I often go to see movies with them. | E40: Eng | F40: =IF(G40="","","https://docs.google.com/uc?export=download&id="&G40) -> https://docs.google.com/uc?export=download&id=1m6HOUuzTTShXRiP8KeqWKVVXZIDEgZlf | G40: =IFERROR(LEFT(RIGHT(H40,LEN(H40)-32),LEN(RIGHT(H40,LEN(H40)-32))-17),"") -> 1m6HOUuzTTShXRiP8KeqWKVVXZIDEgZlf | H40: https://drive.google.com/file/d/1m6HOUuzTTShXRiP8KeqWKVVXZIDEgZlf/view?usp=sharing
B41: 2.2 | C41: =B41&E41 -> 2.2Phon | D41: wɛn aɪ mit maɪ frɛndz, aɪ ˈɔfən ɡoʊ tə si ˈmuviz wɪð ðɛm. | E41: Phon | F41: =IF(G41="","","https://docs.google.com/uc?export=download&id="&G41) | G41: =IFERROR(LEFT(RIGHT(H41,LEN(H41)-32),LEN(RIGHT(H41,LEN(H41)-32))-17),"")
...

Sheet Viet
B2: Sentence | C2: Link | D2: ID | E2: Copy Google drive to …
B3: 01-05 | C3: =IF(D3="","","https://docs.google.com/uc?export=download&id="&D3) -> https://docs.google.com/uc?export=download&id=1ALixiBPK9ec0uEC5V4_ExR5f4MRwnZ5b | D3: =IFERROR(LEFT(RIGHT(E3,LEN(E3)-32),LEN(RIGHT(E3,LEN(E3)-32))-17),"") -> 1ALixiBPK9ec0uEC5V4_ExR5f4MRwnZ5b | E3: https://drive.google.com/file/d/1ALixiBPK9ec0uEC5V4_ExR5f4MRwnZ5b/view?usp=sharing
B4: 06-09 | C4: =IF(D4="","","https://docs.google.com/uc?export=download&id="&D4) -> https://docs.google.com/uc?export=download&id=18kG4N6mnuvuAZ4e1XDSpcxVR036f7ind | D4: =IFERROR(LEFT(RIGHT(E4,LEN(E4)-32),LEN(RIGHT(E4,LEN(E4)-32))-17),"") -> 18kG4N6mnuvuAZ4e1XDSpcxVR036f7ind | E4: https://drive.google.com/file/d/18kG4N6mnuvuAZ4e1XDSpcxVR036f7ind/view?usp=sharing
B5: 10-15 | C5: =IF(D5="","","https://docs.google.com/uc?export=download&id="&D5) -> https://docs.google.com/uc?export=download&id=1sLwwIUTUmYJBLUtsUnnlQdbs_xPjlL_C | D5: =IFERROR(LEFT(RIGHT(E5,LEN(E5)-32),LEN(RIGHT(E5,LEN(E5)-32))-17),"") -> 1sLwwIUTUmYJBLUtsUnnlQdbs_xPjlL_C | E5: https://drive.google.com/file/d/1sLwwIUTUmYJBLUtsUnnlQdbs_xPjlL_C/view?usp=sharing
B6: 16-21 | C6: =IF(D6="","","https://docs.google.com/uc?export=download&id="&D6) -> https://docs.google.com/uc?export=download&id=1nOtnBWWSo5qmTNs0eQ-H4R_xmqlwhffx | D6: =IFERROR(LEFT(RIGHT(E6,LEN(E6)-32),LEN(RIGHT(E6,LEN(E6)-32))-17),"") -> 1nOtnBWWSo5qmTNs0eQ-H4R_xmqlwhffx | E6: https://drive.google.com/file/d/1nOtnBWWSo5qmTNs0eQ-H4R_xmqlwhffx/view?usp=sharing
B7: 01-21 | C7: =IF(D7="","","https://docs.google.com/uc?export=download&id="&D7) -> https://docs.google.com/uc?export=download&id=1uW-jdd7Ed3DxBLuEVvzxIHA1DHA7fQnX | D7: =IFERROR(LEFT(RIGHT(E7,LEN(E7)-32),LEN(RIGHT(E7,LEN(E7)-32))-17),"") -> 1uW-jdd7Ed3DxBLuEVvzxIHA1DHA7fQnX | E7: https://drive.google.com/file/d/1uW-jdd7Ed3DxBLuEVvzxIHA1DHA7fQnX/view?usp=sharing

Sheet Sum
B2: Sentence | C2: Link | D2: ID | E2: Copy Google drive to …
B3: Woman | C3: =IF(D3="","","https://docs.google.com/uc?export=download&id="&D3) | D3: =IFERROR(LEFT(RIGHT(E3,LEN(E3)-32),LEN(RIGHT(E3,LEN(E3)-32))-17),"")
B4: Man | C4: =IF(D4="","","https://docs.google.com/uc?export=download&id="&D4) | D4: =IFERROR(LEFT(RIGHT(E4,LEN(E4)-32),LEN(RIGHT(E4,LEN(E4)-32))-17),"")

Sheet Ramdom
B1: From | C1: 92
B2: To | C2: 123
C3: No | D3: No | E3: Viet | F3: Eng
A4: =C1 -> 92 | B4: =IF(A4="","",RANDBETWEEN($C$1,$C$2)) -> 115 | C4: =IFERROR($C$1-1+_xlfn.RANK.EQ(B4,$B$4:$B$126)+COUNTIF(B$4:$B4,B4)-1,"") -> 102 | D4: =IFERROR(VLOOKUP(C4,Feeling!A:B,2,0),"") -> 18.2 | E4: =IFERROR(VLOOKUP(D4&"Viet",Feeling!C:D,2,0),"") -> Tôi không biết gì về anh ta cả. | F4: =IFERROR(VLOOKUP(D4&"Eng",Feeling!C:D,2,0),"") -> I don’t know anything about him.
A5: =IFERROR(IF(A4+1>$C$2,"",A4+1),"") -> 93 | B5: =IF(A5="","",RANDBETWEEN($C$1,$C$2)) -> 119 | C5: =IFERROR($C$1-1+_xlfn.RANK.EQ(B5,$B$4:$B$126)+COUNTIF(B$4:$B5,B5)-1,"") -> 96 | D5: =IFERROR(VLOOKUP(C5,Feeling!A:B,2,0),"") -> 17.1 | E5: =IFERROR(VLOOKUP(D5&"Viet",Feeling!C:D,2,0),"") -> Tôi đăng cân nhắc về chuyện thay đổi công việc. | F5: =IFERROR(VLOOKUP(D5&"Eng",Feeling!C:D,2,0),"") -> I am considering changing my job.
A6: =IFERROR(IF(A5+1>$C$2,"",A5+1),"") -> 94 | B6: =IF(A6="","",RANDBETWEEN($C$1,$C$2)) -> 114 | C6: =IFERROR($C$1-1+_xlfn.RANK.EQ(B6,$B$4:$B$126)+COUNTIF(B$4:$B6,B6)-1,"") -> 103 | D6: =IFERROR(VLOOKUP(C6,Feeling!A:B,2,0),"") -> 18.3 | E6: =IFERROR(VLOOKUP(D6&"Viet",Feeling!C:D,2,0),"") -> Tôi không biết làm thế nào để giải quyết vấn đề này nữa. | F6: =IFERROR(VLOOKUP(D6&"Eng",Feeling!C:D,2,0),"") -> I don’t know how to solve this problem.
A7: =IFERROR(IF(A6+1>$C$2,"",A6+1),"") -> 95 | B7: =IF(A7="","",RANDBETWEEN($C$1,$C$2)) -> 119 | C7: =IFERROR($C$1-1+_xlfn.RANK.EQ(B7,$B$4:$B$126)+COUNTIF(B$4:$B7,B7)-1,"") -> 97 | D7: =IFERROR(VLOOKUP(C7,Feeling!A:B,2,0),"") -> 17.2 | E7: =IFERROR(VLOOKUP(D7&"Viet",Feeling!C:D,2,0),"") -> Tôi đang cân nhắc về việc tham gia câu lạc bộ. | F7: =IFERROR(VLOOKUP(D7&"Eng",Feeling!C:D,2,0),"") -> I am considering joining the club.
A8: =IFERROR(IF(A7+1>$C$2,"",A7+1),"") -> 96 | B8: =IF(A8="","",RANDBETWEEN($C$1,$C$2)) -> 120 | C8: =IFERROR($C$1-1+_xlfn.RANK.EQ(B8,$B$4:$B$126)+COUNTIF(B$4:$B8,B8)-1,"") -> 95 | D8: =IFERROR(VLOOKUP(C8,Feeling!A:B,2,0),"") -> 16.4 | E8: =IFERROR(VLOOKUP(D8&"Viet",Feeling!C:D,2,0),"") -> Tôi nghĩ về lời đề nghị ấy. | F8: =IFERROR(VLOOKUP(D8&"Eng",Feeling!C:D,2,0),"") -> I think about the offer.
A9: =IFERROR(IF(A8+1>$C$2,"",A8+1),"") -> 97 | B9: =IF(A9="","",RANDBETWEEN($C$1,$C$2)) -> 94 | C9: =IFERROR($C$1-1+_xlfn.RANK.EQ(B9,$B$4:$B$126)+COUNTIF(B$4:$B9,B9)-1,"") -> 123 | D9: =IFERROR(VLOOKUP(C9,Feeling!A:B,2,0),"") -> 21.5 | E9: =IFERROR(VLOOKUP(D9&"Viet",Feeling!C:D,2,0),"") -> Không cần phải gọi lại cho tôi đâu. | F9: =IFERROR(VLOOKUP(D9&"Eng",Feeling!C:D,2,0),"") -> There is no need to call me back .
A10: =IFERROR(IF(A9+1>$C$2,"",A9+1),"") -> 98 | B10: =IF(A10="","",RANDBETWEEN($C$1,$C$2)) -> 113 | C10: =IFERROR($C$1-1+_xlfn.RANK.EQ(B10,$B$4:$B$126)+COUNTIF(B$4:$B10,B10)-1,"") -> 104 | D10: =IFERROR(VLOOKUP(C10,Feeling!A:B,2,0),"") -> 18.4 | E10: =IFERROR(VLOOKUP(D10&"Viet",Feeling!C:D,2,0),"") -> Tôi không biết phải đi đâu nữa. | F10: =IFERROR(VLOOKUP(D10&"Eng",Feeling!C:D,2,0),"") -> I don’t know where to go.
A11: =IFERROR(IF(A10+1>$C$2,"",A10+1),"") -> 99 | B11: =IF(A11="","",RANDBETWEEN($C$1,$C$2)) -> 100 | C11: =IFERROR($C$1-1+_xlfn.RANK.EQ(B11,$B$4:$B$126)+COUNTIF(B$4:$B11,B11)-1,"") -> 118 | D11: =IFERROR(VLOOKUP(C11,Feeling!A:B,2,0),"") -> 20.4 | E11: =IFERROR(VLOOKUP(D11&"Viet",Feeling!C:D,2,0),"") -> Tôi thích điều đó vì nó khiến tôi buồn cười. | F11: =IFERROR(VLOOKUP(D11&"Eng",Feeling!C:D,2,0),"") -> I like it because it makes me laugh.
A12: =IFERROR(IF(A11+1>$C$2,"",A11+1),"") -> 100 | B12: =IF(A12="","",RANDBETWEEN($C$1,$C$2)) -> 111 | C12: =IFERROR($C$1-1+_xlfn.RANK.EQ(B12,$B$4:$B$126)+COUNTIF(B$4:$B12,B12)-1,"") -> 108 | D12: =IFERROR(VLOOKUP(C12,Feeling!A:B,2,0),"") -> 19.1 | E12: =IFERROR(VLOOKUP(D12&"Viet",Feeling!C:D,2,0),"") -> Còn tuỳ vào tâm trạng nữa. | F12: =IFERROR(VLOOKUP(D12&"Eng",Feeling!C:D,2,0),"") -> It depends on the mood.
A13: =IFERROR(IF(A12+1>$C$2,"",A12+1),"") -> 101 | B13: =IF(A13="","",RANDBETWEEN($C$1,$C$2)) -> 97 | C13: =IFERROR($C$1-1+_xlfn.RANK.EQ(B13,$B$4:$B$126)+COUNTIF(B$4:$B13,B13)-1,"") -> 120 | D13: =IFERROR(VLOOKUP(C13,Feeling!A:B,2,0),"") -> 21.2 | E13: =IFERROR(VLOOKUP(D13&"Viet",Feeling!C:D,2,0),"") -> Không cần phải mua café cho anh ta đâu. | F13: =IFERROR(VLOOKUP(D13&"Eng",Feeling!C:D,2,0),"") -> There is no need to buy him coffee.
A14: =IFERROR(IF(A13+1>$C$2,"",A13+1),"") -> 102 | B14: =IF(A14="","",RANDBETWEEN($C$1,$C$2)) -> 95 | C14: =IFERROR($C$1-1+_xlfn.RANK.EQ(B14,$B$4:$B$126)+COUNTIF(B$4:$B14,B14)-1,"") -> 121 | D14: =IFERROR(VLOOKUP(C14,Feeling!A:B,2,0),"") -> 21.3 | E14: =IFERROR(VLOOKUP(D14&"Viet",Feeling!C:D,2,0),"") -> Không cần phải xem chương trình đó đâu. | F14: =IFERROR(VLOOKUP(D14&"Eng",Feeling!C:D,2,0),"") -> There is no need to watch that show.
A15: =IFERROR(IF(A14+1>$C$2,"",A14+1),"") -> 103 | B15: =IF(A15="","",RANDBETWEEN($C$1,$C$2)) -> 109 | C15: =IFERROR($C$1-1+_xlfn.RANK.EQ(B15,$B$4:$B$126)+COUNTIF(B$4:$B15,B15)-1,"") -> 111 | D15: =IFERROR(VLOOKUP(C15,Feeling!A:B,2,0),"") -> 19.4 | E15: =IFERROR(VLOOKUP(D15&"Viet",Feeling!C:D,2,0),"") -> Còn tuỳ thuộc vào giá cả nữa. | F15: =IFERROR(VLOOKUP(D15&"Eng",Feeling!C:D,2,0),"") -> It depends on the price.
A16: =IFERROR(IF(A15+1>$C$2,"",A15+1),"") -> 104 | B16: =IF(A16="","",RANDBETWEEN($C$1,$C$2)) -> 116 | C16: =IFERROR($C$1-1+_xlfn.RANK.EQ(B16,$B$4:$B$126)+COUNTIF(B$4:$B16,B16)-1,"") -> 100 | D16: =IFERROR(VLOOKUP(C16,Feeling!A:B,2,0),"") -> 17.5 | E16: =IFERROR(VLOOKUP(D16&"Viet",Feeling!C:D,2,0),"") -> Tôi đang cân nhắc chuyện chuyển tới nơi khác . | F16: =IFERROR(VLOOKUP(D16&"Eng",Feeling!C:D,2,0),"") -> I am considering moving to another place.
A17: =IFERROR(IF(A16+1>$C$2,"",A16+1),"") -> 105 | B17: =IF(A17="","",RANDBETWEEN($C$1,$C$2)) -> 99 | C17: =IFERROR($C$1-1+_xlfn.RANK.EQ(B17,$B$4:$B$126)+COUNTIF(B$4:$B17,B17)-1,"") -> 119 | D17: =IFERROR(VLOOKUP(C17,Feeling!A:B,2,0),"") -> 21.1 | E17: =IFERROR(VLOOKUP(D17&"Viet",Feeling!C:D,2,0),"") -> Không cần phải mua chiếc máy tính cá nhân khác đâu. | F17: =IFERROR(VLOOKUP(D17&"Eng",Feeling!C:D,2,0),"") -> There is no need to buy another laptop. | L17: 4
A18: =IFERROR(IF(A17+1>$C$2,"",A17+1),"") -> 106 | B18: =IF(A18="","",RANDBETWEEN($C$1,$C$2)) -> 109 | C18: =IFERROR($C$1-1+_xlfn.RANK.EQ(B18,$B$4:$B$126)+COUNTIF(B$4:$B18,B18)-1,"") -> 112 | D18: =IFERROR(VLOOKUP(C18,Feeling!A:B,2,0),"") -> 19.5 | E18: =IFERROR(VLOOKUP(D18&"Viet",Feeling!C:D,2,0),"") -> Còn tuỳ vào cái đó trông thế nào. | F18: =IFERROR(VLOOKUP(D18&"Eng",Feeling!C:D,2,0),"") -> It depends on what it looks like.
A19: =IFERROR(IF(A18+1>$C$2,"",A18+1),"") -> 107 | B19: =IF(A19="","",RANDBETWEEN($C$1,$C$2)) -> 113 | C19: =IFERROR($C$1-1+_xlfn.RANK.EQ(B19,$B$4:$B$126)+COUNTIF(B$4:$B19,B19)-1,"") -> 105 | D19: =IFERROR(VLOOKUP(C19,Feeling!A:B,2,0),"") -> 18.5 | E19: =IFERROR(VLOOKUP(D19&"Viet",Feeling!C:D,2,0),"") -> Tôi không biết gì về việc mua sắm cả. | F19: =IFERROR(VLOOKUP(D19&"Eng",Feeling!C:D,2,0),"") -> I don’t know anything about shopping. | L19: p
A20: =IFERROR(IF(A19+1>$C$2,"",A19+1),"") -> 108 | B20: =IF(A20="","",RANDBETWEEN($C$1,$C$2)) -> 103 | C20: =IFERROR($C$1-1+_xlfn.RANK.EQ(B20,$B$4:$B$126)+COUNTIF(B$4:$B20,B20)-1,"") -> 116 | D20: =IFERROR(VLOOKUP(C20,Feeling!A:B,2,0),"") -> 20.2 | E20: =IFERROR(VLOOKUP(D20&"Viet",Feeling!C:D,2,0),"") -> Tôi thích điều đó vì tôi có thể quên đi mọi thứ. | F20: =IFERROR(VLOOKUP(D20&"Eng",Feeling!C:D,2,0),"") -> I like it because I can forget things.
A21: =IFERROR(IF(A20+1>$C$2,"",A20+1),"") -> 109 | B21: =IF(A21="","",RANDBETWEEN($C$1,$C$2)) -> 110 | C21: =IFERROR($C$1-1+_xlfn.RANK.EQ(B21,$B$4:$B$126)+COUNTIF(B$4:$B21,B21)-1,"") -> 110 | D21: =IFERROR(VLOOKUP(C21,Feeling!A:B,2,0),"") -> 19.3 | E21: =IFERROR(VLOOKUP(D21&"Viet",Feeling!C:D,2,0),"") -> Còn tuỳ vào tình huống nữa. | F21: =IFERROR(VLOOKUP(D21&"Eng",Feeling!C:D,2,0),"") -> It depends on the situation.
A22: =IFERROR(IF(A21+1>$C$2,"",A21+1),"") -> 110 | B22: =IF(A22="","",RANDBETWEEN($C$1,$C$2)) -> 104 | C22: =IFERROR($C$1-1+_xlfn.RANK.EQ(B22,$B$4:$B$126)+COUNTIF(B$4:$B22,B22)-1,"") -> 115 | D22: =IFERROR(VLOOKUP(C22,Feeling!A:B,2,0),"") -> 20.1 | E22: =IFERROR(VLOOKUP(D22&"Viet",Feeling!C:D,2,0),"") -> Tôi thích xem Tivi vì nó giúp tôi giải toả căng thẳng. | F22: =IFERROR(VLOOKUP(D22&"Eng",Feeling!C:D,2,0),"") -> I like watching TV because it releases stress.
A23: =IFERROR(IF(A22+1>$C$2,"",A22+1),"") -> 111 | B23: =IF(A23="","",RANDBETWEEN($C$1,$C$2)) -> 122 | C23: =IFERROR($C$1-1+_xlfn.RANK.EQ(B23,$B$4:$B$126)+COUNTIF(B$4:$B23,B23)-1,"") -> 92 | D23: =IFERROR(VLOOKUP(C23,Feeling!A:B,2,0),"") -> 16.1 | E23: =IFERROR(VLOOKUP(D23&"Viet",Feeling!C:D,2,0),"") -> Tôi nghĩ về việc đó. | F23: =IFERROR(VLOOKUP(D23&"Eng",Feeling!C:D,2,0),"") -> I think about it.
A24: =IFERROR(IF(A23+1>$C$2,"",A23+1),"") -> 112 | B24: =IF(A24="","",RANDBETWEEN($C$1,$C$2)) -> 112 | C24: =IFERROR($C$1-1+_xlfn.RANK.EQ(B24,$B$4:$B$126)+COUNTIF(B$4:$B24,B24)-1,"") -> 107 | D24: =IFERROR(VLOOKUP(C24,Feeling!A:B,2,0),"") -> 18.7 | E24: =IFERROR(VLOOKUP(D24&"Viet",Feeling!C:D,2,0),"") -> Tôi không biết mình có làm được hay không. | F24: =IFERROR(VLOOKUP(D24&"Eng",Feeling!C:D,2,0),"") -> I don’t know if I can do it.
A25: =IFERROR(IF(A24+1>$C$2,"",A24+1),"") -> 113 | B25: =IF(A25="","",RANDBETWEEN($C$1,$C$2)) -> 117 | C25: =IFERROR($C$1-1+_xlfn.RANK.EQ(B25,$B$4:$B$126)+COUNTIF(B$4:$B25,B25)-1,"") -> 98 | D25: =IFERROR(VLOOKUP(C25,Feeling!A:B,2,0),"") -> 17.3 | E25: =IFERROR(VLOOKUP(D25&"Viet",Feeling!C:D,2,0),"") -> Tôi đang cân nhắc về việc đi du lịch. | F25: =IFERROR(VLOOKUP(D25&"Eng",Feeling!C:D,2,0),"") -> I am considering going on a trip.
A26: =IFERROR(IF(A25+1>$C$2,"",A25+1),"") -> 114 | B26: =IF(A26="","",RANDBETWEEN($C$1,$C$2)) -> 113 | C26: =IFERROR($C$1-1+_xlfn.RANK.EQ(B26,$B$4:$B$126)+COUNTIF(B$4:$B26,B26)-1,"") -> 106 | D26: =IFERROR(VLOOKUP(C26,Feeling!A:B,2,0),"") -> 18.6 | E26: =IFERROR(VLOOKUP(D26&"Viet",Feeling!C:D,2,0),"") -> Tôi không biết bạn có thích nó hay không. | F26: =IFERROR(VLOOKUP(D26&"Eng",Feeling!C:D,2,0),"") -> I don’t know if you will like it.
A27: =IFERROR(IF(A26+1>$C$2,"",A26+1),"") -> 115 | B27: =IF(A27="","",RANDBETWEEN($C$1,$C$2)) -> 108 | C27: =IFERROR($C$1-1+_xlfn.RANK.EQ(B27,$B$4:$B$126)+COUNTIF(B$4:$B27,B27)-1,"") -> 113 | D27: =IFERROR(VLOOKUP(C27,Feeling!A:B,2,0),"") -> 19.6 | E27: =IFERROR(VLOOKUP(D27&"Viet",Feeling!C:D,2,0),"") -> Còn tuỳ thuộc vào bao nhiêu người tham gia nữa. | F27: =IFERROR(VLOOKUP(D27&"Eng",Feeling!C:D,2,0),"") -> It depends on how many people will attend.
A28: =IFERROR(IF(A27+1>$C$2,"",A27+1),"") -> 116 | B28: =IF(A28="","",RANDBETWEEN($C$1,$C$2)) -> 117 | C28: =IFERROR($C$1-1+_xlfn.RANK.EQ(B28,$B$4:$B$126)+COUNTIF(B$4:$B28,B28)-1,"") -> 99 | D28: =IFERROR(VLOOKUP(C28,Feeling!A:B,2,0),"") -> 17.4 | E28: =IFERROR(VLOOKUP(D28&"Viet",Feeling!C:D,2,0),"") -> Tôi đang cân nhắc chuyện mua chiếc xe hơi mới. | F28: =IFERROR(VLOOKUP(D28&"Eng",Feeling!C:D,2,0),"") -> I am considering buying a new car.
A29: =IFERROR(IF(A28+1>$C$2,"",A28+1),"") -> 117 | B29: =IF(A29="","",RANDBETWEEN($C$1,$C$2)) -> 95 | C29: =IFERROR($C$1-1+_xlfn.RANK.EQ(B29,$B$4:$B$126)+COUNTIF(B$4:$B29,B29)-1,"") -> 122 | D29: =IFERROR(VLOOKUP(C29,Feeling!A:B,2,0),"") -> 21.4 | E29: =IFERROR(VLOOKUP(D29&"Viet",Feeling!C:D,2,0),"") -> Không cần phải lo lắng về việc đó đâu. | F29: =IFERROR(VLOOKUP(D29&"Eng",Feeling!C:D,2,0),"") -> There is no need to worry about it.
A30: =IFERROR(IF(A29+1>$C$2,"",A29+1),"") -> 118 | B30: =IF(A30="","",RANDBETWEEN($C$1,$C$2)) -> 116 | C30: =IFERROR($C$1-1+_xlfn.RANK.EQ(B30,$B$4:$B$126)+COUNTIF(B$4:$B30,B30)-1,"") -> 101 | D30: =IFERROR(VLOOKUP(C30,Feeling!A:B,2,0),"") -> 18.1 | E30: =IFERROR(VLOOKUP(D30&"Viet",Feeling!C:D,2,0),"") -> Tôi không biết phải bắt đầu từ khi nào. | F30: =IFERROR(VLOOKUP(D30&"Eng",Feeling!C:D,2,0),"") -> I don’t know when to start.
A31: =IFERROR(IF(A30+1>$C$2,"",A30+1),"") -> 119 | B31: =IF(A31="","",RANDBETWEEN($C$1,$C$2)) -> 103 | C31: =IFERROR($C$1-1+_xlfn.RANK.EQ(B31,$B$4:$B$126)+COUNTIF(B$4:$B31,B31)-1,"") -> 117 | D31: =IFERROR(VLOOKUP(C31,Feeling!A:B,2,0),"") -> 20.3 | E31: =IFERROR(VLOOKUP(D31&"Viet",Feeling!C:D,2,0),"") -> Tôi thích điều đó vì nó rất thư giãn. | F31: =IFERROR(VLOOKUP(D31&"Eng",Feeling!C:D,2,0),"") -> I like it because it’s relaxing.
... A72: =IFERROR(IF(A71+1>$C$2,"",A71+1),"") | B72: =IF(A72="","",RANDBETWEEN($C$1,$C$2)) | C72: =IFERROR($C$1-1+_xlfn.RANK.EQ(B72,$B$4:$B$126)+COUNTIF(B$4:$B72,B72)-1,"") | D72: =IFERROR(VLOOKUP(C72,Feeling!A:B,2,0),"") | E72: =IFERROR(VLOOKUP(D72&"Viet",Feeling!C:D,2,0),"") | F72: =IFERROR(VLOOKUP(D72&"Eng",Feeling!C:D,2,0),"")
A73: =IFERROR(IF(A72+1>$C$2,"",A72+1),"") | B73: =IF(A73="","",RANDBETWEEN($C$1,$C$2)) | C73: =IFERROR($C$1-1+_xlfn.RANK.EQ(B73,$B$4:$B$126)+COUNTIF(B$4:$B73,B73)-1,"") | D73: =IFERROR(VLOOKUP(C73,Feeling!A:B,2,0),"")
A74: =IFERROR(IF(A73+1>$C$2,"",A73+1),"") | B74: =IF(A74="","",RANDBETWEEN($C$1,$C$2)) | C74: =IFERROR($C$1-1+_xlfn.RANK.EQ(B74,$B$4:$B$126)+COUNTIF(B$4:$B74,B74)-1,"") | D74: =IFERROR(VLOOKUP(C74,Feeling!A:B,2,0),"")
A75: =IFERROR(IF(A74+1>$C$2,"",A74+1),"") | B75: =IF(A75="","",RANDBETWEEN($C$1,$C$2)) | C75: =IFERROR($C$1-1+_xlfn.RANK.EQ(B75,$B$4:$B$126)+COUNTIF(B$4:$B75,B75)-1,"") | D75: =IFERROR(VLOOKUP(C75,Feeling!A:B,2,0),"")
A76: =IFERROR(IF(A75+1>$C$2,"",A75+1),"") | B76: =IF(A76="","",RANDBETWEEN($C$1,$C$2)) | C76: =IFERROR($C$1-1+_xlfn.RANK.EQ(B76,$B$4:$B$126)+COUNTIF(B$4:$B76,B76)-1,"") | D76: =IFERROR(VLOOKUP(C76,Feeling!A:B,2,0),"")
A77: =IFERROR(IF(A76+1>$C$2,"",A76+1),"") | B77: =IF(A77="","",RANDBETWEEN($C$1,$C$2)) | C77: =IFERROR($C$1-1+_xlfn.RANK.EQ(B77,$B$4:$B$126)+COUNTIF(B$4:$B77,B77)-1,"") | D77: =IFERROR(VLOOKUP(C77,Feeling!A:B,2,0),"")
A78: =IFERROR(IF(A77+1>$C$2,"",A77+1),"") | B78: =IF(A78="","",RANDBETWEEN($C$1,$C$2)) | C78: =IFERROR($C$1-1+_xlfn.RANK.EQ(B78,$B$4:$B$126)+COUNTIF(B$4:$B78,B78)-1,"") | D78: =IFERROR(VLOOKUP(C78,Feeling!A:B,2,0),"")
A79: =IFERROR(IF(A78+1>$C$2,"",A78+1),"") | B79: =IF(A79="","",RANDBETWEEN($C$1,$C$2)) | C79: =IFERROR($C$1-1+_xlfn.RANK.EQ(B79,$B$4:$B$126)+COUNTIF(B$4:$B79,B79)-1,"") | D79: =IFERROR(VLOOKUP(C79,Feeling!A:B,2,0),"")
A80: =IFERROR(IF(A79+1>$C$2,"",A79+1),"") | B80: =IF(A80="","",RANDBETWEEN($C$1,$C$2)) | C80: =IFERROR($C$1-1+_xlfn.RANK.EQ(B80,$B$4:$B$126)+COUNTIF(B$4:$B80,B80)-1,"") | D80: =IFERROR(VLOOKUP(C80,Feeling!A:B,2,0),"")
...

Sheet Sheet1
A1: No | B1: Sentence | C1: Type
A2: 1.1 | B2: Tôi thấy thoải mái. | C2: Viet
A3: 7.2 | B3: It’s fun to go to an amusement park. | C3: Eng | D3: 1
A4: 1.2 | B4: Tôi thấy sảng khoái. | C4: Viet
A5: 1.8 | B5: I feel embarrassed. | C5: Eng | D5: 2
A6: 1.3 | B6: Tôi thấy khá hơn rồi. | C6: Viet
A7: 2.1 | B7: When I am depressed, I go to concerts. | C7: Eng | D7: 3
A8: 1.4 | B8: Tôi thấy căng thẳng. | C8: Viet
A9: 2.2 | B9: When I meet my friends, I often go to see movies with them. | C9: Eng | D9: 4
A10: 1.5 | B10: Tôi thấy lo lắng. | C10: Viet
A11: 2.4 | B11: When I’m down, I often walk in the park. | C11: Eng | D11: 5
A12: 1.6 | B12: Tôi thấy mệt mỏi. | C12: Viet
A13: 6.2 | B13: I want to enjoy the view. | C13: Eng | D13: 6
A14: 1.7 | B14: Tôi thấy như tôi đang nằm mơ vậy. | C14: Viet
A15: 1.6 | B15: I feel tired. | C15: Eng | D15: 7
A16: 1.8 | B16: Tôi thấy xấu hổ. | C16: Viet
A17: 3.3 | B17: I’m happy with my way. | C17: Eng | D17: 7
A18: 1.9 | B18: Tôi thấy mình có vẻ đã thua cuộc rồi. | C18: Viet
A19: 2.5 | B19: When I have money, I spend a lot shopping for clothes. | C19: Eng | D19: 8
A20: 1.10 | B20: Tôi cảm thấy như đang ở nhà vậy. | C20: Viet
A21: 7.6 | B21: It’s enjoyable to play games. | C21: Eng | D21: 9
A22: 2.1 | B22: Khi cảm thấy chán nản, tôi đi xem ca nhạc. | C22: Viet
A23: 7.8 | B23: It’s relaxing to watch TV. | C23: Eng | D23: 10
A24: 2.2 | B24: Khi gặp gỡ bạn bè, tôi thường đi xem phim cùng họ. | C24: Viet
A25: 1.9 | B25: I feel like I lost the game. | C25: Eng | D25: 11
A26: 2.3 | B26: Khi thấy buồn chán,tôi xem video trên điện thoại. | C26: Viet
A27: 7.7 | B27: It’s realistic to watch 3D movie. | C27: Eng | D27: 12
A28: 2.4 | B28: Khi tôi buồn, tôi thường đi bộ trong công viên. | C28: Viet
A29: 6.1 | B29: I want to go to see a movie. | C29: Eng | D29: 13
A30: 2.5 | B30: Khi có tiền , tôi tiêu rất nhiều vào việc mua quần áo. | C30: Viet
A31: 5.1 | B31: I worry about it. | C31: Eng | D31: 14
A32: 2.6 | B32: Khi có thời gian, tôi đến phòng gym. | C32: Viet
A33: 1.5 | B33: I feel nervous. | C33: Eng | D33: 15
A34: 2.7 | B34: Khi tôi thấy mệt mỏi, tôi nghe nhạc trên điện thoại. | C34: Viet
A35: 2.7 | B35: When I am tired, I listen to music on my phone. | C35: Eng | D35: 16
A36: 2.8 | B36: Khi tôi muốn ra ngoài ăn, tôi nhắn tin cho anh ấy. | C36: Viet
A37: 7.1 | B37: It’s meaningful to help people with disabilities. | C37: Eng | D37: 17
A38: 3.1 | B38: Tôi hài lòng với chính mình. | C38: Viet
A39: 3.2 | B39: I’m happy with my job. | C39: Eng | D39: 18
A40: 3.2 | B40: Tôi hài lòng với công việc của mình. | C40: Viet
...

Sheet 1-7
A1: It’s fun to go to an amusement park. | B1: I worry about being late.
A2: I feel embarrassed. | B2: I worry about gaining weight.
A3: When I am depressed, I go to concerts. | B3: I’m happy with my car.
A4: When I meet my friends, I often go to see movies with them. | B4: I want to make you happy.
A5: When I’m down, I often walk in the park. | B5: I want to lose weight.
A6: I want to enjoy the view. | B6: I feel stressed.
A7: I feel tired. | B7: I want to have a talk.
A8: I’m happy with my way. | B8: I feel refreshed.
A9: When I have money, I spend a lot shopping for clothes. | B9: I want to get a job.
A10: It’s enjoyable to play games. | B10: I want to sleep.
A11: It’s relaxing to watch TV. | B11: I feel like I am home.
A12: I feel like I lost the game. | B12: I’m satisfied with my present.
... A21: I worry about failing the exam. | B21: I feel like I’m in a dream.
B22: I’m happy with myself.
B23: I’m satisfied with my result.
B24: it’s helpful to read books.
A46: When I’m bored, I watch videos on my phone.

Sheet 17-21
A1: hrtt | B1: trrr | C1: rert
A2: 18.2 | B2: I don’t know anything about him. | C2: 1
A3: 19.7 | B3: It depends on what you want. | C3: 2
A4: 18.7 | B4: I don’t know if I can do it. | C4: 3
A5: 19.3 | B5: It depends on the situation. | C5: 4
A6: 17.2 | B6: I am considering joining the club. | C6: 5
A7: 18.4 | B7: I don’t know where to go. | C7: 6
A8: 17.1 | B8: I am considering changing my job. | C8: 7
A9: 21.2 | B9: There is no need to buy him coffee. | C9: 7
A10: 21.3 | B10: There is no need to watch that show. | C10: 8
A11: 17.3 | B11: I am considering going on a trip. | C11: 9
A12: 17.4 | B12: I am considering buying a new car. | C12: 10
A13: 19.6 | B13: It depends on how many people will attend. | C13: 11
... A29: 20.1 | B29: I like watching TV because it releases stress. | C29: 28

Sheet Sheet2
A1: Sentence | B1: I want to get a job. | C1: I can’t wait to see her.
A2: When I have money, I spend a lot shopping for clothes. | B2: I am good at playing chess. | C2: I want to make you happy.
A3: I prefer eating out. | B3: I feel refreshed. | C3: I worry about gaining weight.
A4: It takes time to read a book. | B4: I can’t afford to live in Ha Noi. | C4: I am good at writing.
A5: I feel embarrassed. | B5: I can’t even eat alone. | C5: I used to watch TV a lot.
A6: It’s meaningful to help people with disabilities. | B6: I’m satisfied with my present. | C6: I can’t stop talking about her.
A7: I am good at typing. | B7: It takes time to develop a good habit. | C7: I think about the offer.
A8: I am good at dancing. | B8: It takes time to lose weight. | C8: I worry about losing money.
A9: I think about my future. | B9: I used to run everyday. | C9: I can’t even ride a bike.
A10: When I’m down, I often walk in the park. | B10: I am good at English. | C10: I want to lose weight.
A11: I am good at drawing pictures. | B11: I can’t wait to go to the concert. | C11: I can’t afford to live at the hotel.
A12: I want to go to see a movie. | B12: When I meet my friends, I often go to see movies with them. | C12: When I am depressed, I go to concerts.
... A28: I prefer reading. | B28: I am good at taking photos. | C28: I think about the problem.
A29: I can’t even talk to her. | B29: I worry about failing the exam.
A30: I can’t even cook. | B30: I think about it.
A31: I’m happy with myself. | B31: I can’t wait to go on a vacation.
A32: I used to sleep in. | B32: I can’t even sing.
A33: When I have time, I go to the gym. | B33: It’s realistic to watch 3D movie.
A34: I can’t afford to go to Canada. | B34: I used to play games well.
