Workbook

Sheet From morning to night
B2: TOPIC: FROM MORNING TO NIGHT
B3: No | C3: ID | D3: Sentence | E3: Type | F3: Link | G3: ID | H3: Copy Google drive to …
B4: 1 | C4: =B4&E4 -> 1Viet | D4: Tôi thức giấc | E4: Viet | F4: =IF(G4="","","https://docs.google.com/uc?export=download&id="&G4&"""") | G4: =IFERROR(LEFT(RIGHT(H4,LEN(H4)-32),LEN(RIGHT(H4,LEN(H4)-32))-17),"")
B5: =+B4 -> 1 | C5: =B5&E5 -> 1Eng | D5: I wake up. | E5: Eng | F5: =IF(G5="","","https://docs.google.com/uc?export=download&id="&G5) -> https://docs.google.com/uc?export=download&id=1FxbjxA9BgvCrOr8rCv4JpRWehtS5sgHH | G5: =IFERROR(LEFT(RIGHT(H5,LEN(H5)-32),LEN(RIGHT(H5,LEN(H5)-32))-17),"") -> 1FxbjxA9BgvCrOr8rCv4JpRWehtS5sgHH | H5: https://drive.google.com/file/d/1FxbjxA9BgvCrOr8rCv4JpRWehtS5sgHH/view?usp=sharing
B6: =+B5 -> 1 | C6: =B6&E6 -> 1Phon | D6: aɪ weɪk ʌp | E6: Phon | F6: =IF(G6="","","https://docs.google.com/uc?export=download&id="&G6) | G6: =IFERROR(LEFT(RIGHT(H6,LEN(H6)-32),LEN(RIGHT(H6,LEN(H6)-32))-17),"")
B7: 2 | C7: =B7&E7 -> 2Viet | D7: Tôi tắt chuông báo thức | E7: Viet | F7: =IF(G7="","","https://docs.google.com/uc?export=download&id="&G7) | G7: =IFERROR(LEFT(RIGHT(H7,LEN(H7)-32),LEN(RIGHT(H7,LEN(H7)-32))-17),"")
B8: =+B7 -> 2 | C8: =B8&E8 -> 2Eng | D8: I turn off the alarm clock. | E8: Eng | F8: =IF(G8="","","https://docs.google.com/uc?export=download&id="&G8) -> https://docs.google.com/uc?export=download&id=1hvqm3TEVfUOCcLnddpob1BU9dPbaK50k | G8: =IFERROR(LEFT(RIGHT(H8,LEN(H8)-32),LEN(RIGHT(H8,LEN(H8)-32))-17),"") -> 1hvqm3TEVfUOCcLnddpob1BU9dPbaK50k | H8: https://drive.google.com/file/d/1hvqm3TEVfUOCcLnddpob1BU9dPbaK50k/view?usp=sharing
B9: =+B8 -> 2 | C9: =B9&E9 -> 2Phon | D9: aɪ tɜ:rn a:f ði: əˈla:rm kla:k | E9: Phon | F9: =IF(G9="","","https://docs.google.com/uc?export=download&id="&G9) | G9: =IFERROR(LEFT(RIGHT(H9,LEN(H9)-32),LEN(RIGHT(H9,LEN(H9)-32))-17),"")
B10: 3 | C10: =B10&E10 -> 3Viet | D10: Tôi trở mình trên giường | E10: Viet | F10: =IF(G10="","","https://docs.google.com/uc?export=download&id="&G10) | G10: =IFERROR(LEFT(RIGHT(H10,LEN(H10)-32),LEN(RIGHT(H10,LEN(H10)-32))-17),"")
B11: =+B10 -> 3 | C11: =B11&E11 -> 3Eng | D11: I turn over in bed. | E11: Eng | F11: =IF(G11="","","https://docs.google.com/uc?export=download&id="&G11) -> https://docs.google.com/uc?export=download&id=1oX0PvuKwzf8d9uwtw1099TFv2OVH046g | G11: =IFERROR(LEFT(RIGHT(H11,LEN(H11)-32),LEN(RIGHT(H11,LEN(H11)-32))-17),"") -> 1oX0PvuKwzf8d9uwtw1099TFv2OVH046g | H11: https://drive.google.com/file/d/1oX0PvuKwzf8d9uwtw1099TFv2OVH046g/view?usp=sharing
B12: =+B11 -> 3 | C12: =B12&E12 -> 3Phon | D12: aɪ tɜ:rn ˈoʊvər ɪn bɛd | E12: Phon | F12: =IF(G12="","","https://docs.google.com/uc?export=download&id="&G12) | G12: =IFERROR(LEFT(RIGHT(H12,LEN(H12)-32),LEN(RIGHT(H12,LEN(H12)-32))-17),"")
B13: 4 | C13: =B13&E13 -> 4Viet | D13: Tôi nán lại giường thêm 15 phút nữa, tôi vẫn còn buồn ngủ | E13: Viet | F13: =IF(G13="","","https://docs.google.com/uc?export=download&id="&G13) | G13: =IFERROR(LEFT(RIGHT(H13,LEN(H13)-32),LEN(RIGHT(H13,LEN(H13)-32))-17),"")
B14: =+B13 -> 4 | C14: =B14&E14 -> 4Eng | D14: I stay in bed for 15 more minutes, I still feel sleepy. | E14: Eng | F14: =IF(G14="","","https://docs.google.com/uc?export=download&id="&G14) -> https://docs.google.com/uc?export=download&id=1BkGEBwYoN1QSh6xGss8vTm13lYBXLcVS | G14: =IFERROR(LEFT(RIGHT(H14,LEN(H14)-32),LEN(RIGHT(H14,LEN(H14)-32))-17),"") -> 1BkGEBwYoN1QSh6xGss8vTm13lYBXLcVS | H14: https://drive.google.com/file/d/1BkGEBwYoN1QSh6xGss8vTm13lYBXLcVS/view?usp=sharing
B15: =+B14 -> 4 | C15: =B15&E15 -> 4Phon | D15: aɪ steɪ ɪn bɛd fɔ:r fɪfˈti:n mɔ:r ˈmɪnɪts aɪ stɪl fi:l ˈsli:pi | E15: Phon | F15: =IF(G15="","","https://docs.google.com/uc?export=download&id="&G15) | G15: =IFERROR(LEFT(RIGHT(H15,LEN(H15)-32),LEN(RIGHT(H15,LEN(H15)-32))-17),"")
B16: 5 | C16: =B16&E16 -> 5Viet | D16: Tôi ngủ lại | E16: Viet | F16: =IF(G16="","","https://docs.google.com/uc?export=download&id="&G16) | G16: =IFERROR(LEFT(RIGHT(H16,LEN(H16)-32),LEN(RIGHT(H16,LEN(H16)-32))-17),"")
B17: =+B16 -> 5 | C17: =B17&E17 -> 5Eng | D17: I fall back to sleep again. | E17: Eng | F17: =IF(G17="","","https://docs.google.com/uc?export=download&id="&G17) -> https://docs.google.com/uc?export=download&id=11WPMpHjSKgFks6cBHaMwWlRHtnmNTMSd | G17: =IFERROR(LEFT(RIGHT(H17,LEN(H17)-32),LEN(RIGHT(H17,LEN(H17)-32))-17),"") -> 11WPMpHjSKgFks6cBHaMwWlRHtnmNTMSd | H17: https://drive.google.com/file/d/11WPMpHjSKgFks6cBHaMwWlRHtnmNTMSd/view?usp=sharing
B18: =+B17 -> 5 | C18: =B18&E18 -> 5Phon | D18: aɪ fa:l bæk tu: sli:p əˈgɛn | E18: Phon | F18: =IF(G18="","","https://docs.google.com/uc?export=download&id="&G18) | G18: =IFERROR(LEFT(RIGHT(H18,LEN(H18)-32),LEN(RIGHT(H18,LEN(H18)-32))-17),"")
B19: 6 | C19: =B19&E19 -> 6Viet | D19: Tôi thức dậy (ra khỏi giường) | E19: Viet | F19: =IF(G19="","","https://docs.google.com/uc?export=download&id="&G19) | G19: =IFERROR(LEFT(RIGHT(H19,LEN(H19)-32),LEN(RIGHT(H19,LEN(H19)-32))-17),"")
B20: =+B19 -> 6 | C20: =B20&E20 -> 6Eng | D20: I get up. | E20: Eng | F20: =IF(G20="","","https://docs.google.com/uc?export=download&id="&G20) -> https://docs.google.com/uc?export=download&id=1iBRvVGFV_u7YRHgiL8wyPv0Q0OQaStB7 | G20: =IFERROR(LEFT(RIGHT(H20,LEN(H20)-32),LEN(RIGHT(H20,LEN(H20)-32))-17),"") -> 1iBRvVGFV_u7YRHgiL8wyPv0Q0OQaStB7 | H20: https://drive.google.com/file/d/1iBRvVGFV_u7YRHgiL8wyPv0Q0OQaStB7/view?usp=sharing
B21: =+B20 -> 6 | C21: =B21&E21 -> 6Phon | D21: aɪ gɛt ʌp | E21: Phon | F21: =IF(G21="","","https://docs.google.com/uc?export=download&id="&G21) | G21: =IFERROR(LEFT(RIGHT(H21,LEN(H21)-32),LEN(RIGHT(H21,LEN(H21)-32))-17),"")
B22: 7 | C22: =B22&E22 -> 7Viet | D22: Tôi lau gỉ mắt đi | E22: Viet | F22: =IF(G22="","","https://docs.google.com/uc?export=download&id="&G22) | G22: =IFERROR(LEFT(RIGHT(H22,LEN(H22)-32),LEN(RIGHT(H22,LEN(H22)-32))-17),"")
B23: =+B22 -> 7 | C23: =B23&E23 -> 7Eng | D23: I take out eye booger. | E23: Eng | F23: =IF(G23="","","https://docs.google.com/uc?export=download&id="&G23) -> https://docs.google.com/uc?export=download&id=1QrTpKdig-NrlsiiZ-9ZE-GX5ldmQAozF | G23: =IFERROR(LEFT(RIGHT(H23,LEN(H23)-32),LEN(RIGHT(H23,LEN(H23)-32))-17),"") -> 1QrTpKdig-NrlsiiZ-9ZE-GX5ldmQAozF | H23: https://drive.google.com/file/d/1QrTpKdig-NrlsiiZ-9ZE-GX5ldmQAozF/view?usp=sharing
B24: =+B23 -> 7 | C24: =B24&E24 -> 7Phon | D24: aɪ teɪk aʊt aɪ ˈbʊɡər | E24: Phon | F24: =IF(G24="","","https://docs.google.com/uc?export=download&id="&G24) | G24: =IFERROR(LEFT(RIGHT(H24,LEN(H24)-32),LEN(RIGHT(H24,LEN(H24)-32))-17),"")
B25: 8 | C25: =B25&E25 -> 8Viet | D25: Tôi ra khỏi giường | E25: Viet | F25: =IF(G25="","","https://docs.google.com/uc?export=download&id="&G25) | G25: =IFERROR(LEFT(RIGHT(H25,LEN(H25)-32),LEN(RIGHT(H25,LEN(H25)-32))-17),"")
B26: =+B25 -> 8 | C26: =B26&E26 -> 8Eng | D26: I get out of bed. | E26: Eng | F26: =IF(G26="","","https://docs.google.com/uc?export=download&id="&G26) -> https://docs.google.com/uc?export=download&id=1CqvhN2g_ZzJYU2d023Pc5OfAZgxETuaZ | G26: =IFERROR(LEFT(RIGHT(H26,LEN(H26)-32),LEN(RIGHT(H26,LEN(H26)-32))-17),"") -> 1CqvhN2g_ZzJYU2d023Pc5OfAZgxETuaZ | H26: https://drive.google.com/file/d/1CqvhN2g_ZzJYU2d023Pc5OfAZgxETuaZ/view?usp=sharing
B27: =+B26 -> 8 | C27: =B27&E27 -> 8Phon | D27: aɪ gɛt aʊt ʌv bɛd | E27: Phon | F27: =IF(G27="","","https://docs.google.com/uc?export=download&id="&G27) | G27: =IFERROR(LEFT(RIGHT(H27,LEN(H27)-32),LEN(RIGHT(H27,LEN(H27)-32))-17),"")
B28: 9 | C28: =B28&E28 -> 9Viet | D28: Tôi dọn giường | E28: Viet | F28: =IF(G28="","","https://docs.google.com/uc?export=download&id="&G28) | G28: =IFERROR(LEFT(RIGHT(H28,LEN(H28)-32),LEN(RIGHT(H28,LEN(H28)-32))-17),"")
B29: =+B28 -> 9 | C29: =B29&E29 -> 9Eng | D29: I make the bed. | E29: Eng | F29: =IF(G29="","","https://docs.google.com/uc?export=download&id="&G29) -> https://docs.google.com/uc?export=download&id=1pnlQWZJdbLtPdfCjyXv4TCMYOwdCStCX | G29: =IFERROR(LEFT(RIGHT(H29,LEN(H29)-32),LEN(RIGHT(H29,LEN(H29)-32))-17),"") -> 1pnlQWZJdbLtPdfCjyXv4TCMYOwdCStCX | H29: https://drive.google.com/file/d/1pnlQWZJdbLtPdfCjyXv4TCMYOwdCStCX/view?usp=sharing
B30: =+B29 -> 9 | C30: =B30&E30 -> 9Phon | D30: aɪ meɪk ðə bɛd | E30: Phon | F30: =IF(G30="","","https://docs.google.com/uc?export=download&id="&G30) | G30: =IFERROR(LEFT(RIGHT(H30,LEN(H30)-32),LEN(RIGHT(H30,LEN(H30)-32))-17),"")
B31: 10 | C31: =B31&E31 -> 10Viet | D31: Tôi không bao giờ quên dọn giường. | E31: Viet | F31: =IF(G31="","","https://docs.google.com/uc?export=download&id="&G31) | G31: =IFERROR(LEFT(RIGHT(H31,LEN(H31)-32),LEN(RIGHT(H31,LEN(H31)-32))-17),"")
B32: =+B31 -> 10 | C32: =B32&E32 -> 10Eng | D32: I never forget making my own bed. | E32: Eng | F32: =IF(G32="","","https://docs.google.com/uc?export=download&id="&G32) -> https://docs.google.com/uc?export=download&id=14RHYD9kXBnQYYJfQt1qEQ7fX-1yMFYxr | G32: =IFERROR(LEFT(RIGHT(H32,LEN(H32)-32),LEN(RIGHT(H32,LEN(H32)-32))-17),"") -> 14RHYD9kXBnQYYJfQt1qEQ7fX-1yMFYxr | H32: https://drive.google.com/file/d/14RHYD9kXBnQYYJfQt1qEQ7fX-1yMFYxr/view?usp=sharing
B33: =+B32 -> 10 | C33: =B33&E33 -> 10Phon | D33: aɪ ˈevər fərˈget ˈmeɪkɪŋ maɪ oʊn bed | E33: Phon | F33: =IF(G33="","","https://docs.google.com/uc?export=download&id="&G33) | G33: =IFERROR(LEFT(RIGHT(H33,LEN(H33)-32),LEN(RIGHT(H33,LEN(H33)-32))-17),"")
B34: 11 | C34: =B34&E34 -> 11Viet | D34: Tôi vặn/khoá vòi nước. | E34: Viet | F34: =IF(G34="","","https://docs.google.com/uc?export=download&id="&G34) | G34: =IFERROR(LEFT(RIGHT(H34,LEN(H34)-32),LEN(RIGHT(H34,LEN(H34)-32))-17),"")
B35: =+B34 -> 11 | C35: =B35&E35 -> 11Eng | D35: I turn the faucet on (off). | E35: Eng | F35: =IF(G35="","","https://docs.google.com/uc?export=download&id="&G35) -> https://docs.google.com/uc?export=download&id=1wKMI_H4Pdsmfzen7SEAQiSN09md25TdG | G35: =IFERROR(LEFT(RIGHT(H35,LEN(H35)-32),LEN(RIGHT(H35,LEN(H35)-32))-17),"") -> 1wKMI_H4Pdsmfzen7SEAQiSN09md25TdG | H35: https://drive.google.com/file/d/1wKMI_H4Pdsmfzen7SEAQiSN09md25TdG/view?usp=sharing
B36: =+B35 -> 11 | C36: =B36&E36 -> 11Phon | D36: aɪ tɜ:rn ðə ˈfa:sət a:n (a:f) | E36: Phon | F36: =IF(G36="","","https://docs.google.com/uc?export=download&id="&G36) | G36: =IFERROR(LEFT(RIGHT(H36,LEN(H36)-32),LEN(RIGHT(H36,LEN(H36)-32))-17),"")
B37: 12 | C37: =B37&E37 -> 12Viet | D37: Tôi lau khô tay. | E37: Viet | F37: =IF(G37="","","https://docs.google.com/uc?export=download&id="&G37) | G37: =IFERROR(LEFT(RIGHT(H37,LEN(H37)-32),LEN(RIGHT(H37,LEN(H37)-32))-17),"")
B38: =+B37 -> 12 | C38: =B38&E38 -> 12Eng | D38: I dry my hands. | E38: Eng | F38: =IF(G38="","","https://docs.google.com/uc?export=download&id="&G38) -> https://docs.google.com/uc?export=download&id=1_VmbL67N6Jzqa-CEYApmsLr_-95sXH77 | G38: =IFERROR(LEFT(RIGHT(H38,LEN(H38)-32),LEN(RIGHT(H38,LEN(H38)-32))-17),"") -> 1_VmbL67N6Jzqa-CEYApmsLr_-95sXH77 | H38: https://drive.google.com/file/d/1_VmbL67N6Jzqa-CEYApmsLr_-95sXH77/view?usp=sharing
B39: =+B38 -> 12 | C39: =B39&E39 -> 12Phon | D39: aɪ draɪ maɪ hændz | E39: Phon | F39: =IF(G39="","","https://docs.google.com/uc?export=download&id="&G39) | G39: =IFERROR(LEFT(RIGHT(H39,LEN(H39)-32),LEN(RIGHT(H39,LEN(H39)-32))-17),"")
B40: 13 | C40: =B40&E40 -> 13Viet | D40: Tôi đi tắm. | E40: Viet | F40: =IF(G40="","","https://docs.google.com/uc?export=download&id="&G40) | G40: =IFERROR(LEFT(RIGHT(H40,LEN(H40)-32),LEN(RIGHT(H40,LEN(H40)-32))-17),"")
B41: =+B40 -> 13 | C41: =B41&E41 -> 13Eng | D41: I take a shower. | E41: Eng | F41: =IF(G41="","","https://docs.google.com/uc?export=download&id="&G41) -> https://docs.google.com/uc?export=download&id=1e6JFUOudrCngOrqRSk_ZbggKIQp_tDlV | G41: =IFERROR(LEFT(RIGHT(H41,LEN(H41)-32),LEN(RIGHT(H41,LEN(H41)-32))-17),"") -> 1e6JFUOudrCngOrqRSk_ZbggKIQp_tDlV | H41: https://drive.google.com/file/d/1e6JFUOudrCngOrqRSk_ZbggKIQp_tDlV/view?usp=sharing
...

Sheet Viet
B2: Sentence | C2: Link | D2: ID | E2: Copy Google drive to …
B3: 01-10 | C3: =IF(D3="","","https://docs.google.com/uc?export=download&id="&D3) -> https://docs.google.com/uc?export=download&id=1ndpvRnnqmfiCaBhFYLcxI5-Z7y4ZX8P4 | D3: =IFERROR(LEFT(RIGHT(E3,LEN(E3)-32),LEN(RIGHT(E3,LEN(E3)-32))-17),"") -> 1ndpvRnnqmfiCaBhFYLcxI5-Z7y4ZX8P4 | E3: https://drive.google.com/file/d/1ndpvRnnqmfiCaBhFYLcxI5-Z7y4ZX8P4/view?usp=sharing
B4: 11-20 | C4: =IF(D4="","","https://docs.google.com/uc?export=download&id="&D4) -> https://docs.google.com/uc?export=download&id=1ZsTPpEIrmiswPVaYqc9hq67Dh-_tYw9P | D4: =IFERROR(LEFT(RIGHT(E4,LEN(E4)-32),LEN(RIGHT(E4,LEN(E4)-32))-17),"") -> 1ZsTPpEIrmiswPVaYqc9hq67Dh-_tYw9P | E4: https://drive.google.com/file/d/1ZsTPpEIrmiswPVaYqc9hq67Dh-_tYw9P/view?usp=sharing
B5: 21-30 | C5: =IF(D5="","","https://docs.google.com/uc?export=download&id="&D5) -> https://docs.google.com/uc?export=download&id=1kZt8G3Ur6-OxKdzqWQMTrg-0BYGw7TbN | D5: =IFERROR(LEFT(RIGHT(E5,LEN(E5)-32),LEN(RIGHT(E5,LEN(E5)-32))-17),"") -> 1kZt8G3Ur6-OxKdzqWQMTrg-0BYGw7TbN | E5: https://drive.google.com/file/d/1kZt8G3Ur6-OxKdzqWQMTrg-0BYGw7TbN/view?usp=sharing
B6: 31-40 | C6: =IF(D6="","","https://docs.google.com/uc?export=download&id="&D6) -> https://docs.google.com/uc?export=download&id=1NohrN30XVWtJq8ooXLVZWtZtaj4fkH4R | D6: =IFERROR(LEFT(RIGHT(E6,LEN(E6)-32),LEN(RIGHT(E6,LEN(E6)-32))-17),"") -> 1NohrN30XVWtJq8ooXLVZWtZtaj4fkH4R | E6: https://drive.google.com/file/d/1NohrN30XVWtJq8ooXLVZWtZtaj4fkH4R/view?usp=sharing
B7: 41-50 | C7: =IF(D7="","","https://docs.google.com/uc?export=download&id="&D7) -> https://docs.google.com/uc?export=download&id=18QAHiw7kPXfrtkFX4oeNND29dAy_FLuR | D7: =IFERROR(LEFT(RIGHT(E7,LEN(E7)-32),LEN(RIGHT(E7,LEN(E7)-32))-17),"") -> 18QAHiw7kPXfrtkFX4oeNND29dAy_FLuR | E7: https://drive.google.com/file/d/18QAHiw7kPXfrtkFX4oeNND29dAy_FLuR/view?usp=sharing
B8: 51-60 | C8: =IF(D8="","","https://docs.google.com/uc?export=download&id="&D8) -> https://docs.google.com/uc?export=download&id=12RabXvVqEXD6eKB6CmRqe5QiFlKk_oZR | D8: =IFERROR(LEFT(RIGHT(E8,LEN(E8)-32),LEN(RIGHT(E8,LEN(E8)-32))-17),"") -> 12RabXvVqEXD6eKB6CmRqe5QiFlKk_oZR | E8: https://drive.google.com/file/d/12RabXvVqEXD6eKB6CmRqe5QiFlKk_oZR/view?usp=sharing
B9: 61-69 | C9: =IF(D9="","","https://docs.google.com/uc?export=download&id="&D9) -> https://docs.google.com/uc?export=download&id=1gb97azDSY0J_c29t8FCBs_2_bWILFjn6 | D9: =IFERROR(LEFT(RIGHT(E9,LEN(E9)-32),LEN(RIGHT(E9,LEN(E9)-32))-17),"") -> 1gb97azDSY0J_c29t8FCBs_2_bWILFjn6 | E9: https://drive.google.com/file/d/1gb97azDSY0J_c29t8FCBs_2_bWILFjn6/view?usp=sharing
B10: 01-69 | C10: =IF(D10="","","https://docs.google.com/uc?export=download&id="&D10) -> https://docs.google.com/uc?export=download&id=1FTvAp4Al8Yuf9KMiYWchbvvDmqSIJYec | D10: =IFERROR(LEFT(RIGHT(E10,LEN(E10)-32),LEN(RIGHT(E10,LEN(E10)-32))-17),"") -> 1FTvAp4Al8Yuf9KMiYWchbvvDmqSIJYec | E10: https://drive.google.com/file/d/1FTvAp4Al8Yuf9KMiYWchbvvDmqSIJYec/view?usp=sharing
C11: =IF(D11="","","https://docs.google.com/uc?export=download&id="&D11) | D11: =IFERROR(LEFT(RIGHT(E11,LEN(E11)-32),LEN(RIGHT(E11,LEN(E11)-32))-17),"")
C12: =IF(D12="","","https://docs.google.com/uc?export=download&id="&D12) | D12: =IFERROR(LEFT(RIGHT(E12,LEN(E12)-32),LEN(RIGHT(E12,LEN(E12)-32))-17),"")
C13: =IF(D13="","","https://docs.google.com/uc?export=download&id="&D13) | D13: =IFERROR(LEFT(RIGHT(E13,LEN(E13)-32),LEN(RIGHT(E13,LEN(E13)-32))-17),"")

Sheet Ramdom
B1: From | C1: 61
B2: To | C2: 69
C3: No | D3: Viet | E3: Eng
A4: =C1 -> 61 | B4: =IF(A4="","",RANDBETWEEN($C$1,$C$2)) -> 69 | C4: =IFERROR($C$1-1+_xlfn.RANK.EQ(B4,$B$4:$B$72)+COUNTIF(B$4:$B4,B4)-1,"") -> 61 | D4: =IFERROR(VLOOKUP(C4&"Viet",'From morning to night'!C:D,2,0),"") -> Tôi gấp quần áo. | E4: =IFERROR(VLOOKUP(C4&"Eng",'From morning to night'!C:D,2,0),"") -> I fold the clothes.
A5: =IFERROR(IF(A4+1>$C$2,"",A4+1),"") -> 62 | B5: =IF(A5="","",RANDBETWEEN($C$1,$C$2)) -> 62 | C5: =IFERROR($C$1-1+_xlfn.RANK.EQ(B5,$B$4:$B$72)+COUNTIF(B$4:$B5,B5)-1,"") -> 69 | D5: =IFERROR(VLOOKUP(C5&"Viet",'From morning to night'!C:D,2,0),"") -> Tôi ngủ ngay khi vừa ngả đầu xuống gối. | E5: =IFERROR(VLOOKUP(C5&"Eng",'From morning to night'!C:D,2,0),"") -> I fall asleep as soon as my head hits the pillow.
A6: =IFERROR(IF(A5+1>$C$2,"",A5+1),"") -> 63 | B6: =IF(A6="","",RANDBETWEEN($C$1,$C$2)) -> 63 | C6: =IFERROR($C$1-1+_xlfn.RANK.EQ(B6,$B$4:$B$72)+COUNTIF(B$4:$B6,B6)-1,"") -> 67 | D6: =IFERROR(VLOOKUP(C6&"Viet",'From morning to night'!C:D,2,0),"") -> Tôi đặt báo thức lúc 6 giờ sáng. | E6: =IFERROR(VLOOKUP(C6&"Eng",'From morning to night'!C:D,2,0),"") -> I set the alarm clock for 6 a.m.
A7: =IFERROR(IF(A6+1>$C$2,"",A6+1),"") -> 64 | B7: =IF(A7="","",RANDBETWEEN($C$1,$C$2)) -> 67 | C7: =IFERROR($C$1-1+_xlfn.RANK.EQ(B7,$B$4:$B$72)+COUNTIF(B$4:$B7,B7)-1,"") -> 63 | D7: =IFERROR(VLOOKUP(C7&"Viet",'From morning to night'!C:D,2,0),"") -> Tôi đi đổ rác. | E7: =IFERROR(VLOOKUP(C7&"Eng",'From morning to night'!C:D,2,0),"") -> I take out the trash.
A8: =IFERROR(IF(A7+1>$C$2,"",A7+1),"") -> 65 | B8: =IF(A8="","",RANDBETWEEN($C$1,$C$2)) -> 65 | C8: =IFERROR($C$1-1+_xlfn.RANK.EQ(B8,$B$4:$B$72)+COUNTIF(B$4:$B8,B8)-1,"") -> 64 | D8: =IFERROR(VLOOKUP(C8&"Viet",'From morning to night'!C:D,2,0),"") -> Tôi tập Yoga. | E8: =IFERROR(VLOOKUP(C8&"Eng",'From morning to night'!C:D,2,0),"") -> I do yoga.
A9: =IFERROR(IF(A8+1>$C$2,"",A8+1),"") -> 66 | B9: =IF(A9="","",RANDBETWEEN($C$1,$C$2)) -> 63 | C9: =IFERROR($C$1-1+_xlfn.RANK.EQ(B9,$B$4:$B$72)+COUNTIF(B$4:$B9,B9)-1,"") -> 68 | D9: =IFERROR(VLOOKUP(C9&"Viet",'From morning to night'!C:D,2,0),"") -> Tôi mệt mỏi và ngủ gật trên ghế sô pha. | E9: =IFERROR(VLOOKUP(C9&"Eng",'From morning to night'!C:D,2,0),"") -> I am worn out and nod off on the couch.
A10: =IFERROR(IF(A9+1>$C$2,"",A9+1),"") -> 67 | B10: =IF(A10="","",RANDBETWEEN($C$1,$C$2)) -> 65 | C10: =IFERROR($C$1-1+_xlfn.RANK.EQ(B10,$B$4:$B$72)+COUNTIF(B$4:$B10,B10)-1,"") -> 65 | D10: =IFERROR(VLOOKUP(C10&"Viet",'From morning to night'!C:D,2,0),"") -> Tôi tập thể hình. | E10: =IFERROR(VLOOKUP(C10&"Eng",'From morning to night'!C:D,2,0),"") -> I do the gym.
A11: =IFERROR(IF(A10+1>$C$2,"",A10+1),"") -> 68 | B11: =IF(A11="","",RANDBETWEEN($C$1,$C$2)) -> 65 | C11: =IFERROR($C$1-1+_xlfn.RANK.EQ(B11,$B$4:$B$72)+COUNTIF(B$4:$B11,B11)-1,"") -> 66 | D11: =IFERROR(VLOOKUP(C11&"Viet",'From morning to night'!C:D,2,0),"") -> Tôi đắp mặt nạ. | E11: =IFERROR(VLOOKUP(C11&"Eng",'From morning to night'!C:D,2,0),"") -> I apply a mask on my face.
A12: =IFERROR(IF(A11+1>$C$2,"",A11+1),"") -> 69 | B12: =IF(A12="","",RANDBETWEEN($C$1,$C$2)) -> 68 | C12: =IFERROR($C$1-1+_xlfn.RANK.EQ(B12,$B$4:$B$72)+COUNTIF(B$4:$B12,B12)-1,"") -> 62 | D12: =IFERROR(VLOOKUP(C12&"Viet",'From morning to night'!C:D,2,0),"") -> Tôi lau nhà. | E12: =IFERROR(VLOOKUP(C12&"Eng",'From morning to night'!C:D,2,0),"") -> I mop the floor.
A13: =IFERROR(IF(A12+1>$C$2,"",A12+1),"") | B13: =IF(A13="","",RANDBETWEEN($C$1,$C$2)) | C13: =IFERROR($C$1-1+_xlfn.RANK.EQ(B13,$B$4:$B$72)+COUNTIF(B$4:$B13,B13)-1,"") | D13: =IFERROR(VLOOKUP(C13&"Viet",'From morning to night'!C:D,2,0),"") | E13: =IFERROR(VLOOKUP(C13&"Eng",'From morning to night'!C:D,2,0),"")
A14: =IFERROR(IF(A13+1>$C$2,"",A13+1),"") | B14: =IF(A14="","",RANDBETWEEN($C$1,$C$2)) | C14: =IFERROR($C$1-1+_xlfn.RANK.EQ(B14,$B$4:$B$72)+COUNTIF(B$4:$B14,B14)-1,"") | D14: =IFERROR(VLOOKUP(C14&"Viet",'From morning to night'!C:D,2,0),"") | E14: =IFERROR(VLOOKUP(C14&"Eng",'From morning to night'!C:D,2,0),"")
A15: =IFERROR(IF(A14+1>$C$2,"",A14+1),"") | B15: =IF(A15="","",RANDBETWEEN($C$1,$C$2)) | C15: =IFERROR($C$1-1+_xlfn.RANK.EQ(B15,$B$4:$B$72)+COUNTIF(B$4:$B15,B15)-1,"") | D15: =IFERROR(VLOOKUP(C15&"Viet",'From morning to night'!C:D,2,0),"") | E15: =IFERROR(VLOOKUP(C15&"Eng",'From morning to night'!C:D,2,0),"")
A16: =IFERROR(IF(A15+1>$C$2,"",A15+1),"") | B16: =IF(A16="","",RANDBETWEEN($C$1,$C$2)) | C16: =IFERROR($C$1-1+_xlfn.RANK.EQ(B16,$B$4:$B$72)+COUNTIF(B$4:$B16,B16)-1,"") | D16: =IFERROR(VLOOKUP(C16&"Viet",'From morning to night'!C:D,2,0),"") | E16: =IFERROR(VLOOKUP(C16&"Eng",'From morning to night'!C:D,2,0),"")
... A72: =IFERROR(IF(A71+1>$C$2,"",A71+1),"") | B72: =IF(A72="","",RANDBETWEEN($C$1,$C$2)) | C72: =IFERROR($C$1-1+_xlfn.RANK.EQ(B72,$B$4:$B$72)+COUNTIF(B$4:$B72,B72)-1,"") | D72: =IFERROR(VLOOKUP(C72&"Viet",'From morning to night'!C:D,2,0),"") | E72: =IFERROR(VLOOKUP(C72&"Eng",'From morning to night'!C:D,2,0),"")
A73: =IFERROR(IF(A72+1>$C$2,"",A72+1),"") | B73: =IF(A73="","",RANDBETWEEN($C$1,$C$2))
A74: =IFERROR(IF(A73+1>$C$2,"",A73+1),"") | B74: =IF(A74="","",RANDBETWEEN($C$1,$C$2))
A75: =IFERROR(IF(A74+1>$C$2,"",A74+1),"") | B75: =IF(A75="","",RANDBETWEEN($C$1,$C$2))
A76: =IFERROR(IF(A75+1>$C$2,"",A75+1),"") | B76: =IF(A76="","",RANDBETWEEN($C$1,$C$2))
A77: =IFERROR(IF(A76+1>$C$2,"",A76+1),"") | B77: =IF(A77="","",RANDBETWEEN($C$1,$C$2))
A78: =IFERROR(IF(A77+1>$C$2,"",A77+1),"") | B78: =IF(A78="","",RANDBETWEEN($C$1,$C$2))
A79: =IFERROR(IF(A78+1>$C$2,"",A78+1),"") | B79: =IF(A79="","",RANDBETWEEN($C$1,$C$2))
A80: =IFERROR(IF(A79+1>$C$2,"",A79+1),"") | B80: =IF(A80="","",RANDBETWEEN($C$1,$C$2))
A81: =IFERROR(IF(A80+1>$C$2,"",A80+1),"") | B81: =IF(A81="","",RANDBETWEEN($C$1,$C$2))
A82: =IFERROR(IF(A81+1>$C$2,"",A81+1),"") | B82: =IF(A82="","",RANDBETWEEN($C$1,$C$2))
A83: =IFERROR(IF(A82+1>$C$2,"",A82+1),"") | B83: =IF(A83="","",RANDBETWEEN($C$1,$C$2))
A84: =IFERROR(IF(A83+1>$C$2,"",A83+1),"") | B84: =IF(A84="","",RANDBETWEEN($C$1,$C$2))
... A295: =IFERROR(IF(A294+1>$C$2,"",A294+1),"") | B295: =IF(A295="","",RANDBETWEEN($C$1,$C$2))

Sheet Sheet1
