Workbook

Sheet Gossip
B2: TOPIC: GOSSIP
A3: No | B3: No | C3: ID | D3: Sentence | E3: Type | F3: Link | G3: ID | H3: Copy Google drive to …
B4: 1 | C4: 1Struc | D4: I DON’T MEAN TO GOSSIP, BUT... /Tôi không muốn ngồi lê đôi mách, nhưng…/ | E4: Struc | F4: =IF(G4="","","https://docs.google.com/uc?export=download&id="&G4)
B5: 1.1 | C5: 1.1Viet | D5: Tôi không muốn ngồi lê đôi mách, nhưng mà cô ta nói nhiều quá. | E5: Viet | F5: =IF(G5="","","https://docs.google.com/uc?export=download&id="&G5) | G5: =IFERROR(LEFT(RIGHT(H5,LEN(H5)-32),LEN(RIGHT(H5,LEN(H5)-32))-17),"")
A6: 1 | B6: 1.1 | C6: 1.1Eng | D6: I don’t mean to gossip, but she talks too much. | E6: Eng | F6: =IF(G6="","","https://docs.google.com/uc?export=download&id="&G6) -> https://docs.google.com/uc?export=download&id=13V5pNLKDCtgLKZM6vxavg8rdIY94OBW- | G6: =IFERROR(LEFT(RIGHT(H6,LEN(H6)-32),LEN(RIGHT(H6,LEN(H6)-32))-17),"") -> 13V5pNLKDCtgLKZM6vxavg8rdIY94OBW- | H6: https://drive.google.com/file/d/13V5pNLKDCtgLKZM6vxavg8rdIY94OBW-/view?usp=sharing
B7: 1.1 | C7: 1.1Phon | D7: aɪ doʊnt mi:n tu: ˈga:sɪp bʌt ʃi: ta:ks tu: mʌʧ | E7: Phon | F7: =IF(G7="","","https://docs.google.com/uc?export=download&id="&G7) | G7: =IFERROR(LEFT(RIGHT(H7,LEN(H7)-32),LEN(RIGHT(H7,LEN(H7)-32))-17),"")
B8: 1.2 | C8: 1.2Viet | D8: Tôi không muốn ngồi lê đôi mách, nhưng mà anh ta hách dịch quá. | E8: Viet | F8: =IF(G8="","","https://docs.google.com/uc?export=download&id="&G8) | G8: =IFERROR(LEFT(RIGHT(H8,LEN(H8)-32),LEN(RIGHT(H8,LEN(H8)-32))-17),"")
A9: 2 | B9: 1.2 | C9: 1.2Eng | D9: I don’t mean to gossip, but he is bossy. | E9: Eng | F9: =IF(G9="","","https://docs.google.com/uc?export=download&id="&G9) -> https://docs.google.com/uc?export=download&id=1ov_KwvJF8EepjVzPKo4WXWmuxJorTxZp | G9: =IFERROR(LEFT(RIGHT(H9,LEN(H9)-32),LEN(RIGHT(H9,LEN(H9)-32))-17),"") -> 1ov_KwvJF8EepjVzPKo4WXWmuxJorTxZp | H9: https://drive.google.com/file/d/1ov_KwvJF8EepjVzPKo4WXWmuxJorTxZp/view?usp=sharing
B10: 1.2 | C10: 1.2Phon | D10: aɪ doʊnt mi:n tu: ˈga:sɪp bʌt hi: ɪz ˈba:si | E10: Phon | F10: =IF(G10="","","https://docs.google.com/uc?export=download&id="&G10) | G10: =IFERROR(LEFT(RIGHT(H10,LEN(H10)-32),LEN(RIGHT(H10,LEN(H10)-32))-17),"")
B11: 1.3 | C11: 1.3Viet | D11: Tôi không muốn ngồi lê đôi mách, nhưng mà cô ta làm phiền tôi quá. | E11: Viet | F11: =IF(G11="","","https://docs.google.com/uc?export=download&id="&G11) | G11: =IFERROR(LEFT(RIGHT(H11,LEN(H11)-32),LEN(RIGHT(H11,LEN(H11)-32))-17),"")
A12: 3 | B12: 1.3 | C12: 1.3Eng | D12: I don’t mean to gossip, but she bothers me a lot. | E12: Eng | F12: =IF(G12="","","https://docs.google.com/uc?export=download&id="&G12) -> https://docs.google.com/uc?export=download&id=1K4psT7ee-X5ISVCTmYlkspIrO8z0PB30 | G12: =IFERROR(LEFT(RIGHT(H12,LEN(H12)-32),LEN(RIGHT(H12,LEN(H12)-32))-17),"") -> 1K4psT7ee-X5ISVCTmYlkspIrO8z0PB30 | H12: https://drive.google.com/file/d/1K4psT7ee-X5ISVCTmYlkspIrO8z0PB30/view?usp=sharing
B13: 1.3 | C13: 1.3Phon | D13: aɪ doʊnt mi:n tu: ˈga:sɪp bʌt ʃi: ˈba:ðərz mi: ə la:t | E13: Phon | F13: =IF(G13="","","https://docs.google.com/uc?export=download&id="&G13) | G13: =IFERROR(LEFT(RIGHT(H13,LEN(H13)-32),LEN(RIGHT(H13,LEN(H13)-32))-17),"")
B14: 1.4 | C14: 1.4Viet | D14: Tôi không muốn ngồi lê đôi mách, nhưng mà tôi vừa nghe nhiều điều khá thú vị. | E14: Viet | F14: =IF(G14="","","https://docs.google.com/uc?export=download&id="&G14) | G14: =IFERROR(LEFT(RIGHT(H14,LEN(H14)-32),LEN(RIGHT(H14,LEN(H14)-32))-17),"")
A15: 4 | B15: 1.4 | C15: 1.4Eng | D15: I don’t mean to gossip, but I just heard something interesting. | E15: Eng | F15: =IF(G15="","","https://docs.google.com/uc?export=download&id="&G15) -> https://docs.google.com/uc?export=download&id=1jToZDxSRMUZ6_o8dFm0Sf2D2MH08udRJ | G15: =IFERROR(LEFT(RIGHT(H15,LEN(H15)-32),LEN(RIGHT(H15,LEN(H15)-32))-17),"") -> 1jToZDxSRMUZ6_o8dFm0Sf2D2MH08udRJ | H15: https://drive.google.com/file/d/1jToZDxSRMUZ6_o8dFm0Sf2D2MH08udRJ/view?usp=sharing
B16: 1.4 | C16: 1.4Phon | D16: aɪ doʊnt mi:n tu: ˈga:sɪp bʌt aɪ ʤʌst hɜ:rd ˈsʌmθɪŋ ˈɪntrəstɪŋ | E16: Phon | F16: =IF(G16="","","https://docs.google.com/uc?export=download&id="&G16) | G16: =IFERROR(LEFT(RIGHT(H16,LEN(H16)-32),LEN(RIGHT(H16,LEN(H16)-32))-17),"")
B17: 1.5 | C17: 1.5Viet | D17: Tôi không muốn ngồi lê đôi mách, nhưng mà A sắp nghỉ việc rồi. | E17: Viet | F17: =IF(G17="","","https://docs.google.com/uc?export=download&id="&G17) | G17: =IFERROR(LEFT(RIGHT(H17,LEN(H17)-32),LEN(RIGHT(H17,LEN(H17)-32))-17),"")
A18: 5 | B18: 1.5 | C18: 1.5Eng | D18: I don’t mean to gossip, but I heard that A is quitting. | E18: Eng | F18: =IF(G18="","","https://docs.google.com/uc?export=download&id="&G18) -> https://docs.google.com/uc?export=download&id=1v20LBoVMGNtdDD8a_l7qRaRt3JO3f2rJ | G18: =IFERROR(LEFT(RIGHT(H18,LEN(H18)-32),LEN(RIGHT(H18,LEN(H18)-32))-17),"") -> 1v20LBoVMGNtdDD8a_l7qRaRt3JO3f2rJ | H18: https://drive.google.com/file/d/1v20LBoVMGNtdDD8a_l7qRaRt3JO3f2rJ/view?usp=sharing
B19: 1.5 | C19: 1.5Phon | D19: aɪ doʊnt mi:n tu: ˈga:sɪp bʌt aɪ hɜ:rd ðæt eɪ ɪz ˈkwɪtɪŋ | E19: Phon | F19: =IF(G19="","","https://docs.google.com/uc?export=download&id="&G19) | G19: =IFERROR(LEFT(RIGHT(H19,LEN(H19)-32),LEN(RIGHT(H19,LEN(H19)-32))-17),"")
B20: 2 | C20: 2Struc | D20: ACTUALLY, THE WORD AROUND THE OFFICE IS THAT… /Cả văn phòng đều đồn là…/ | E20: Struc | F20: =IF(G20="","","https://docs.google.com/uc?export=download&id="&G20) | G20: =IFERROR(LEFT(RIGHT(H20,LEN(H20)-32),LEN(RIGHT(H20,LEN(H20)-32))-17),"")
B21: 2.1 | C21: 2.1Viet | D21: Cả văn phòng đều đồn là Tom sắp bị sa thải. | E21: Viet | F21: =IF(G21="","","https://docs.google.com/uc?export=download&id="&G21) | G21: =IFERROR(LEFT(RIGHT(H21,LEN(H21)-32),LEN(RIGHT(H21,LEN(H21)-32))-17),"")
A22: 6 | B22: 2.1 | C22: 2.1Eng | D22: Actually, the word around the office is that Tom is going to be fired. | E22: Eng | F22: =IF(G22="","","https://docs.google.com/uc?export=download&id="&G22) -> https://docs.google.com/uc?export=download&id=1tnGlxy11wzdgoSc3p715ZocBiyl5O2k- | G22: =IFERROR(LEFT(RIGHT(H22,LEN(H22)-32),LEN(RIGHT(H22,LEN(H22)-32))-17),"") -> 1tnGlxy11wzdgoSc3p715ZocBiyl5O2k- | H22: https://drive.google.com/file/d/1tnGlxy11wzdgoSc3p715ZocBiyl5O2k-/view?usp=sharing
B23: 2.1 | C23: 2.1Phon | D23: ˈækʧuəli ðə wɜ:rd əˈraʊnd ði: ˈa:fɪs ɪz ðæt ta:m ɪz ˈgoʊɪŋ tu: bi: ˈfaɪərd | E23: Phon | F23: =IF(G23="","","https://docs.google.com/uc?export=download&id="&G23) | G23: =IFERROR(LEFT(RIGHT(H23,LEN(H23)-32),LEN(RIGHT(H23,LEN(H23)-32))-17),"")
B24: 2.2 | C24: 2.2Viet | D24: Cả văn phòng đều đồn là Lan sẽ được thăng chức. | E24: Viet | F24: =IF(G24="","","https://docs.google.com/uc?export=download&id="&G24) | G24: =IFERROR(LEFT(RIGHT(H24,LEN(H24)-32),LEN(RIGHT(H24,LEN(H24)-32))-17),"")
A25: 7 | B25: 2.2 | C25: 2.2Eng | D25: Actually, the word around the office is that Lan will be promoted. | E25: Eng | F25: =IF(G25="","","https://docs.google.com/uc?export=download&id="&G25) -> https://docs.google.com/uc?export=download&id=14cMKMJn5mp1UJWQKurmGnUeFRk-oMOGW | G25: =IFERROR(LEFT(RIGHT(H25,LEN(H25)-32),LEN(RIGHT(H25,LEN(H25)-32))-17),"") -> 14cMKMJn5mp1UJWQKurmGnUeFRk-oMOGW | H25: https://drive.google.com/file/d/14cMKMJn5mp1UJWQKurmGnUeFRk-oMOGW/view?usp=sharing
B26: 2.2 | C26: 2.2Phon | D26: ˈækʧuəli ðə wɜ:rd əˈraʊnd ði: ˈa:fɪs ɪz ðæt læn wɪl bi: prəˈmoʊtɪd | E26: Phon | F26: =IF(G26="","","https://docs.google.com/uc?export=download&id="&G26) | G26: =IFERROR(LEFT(RIGHT(H26,LEN(H26)-32),LEN(RIGHT(H26,LEN(H26)-32))-17),"")
B27: 2.3 | C27: 2.3Viet | D27: Cả văn phòng đều đồn tháng 4 này là tháng sa thải. | E27: Viet | F27: =IF(G27="","","https://docs.google.com/uc?export=download&id="&G27) | G27: =IFERROR(LEFT(RIGHT(H27,LEN(H27)-32),LEN(RIGHT(H27,LEN(H27)-32))-17),"")
A28: 8 | B28: 2.3 | C28: 2.3Eng | D28: Actually, the word around the office is that April is getting fired. | E28: Eng | F28: =IF(G28="","","https://docs.google.com/uc?export=download&id="&G28) -> https://docs.google.com/uc?export=download&id=1ssTTF5CiL8i47gVXTpj4FVxYLj2v8mTg | G28: =IFERROR(LEFT(RIGHT(H28,LEN(H28)-32),LEN(RIGHT(H28,LEN(H28)-32))-17),"") -> 1ssTTF5CiL8i47gVXTpj4FVxYLj2v8mTg | H28: https://drive.google.com/file/d/1ssTTF5CiL8i47gVXTpj4FVxYLj2v8mTg/view?usp=sharing
B29: 2.3 | C29: 2.3Phon | D29: ˈækʧuəli ðə wɜ:rd əˈraʊnd ði: ˈa:fɪs ɪz ðæt ˈeɪprəl ɪz ˈgɛtɪŋ ˈfaɪərd | E29: Phon | F29: =IF(G29="","","https://docs.google.com/uc?export=download&id="&G29) | G29: =IFERROR(LEFT(RIGHT(H29,LEN(H29)-32),LEN(RIGHT(H29,LEN(H29)-32))-17),"")
B30: 2.4 | C30: 2.4Viet | D30: Cả văn phòng đều đồn là ông A đang tán cô B. | E30: Viet | F30: =IF(G30="","","https://docs.google.com/uc?export=download&id="&G30) | G30: =IFERROR(LEFT(RIGHT(H30,LEN(H30)-32),LEN(RIGHT(H30,LEN(H30)-32))-17),"")
A31: 9 | B31: 2.4 | C31: 2.4Eng | D31: Actually, the word around the office is that Mr. A is flirting Ms. B. | E31: Eng | F31: =IF(G31="","","https://docs.google.com/uc?export=download&id="&G31) -> https://docs.google.com/uc?export=download&id=1bu7SYP34oits7fPnhghj0nDEh06Gjp0F | G31: =IFERROR(LEFT(RIGHT(H31,LEN(H31)-32),LEN(RIGHT(H31,LEN(H31)-32))-17),"") -> 1bu7SYP34oits7fPnhghj0nDEh06Gjp0F | H31: https://drive.google.com/file/d/1bu7SYP34oits7fPnhghj0nDEh06Gjp0F/view?usp=sharing
B32: 2.4 | C32: 2.4Phon | D32: ˈækʧuəli ðə wɜ:rd əˈraʊnd ði: ˈa:fɪs ɪz ðæt ˈmɪstər eɪ ɪz ˈflɜ:rtɪŋ mɪz bi: | E32: Phon | F32: =IF(G32="","","https://docs.google.com/uc?export=download&id="&G32) | G32: =IFERROR(LEFT(RIGHT(H32,LEN(H32)-32),LEN(RIGHT(H32,LEN(H32)-32))-17),"")
B33: 3 | C33: 3Struc | D33: HAVE YOU HEARD THE LATEST NEWS ABOUT…? /Bạn có nghe tin về… chưa?/ | E33: Struc | F33: =IF(G33="","","https://docs.google.com/uc?export=download&id="&G33) | G33: =IFERROR(LEFT(RIGHT(H33,LEN(H33)-32),LEN(RIGHT(H33,LEN(H33)-32))-17),"")
B34: 3.1 | C34: 3.1Viet | D34: Bạn có nghe tin về An chưa? | E34: Viet | F34: =IF(G34="","","https://docs.google.com/uc?export=download&id="&G34) | G34: =IFERROR(LEFT(RIGHT(H34,LEN(H34)-32),LEN(RIGHT(H34,LEN(H34)-32))-17),"")
A35: 10 | B35: 3.1 | C35: 3.1Eng | D35: Have you heard the latest news about An? | E35: Eng | F35: =IF(G35="","","https://docs.google.com/uc?export=download&id="&G35) -> https://docs.google.com/uc?export=download&id=1hOiA8nCxKjAQeybyV2L6qJuXJCIBVKVn | G35: =IFERROR(LEFT(RIGHT(H35,LEN(H35)-32),LEN(RIGHT(H35,LEN(H35)-32))-17),"") -> 1hOiA8nCxKjAQeybyV2L6qJuXJCIBVKVn | H35: https://drive.google.com/file/d/1hOiA8nCxKjAQeybyV2L6qJuXJCIBVKVn/view?usp=sharing
B36: 3.1 | C36: 3.1Phon | D36: hæv ju: hɜ:rd ðə ˈleɪtɪst nu:z əˈbaʊt æn | E36: Phon | F36: =IF(G36="","","https://docs.google.com/uc?export=download&id="&G36) | G36: =IFERROR(LEFT(RIGHT(H36,LEN(H36)-32),LEN(RIGHT(H36,LEN(H36)-32))-17),"")
B37: 3.2 | C37: 3.2Viet | D37: Bạn có nghe tin về sếp mới của chúng ta chưa? | E37: Viet | F37: =IF(G37="","","https://docs.google.com/uc?export=download&id="&G37) | G37: =IFERROR(LEFT(RIGHT(H37,LEN(H37)-32),LEN(RIGHT(H37,LEN(H37)-32))-17),"")
A38: 11 | B38: 3.2 | C38: 3.2Eng | D38: Have you heard the latest news about our new boss? | E38: Eng | F38: =IF(G38="","","https://docs.google.com/uc?export=download&id="&G38) -> https://docs.google.com/uc?export=download&id=1UTQpawb_S2EZ1PRqYzTEvvtZJFCxDCoY | G38: =IFERROR(LEFT(RIGHT(H38,LEN(H38)-32),LEN(RIGHT(H38,LEN(H38)-32))-17),"") -> 1UTQpawb_S2EZ1PRqYzTEvvtZJFCxDCoY | H38: https://drive.google.com/file/d/1UTQpawb_S2EZ1PRqYzTEvvtZJFCxDCoY/view?usp=sharing
B39: 3.2 | C39: 3.2Phon | D39: hæv ju: hɜ:rd ðə ˈleɪtɪst nu:z əˈbaʊt aʊr nu: ba:s | E39: Phon | F39: =IF(G39="","","https://docs.google.com/uc?export=download&id="&G39) | G39: =IFERROR(LEFT(RIGHT(H39,LEN(H39)-32),LEN(RIGHT(H39,LEN(H39)-32))-17),"")
B40: 3.3 | C40: 3.3Viet | D40: Bạn có nghe tin về phòng Marketing chưa? | E40: Viet | F40: =IF(G40="","","https://docs.google.com/uc?export=download&id="&G40) | G40: =IFERROR(LEFT(RIGHT(H40,LEN(H40)-32),LEN(RIGHT(H40,LEN(H40)-32))-17),"")
A41: 12 | B41: 3.3 | C41: 3.3Eng | D41: Have you heard the latest news about the marketing department? | E41: Eng | F41: =IF(G41="","","https://docs.google.com/uc?export=download&id="&G41) -> https://docs.google.com/uc?export=download&id=1O9_vhPnRrRQCHgB3_vgytBYuhxy1NY4- | G41: =IFERROR(LEFT(RIGHT(H41,LEN(H41)-32),LEN(RIGHT(H41,LEN(H41)-32))-17),"") -> 1O9_vhPnRrRQCHgB3_vgytBYuhxy1NY4- | H41: https://drive.google.com/file/d/1O9_vhPnRrRQCHgB3_vgytBYuhxy1NY4-/view?usp=sharing
...

Sheet Viet
B2: Sentence | C2: Link | D2: ID | E2: Copy Google drive to …
B3: 01-05 | C3: =IF(D3="","","https://docs.google.com/uc?export=download&id="&D3) -> https://docs.google.com/uc?export=download&id=1FOwPz1qUjFzGUrPSJxXDEufdkIWjNSm6 | D3: =IFERROR(LEFT(RIGHT(E3,LEN(E3)-32),LEN(RIGHT(E3,LEN(E3)-32))-17),"") -> 1FOwPz1qUjFzGUrPSJxXDEufdkIWjNSm6 | E3: https://drive.google.com/file/d/1FOwPz1qUjFzGUrPSJxXDEufdkIWjNSm6/view?usp=sharing
C4: =IF(D4="","","https://docs.google.com/uc?export=download&id="&D4) | D4: =IFERROR(LEFT(RIGHT(E4,LEN(E4)-32),LEN(RIGHT(E4,LEN(E4)-32))-17),"")
C5: =IF(D5="","","https://docs.google.com/uc?export=download&id="&D5) | D5: =IFERROR(LEFT(RIGHT(E5,LEN(E5)-32),LEN(RIGHT(E5,LEN(E5)-32))-17),"")
C6: =IF(D6="","","https://docs.google.com/uc?export=download&id="&D6) | D6: =IFERROR(LEFT(RIGHT(E6,LEN(E6)-32),LEN(RIGHT(E6,LEN(E6)-32))-17),"")
C7: =IF(D7="","","https://docs.google.com/uc?export=download&id="&D7) | D7: =IFERROR(LEFT(RIGHT(E7,LEN(E7)-32),LEN(RIGHT(E7,LEN(E7)-32))-17),"")

Sheet Sum
B2: Sentence | C2: Link | D2: ID | E2: Copy Google drive to …
B3: Woman | C3: =IF(D3="","","https://docs.google.com/uc?export=download&id="&D3) | D3: =IFERROR(LEFT(RIGHT(E3,LEN(E3)-32),LEN(RIGHT(E3,LEN(E3)-32))-17),"")
B4: Man | C4: =IF(D4="","","https://docs.google.com/uc?export=download&id="&D4) | D4: =IFERROR(LEFT(RIGHT(E4,LEN(E4)-32),LEN(RIGHT(E4,LEN(E4)-32))-17),"")

Sheet Ramdom
B1: From | C1: 1
B2: To | C2: 18
C3: No | D3: No | E3: Viet | F3: Eng
A4: =C1 -> 1 | B4: =IF(A4="","",RANDBETWEEN($C$1,$C$2)) -> 9 | C4: =IFERROR($C$1-1+_xlfn.RANK.EQ(B4,$B$4:$B$21)+COUNTIF(B$4:$B4,B4)-1,"") -> 9 | D4: =IFERROR(VLOOKUP(C4,Gossip!A:B,2,0),"") -> 2.4 | E4: =IFERROR(VLOOKUP(D4&"Viet",Gossip!C:D,2,0),"") -> Cả văn phòng đều đồn là ông A đang tán cô B. | F4: =IFERROR(VLOOKUP(D4&"Eng",Gossip!C:D,2,0),"") -> Actually, the word around the office is that Mr. A is flirting Ms. B.
A5: =IFERROR(IF(A4+1>$C$2,"",A4+1),"") -> 2 | B5: =IF(A5="","",RANDBETWEEN($C$1,$C$2)) -> 5 | C5: =IFERROR($C$1-1+_xlfn.RANK.EQ(B5,$B$4:$B$40)+COUNTIF(B$4:$B5,B5)-1,"") -> 13 | D5: =IFERROR(VLOOKUP(C5,Gossip!A:B,2,0),"") -> 4.1 | E5: =IFERROR(VLOOKUP(D5&"Viet",Gossip!C:D,2,0),"") -> Bạn nên kiểm tra lại nguồn thông tin của bạn đi. | F5: =IFERROR(VLOOKUP(D5&"Eng",Gossip!C:D,2,0),"") -> You should double-check your sources.
A6: =IFERROR(IF(A5+1>$C$2,"",A5+1),"") -> 3 | B6: =IF(A6="","",RANDBETWEEN($C$1,$C$2)) -> 4 | C6: =IFERROR($C$1-1+_xlfn.RANK.EQ(B6,$B$4:$B$40)+COUNTIF(B$4:$B6,B6)-1,"") -> 14 | D6: =IFERROR(VLOOKUP(C6,Gossip!A:B,2,0),"") -> 4.2 | E6: =IFERROR(VLOOKUP(D6&"Viet",Gossip!C:D,2,0),"") -> Tôi yêu cầu cô ta kiểm tra lại nguồn thông tin. | F6: =IFERROR(VLOOKUP(D6&"Eng",Gossip!C:D,2,0),"") -> I ask her to double-check her sources.
A7: =IFERROR(IF(A6+1>$C$2,"",A6+1),"") -> 4 | B7: =IF(A7="","",RANDBETWEEN($C$1,$C$2)) -> 15 | C7: =IFERROR($C$1-1+_xlfn.RANK.EQ(B7,$B$4:$B$40)+COUNTIF(B$4:$B7,B7)-1,"") -> 3 | D7: =IFERROR(VLOOKUP(C7,Gossip!A:B,2,0),"") -> 1.3 | E7: =IFERROR(VLOOKUP(D7&"Viet",Gossip!C:D,2,0),"") -> Tôi không muốn ngồi lê đôi mách, nhưng mà cô ta làm phiền tôi quá. | F7: =IFERROR(VLOOKUP(D7&"Eng",Gossip!C:D,2,0),"") -> I don’t mean to gossip, but she bothers me a lot.
A8: =IFERROR(IF(A7+1>$C$2,"",A7+1),"") -> 5 | B8: =IF(A8="","",RANDBETWEEN($C$1,$C$2)) -> 9 | C8: =IFERROR($C$1-1+_xlfn.RANK.EQ(B8,$B$4:$B$40)+COUNTIF(B$4:$B8,B8)-1,"") -> 10 | D8: =IFERROR(VLOOKUP(C8,Gossip!A:B,2,0),"") -> 3.1 | E8: =IFERROR(VLOOKUP(D8&"Viet",Gossip!C:D,2,0),"") -> Bạn có nghe tin về An chưa? | F8: =IFERROR(VLOOKUP(D8&"Eng",Gossip!C:D,2,0),"") -> Have you heard the latest news about An?
A9: =IFERROR(IF(A8+1>$C$2,"",A8+1),"") -> 6 | B9: =IF(A9="","",RANDBETWEEN($C$1,$C$2)) -> 14 | C9: =IFERROR($C$1-1+_xlfn.RANK.EQ(B9,$B$4:$B$40)+COUNTIF(B$4:$B9,B9)-1,"") -> 4 | D9: =IFERROR(VLOOKUP(C9,Gossip!A:B,2,0),"") -> 1.4 | E9: =IFERROR(VLOOKUP(D9&"Viet",Gossip!C:D,2,0),"") -> Tôi không muốn ngồi lê đôi mách, nhưng mà tôi vừa nghe nhiều điều khá thú vị. | F9: =IFERROR(VLOOKUP(D9&"Eng",Gossip!C:D,2,0),"") -> I don’t mean to gossip, but I just heard something interesting.
A10: =IFERROR(IF(A9+1>$C$2,"",A9+1),"") -> 7 | B10: =IF(A10="","",RANDBETWEEN($C$1,$C$2)) -> 4 | C10: =IFERROR($C$1-1+_xlfn.RANK.EQ(B10,$B$4:$B$40)+COUNTIF(B$4:$B10,B10)-1,"") -> 15 | D10: =IFERROR(VLOOKUP(C10,Gossip!A:B,2,0),"") -> 4.3 | E10: =IFERROR(VLOOKUP(D10&"Viet",Gossip!C:D,2,0),"") -> Bạn có kiểm tra lại nguồn thông tin chưa? | F10: =IFERROR(VLOOKUP(D10&"Eng",Gossip!C:D,2,0),"") -> Have you double-checked your sources?
A11: =IFERROR(IF(A10+1>$C$2,"",A10+1),"") -> 8 | B11: =IF(A11="","",RANDBETWEEN($C$1,$C$2)) -> 2 | C11: =IFERROR($C$1-1+_xlfn.RANK.EQ(B11,$B$4:$B$40)+COUNTIF(B$4:$B11,B11)-1,"") -> 18 | D11: =IFERROR(VLOOKUP(C11,Gossip!A:B,2,0),"") -> 5.3 | E11: =IFERROR(VLOOKUP(D11&"Viet",Gossip!C:D,2,0),"") -> Tôi nghe từ chính trưởng phòng. | F11: =IFERROR(VLOOKUP(D11&"Eng",Gossip!C:D,2,0),"") -> I got it straight from the departmental manager.
A12: =IFERROR(IF(A11+1>$C$2,"",A11+1),"") -> 9 | B12: =IF(A12="","",RANDBETWEEN($C$1,$C$2)) -> 8 | C12: =IFERROR($C$1-1+_xlfn.RANK.EQ(B12,$B$4:$B$40)+COUNTIF(B$4:$B12,B12)-1,"") -> 11 | D12: =IFERROR(VLOOKUP(C12,Gossip!A:B,2,0),"") -> 3.2 | E12: =IFERROR(VLOOKUP(D12&"Viet",Gossip!C:D,2,0),"") -> Bạn có nghe tin về sếp mới của chúng ta chưa? | F12: =IFERROR(VLOOKUP(D12&"Eng",Gossip!C:D,2,0),"") -> Have you heard the latest news about our new boss?
A13: =IFERROR(IF(A12+1>$C$2,"",A12+1),"") -> 10 | B13: =IF(A13="","",RANDBETWEEN($C$1,$C$2)) -> 13 | C13: =IFERROR($C$1-1+_xlfn.RANK.EQ(B13,$B$4:$B$40)+COUNTIF(B$4:$B13,B13)-1,"") -> 5 | D13: =IFERROR(VLOOKUP(C13,Gossip!A:B,2,0),"") -> 1.5 | E13: =IFERROR(VLOOKUP(D13&"Viet",Gossip!C:D,2,0),"") -> Tôi không muốn ngồi lê đôi mách, nhưng mà A sắp nghỉ việc rồi. | F13: =IFERROR(VLOOKUP(D13&"Eng",Gossip!C:D,2,0),"") -> I don’t mean to gossip, but I heard that A is quitting.
A14: =IFERROR(IF(A13+1>$C$2,"",A13+1),"") -> 11 | B14: =IF(A14="","",RANDBETWEEN($C$1,$C$2)) -> 13 | C14: =IFERROR($C$1-1+_xlfn.RANK.EQ(B14,$B$4:$B$40)+COUNTIF(B$4:$B14,B14)-1,"") -> 6 | D14: =IFERROR(VLOOKUP(C14,Gossip!A:B,2,0),"") -> 2.1 | E14: =IFERROR(VLOOKUP(D14&"Viet",Gossip!C:D,2,0),"") -> Cả văn phòng đều đồn là Tom sắp bị sa thải. | F14: =IFERROR(VLOOKUP(D14&"Eng",Gossip!C:D,2,0),"") -> Actually, the word around the office is that Tom is going to be fired.
A15: =IFERROR(IF(A14+1>$C$2,"",A14+1),"") -> 12 | B15: =IF(A15="","",RANDBETWEEN($C$1,$C$2)) -> 18 | C15: =IFERROR($C$1-1+_xlfn.RANK.EQ(B15,$B$4:$B$40)+COUNTIF(B$4:$B15,B15)-1,"") -> 1 | D15: =IFERROR(VLOOKUP(C15,Gossip!A:B,2,0),"") -> 1.1 | E15: =IFERROR(VLOOKUP(D15&"Viet",Gossip!C:D,2,0),"") -> Tôi không muốn ngồi lê đôi mách, nhưng mà cô ta nói nhiều quá. | F15: =IFERROR(VLOOKUP(D15&"Eng",Gossip!C:D,2,0),"") -> I don’t mean to gossip, but she talks too much.
A16: =IFERROR(IF(A15+1>$C$2,"",A15+1),"") -> 13 | B16: =IF(A16="","",RANDBETWEEN($C$1,$C$2)) -> 11 | C16: =IFERROR($C$1-1+_xlfn.RANK.EQ(B16,$B$4:$B$40)+COUNTIF(B$4:$B16,B16)-1,"") -> 8 | D16: =IFERROR(VLOOKUP(C16,Gossip!A:B,2,0),"") -> 2.3 | E16: =IFERROR(VLOOKUP(D16&"Viet",Gossip!C:D,2,0),"") -> Cả văn phòng đều đồn tháng 4 này là tháng sa thải. | F16: =IFERROR(VLOOKUP(D16&"Eng",Gossip!C:D,2,0),"") -> Actually, the word around the office is that April is getting fired.
... A72: =IFERROR(IF(A71+1>$C$2,"",A71+1),"") | B72: =IF(A72="","",RANDBETWEEN($C$1,$C$2)) | C72: =IFERROR($C$1-1+_xlfn.RANK.EQ(B72,$B$4:$B$40)+COUNTIF(B$4:$B72,B72)-1,"") | D72: =IFERROR(VLOOKUP(C72,Gossip!A:B,2,0),"") | E72: =IFERROR(VLOOKUP(D72&"Viet",Gossip!C:D,2,0),"") | F72: =IFERROR(VLOOKUP(D72&"Eng",Gossip!C:D,2,0),"")
A73: =IFERROR(IF(A72+1>$C$2,"",A72+1),"") | B73: =IF(A73="","",RANDBETWEEN($C$1,$C$2)) | C73: =IFERROR($C$1-1+_xlfn.RANK.EQ(B73,$B$4:$B$40)+COUNTIF(B$4:$B73,B73)-1,"") | D73: =IFERROR(VLOOKUP(C73,Gossip!A:B,2,0),"")
A74: =IFERROR(IF(A73+1>$C$2,"",A73+1),"") | B74: =IF(A74="","",RANDBETWEEN($C$1,$C$2)) | C74: =IFERROR($C$1-1+_xlfn.RANK.EQ(B74,$B$4:$B$40)+COUNTIF(B$4:$B74,B74)-1,"") | D74: =IFERROR(VLOOKUP(C74,Gossip!A:B,2,0),"")
A75: =IFERROR(IF(A74+1>$C$2,"",A74+1),"") | B75: =IF(A75="","",RANDBETWEEN($C$1,$C$2)) | C75: =IFERROR($C$1-1+_xlfn.RANK.EQ(B75,$B$4:$B$40)+COUNTIF(B$4:$B75,B75)-1,"") | D75: =IFERROR(VLOOKUP(C75,Gossip!A:B,2,0),"")
A76: =IFERROR(IF(A75+1>$C$2,"",A75+1),"") | B76: =IF(A76="","",RANDBETWEEN($C$1,$C$2)) | C76: =IFERROR($C$1-1+_xlfn.RANK.EQ(B76,$B$4:$B$40)+COUNTIF(B$4:$B76,B76)-1,"") | D76: =IFERROR(VLOOKUP(C76,Gossip!A:B,2,0),"")
A77: =IFERROR(IF(A76+1>$C$2,"",A76+1),"") | B77: =IF(A77="","",RANDBETWEEN($C$1,$C$2)) | C77: =IFERROR($C$1-1+_xlfn.RANK.EQ(B77,$B$4:$B$40)+COUNTIF(B$4:$B77,B77)-1,"") | D77: =IFERROR(VLOOKUP(C77,Gossip!A:B,2,0),"")
A78: =IFERROR(IF(A77+1>$C$2,"",A77+1),"") | B78: =IF(A78="","",RANDBETWEEN($C$1,$C$2)) | C78: =IFERROR($C$1-1+_xlfn.RANK.EQ(B78,$B$4:$B$40)+COUNTIF(B$4:$B78,B78)-1,"") | D78: =IFERROR(VLOOKUP(C78,Gossip!A:B,2,0),"")
A79: =IFERROR(IF(A78+1>$C$2,"",A78+1),"") | B79: =IF(A79="","",RANDBETWEEN($C$1,$C$2)) | C79: =IFERROR($C$1-1+_xlfn.RANK.EQ(B79,$B$4:$B$40)+COUNTIF(B$4:$B79,B79)-1,"") | D79: =IFERROR(VLOOKUP(C79,Gossip!A:B,2,0),"")
A80: =IFERROR(IF(A79+1>$C$2,"",A79+1),"") | B80: =IF(A80="","",RANDBETWEEN($C$1,$C$2)) | C80: =IFERROR($C$1-1+_xlfn.RANK.EQ(B80,$B$4:$B$40)+COUNTIF(B$4:$B80,B80)-1,"") | D80: =IFERROR(VLOOKUP(C80,Gossip!A:B,2,0),"")
A81: =IFERROR(IF(A80+1>$C$2,"",A80+1),"") | B81: =IF(A81="","",RANDBETWEEN($C$1,$C$2)) | C81: =IFERROR($C$1-1+_xlfn.RANK.EQ(B81,$B$4:$B$40)+COUNTIF(B$4:$B81,B81)-1,"") | D81: =IFERROR(VLOOKUP(C81,Gossip!A:B,2,0),"")
A82: =IFERROR(IF(A81+1>$C$2,"",A81+1),"") | B82: =IF(A82="","",RANDBETWEEN($C$1,$C$2)) | C82: =IFERROR($C$1-1+_xlfn.RANK.EQ(B82,$B$4:$B$40)+COUNTIF(B$4:$B82,B82)-1,"") | D82: =IFERROR(VLOOKUP(C82,Gossip!A:B,2,0),"")
A83: =IFERROR(IF(A82+1>$C$2,"",A82+1),"") | B83: =IF(A83="","",RANDBETWEEN($C$1,$C$2)) | C83: =IFERROR($C$1-1+_xlfn.RANK.EQ(B83,$B$4:$B$40)+COUNTIF(B$4:$B83,B83)-1,"") | D83: =IFERROR(VLOOKUP(C83,Gossip!A:B,2,0),"")
A84: =IFERROR(IF(A83+1>$C$2,"",A83+1),"") | B84: =IF(A84="","",RANDBETWEEN($C$1,$C$2)) | C84: =IFERROR($C$1-1+_xlfn.RANK.EQ(B84,$B$4:$B$40)+COUNTIF(B$4:$B84,B84)-1,"") | D84: =IFERROR(VLOOKUP(C84,Gossip!A:B,2,0),"")
... A142: =IFERROR(IF(A141+1>$C$2,"",A141+1),"") | B142: =IF(A142="","",RANDBETWEEN($C$1,$C$2)) | C142: =IFERROR($C$1-1+_xlfn.RANK.EQ(B142,$B$4:$B$40)+COUNTIF(B$4:$B142,B142)-1,"") | D142: =IFERROR(VLOOKUP(C142,Gossip!A:B,2,0),"")
A143: =IFERROR(IF(A142+1>$C$2,"",A142+1),"") | B143: =IF(A143="","",RANDBETWEEN($C$1,$C$2))
A144: =IFERROR(IF(A143+1>$C$2,"",A143+1),"") | B144: =IF(A144="","",RANDBETWEEN($C$1,$C$2))
A145: =IFERROR(IF(A144+1>$C$2,"",A144+1),"") | B145: =IF(A145="","",RANDBETWEEN($C$1,$C$2))
A146: =IFERROR(IF(A145+1>$C$2,"",A145+1),"") | B146: =IF(A146="","",RANDBETWEEN($C$1,$C$2))
A147: =IFERROR(IF(A146+1>$C$2,"",A146+1),"") | B147: =IF(A147="","",RANDBETWEEN($C$1,$C$2))
A148: =IFERROR(IF(A147+1>$C$2,"",A147+1),"") | B148: =IF(A148="","",RANDBETWEEN($C$1,$C$2))
A149: =IFERROR(IF(A148+1>$C$2,"",A148+1),"") | B149: =IF(A149="","",RANDBETWEEN($C$1,$C$2))
A150: =IFERROR(IF(A149+1>$C$2,"",A149+1),"") | B150: =IF(A150="","",RANDBETWEEN($C$1,$C$2))
A151: =IFERROR(IF(A150+1>$C$2,"",A150+1),"") | B151: =IF(A151="","",RANDBETWEEN($C$1,$C$2))
A152: =IFERROR(IF(A151+1>$C$2,"",A151+1),"") | B152: =IF(A152="","",RANDBETWEEN($C$1,$C$2))
...

Sheet Sheet1

Sheet Sheet2
