Workbook

Sheet Question structure
B2: TOPIC:QUESTION AND STRUCTURE
A3: No | B3: NoSort | C3: No | D3: ID | E3: Sentence | F3: Type | G3: Link | H3: ID | I3: Copy Google drive to …
B4: 1001 | C4: 1 | D4: =C4&F4 -> 1Struc0 | E4: HOW + TOBE..? /(AI, CÁI GÌ) NHƯ THẾ NÀO?/ | F4: Struc0 | G4: =IF(H4="","","https://docs.google.com/uc?export=download&id="&H4) | H4: =IFERROR(LEFT(RIGHT(I4,LEN(I4)-32),LEN(RIGHT(I4,LEN(I4)-32))-17),"")
B5: 1002 | C5: 1.1 | D5: =C5&F5 -> 1.1Struc | E5: HOW IS/ARE..? /NHƯ THẾ NÀO?/ | F5: Struc | G5: =IF(H5="","","https://docs.google.com/uc?export=download&id="&H5) -> https://docs.google.com/uc?export=download&id=1z80hhUvTWE6zPjPyjLUzcMN8yPeUijos | H5: =IFERROR(LEFT(RIGHT(I5,LEN(I5)-32),LEN(RIGHT(I5,LEN(I5)-32))-17),"") -> 1z80hhUvTWE6zPjPyjLUzcMN8yPeUijos | I5: https://drive.google.com/file/d/1z80hhUvTWE6zPjPyjLUzcMN8yPeUijos/view?usp=sharing
B6: 1003 | C6: 1.1.1 | D6: =C6&F6 -> 1.1.1Viet | E6: Thời tiết thế nào? | F6: Viet | G6: =IF(H6="","","https://docs.google.com/uc?export=download&id="&H6) | H6: =IFERROR(LEFT(RIGHT(I6,LEN(I6)-32),LEN(RIGHT(I6,LEN(I6)-32))-17),"")
A7: 1 | B7: 1004 | C7: 1.1.1 | D7: =C7&F7 -> 1.1.1Eng | E7: How is the weather? | F7: Eng | G7: =IF(H7="","","https://docs.google.com/uc?export=download&id="&H7) | H7: =IFERROR(LEFT(RIGHT(I7,LEN(I7)-32),LEN(RIGHT(I7,LEN(I7)-32))-17),"")
B8: 1005 | C8: 1.1.1 | D8: =C8&F8 -> 1.1.1Phon | E8: haʊ ɪz ðə ˈwɛðər? | F8: Phon | G8: =IF(H8="","","https://docs.google.com/uc?export=download&id="&H8) | H8: =IFERROR(LEFT(RIGHT(I8,LEN(I8)-32),LEN(RIGHT(I8,LEN(I8)-32))-17),"")
B9: 1006 | C9: 1.1.2 | D9: =C9&F9 -> 1.1.2Viet | E9: Anh ấy khoẻ chứ? | F9: Viet | G9: =IF(H9="","","https://docs.google.com/uc?export=download&id="&H9) | H9: =IFERROR(LEFT(RIGHT(I9,LEN(I9)-32),LEN(RIGHT(I9,LEN(I9)-32))-17),"")
A10: 2 | B10: 1007 | C10: 1.1.2 | D10: =C10&F10 -> 1.1.2Eng | E10: How is he? | F10: Eng | G10: =IF(H10="","","https://docs.google.com/uc?export=download&id="&H10) | H10: =IFERROR(LEFT(RIGHT(I10,LEN(I10)-32),LEN(RIGHT(I10,LEN(I10)-32))-17),"")
B11: 1008 | C11: 1.1.2 | D11: =C11&F11 -> 1.1.2Phon | E11: haʊ ɪz hi? | F11: Phon | G11: =IF(H11="","","https://docs.google.com/uc?export=download&id="&H11) | H11: =IFERROR(LEFT(RIGHT(I11,LEN(I11)-32),LEN(RIGHT(I11,LEN(I11)-32))-17),"")
B12: 1009 | C12: 1.1.3 | D12: =C12&F12 -> 1.1.3Viet | E12: Dự án đang được tiến hành như thế nào rồi? | F12: Viet | G12: =IF(H12="","","https://docs.google.com/uc?export=download&id="&H12) | H12: =IFERROR(LEFT(RIGHT(I12,LEN(I12)-32),LEN(RIGHT(I12,LEN(I12)-32))-17),"")
A13: 3 | B13: 1010 | C13: 1.1.3 | D13: =C13&F13 -> 1.1.3Eng | E13: How is the project going? | F13: Eng | G13: =IF(H13="","","https://docs.google.com/uc?export=download&id="&H13) | H13: =IFERROR(LEFT(RIGHT(I13,LEN(I13)-32),LEN(RIGHT(I13,LEN(I13)-32))-17),"")
B14: 1011 | C14: 1.1.3 | D14: =C14&F14 -> 1.1.3Phon | E14: haʊ ɪz ðə ˈprɑʤɛkt ˈɡoʊɪŋ? | F14: Phon | G14: =IF(H14="","","https://docs.google.com/uc?export=download&id="&H14) | H14: =IFERROR(LEFT(RIGHT(I14,LEN(I14)-32),LEN(RIGHT(I14,LEN(I14)-32))-17),"")
B15: 1012 | C15: 1.1.4 | D15: =C15&F15 -> 1.1.4Viet | E15: Cậu dạo này thế nào? | F15: Viet | G15: =IF(H15="","","https://docs.google.com/uc?export=download&id="&H15) | H15: =IFERROR(LEFT(RIGHT(I15,LEN(I15)-32),LEN(RIGHT(I15,LEN(I15)-32))-17),"")
A16: 4 | B16: 1013 | C16: 1.1.4 | D16: =C16&F16 -> 1.1.4Eng | E16: How are you doing? | F16: Eng | G16: =IF(H16="","","https://docs.google.com/uc?export=download&id="&H16) | H16: =IFERROR(LEFT(RIGHT(I16,LEN(I16)-32),LEN(RIGHT(I16,LEN(I16)-32))-17),"")
B17: 1014 | C17: 1.1.4 | D17: =C17&F17 -> 1.1.4Phon | E17: haʊ ɑr ju ˈduɪŋ? | F17: Phon | G17: =IF(H17="","","https://docs.google.com/uc?export=download&id="&H17) | H17: =IFERROR(LEFT(RIGHT(I17,LEN(I17)-32),LEN(RIGHT(I17,LEN(I17)-32))-17),"")
B18: 1015 | C18: 1.2 | D18: =C18&F18 -> 1.2Struc | E18: HOW + ADJ + IS/ARE...? /ĐẾN MỨC NÀO?/ | F18: Struc | G18: =IF(H18="","","https://docs.google.com/uc?export=download&id="&H18) -> https://docs.google.com/uc?export=download&id=10Uw-DWjIQ15fWR9g7K5jJ6K1MVkRNUtK | H18: =IFERROR(LEFT(RIGHT(I18,LEN(I18)-32),LEN(RIGHT(I18,LEN(I18)-32))-17),"") -> 10Uw-DWjIQ15fWR9g7K5jJ6K1MVkRNUtK | I18: https://drive.google.com/file/d/10Uw-DWjIQ15fWR9g7K5jJ6K1MVkRNUtK/view?usp=sharing
B19: 1016 | C19: 1.2.1 | D19: =C19&F19 -> 1.2.1Viet | E19: Nó tệ đến mức nào? | F19: Viet | G19: =IF(H19="","","https://docs.google.com/uc?export=download&id="&H19) | H19: =IFERROR(LEFT(RIGHT(I19,LEN(I19)-32),LEN(RIGHT(I19,LEN(I19)-32))-17),"")
A20: 5 | B20: 1017 | C20: 1.2.1 | D20: =C20&F20 -> 1.2.1Eng | E20: How bad is it? | F20: Eng | G20: =IF(H20="","","https://docs.google.com/uc?export=download&id="&H20) | H20: =IFERROR(LEFT(RIGHT(I20,LEN(I20)-32),LEN(RIGHT(I20,LEN(I20)-32))-17),"")
B21: 1018 | C21: 1.2.1 | D21: =C21&F21 -> 1.2.1Phon | E21: haʊ bæd ɪz ɪt? | F21: Phon | G21: =IF(H21="","","https://docs.google.com/uc?export=download&id="&H21) | H21: =IFERROR(LEFT(RIGHT(I21,LEN(I21)-32),LEN(RIGHT(I21,LEN(I21)-32))-17),"")
B22: 1019 | C22: 1.2.2 | D22: =C22&F22 -> 1.2.2Viet | E22: Anh ấy ốm như thế nào? | F22: Viet | G22: =IF(H22="","","https://docs.google.com/uc?export=download&id="&H22) | H22: =IFERROR(LEFT(RIGHT(I22,LEN(I22)-32),LEN(RIGHT(I22,LEN(I22)-32))-17),"")
A23: 6 | B23: 1020 | C23: 1.2.2 | D23: =C23&F23 -> 1.2.2Eng | E23: How sick is he? | F23: Eng | G23: =IF(H23="","","https://docs.google.com/uc?export=download&id="&H23) | H23: =IFERROR(LEFT(RIGHT(I23,LEN(I23)-32),LEN(RIGHT(I23,LEN(I23)-32))-17),"")
B24: 1021 | C24: 1.2.2 | D24: =C24&F24 -> 1.2.2Phon | E24: haʊ sɪk ɪz hi? | F24: Phon | G24: =IF(H24="","","https://docs.google.com/uc?export=download&id="&H24) | H24: =IFERROR(LEFT(RIGHT(I24,LEN(I24)-32),LEN(RIGHT(I24,LEN(I24)-32))-17),"")
B25: 1022 | C25: 1.2.3 | D25: =C25&F25 -> 1.2.3Viet | E25: Cô ấy đẹp đến mức nào? | F25: Viet | G25: =IF(H25="","","https://docs.google.com/uc?export=download&id="&H25) | H25: =IFERROR(LEFT(RIGHT(I25,LEN(I25)-32),LEN(RIGHT(I25,LEN(I25)-32))-17),"")
A26: 7 | B26: 1023 | C26: 1.2.3 | D26: =C26&F26 -> 1.2.3Eng | E26: How beautiful is she? | F26: Eng | G26: =IF(H26="","","https://docs.google.com/uc?export=download&id="&H26) | H26: =IFERROR(LEFT(RIGHT(I26,LEN(I26)-32),LEN(RIGHT(I26,LEN(I26)-32))-17),"")
B27: 1024 | C27: 1.2.3 | D27: =C27&F27 -> 1.2.3Phon | E27: haʊ ˈbjutəfəl ɪz ʃi? | F27: Phon | G27: =IF(H27="","","https://docs.google.com/uc?export=download&id="&H27) | H27: =IFERROR(LEFT(RIGHT(I27,LEN(I27)-32),LEN(RIGHT(I27,LEN(I27)-32))-17),"")
B28: 1025 | C28: 1.2.4 | D28: =C28&F28 -> 1.2.4Viet | E28: Nó khó đến mức nào? | F28: Viet | G28: =IF(H28="","","https://docs.google.com/uc?export=download&id="&H28) | H28: =IFERROR(LEFT(RIGHT(I28,LEN(I28)-32),LEN(RIGHT(I28,LEN(I28)-32))-17),"")
A29: 8 | B29: 1026 | C29: 1.2.4 | D29: =C29&F29 -> 1.2.4Eng | E29: How difficult is it? | F29: Eng | G29: =IF(H29="","","https://docs.google.com/uc?export=download&id="&H29) | H29: =IFERROR(LEFT(RIGHT(I29,LEN(I29)-32),LEN(RIGHT(I29,LEN(I29)-32))-17),"")
B30: 1027 | C30: 1.2.4 | D30: =C30&F30 -> 1.2.4Phon | E30: haʊ ˈdɪfəkəlt ɪz ɪt? | F30: Phon | G30: =IF(H30="","","https://docs.google.com/uc?export=download&id="&H30) | H30: =IFERROR(LEFT(RIGHT(I30,LEN(I30)-32),LEN(RIGHT(I30,LEN(I30)-32))-17),"")
B31: 1028 | C31: 1.3 | D31: =C31&F31 -> 1.3Struc | E31: HOW WAS/WERE..? /ĐÃ NHƯ THẾ NÀO?/ | F31: Struc | G31: =IF(H31="","","https://docs.google.com/uc?export=download&id="&H31) -> https://docs.google.com/uc?export=download&id=12V2o1UvvCe1_Rj3819zXK0T9itbU_07U | H31: =IFERROR(LEFT(RIGHT(I31,LEN(I31)-32),LEN(RIGHT(I31,LEN(I31)-32))-17),"") -> 12V2o1UvvCe1_Rj3819zXK0T9itbU_07U | I31: https://drive.google.com/file/d/12V2o1UvvCe1_Rj3819zXK0T9itbU_07U/view?usp=sharing
B32: 1029 | C32: 1.3.1 | D32: =C32&F32 -> 1.3.1Viet | E32: Ngày hôm nay của cậu thế nào? | F32: Viet | G32: =IF(H32="","","https://docs.google.com/uc?export=download&id="&H32) | H32: =IFERROR(LEFT(RIGHT(I32,LEN(I32)-32),LEN(RIGHT(I32,LEN(I32)-32))-17),"")
A33: 9 | B33: 1030 | C33: 1.3.1 | D33: =C33&F33 -> 1.3.1Eng | E33: How was your day? | F33: Eng | G33: =IF(H33="","","https://docs.google.com/uc?export=download&id="&H33) | H33: =IFERROR(LEFT(RIGHT(I33,LEN(I33)-32),LEN(RIGHT(I33,LEN(I33)-32))-17),"")
B34: 1031 | C34: 1.3.1 | D34: =C34&F34 -> 1.3.1Phon | E34: haʊ wʌz jʊər deɪ? | F34: Phon | G34: =IF(H34="","","https://docs.google.com/uc?export=download&id="&H34) | H34: =IFERROR(LEFT(RIGHT(I34,LEN(I34)-32),LEN(RIGHT(I34,LEN(I34)-32))-17),"")
B35: 1032 | C35: 1.3.2 | D35: =C35&F35 -> 1.3.2Viet | E35: Đêm qua thế nào? | F35: Viet | G35: =IF(H35="","","https://docs.google.com/uc?export=download&id="&H35) | H35: =IFERROR(LEFT(RIGHT(I35,LEN(I35)-32),LEN(RIGHT(I35,LEN(I35)-32))-17),"")
A36: 10 | B36: 1033 | C36: 1.3.2 | D36: =C36&F36 -> 1.3.2Eng | E36: How was your night? | F36: Eng | G36: =IF(H36="","","https://docs.google.com/uc?export=download&id="&H36) | H36: =IFERROR(LEFT(RIGHT(I36,LEN(I36)-32),LEN(RIGHT(I36,LEN(I36)-32))-17),"")
B37: 1034 | C37: 1.3.2 | D37: =C37&F37 -> 1.3.2Phon | E37: haʊ wʌz jʊər naɪt? | F37: Phon | G37: =IF(H37="","","https://docs.google.com/uc?export=download&id="&H37) | H37: =IFERROR(LEFT(RIGHT(I37,LEN(I37)-32),LEN(RIGHT(I37,LEN(I37)-32))-17),"")
B38: 1035 | C38: 1.3.3 | D38: =C38&F38 -> 1.3.3Viet | E38: Buổi hẹn của cậu thế nào? | F38: Viet | G38: =IF(H38="","","https://docs.google.com/uc?export=download&id="&H38) | H38: =IFERROR(LEFT(RIGHT(I38,LEN(I38)-32),LEN(RIGHT(I38,LEN(I38)-32))-17),"")
A39: 11 | B39: 1036 | C39: 1.3.3 | D39: =C39&F39 -> 1.3.3Eng | E39: How was your date? | F39: Eng | G39: =IF(H39="","","https://docs.google.com/uc?export=download&id="&H39) | H39: =IFERROR(LEFT(RIGHT(I39,LEN(I39)-32),LEN(RIGHT(I39,LEN(I39)-32))-17),"")
B40: 1037 | C40: 1.3.3 | D40: =C40&F40 -> 1.3.3Phon | E40: haʊ wʌz jʊər deɪt? | F40: Phon | G40: =IF(H40="","","https://docs.google.com/uc?export=download&id="&H40) | H40: =IFERROR(LEFT(RIGHT(I40,LEN(I40)-32),LEN(RIGHT(I40,LEN(I40)-32))-17),"")
B41: 1038 | C41: 1.3.4 | D41: =C41&F41 -> 1.3.4Viet | E41: Chuyến đi của cậu thế nào? | F41: Viet | G41: =IF(H41="","","https://docs.google.com/uc?export=download&id="&H41) | H41: =IFERROR(LEFT(RIGHT(I41,LEN(I41)-32),LEN(RIGHT(I41,LEN(I41)-32))-17),"")
...

Sheet Viet
B2: Sentence | C2: Link | D2: ID | E2: Copy Google drive to …
B3: 01-03 | C3: =IF(D3="","","https://docs.google.com/uc?export=download&id="&D3) -> https://docs.google.com/uc?export=download&id=1WlhJy02xnijddD6N5koDbDTVZ9DK7Pim | D3: =IFERROR(LEFT(RIGHT(E3,LEN(E3)-32),LEN(RIGHT(E3,LEN(E3)-32))-17),"") -> 1WlhJy02xnijddD6N5koDbDTVZ9DK7Pim | E3: https://drive.google.com/file/d/1WlhJy02xnijddD6N5koDbDTVZ9DK7Pim/view?usp=sharing
B4: 04-06 | C4: =IF(D4="","","https://docs.google.com/uc?export=download&id="&D4) -> https://docs.google.com/uc?export=download&id=1izmrYLQ5y8-Yg_iuxc2cfxPP3WCabhgI | D4: =IFERROR(LEFT(RIGHT(E4,LEN(E4)-32),LEN(RIGHT(E4,LEN(E4)-32))-17),"") -> 1izmrYLQ5y8-Yg_iuxc2cfxPP3WCabhgI | E4: https://drive.google.com/file/d/1izmrYLQ5y8-Yg_iuxc2cfxPP3WCabhgI/view?usp=sharing
B5: 07-09 | C5: =IF(D5="","","https://docs.google.com/uc?export=download&id="&D5) -> https://docs.google.com/uc?export=download&id=1bad3ljMqU25cudXPEEEpDi0NGJH4dHoY | D5: =IFERROR(LEFT(RIGHT(E5,LEN(E5)-32),LEN(RIGHT(E5,LEN(E5)-32))-17),"") -> 1bad3ljMqU25cudXPEEEpDi0NGJH4dHoY | E5: https://drive.google.com/file/d/1bad3ljMqU25cudXPEEEpDi0NGJH4dHoY/view?usp=sharing
B6: 10-12 | C6: =IF(D6="","","https://docs.google.com/uc?export=download&id="&D6) -> https://docs.google.com/uc?export=download&id=1qIcvRICDzWjgJhXewvFVlDrS4UYH3CMm | D6: =IFERROR(LEFT(RIGHT(E6,LEN(E6)-32),LEN(RIGHT(E6,LEN(E6)-32))-17),"") -> 1qIcvRICDzWjgJhXewvFVlDrS4UYH3CMm | E6: https://drive.google.com/file/d/1qIcvRICDzWjgJhXewvFVlDrS4UYH3CMm/view?usp=sharing
B7: 13-15 | C7: =IF(D7="","","https://docs.google.com/uc?export=download&id="&D7) -> https://docs.google.com/uc?export=download&id=1N4roV4yHCjVyCJiZpJEFJj4jBdJ5HZ-V | D7: =IFERROR(LEFT(RIGHT(E7,LEN(E7)-32),LEN(RIGHT(E7,LEN(E7)-32))-17),"") -> 1N4roV4yHCjVyCJiZpJEFJj4jBdJ5HZ-V | E7: https://drive.google.com/file/d/1N4roV4yHCjVyCJiZpJEFJj4jBdJ5HZ-V/view?usp=sharing
B8: 16-19 | C8: =IF(D8="","","https://docs.google.com/uc?export=download&id="&D8) -> https://docs.google.com/uc?export=download&id=1N80QBg7OQeIG0WLaO-ifS4SgW4XBoBQS | D8: =IFERROR(LEFT(RIGHT(E8,LEN(E8)-32),LEN(RIGHT(E8,LEN(E8)-32))-17),"") -> 1N80QBg7OQeIG0WLaO-ifS4SgW4XBoBQS | E8: https://drive.google.com/file/d/1N80QBg7OQeIG0WLaO-ifS4SgW4XBoBQS/view?usp=sharing
B9: 01-19 | C9: =IF(D9="","","https://docs.google.com/uc?export=download&id="&D9) -> https://docs.google.com/uc?export=download&id=1KWi178kmcCSx14Bq34wTXven07Y7-pws | D9: =IFERROR(LEFT(RIGHT(E9,LEN(E9)-32),LEN(RIGHT(E9,LEN(E9)-32))-17),"") -> 1KWi178kmcCSx14Bq34wTXven07Y7-pws | E9: https://drive.google.com/file/d/1KWi178kmcCSx14Bq34wTXven07Y7-pws/view?usp=sharing

Sheet Sum
B2: Sentence | C2: Link | D2: ID | E2: Copy Google drive to …
B3: Woman | C3: =IF(D3="","","https://docs.google.com/uc?export=download&id="&D3) | D3: =IFERROR(LEFT(RIGHT(E3,LEN(E3)-32),LEN(RIGHT(E3,LEN(E3)-32))-17),"")
B4: Man | C4: =IF(D4="","","https://docs.google.com/uc?export=download&id="&D4) | D4: =IFERROR(LEFT(RIGHT(E4,LEN(E4)-32),LEN(RIGHT(E4,LEN(E4)-32))-17),"")

Sheet Ramdom
B1: From | C1: 1
B2: To | C2: 186
C3: No | D3: No | E3: Viet | F3: Eng
A4: =C1 -> 1 | B4: =IF(A4="","",RANDBETWEEN($C$1,$C$2)) -> 88 | C4: =IFERROR($C$1-1+_xlfn.RANK.EQ(B4,$B$4:$B$189)+COUNTIF(B$4:$B4,B4)-1,"") -> 104 | D4: =IFERROR(VLOOKUP(C4,'Question structure'!A:E,3,0),"") -> 12.2.3 | E4: =IFERROR(VLOOKUP(D4&"Viet",'Question structure'!D:H,2,0),"") -> Buổi họp sẽ kéo dài trong bao lâu? | F4: =IFERROR(VLOOKUP(D4&"Eng",'Question structure'!D:H,2,0),"") -> How long will the meeting last?
A5: =IFERROR(IF(A4+1>$C$2,"",A4+1),"") -> 2 | B5: =IF(A5="","",RANDBETWEEN($C$1,$C$2)) -> 132 | C5: =IFERROR($C$1-1+_xlfn.RANK.EQ(B5,$B$4:$B$78)+COUNTIF(B$4:$B5,B5)-1,"") -> 28 | D5: =IFERROR(VLOOKUP(C5,'Question structure'!A:E,3,0),"") -> 3.2.3 | E5: =IFERROR(VLOOKUP(D5&"Viet",'Question structure'!D:H,2,0),"") -> Cậu có muốn ở lại ăn tối không? | F5: =IFERROR(VLOOKUP(D5&"Eng",'Question structure'!D:H,2,0),"") -> Do you want to stay for dinner?
A6: =IFERROR(IF(A5+1>$C$2,"",A5+1),"") -> 3 | B6: =IF(A6="","",RANDBETWEEN($C$1,$C$2)) -> 66 | C6: =IFERROR($C$1-1+_xlfn.RANK.EQ(B6,$B$4:$B$78)+COUNTIF(B$4:$B6,B6)-1,"") -> 57 | D6: =IFERROR(VLOOKUP(C6,'Question structure'!A:E,3,0),"") -> 7.2.3 | E6: =IFERROR(VLOOKUP(D6&"Viet",'Question structure'!D:H,2,0),"") -> Cậu định tổ chức tiệc à? | F6: =IFERROR(VLOOKUP(D6&"Eng",'Question structure'!D:H,2,0),"") -> Are you planning to throw a party?
A7: =IFERROR(IF(A6+1>$C$2,"",A6+1),"") -> 4 | B7: =IF(A7="","",RANDBETWEEN($C$1,$C$2)) -> 112 | C7: =IFERROR($C$1-1+_xlfn.RANK.EQ(B7,$B$4:$B$78)+COUNTIF(B$4:$B7,B7)-1,"") -> 38 | D7: =IFERROR(VLOOKUP(C7,'Question structure'!A:E,3,0),"") -> 4.2.2 | E7: =IFERROR(VLOOKUP(D7&"Viet",'Question structure'!D:H,2,0),"") -> Cậu muốn tôi nói gì với anh ấy? | F7: =IFERROR(VLOOKUP(D7&"Eng",'Question structure'!D:H,2,0),"") -> What do you want me to say to him?
A8: =IFERROR(IF(A7+1>$C$2,"",A7+1),"") -> 5 | B8: =IF(A8="","",RANDBETWEEN($C$1,$C$2)) -> 4 | C8: =IFERROR($C$1-1+_xlfn.RANK.EQ(B8,$B$4:$B$78)+COUNTIF(B$4:$B8,B8)-1,"") -> 73 | D8: =IFERROR(VLOOKUP(C8,'Question structure'!A:E,3,0),"") -> 9.1.4 | E8: =IFERROR(VLOOKUP(D8&"Viet",'Question structure'!D:H,2,0),"") -> Sao cậu lại ủ rũ thế? | F8: =IFERROR(VLOOKUP(D8&"Eng",'Question structure'!D:H,2,0),"") -> How come you are so depressed?
A9: =IFERROR(IF(A8+1>$C$2,"",A8+1),"") -> 6 | B9: =IF(A9="","",RANDBETWEEN($C$1,$C$2)) -> 142 | C9: =IFERROR($C$1-1+_xlfn.RANK.EQ(B9,$B$4:$B$78)+COUNTIF(B$4:$B9,B9)-1,"") -> 20 | D9: =IFERROR(VLOOKUP(C9,'Question structure'!A:E,3,0),"") -> 2.3.1 | E9: =IFERROR(VLOOKUP(D9&"Viet",'Question structure'!D:H,2,0),"") -> Cậu nghĩ tôi nên làm gì? | F9: =IFERROR(VLOOKUP(D9&"Eng",'Question structure'!D:H,2,0),"") -> What do you think I have to do?
A10: =IFERROR(IF(A9+1>$C$2,"",A9+1),"") -> 7 | B10: =IF(A10="","",RANDBETWEEN($C$1,$C$2)) -> 143 | C10: =IFERROR($C$1-1+_xlfn.RANK.EQ(B10,$B$4:$B$78)+COUNTIF(B$4:$B10,B10)-1,"") -> 18 | D10: =IFERROR(VLOOKUP(C10,'Question structure'!A:E,3,0),"") -> 2.2.2 | E10: =IFERROR(VLOOKUP(D10&"Viet",'Question structure'!D:H,2,0),"") -> Cậu nghĩ thế nào về đề xuất của anh ta? | F10: =IFERROR(VLOOKUP(D10&"Eng",'Question structure'!D:H,2,0),"") -> What do you think about his suggestion?
A11: =IFERROR(IF(A10+1>$C$2,"",A10+1),"") -> 8 | B11: =IF(A11="","",RANDBETWEEN($C$1,$C$2)) -> 145 | C11: =IFERROR($C$1-1+_xlfn.RANK.EQ(B11,$B$4:$B$78)+COUNTIF(B$4:$B11,B11)-1,"") -> 16 | D11: =IFERROR(VLOOKUP(C11,'Question structure'!A:E,3,0),"") -> 2.1.4 | E11: =IFERROR(VLOOKUP(D11&"Viet",'Question structure'!D:H,2,0),"") -> Cậu nghĩ thế nào về cách anh ấy nói chuyện? | F11: =IFERROR(VLOOKUP(D11&"Eng",'Question structure'!D:H,2,0),"") -> What do you think of the way he talks?
A12: =IFERROR(IF(A11+1>$C$2,"",A11+1),"") -> 9 | B12: =IF(A12="","",RANDBETWEEN($C$1,$C$2)) -> 174 | C12: =IFERROR($C$1-1+_xlfn.RANK.EQ(B12,$B$4:$B$78)+COUNTIF(B$4:$B12,B12)-1,"") -> 6 | D12: =IFERROR(VLOOKUP(C12,'Question structure'!A:E,3,0),"") -> 1.2.2 | E12: =IFERROR(VLOOKUP(D12&"Viet",'Question structure'!D:H,2,0),"") -> Anh ấy ốm như thế nào? | F12: =IFERROR(VLOOKUP(D12&"Eng",'Question structure'!D:H,2,0),"") -> How sick is he?
A13: =IFERROR(IF(A12+1>$C$2,"",A12+1),"") -> 10 | B13: =IF(A13="","",RANDBETWEEN($C$1,$C$2)) -> 50 | C13: =IFERROR($C$1-1+_xlfn.RANK.EQ(B13,$B$4:$B$78)+COUNTIF(B$4:$B13,B13)-1,"") -> 60 | D13: =IFERROR(VLOOKUP(C13,'Question structure'!A:E,3,0),"") -> 7.3.3 | E13: =IFERROR(VLOOKUP(D13&"Viet",'Question structure'!D:H,2,0),"") -> Cậu đã có kế hoạch gì cho ngày sinh nhật chưa? | F13: =IFERROR(VLOOKUP(D13&"Eng",'Question structure'!D:H,2,0),"") -> Have you made plans for your birthday?
A14: =IFERROR(IF(A13+1>$C$2,"",A13+1),"") -> 11 | B14: =IF(A14="","",RANDBETWEEN($C$1,$C$2)) -> 158 | C14: =IFERROR($C$1-1+_xlfn.RANK.EQ(B14,$B$4:$B$78)+COUNTIF(B$4:$B14,B14)-1,"") -> 11 | D14: =IFERROR(VLOOKUP(C14,'Question structure'!A:E,3,0),"") -> 1.3.3 | E14: =IFERROR(VLOOKUP(D14&"Viet",'Question structure'!D:H,2,0),"") -> Buổi hẹn của cậu thế nào? | F14: =IFERROR(VLOOKUP(D14&"Eng",'Question structure'!D:H,2,0),"") -> How was your date?
A15: =IFERROR(IF(A14+1>$C$2,"",A14+1),"") -> 12 | B15: =IF(A15="","",RANDBETWEEN($C$1,$C$2)) -> 110 | C15: =IFERROR($C$1-1+_xlfn.RANK.EQ(B15,$B$4:$B$78)+COUNTIF(B$4:$B15,B15)-1,"") -> 40 | D15: =IFERROR(VLOOKUP(C15,'Question structure'!A:E,3,0),"") -> 4.3.1 | E15: =IFERROR(VLOOKUP(D15&"Viet",'Question structure'!D:H,2,0),"") -> Cậu muốn anh ấy mang cái gì đến? | F15: =IFERROR(VLOOKUP(D15&"Eng",'Question structure'!D:H,2,0),"") -> What do you want him to bring?
A16: =IFERROR(IF(A15+1>$C$2,"",A15+1),"") -> 13 | B16: =IF(A16="","",RANDBETWEEN($C$1,$C$2)) -> 29 | C16: =IFERROR($C$1-1+_xlfn.RANK.EQ(B16,$B$4:$B$78)+COUNTIF(B$4:$B16,B16)-1,"") -> 66 | D16: =IFERROR(VLOOKUP(C16,'Question structure'!A:E,3,0),"") -> 8.2.3 | E16: =IFERROR(VLOOKUP(D16&"Viet",'Question structure'!D:H,2,0),"") -> Tại sao cậu cứ hỏi tôi chuyện đó mãi thế? | F16: =IFERROR(VLOOKUP(D16&"Eng",'Question structure'!D:H,2,0),"") -> Why do you keep asking me that?
... A295: =IFERROR(IF(A294+1>$C$2,"",A294+1),"") | B295: =IF(A295="","",RANDBETWEEN($C$1,$C$2)) | C295: =IFERROR($C$1-1+_xlfn.RANK.EQ(B295,$B$4:$B$78)+COUNTIF(B$4:$B295,B295)-1,"") | D295: =IFERROR(VLOOKUP(C295,'Question structure'!A:E,3,0),"") | E295: =IFERROR(VLOOKUP(D295&"Viet",'Question structure'!D:H,2,0),"") | F295: =IFERROR(VLOOKUP(D295&"Eng",'Question structure'!D:H,2,0),"")
C296: =IFERROR($C$1-1+_xlfn.RANK.EQ(B296,$B$4:$B$78)+COUNTIF(B$4:$B296,B296)-1,"") | D296: =IFERROR(VLOOKUP(C296,'Question structure'!A:E,3,0),"") | E296: =IFERROR(VLOOKUP(D296&"Viet",'Question structure'!D:H,2,0),"") | F296: =IFERROR(VLOOKUP(D296&"Eng",'Question structure'!D:H,2,0),"")
C297: =IFERROR($C$1-1+_xlfn.RANK.EQ(B297,$B$4:$B$78)+COUNTIF(B$4:$B297,B297)-1,"") | D297: =IFERROR(VLOOKUP(C297,'Question structure'!A:E,3,0),"") | E297: =IFERROR(VLOOKUP(D297&"Viet",'Question structure'!D:H,2,0),"") | F297: =IFERROR(VLOOKUP(D297&"Eng",'Question structure'!D:H,2,0),"")
C298: =IFERROR($C$1-1+_xlfn.RANK.EQ(B298,$B$4:$B$78)+COUNTIF(B$4:$B298,B298)-1,"") | D298: =IFERROR(VLOOKUP(C298,'Question structure'!A:E,3,0),"") | E298: =IFERROR(VLOOKUP(D298&"Viet",'Question structure'!D:H,2,0),"") | F298: =IFERROR(VLOOKUP(D298&"Eng",'Question structure'!D:H,2,0),"")
C299: =IFERROR($C$1-1+_xlfn.RANK.EQ(B299,$B$4:$B$78)+COUNTIF(B$4:$B299,B299)-1,"") | D299: =IFERROR(VLOOKUP(C299,'Question structure'!A:E,3,0),"") | E299: =IFERROR(VLOOKUP(D299&"Viet",'Question structure'!D:H,2,0),"") | F299: =IFERROR(VLOOKUP(D299&"Eng",'Question structure'!D:H,2,0),"")
C300: =IFERROR($C$1-1+_xlfn.RANK.EQ(B300,$B$4:$B$78)+COUNTIF(B$4:$B300,B300)-1,"") | D300: =IFERROR(VLOOKUP(C300,'Question structure'!A:E,3,0),"") | E300: =IFERROR(VLOOKUP(D300&"Viet",'Question structure'!D:H,2,0),"") | F300: =IFERROR(VLOOKUP(D300&"Eng",'Question structure'!D:H,2,0),"")
C301: =IFERROR($C$1-1+_xlfn.RANK.EQ(B301,$B$4:$B$78)+COUNTIF(B$4:$B301,B301)-1,"") | D301: =IFERROR(VLOOKUP(C301,'Question structure'!A:E,3,0),"") | E301: =IFERROR(VLOOKUP(D301&"Viet",'Question structure'!D:H,2,0),"") | F301: =IFERROR(VLOOKUP(D301&"Eng",'Question structure'!D:H,2,0),"")
C302: =IFERROR($C$1-1+_xlfn.RANK.EQ(B302,$B$4:$B$78)+COUNTIF(B$4:$B302,B302)-1,"") | D302: =IFERROR(VLOOKUP(C302,'Question structure'!A:E,3,0),"") | E302: =IFERROR(VLOOKUP(D302&"Viet",'Question structure'!D:H,2,0),"") | F302: =IFERROR(VLOOKUP(D302&"Eng",'Question structure'!D:H,2,0),"")
C303: =IFERROR($C$1-1+_xlfn.RANK.EQ(B303,$B$4:$B$78)+COUNTIF(B$4:$B303,B303)-1,"") | D303: =IFERROR(VLOOKUP(C303,'Question structure'!A:E,3,0),"") | E303: =IFERROR(VLOOKUP(D303&"Viet",'Question structure'!D:H,2,0),"") | F303: =IFERROR(VLOOKUP(D303&"Eng",'Question structure'!D:H,2,0),"")
C304: =IFERROR($C$1-1+_xlfn.RANK.EQ(B304,$B$4:$B$78)+COUNTIF(B$4:$B304,B304)-1,"") | D304: =IFERROR(VLOOKUP(C304,'Question structure'!A:E,3,0),"") | E304: =IFERROR(VLOOKUP(D304&"Viet",'Question structure'!D:H,2,0),"") | F304: =IFERROR(VLOOKUP(D304&"Eng",'Question structure'!D:H,2,0),"")
C305: =IFERROR($C$1-1+_xlfn.RANK.EQ(B305,$B$4:$B$78)+COUNTIF(B$4:$B305,B305)-1,"") | D305: =IFERROR(VLOOKUP(C305,'Question structure'!A:E,3,0),"") | E305: =IFERROR(VLOOKUP(D305&"Viet",'Question structure'!D:H,2,0),"") | F305: =IFERROR(VLOOKUP(D305&"Eng",'Question structure'!D:H,2,0),"")
C306: =IFERROR($C$1-1+_xlfn.RANK.EQ(B306,$B$4:$B$78)+COUNTIF(B$4:$B306,B306)-1,"") | D306: =IFERROR(VLOOKUP(C306,'Question structure'!A:E,3,0),"") | E306: =IFERROR(VLOOKUP(D306&"Viet",'Question structure'!D:H,2,0),"") | F306: =IFERROR(VLOOKUP(D306&"Eng",'Question structure'!D:H,2,0),"")
C307: =IFERROR($C$1-1+_xlfn.RANK.EQ(B307,$B$4:$B$78)+COUNTIF(B$4:$B307,B307)-1,"") | D307: =IFERROR(VLOOKUP(C307,'Question structure'!A:E,3,0),"") | E307: =IFERROR(VLOOKUP(D307&"Viet",'Question structure'!D:H,2,0),"") | F307: =IFERROR(VLOOKUP(D307&"Eng",'Question structure'!D:H,2,0),"")
... C359: =IFERROR($C$1-1+_xlfn.RANK.EQ(B359,$B$4:$B$78)+COUNTIF(B$4:$B359,B359)-1,"") | D359: =IFERROR(VLOOKUP(C359,'Question structure'!A:E,3,0),"") | E359: =IFERROR(VLOOKUP(D359&"Viet",'Question structure'!D:H,2,0),"") | F359: =IFERROR(VLOOKUP(D359&"Eng",'Question structure'!D:H,2,0),"")

Sheet 0-82
A1: dsd | B1: sdsd
A2: 1 | B2: Do you want me to drive you home?
A3: 2 | B3: What do you think I should recommend?
A4: 3 | B4: Why are you so confused?
A5: 4 | B5: How come you know so much about me?
A6: 5 | B6: How can I explain this to him?
A7: 6 | B7: What am I supposed to talk to him about?
A8: 7 | B8: What do you want me to bring?
A9: 8 | B9: How was your trip?
A10: 9 | B10: What do you think he wants to eat?
A11: 10 | B11: How is the weather?
A12: 11 | B12: How bad is it?
A13: 12 | B13: Do you want to take a shower?
... A47: 46 | B47: What should I pack in my carry-on?
I53: 3

Sheet 83-100
A1: ghỵ | B1: ỵyu
A2: 1 | B2: How did you happen to know him?
A3: 2 | B3: When did you hear that?
A4: 3 | B4: How long does it take to get it done?
A5: 4 | B5: How do you work under him?
A6: 5 | B6: How do you put up with it?
A7: 6 | B7: When do you need these by?
A8: 7 | B8: When did you make up your mind?
A9: 8 | B9: When will you call him?
A10: 9 | B10: How long does it take to finish this course?
A11: 10 | B11: When do you want to start?
A12: 11 | B12: How do you handle it?
A13: 12 | B13: How did you get his permission?
... A20: 19 | B20: When did you get that?

Sheet 100-128
A1: âs | B1: ấ
A2: How long have you been waiting?
A3: Where are you?
A4: Don't you agree?
A5: How long will it take to finish the book?
A6: Don't you like him?
A7: Isn't it your responsibility?
A8: How long will the battery last?
A9: Where do you work?
A10: Where did you get that?
A11: Do you agree with that?
A12: Isn't it interesting?
A13: Where are you off to?
... A26: Do you agree to work with her?
