Workbook

Sheet Restaurant
B2: TOPIC: RESTAURANT
A3: No | B3: No | C3: ID | D3: Sentence | E3: Type | F3: Link | G3: ID | H3: Copy Google drive to …
B4: 1 | C4: 1Struc | D4: DO YOU KNOW ANY… AROUND HERE? /Cậu có biết… ở quanh đây không?/ | E4: Struc
B5: 1.1 | C5: 1.1Viet | D5: Cậu có biết nhà hàng nào ngon ở quanh đây không? | E5: Viet | G5: =IFERROR(LEFT(RIGHT(H5,LEN(H5)-32),LEN(RIGHT(H5,LEN(H5)-32))-17),"")
A6: 1 | B6: 1.1 | C6: 1.1Eng | D6: Do you know any good restaurants around here? | E6: Eng | F6: =IF(G6="","","https://docs.google.com/uc?export=download&id="&G6) -> https://docs.google.com/uc?export=download&id=16en5UYWOZqr7QaIvQrWw6vA1x9DYkJ4D | G6: =IFERROR(LEFT(RIGHT(H6,LEN(H6)-32),LEN(RIGHT(H6,LEN(H6)-32))-17),"") -> 16en5UYWOZqr7QaIvQrWw6vA1x9DYkJ4D | H6: https://drive.google.com/file/d/16en5UYWOZqr7QaIvQrWw6vA1x9DYkJ4D/view?usp=sharing
B7: 1.1 | C7: 1.1Phon | D7: duː juː noʊ ˈɛni gʊd ˈrestraːnts əˈraʊnd hɪr | E7: Phon | F7: =IF(G7="","","https://docs.google.com/uc?export=download&id="&G7) | G7: =IFERROR(LEFT(RIGHT(H7,LEN(H7)-32),LEN(RIGHT(H7,LEN(H7)-32))-17),"")
B8: 1.2 | C8: 1.2Viet | D8: Cậu có biết nhà hàng Nhật Bản nào ở quanh đây không? | E8: Viet | F8: =IF(G8="","","https://docs.google.com/uc?export=download&id="&G8) | G8: =IFERROR(LEFT(RIGHT(H8,LEN(H8)-32),LEN(RIGHT(H8,LEN(H8)-32))-17),"")
A9: 2 | B9: 1.2 | C9: 1.2Eng | D9: Do you know any Japanese restaurant around here? | E9: Eng | F9: =IF(G9="","","https://docs.google.com/uc?export=download&id="&G9) -> https://docs.google.com/uc?export=download&id=1mPa23EjqSy1DVpmZrrjetf2-VoOstiLT | G9: =IFERROR(LEFT(RIGHT(H9,LEN(H9)-32),LEN(RIGHT(H9,LEN(H9)-32))-17),"") -> 1mPa23EjqSy1DVpmZrrjetf2-VoOstiLT | H9: https://drive.google.com/file/d/1mPa23EjqSy1DVpmZrrjetf2-VoOstiLT/view?usp=sharing
B10: 1.2 | C10: 1.2Phon | D10: du: ju: noʊ ˈɛni ˌʤæpəˈni:z ˈrɛstra:nt əˈraʊnd hɪr | E10: Phon | F10: =IF(G10="","","https://docs.google.com/uc?export=download&id="&G10) | G10: =IFERROR(LEFT(RIGHT(H10,LEN(H10)-32),LEN(RIGHT(H10,LEN(H10)-32))-17),"")
B11: 1.3 | C11: 1.3Viet | D11: Cậu có biết nhà hàng Tây nào ở quanh đây không? | E11: Viet | F11: =IF(G11="","","https://docs.google.com/uc?export=download&id="&G11) | G11: =IFERROR(LEFT(RIGHT(H11,LEN(H11)-32),LEN(RIGHT(H11,LEN(H11)-32))-17),"")
A12: 3 | B12: 1.3 | C12: 1.3Eng | D12: Do you know any Western restaurant around here? | E12: Eng | F12: =IF(G12="","","https://docs.google.com/uc?export=download&id="&G12) -> https://docs.google.com/uc?export=download&id=1jpHsFyxAuOiVuOId3W6V57PG9tN1Hvoa | G12: =IFERROR(LEFT(RIGHT(H12,LEN(H12)-32),LEN(RIGHT(H12,LEN(H12)-32))-17),"") -> 1jpHsFyxAuOiVuOId3W6V57PG9tN1Hvoa | H12: https://drive.google.com/file/d/1jpHsFyxAuOiVuOId3W6V57PG9tN1Hvoa/view?usp=sharing
B13: 1.3 | C13: 1.3Phon | D13: du: ju: noʊ ˈɛni ˈwɛstərn ˈrɛstra:nt əˈraʊnd hɪr | E13: Phon | F13: =IF(G13="","","https://docs.google.com/uc?export=download&id="&G13) | G13: =IFERROR(LEFT(RIGHT(H13,LEN(H13)-32),LEN(RIGHT(H13,LEN(H13)-32))-17),"")
B14: 1.4 | C14: 1.4Viet | D14: Cậu có biết nhà hàng thức ăn nhanh nào ở gần đây không? | E14: Viet | F14: =IF(G14="","","https://docs.google.com/uc?export=download&id="&G14) | G14: =IFERROR(LEFT(RIGHT(H14,LEN(H14)-32),LEN(RIGHT(H14,LEN(H14)-32))-17),"")
A15: 4 | B15: 1.4 | C15: 1.4Eng | D15: Do you know any fast food restaurant around here? | E15: Eng | F15: =IF(G15="","","https://docs.google.com/uc?export=download&id="&G15) -> https://docs.google.com/uc?export=download&id=1uMj-EZeWo8cqJ4gthYkcU3PO5-ADleRX | G15: =IFERROR(LEFT(RIGHT(H15,LEN(H15)-32),LEN(RIGHT(H15,LEN(H15)-32))-17),"") -> 1uMj-EZeWo8cqJ4gthYkcU3PO5-ADleRX | H15: https://drive.google.com/file/d/1uMj-EZeWo8cqJ4gthYkcU3PO5-ADleRX/view?usp=sharing
B16: 1.4 | C16: 1.4Phon | D16: du: ju: noʊ ˈɛni fæst fu:d ˈrɛstra:nt əˈraʊnd hɪr | E16: Phon | F16: =IF(G16="","","https://docs.google.com/uc?export=download&id="&G16) | G16: =IFERROR(LEFT(RIGHT(H16,LEN(H16)-32),LEN(RIGHT(H16,LEN(H16)-32))-17),"")
B17: 1.5 | C17: 1.5Viet | D17: Cậu có biết nhà hàng hải sản nào ở gần đây không? | E17: Viet | F17: =IF(G17="","","https://docs.google.com/uc?export=download&id="&G17) | G17: =IFERROR(LEFT(RIGHT(H17,LEN(H17)-32),LEN(RIGHT(H17,LEN(H17)-32))-17),"")
A18: 5 | B18: 1.5 | C18: 1.5Eng | D18: Do you know any seafood restaurant around here? | E18: Eng | F18: =IF(G18="","","https://docs.google.com/uc?export=download&id="&G18) -> https://docs.google.com/uc?export=download&id=1w99NNIxFgtbxSm115_vOzzbeUyaRdX3d | G18: =IFERROR(LEFT(RIGHT(H18,LEN(H18)-32),LEN(RIGHT(H18,LEN(H18)-32))-17),"") -> 1w99NNIxFgtbxSm115_vOzzbeUyaRdX3d | H18: https://drive.google.com/file/d/1w99NNIxFgtbxSm115_vOzzbeUyaRdX3d/view?usp=sharing
B19: 1.5 | C19: 1.5Phon | D19: du: ju: noʊ ˈɛni ˈsi:fu:d ˈrɛstra:nt əˈraʊnd hɪr | E19: Phon | F19: =IF(G19="","","https://docs.google.com/uc?export=download&id="&G19) | G19: =IFERROR(LEFT(RIGHT(H19,LEN(H19)-32),LEN(RIGHT(H19,LEN(H19)-32))-17),"")
B20: 2 | C20: 2Struc | D20: CAN I MAKE A RESERVATION…? /Vui lòng cho tôi đặt chỗ.../ | E20: Struc | F20: =IF(G20="","","https://docs.google.com/uc?export=download&id="&G20) | G20: =IFERROR(LEFT(RIGHT(H20,LEN(H20)-32),LEN(RIGHT(H20,LEN(H20)-32))-17),"")
B21: 2.1 | C21: 2.1Viet | D21: Vui lòng cho tôi đặt chỗ tối nay? | E21: Viet | F21: =IF(G21="","","https://docs.google.com/uc?export=download&id="&G21) | G21: =IFERROR(LEFT(RIGHT(H21,LEN(H21)-32),LEN(RIGHT(H21,LEN(H21)-32))-17),"")
A22: 6 | B22: 2.1 | C22: 2.1Eng | D22: Can I make a reservation tonight? | E22: Eng | F22: =IF(G22="","","https://docs.google.com/uc?export=download&id="&G22) -> https://docs.google.com/uc?export=download&id=1hBed7Sm0Uu7_ebFFuhB7r5eSSD6XmxGc | G22: =IFERROR(LEFT(RIGHT(H22,LEN(H22)-32),LEN(RIGHT(H22,LEN(H22)-32))-17),"") -> 1hBed7Sm0Uu7_ebFFuhB7r5eSSD6XmxGc | H22: https://drive.google.com/file/d/1hBed7Sm0Uu7_ebFFuhB7r5eSSD6XmxGc/view?usp=sharing
B23: 2.1 | C23: 2.1Phon | D23: kæn aɪ meɪk ə ˌrɛzərˈveɪʃən təˈnaɪt | E23: Phon | F23: =IF(G23="","","https://docs.google.com/uc?export=download&id="&G23) | G23: =IFERROR(LEFT(RIGHT(H23,LEN(H23)-32),LEN(RIGHT(H23,LEN(H23)-32))-17),"")
B24: 2.2 | C24: 2.2Viet | D24: Vui lòng cho tôi đặt chỗ qua điện thoại? | E24: Viet | F24: =IF(G24="","","https://docs.google.com/uc?export=download&id="&G24) | G24: =IFERROR(LEFT(RIGHT(H24,LEN(H24)-32),LEN(RIGHT(H24,LEN(H24)-32))-17),"")
A25: 7 | B25: 2.2 | C25: 2.2Eng | D25: Can I make a reservation over the phone? | E25: Eng | F25: =IF(G25="","","https://docs.google.com/uc?export=download&id="&G25) -> https://docs.google.com/uc?export=download&id=1BJcTAxHo57DwTtZMMz-vIcUiwVoE6PSF | G25: =IFERROR(LEFT(RIGHT(H25,LEN(H25)-32),LEN(RIGHT(H25,LEN(H25)-32))-17),"") -> 1BJcTAxHo57DwTtZMMz-vIcUiwVoE6PSF | H25: https://drive.google.com/file/d/1BJcTAxHo57DwTtZMMz-vIcUiwVoE6PSF/view?usp=sharing
B26: 2.2 | C26: 2.2Phon | D26: kæn aɪ meɪk ə ˌrɛzərˈveɪʃən ˈoʊvər ðə foʊn | E26: Phon | F26: =IF(G26="","","https://docs.google.com/uc?export=download&id="&G26) | G26: =IFERROR(LEFT(RIGHT(H26,LEN(H26)-32),LEN(RIGHT(H26,LEN(H26)-32))-17),"")
B27: 2.3 | C27: 2.3Viet | D27: Vui lòng cho tôi đặt chỗ qua trang web? | E27: Viet | F27: =IF(G27="","","https://docs.google.com/uc?export=download&id="&G27) | G27: =IFERROR(LEFT(RIGHT(H27,LEN(H27)-32),LEN(RIGHT(H27,LEN(H27)-32))-17),"")
A28: 8 | B28: 2.3 | C28: 2.3Eng | D28: Can I make a reservation on your website? | E28: Eng | F28: =IF(G28="","","https://docs.google.com/uc?export=download&id="&G28) -> https://docs.google.com/uc?export=download&id=1P7bmCW58ywp6JcyGrAyXOHcqGNlSeTd6 | G28: =IFERROR(LEFT(RIGHT(H28,LEN(H28)-32),LEN(RIGHT(H28,LEN(H28)-32))-17),"") -> 1P7bmCW58ywp6JcyGrAyXOHcqGNlSeTd6 | H28: https://drive.google.com/file/d/1P7bmCW58ywp6JcyGrAyXOHcqGNlSeTd6/view?usp=sharing
B29: 2.3 | C29: 2.3Phon | D29: kæn aɪ meɪk ə ˌrɛzərˈveɪʃən a:n jʊr ˈwɛbsaɪt | E29: Phon | F29: =IF(G29="","","https://docs.google.com/uc?export=download&id="&G29) | G29: =IFERROR(LEFT(RIGHT(H29,LEN(H29)-32),LEN(RIGHT(H29,LEN(H29)-32))-17),"")
B30: 2.4 | C30: 2.4Viet | D30: Vui lòng cho tôi đặt chỗ cho 4 người. | E30: Viet | F30: =IF(G30="","","https://docs.google.com/uc?export=download&id="&G30) | G30: =IFERROR(LEFT(RIGHT(H30,LEN(H30)-32),LEN(RIGHT(H30,LEN(H30)-32))-17),"")
A31: 9 | B31: 2.4 | C31: 2.4Eng | D31: Can I make a reservation for 4 please? | E31: Eng | F31: =IF(G31="","","https://docs.google.com/uc?export=download&id="&G31) -> https://docs.google.com/uc?export=download&id=1V-h8aG8t6t2uUWMLn-5FLSkHw1KkoKsD | G31: =IFERROR(LEFT(RIGHT(H31,LEN(H31)-32),LEN(RIGHT(H31,LEN(H31)-32))-17),"") -> 1V-h8aG8t6t2uUWMLn-5FLSkHw1KkoKsD | H31: https://drive.google.com/file/d/1V-h8aG8t6t2uUWMLn-5FLSkHw1KkoKsD/view?usp=sharing
B32: 2.4 | C32: 2.4Phon | D32: kæn aɪ meɪk ə ˌrɛzərˈveɪʃən fɔ:r fɔ:r pli:z | E32: Phon | F32: =IF(G32="","","https://docs.google.com/uc?export=download&id="&G32) | G32: =IFERROR(LEFT(RIGHT(H32,LEN(H32)-32),LEN(RIGHT(H32,LEN(H32)-32))-17),"")
B33: 2.5 | C33: 2.5Viet | D33: Cho tôi đặt một bàn vào 8 giờ tối ngày mai nhé? | E33: Viet | F33: =IF(G33="","","https://docs.google.com/uc?export=download&id="&G33) | G33: =IFERROR(LEFT(RIGHT(H33,LEN(H33)-32),LEN(RIGHT(H33,LEN(H33)-32))-17),"")
A34: 10 | B34: 2.5 | C34: 2.5Eng | D34: Can I make a reservation for tomorrow night at eight? | E34: Eng | F34: =IF(G34="","","https://docs.google.com/uc?export=download&id="&G34) -> https://docs.google.com/uc?export=download&id=1DZz2GK2fssD7ZrjTx9ouQsvA09zXNpkC | G34: =IFERROR(LEFT(RIGHT(H34,LEN(H34)-32),LEN(RIGHT(H34,LEN(H34)-32))-17),"") -> 1DZz2GK2fssD7ZrjTx9ouQsvA09zXNpkC | H34: https://drive.google.com/file/d/1DZz2GK2fssD7ZrjTx9ouQsvA09zXNpkC/view?usp=sharing
B35: 2.5 | C35: 2.5Phon | D35: kæn aɪ meɪk ə ˌrɛzərˈveɪʃən fɔ:r təˈma:roʊ naɪt æt eɪt | E35: Phon | F35: =IF(G35="","","https://docs.google.com/uc?export=download&id="&G35) | G35: =IFERROR(LEFT(RIGHT(H35,LEN(H35)-32),LEN(RIGHT(H35,LEN(H35)-32))-17),"")
B36: 3 | C36: 3Struc | D36: WOULD YOU PLEASE HOLD THE TABLE…? /Bạn giữ chỗ giúp tôi được không?/ | E36: Struc | F36: =IF(G36="","","https://docs.google.com/uc?export=download&id="&G36) | G36: =IFERROR(LEFT(RIGHT(H36,LEN(H36)-32),LEN(RIGHT(H36,LEN(H36)-32))-17),"")
B37: 3.1 | C37: 3.1Viet | D37: Bạn giữ chỗ giúp mình được không, mình sẽ tới trễ 20 phút. | E37: Viet | F37: =IF(G37="","","https://docs.google.com/uc?export=download&id="&G37) | G37: =IFERROR(LEFT(RIGHT(H37,LEN(H37)-32),LEN(RIGHT(H37,LEN(H37)-32))-17),"")
A38: 11 | B38: 3.1 | C38: 3.1Eng | D38: Would you please hold my table, I’ll be 20 minutes late? | E38: Eng | F38: =IF(G38="","","https://docs.google.com/uc?export=download&id="&G38) -> https://docs.google.com/uc?export=download&id=1Y6WzkKIn8yW10Xp7MbKpyNGKz2fvT3Qs | G38: =IFERROR(LEFT(RIGHT(H38,LEN(H38)-32),LEN(RIGHT(H38,LEN(H38)-32))-17),"") -> 1Y6WzkKIn8yW10Xp7MbKpyNGKz2fvT3Qs | H38: https://drive.google.com/file/d/1Y6WzkKIn8yW10Xp7MbKpyNGKz2fvT3Qs/view?usp=sharing
B39: 3.1 | C39: 3.1Phon | D39: wʊd ju: pli:z hoʊld maɪ ˈteɪbəl aɪl bi: ˈtwenti ˈmɪnɪts leɪt | E39: Phon | F39: =IF(G39="","","https://docs.google.com/uc?export=download&id="&G39) | G39: =IFERROR(LEFT(RIGHT(H39,LEN(H39)-32),LEN(RIGHT(H39,LEN(H39)-32))-17),"")
B40: 3.2 | C40: 3.2Viet | D40: Bạn giữ chỗ giúp mình được không, e rằng mình sẽ đến trễ. | E40: Viet | F40: =IF(G40="","","https://docs.google.com/uc?export=download&id="&G40) | G40: =IFERROR(LEFT(RIGHT(H40,LEN(H40)-32),LEN(RIGHT(H40,LEN(H40)-32))-17),"")
A41: 12 | B41: 3.2 | C41: 3.2Eng | D41: Would you please hold my table, I am afraid I will be late? | E41: Eng | F41: =IF(G41="","","https://docs.google.com/uc?export=download&id="&G41) -> https://docs.google.com/uc?export=download&id=1knF9Abeb4cHZIhAgg2NI5cywAJj2PgqW | G41: =IFERROR(LEFT(RIGHT(H41,LEN(H41)-32),LEN(RIGHT(H41,LEN(H41)-32))-17),"") -> 1knF9Abeb4cHZIhAgg2NI5cywAJj2PgqW | H41: https://drive.google.com/file/d/1knF9Abeb4cHZIhAgg2NI5cywAJj2PgqW/view?usp=sharing
...

Sheet Viet
B2: Sentence | C2: Link | D2: ID | E2: Copy Google drive to …
B3: 01-05 | C3: =IF(D3="","","https://docs.google.com/uc?export=download&id="&D3) -> https://docs.google.com/uc?export=download&id=1CMvsfJ0HhFL0BCmaLAHxZvSd4i5Y1-42 | D3: =IFERROR(LEFT(RIGHT(E3,LEN(E3)-32),LEN(RIGHT(E3,LEN(E3)-32))-17),"") -> 1CMvsfJ0HhFL0BCmaLAHxZvSd4i5Y1-42 | E3: https://drive.google.com/file/d/1CMvsfJ0HhFL0BCmaLAHxZvSd4i5Y1-42/view?usp=sharing
B4: 06-10 | C4: =IF(D4="","","https://docs.google.com/uc?export=download&id="&D4) -> https://docs.google.com/uc?export=download&id=146WHmNxMtDrfnMyTmP19o7RPM2UR7rAP | D4: =IFERROR(LEFT(RIGHT(E4,LEN(E4)-32),LEN(RIGHT(E4,LEN(E4)-32))-17),"") -> 146WHmNxMtDrfnMyTmP19o7RPM2UR7rAP | E4: https://drive.google.com/file/d/146WHmNxMtDrfnMyTmP19o7RPM2UR7rAP/view?usp=sharing
B5: 11-15 | C5: =IF(D5="","","https://docs.google.com/uc?export=download&id="&D5) -> https://docs.google.com/uc?export=download&id=1y2DBC-IxXzp1J04TIqh1SAzDkS9eaHMF | D5: =IFERROR(LEFT(RIGHT(E5,LEN(E5)-32),LEN(RIGHT(E5,LEN(E5)-32))-17),"") -> 1y2DBC-IxXzp1J04TIqh1SAzDkS9eaHMF | E5: https://drive.google.com/file/d/1y2DBC-IxXzp1J04TIqh1SAzDkS9eaHMF/view?usp=sharing
B6: 16-21 | C6: =IF(D6="","","https://docs.google.com/uc?export=download&id="&D6) -> https://docs.google.com/uc?export=download&id=1u5DO6HFdqBGKu12Kdhfs5orC6qktxnLK | D6: =IFERROR(LEFT(RIGHT(E6,LEN(E6)-32),LEN(RIGHT(E6,LEN(E6)-32))-17),"") -> 1u5DO6HFdqBGKu12Kdhfs5orC6qktxnLK | E6: https://drive.google.com/file/d/1u5DO6HFdqBGKu12Kdhfs5orC6qktxnLK/view?usp=sharing
B7: 01-21 | C7: =IF(D7="","","https://docs.google.com/uc?export=download&id="&D7) -> https://docs.google.com/uc?export=download&id=1T3Cu8i_YzrfsdyW0VsIZuY9b-nfn7EPO | D7: =IFERROR(LEFT(RIGHT(E7,LEN(E7)-32),LEN(RIGHT(E7,LEN(E7)-32))-17),"") -> 1T3Cu8i_YzrfsdyW0VsIZuY9b-nfn7EPO | E7: https://drive.google.com/file/d/1T3Cu8i_YzrfsdyW0VsIZuY9b-nfn7EPO/view?usp=sharing

Sheet Sum
B2: Sentence | C2: Link | D2: ID | E2: Copy Google drive to …
B3: Woman | C3: =IF(D3="","","https://docs.google.com/uc?export=download&id="&D3) | D3: =IFERROR(LEFT(RIGHT(E3,LEN(E3)-32),LEN(RIGHT(E3,LEN(E3)-32))-17),"")
B4: Man | C4: =IF(D4="","","https://docs.google.com/uc?export=download&id="&D4) | D4: =IFERROR(LEFT(RIGHT(E4,LEN(E4)-32),LEN(RIGHT(E4,LEN(E4)-32))-17),"")

Sheet Ramdom
B1: From | C1: 74
B2: To | C2: 94
C3: No | D3: No | E3: Viet | F3: Eng
A4: =C1 -> 74 | B4: =IF(A4="","",RANDBETWEEN($C$1,$C$2)) -> 90 | C4: =IFERROR($C$1-1+_xlfn.RANK.EQ(B4,$B$4:$B$101)+COUNTIF(B$4:$B4,B4)-1,"") -> 78 | D4: =IFERROR(VLOOKUP(C4,Restaurant!A:B,2,0),"") -> 17.3 | E4: =IFERROR(VLOOKUP(D4&"Viet",Restaurant!C:D,2,0),"") -> Thành thật mà nói, món đó rất ngon. | F4: =IFERROR(VLOOKUP(D4&"Eng",Restaurant!C:D,2,0),"") -> To be honest, that was really delicious.
A5: =IFERROR(IF(A4+1>$C$2,"",A4+1),"") -> 75 | B5: =IF(A5="","",RANDBETWEEN($C$1,$C$2)) -> 75 | C5: =IFERROR($C$1-1+_xlfn.RANK.EQ(B5,$B$4:$B$101)+COUNTIF(B$4:$B5,B5)-1,"") -> 92 | D5: =IFERROR(VLOOKUP(C5,Restaurant!A:B,2,0),"") -> 21.3 | E5: =IFERROR(VLOOKUP(D5&"Viet",Restaurant!C:D,2,0),"") -> Cho tôi một bàn ở trong góc nhé. | F5: =IFERROR(VLOOKUP(D5&"Eng",Restaurant!C:D,2,0),"") -> I would like a table in the corner.
A6: =IFERROR(IF(A5+1>$C$2,"",A5+1),"") -> 76 | B6: =IF(A6="","",RANDBETWEEN($C$1,$C$2)) -> 75 | C6: =IFERROR($C$1-1+_xlfn.RANK.EQ(B6,$B$4:$B$101)+COUNTIF(B$4:$B6,B6)-1,"") -> 93 | D6: =IFERROR(VLOOKUP(C6,Restaurant!A:B,2,0),"") -> 21.4 | E6: =IFERROR(VLOOKUP(D6&"Viet",Restaurant!C:D,2,0),"") -> Cho tôi một bàn ở khu không hút thuốc nhé. | F6: =IFERROR(VLOOKUP(D6&"Eng",Restaurant!C:D,2,0),"") -> I would like a table in the non-smoking area. | K6: l
A7: =IFERROR(IF(A6+1>$C$2,"",A6+1),"") -> 77 | B7: =IF(A7="","",RANDBETWEEN($C$1,$C$2)) -> 81 | C7: =IFERROR($C$1-1+_xlfn.RANK.EQ(B7,$B$4:$B$101)+COUNTIF(B$4:$B7,B7)-1,"") -> 88 | D7: =IFERROR(VLOOKUP(C7,Restaurant!A:B,2,0),"") -> 20.2 | E7: =IFERROR(VLOOKUP(D7&"Viet",Restaurant!C:D,2,0),"") -> Bạn đã ăn gỏi sứa bao giờ chưa? | F7: =IFERROR(VLOOKUP(D7&"Eng",Restaurant!C:D,2,0),"") -> Have you eaten jelly fish salad before?
A8: =IFERROR(IF(A7+1>$C$2,"",A7+1),"") -> 78 | B8: =IF(A8="","",RANDBETWEEN($C$1,$C$2)) -> 94 | C8: =IFERROR($C$1-1+_xlfn.RANK.EQ(B8,$B$4:$B$101)+COUNTIF(B$4:$B8,B8)-1,"") -> 74 | D8: =IFERROR(VLOOKUP(C8,Restaurant!A:B,2,0),"") -> 16.1 | E8: =IFERROR(VLOOKUP(D8&"Viet",Restaurant!C:D,2,0),"") -> A: Bạn thấy thèm ăn cái gì?, B: Tôi thấy thèm ăn bít tết. | F8: =IFERROR(VLOOKUP(D8&"Eng",Restaurant!C:D,2,0),"") -> A: What do you feel like eating?, B: I feel like eating steak.
A9: =IFERROR(IF(A8+1>$C$2,"",A8+1),"") -> 79 | B9: =IF(A9="","",RANDBETWEEN($C$1,$C$2)) -> 77 | C9: =IFERROR($C$1-1+_xlfn.RANK.EQ(B9,$B$4:$B$101)+COUNTIF(B$4:$B9,B9)-1,"") -> 91 | D9: =IFERROR(VLOOKUP(C9,Restaurant!A:B,2,0),"") -> 21.2 | E9: =IFERROR(VLOOKUP(D9&"Viet",Restaurant!C:D,2,0),"") -> Cho tôi một bàn ngoài ban công nhé. | F9: =IFERROR(VLOOKUP(D9&"Eng",Restaurant!C:D,2,0),"") -> I would like a table on the terrace.
A10: =IFERROR(IF(A9+1>$C$2,"",A9+1),"") -> 80 | B10: =IF(A10="","",RANDBETWEEN($C$1,$C$2)) -> 79 | C10: =IFERROR($C$1-1+_xlfn.RANK.EQ(B10,$B$4:$B$101)+COUNTIF(B$4:$B10,B10)-1,"") -> 89 | D10: =IFERROR(VLOOKUP(C10,Restaurant!A:B,2,0),"") -> 20.3 | E10: =IFERROR(VLOOKUP(D10&"Viet",Restaurant!C:D,2,0),"") -> Bạn đã ăn sườn cừu bao giờ chưa? | F10: =IFERROR(VLOOKUP(D10&"Eng",Restaurant!C:D,2,0),"") -> Have you eaten lamb chop before?
A11: =IFERROR(IF(A10+1>$C$2,"",A10+1),"") -> 81 | B11: =IF(A11="","",RANDBETWEEN($C$1,$C$2)) -> 83 | C11: =IFERROR($C$1-1+_xlfn.RANK.EQ(B11,$B$4:$B$101)+COUNTIF(B$4:$B11,B11)-1,"") -> 87 | D11: =IFERROR(VLOOKUP(C11,Restaurant!A:B,2,0),"") -> 20.1 | E11: =IFERROR(VLOOKUP(D11&"Viet",Restaurant!C:D,2,0),"") -> Bạn đã ăn cua hoàng đế bao giờ chưa? | F11: =IFERROR(VLOOKUP(D11&"Eng",Restaurant!C:D,2,0),"") -> Have you eaten king crab before?
A12: =IFERROR(IF(A11+1>$C$2,"",A11+1),"") -> 82 | B12: =IF(A12="","",RANDBETWEEN($C$1,$C$2)) -> 89 | C12: =IFERROR($C$1-1+_xlfn.RANK.EQ(B12,$B$4:$B$101)+COUNTIF(B$4:$B12,B12)-1,"") -> 79 | D12: =IFERROR(VLOOKUP(C12,Restaurant!A:B,2,0),"") -> 17.4 | E12: =IFERROR(VLOOKUP(D12&"Viet",Restaurant!C:D,2,0),"") -> Thành thật mà nói, mọi thứ đều hoàn hảo. | F12: =IFERROR(VLOOKUP(D12&"Eng",Restaurant!C:D,2,0),"") -> To be honest, everything was perfect.
A13: =IFERROR(IF(A12+1>$C$2,"",A12+1),"") -> 83 | B13: =IF(A13="","",RANDBETWEEN($C$1,$C$2)) -> 75 | C13: =IFERROR($C$1-1+_xlfn.RANK.EQ(B13,$B$4:$B$101)+COUNTIF(B$4:$B13,B13)-1,"") -> 94 | D13: =IFERROR(VLOOKUP(C13,Restaurant!A:B,2,0),"") -> 21.5 | E13: =IFERROR(VLOOKUP(D13&"Viet",Restaurant!C:D,2,0),"") -> Cho tôi một bàn ở ngoài vườn nhé. | F13: =IFERROR(VLOOKUP(D13&"Eng",Restaurant!C:D,2,0),"") -> I would like a table in the garden.
A14: =IFERROR(IF(A13+1>$C$2,"",A13+1),"") -> 84 | B14: =IF(A14="","",RANDBETWEEN($C$1,$C$2)) -> 89 | C14: =IFERROR($C$1-1+_xlfn.RANK.EQ(B14,$B$4:$B$101)+COUNTIF(B$4:$B14,B14)-1,"") -> 80 | D14: =IFERROR(VLOOKUP(C14,Restaurant!A:B,2,0),"") -> 17.5 | E14: =IFERROR(VLOOKUP(D14&"Viet",Restaurant!C:D,2,0),"") -> Thành thật mà nói, thịt bị khét. | F14: =IFERROR(VLOOKUP(D14&"Eng",Restaurant!C:D,2,0),"") -> To be honest, the meat is burnt. | L14: k
A15: =IFERROR(IF(A14+1>$C$2,"",A14+1),"") -> 85 | B15: =IF(A15="","",RANDBETWEEN($C$1,$C$2)) -> 91 | C15: =IFERROR($C$1-1+_xlfn.RANK.EQ(B15,$B$4:$B$101)+COUNTIF(B$4:$B15,B15)-1,"") -> 76 | D15: =IFERROR(VLOOKUP(C15,Restaurant!A:B,2,0),"") -> 17.1 | E15: =IFERROR(VLOOKUP(D15&"Viet",Restaurant!C:D,2,0),"") -> Thành thật mà nói, nó không ngon lắm. | F15: =IFERROR(VLOOKUP(D15&"Eng",Restaurant!C:D,2,0),"") -> To be honest, it wasn’t great.
A16: =IFERROR(IF(A15+1>$C$2,"",A15+1),"") -> 86 | B16: =IF(A16="","",RANDBETWEEN($C$1,$C$2)) -> 88 | C16: =IFERROR($C$1-1+_xlfn.RANK.EQ(B16,$B$4:$B$101)+COUNTIF(B$4:$B16,B16)-1,"") -> 81 | D16: =IFERROR(VLOOKUP(C16,Restaurant!A:B,2,0),"") -> 18.1 | E16: =IFERROR(VLOOKUP(D16&"Viet",Restaurant!C:D,2,0),"") -> Xin lỗi, tôi không có gọi món này. Tôi gọi thịt bò nướng. | F16: =IFERROR(VLOOKUP(D16&"Eng",Restaurant!C:D,2,0),"") -> Excuse me, this is not what I ordered.I asked for roast beef.
A17: =IFERROR(IF(A16+1>$C$2,"",A16+1),"") -> 87 | B17: =IF(A17="","",RANDBETWEEN($C$1,$C$2)) -> 88 | C17: =IFERROR($C$1-1+_xlfn.RANK.EQ(B17,$B$4:$B$101)+COUNTIF(B$4:$B17,B17)-1,"") -> 82 | D17: =IFERROR(VLOOKUP(C17,Restaurant!A:B,2,0),"") -> 18.2 | E17: =IFERROR(VLOOKUP(D17&"Viet",Restaurant!C:D,2,0),"") -> Xin lỗi, tôi không có gọi món này. Tôi gọi súp cà chua. | F17: =IFERROR(VLOOKUP(D17&"Eng",Restaurant!C:D,2,0),"") -> Excuse me, this is not what I ordered. I asked for tomato soup.
A18: =IFERROR(IF(A17+1>$C$2,"",A17+1),"") -> 88 | B18: =IF(A18="","",RANDBETWEEN($C$1,$C$2)) -> 85 | C18: =IFERROR($C$1-1+_xlfn.RANK.EQ(B18,$B$4:$B$101)+COUNTIF(B$4:$B18,B18)-1,"") -> 85 | D18: =IFERROR(VLOOKUP(C18,Restaurant!A:B,2,0),"") -> 19.2 | E18: =IFERROR(VLOOKUP(D18&"Viet",Restaurant!C:D,2,0),"") -> Tôi bị dị ứng với sầu riêng, tôi không thích mùi của nó. Mỗi lần ăn xong, tôi bị tiêu chảy. | F18: =IFERROR(VLOOKUP(D18&"Eng",Restaurant!C:D,2,0),"") -> I am allergic to durian, and I dislike the smell. Whenever I have it, I will have diarrhea. | L18: j
A19: =IFERROR(IF(A18+1>$C$2,"",A18+1),"") -> 89 | B19: =IF(A19="","",RANDBETWEEN($C$1,$C$2)) -> 87 | C19: =IFERROR($C$1-1+_xlfn.RANK.EQ(B19,$B$4:$B$101)+COUNTIF(B$4:$B19,B19)-1,"") -> 84 | D19: =IFERROR(VLOOKUP(C19,Restaurant!A:B,2,0),"") -> 19.1 | E19: =IFERROR(VLOOKUP(D19&"Viet",Restaurant!C:D,2,0),"") -> Tôi bị dị ứng với đồ hải sản, tôi không thích mùi của nó. Mỗi lần ăn xong, tôi bị tiêu chảy. | F19: =IFERROR(VLOOKUP(D19&"Eng",Restaurant!C:D,2,0),"") -> I am allergic to seafood, and I dislike the smell. Whenever I have it, I will have diarrhea.
A20: =IFERROR(IF(A19+1>$C$2,"",A19+1),"") -> 90 | B20: =IF(A20="","",RANDBETWEEN($C$1,$C$2)) -> 88 | C20: =IFERROR($C$1-1+_xlfn.RANK.EQ(B20,$B$4:$B$101)+COUNTIF(B$4:$B20,B20)-1,"") -> 83 | D20: =IFERROR(VLOOKUP(C20,Restaurant!A:B,2,0),"") -> 18.3 | E20: =IFERROR(VLOOKUP(D20&"Viet",Restaurant!C:D,2,0),"") -> Xin lỗi, tôi không có gọi món này. Tôi gọi thịt hầm. | F20: =IFERROR(VLOOKUP(D20&"Eng",Restaurant!C:D,2,0),"") -> Excuse me, this is not what I ordered. I asked for a stew.
A21: =IFERROR(IF(A20+1>$C$2,"",A20+1),"") -> 91 | B21: =IF(A21="","",RANDBETWEEN($C$1,$C$2)) -> 79 | C21: =IFERROR($C$1-1+_xlfn.RANK.EQ(B21,$B$4:$B$101)+COUNTIF(B$4:$B21,B21)-1,"") -> 90 | D21: =IFERROR(VLOOKUP(C21,Restaurant!A:B,2,0),"") -> 21.1 | E21: =IFERROR(VLOOKUP(D21&"Viet",Restaurant!C:D,2,0),"") -> Cho tôi một bàn bên cạnh cửa sổ nhé? | F21: =IFERROR(VLOOKUP(D21&"Eng",Restaurant!C:D,2,0),"") -> I would like a table by the window. | M21: j
A22: =IFERROR(IF(A21+1>$C$2,"",A21+1),"") -> 92 | B22: =IF(A22="","",RANDBETWEEN($C$1,$C$2)) -> 93 | C22: =IFERROR($C$1-1+_xlfn.RANK.EQ(B22,$B$4:$B$101)+COUNTIF(B$4:$B22,B22)-1,"") -> 75 | D22: =IFERROR(VLOOKUP(C22,Restaurant!A:B,2,0),"") -> 16.2 | E22: =IFERROR(VLOOKUP(D22&"Viet",Restaurant!C:D,2,0),"") -> A: Bạn thấy thèm ăn cái gì? B: Tôi thấy thèm ăn mì ý. | F22: =IFERROR(VLOOKUP(D22&"Eng",Restaurant!C:D,2,0),"") -> A: What do you feel like eating?, B: I feel like eating pasta.
A23: =IFERROR(IF(A22+1>$C$2,"",A22+1),"") -> 93 | B23: =IF(A23="","",RANDBETWEEN($C$1,$C$2)) -> 84 | C23: =IFERROR($C$1-1+_xlfn.RANK.EQ(B23,$B$4:$B$101)+COUNTIF(B$4:$B23,B23)-1,"") -> 86 | D23: =IFERROR(VLOOKUP(C23,Restaurant!A:B,2,0),"") -> 19.3 | E23: =IFERROR(VLOOKUP(D23&"Viet",Restaurant!C:D,2,0),"") -> Tôi bị dị ứng với bột ngọt. Mỗi lần ăn xong, tôi bị đau đầu. | F23: =IFERROR(VLOOKUP(D23&"Eng",Restaurant!C:D,2,0),"") -> I am allergic to monosodium glutamate (MSG). Whenever I have it, I will have a headache.
A24: =IFERROR(IF(A23+1>$C$2,"",A23+1),"") -> 94 | B24: =IF(A24="","",RANDBETWEEN($C$1,$C$2)) -> 91 | C24: =IFERROR($C$1-1+_xlfn.RANK.EQ(B24,$B$4:$B$101)+COUNTIF(B$4:$B24,B24)-1,"") -> 77 | D24: =IFERROR(VLOOKUP(C24,Restaurant!A:B,2,0),"") -> 17.2 | E24: =IFERROR(VLOOKUP(D24&"Viet",Restaurant!C:D,2,0),"") -> Thành thật mà nói, món đó còn có thể ngon hơn. | F24: =IFERROR(VLOOKUP(D24&"Eng",Restaurant!C:D,2,0),"") -> To be honest, it could have been better.
A25: =IFERROR(IF(A24+1>$C$2,"",A24+1),"") | B25: =IF(A25="","",RANDBETWEEN($C$1,$C$2)) | C25: =IFERROR($C$1-1+_xlfn.RANK.EQ(B25,$B$4:$B$101)+COUNTIF(B$4:$B25,B25)-1,"") | D25: =IFERROR(VLOOKUP(C25,Restaurant!A:B,2,0),"") | E25: =IFERROR(VLOOKUP(D25&"Viet",Restaurant!C:D,2,0),"") | F25: =IFERROR(VLOOKUP(D25&"Eng",Restaurant!C:D,2,0),"")
A26: =IFERROR(IF(A25+1>$C$2,"",A25+1),"") | B26: =IF(A26="","",RANDBETWEEN($C$1,$C$2)) | C26: =IFERROR($C$1-1+_xlfn.RANK.EQ(B26,$B$4:$B$101)+COUNTIF(B$4:$B26,B26)-1,"") | D26: =IFERROR(VLOOKUP(C26,Restaurant!A:B,2,0),"") | E26: =IFERROR(VLOOKUP(D26&"Viet",Restaurant!C:D,2,0),"") | F26: =IFERROR(VLOOKUP(D26&"Eng",Restaurant!C:D,2,0),"")
A27: =IFERROR(IF(A26+1>$C$2,"",A26+1),"") | B27: =IF(A27="","",RANDBETWEEN($C$1,$C$2)) | C27: =IFERROR($C$1-1+_xlfn.RANK.EQ(B27,$B$4:$B$101)+COUNTIF(B$4:$B27,B27)-1,"") | D27: =IFERROR(VLOOKUP(C27,Restaurant!A:B,2,0),"") | E27: =IFERROR(VLOOKUP(D27&"Viet",Restaurant!C:D,2,0),"") | F27: =IFERROR(VLOOKUP(D27&"Eng",Restaurant!C:D,2,0),"")
A28: =IFERROR(IF(A27+1>$C$2,"",A27+1),"") | B28: =IF(A28="","",RANDBETWEEN($C$1,$C$2)) | C28: =IFERROR($C$1-1+_xlfn.RANK.EQ(B28,$B$4:$B$101)+COUNTIF(B$4:$B28,B28)-1,"") | D28: =IFERROR(VLOOKUP(C28,Restaurant!A:B,2,0),"") | E28: =IFERROR(VLOOKUP(D28&"Viet",Restaurant!C:D,2,0),"") | F28: =IFERROR(VLOOKUP(D28&"Eng",Restaurant!C:D,2,0),"")
A29: =IFERROR(IF(A28+1>$C$2,"",A28+1),"") | B29: =IF(A29="","",RANDBETWEEN($C$1,$C$2)) | C29: =IFERROR($C$1-1+_xlfn.RANK.EQ(B29,$B$4:$B$101)+COUNTIF(B$4:$B29,B29)-1,"") | D29: =IFERROR(VLOOKUP(C29,Restaurant!A:B,2,0),"") | E29: =IFERROR(VLOOKUP(D29&"Viet",Restaurant!C:D,2,0),"") | F29: =IFERROR(VLOOKUP(D29&"Eng",Restaurant!C:D,2,0),"")
A30: =IFERROR(IF(A29+1>$C$2,"",A29+1),"") | B30: =IF(A30="","",RANDBETWEEN($C$1,$C$2)) | C30: =IFERROR($C$1-1+_xlfn.RANK.EQ(B30,$B$4:$B$101)+COUNTIF(B$4:$B30,B30)-1,"") | D30: =IFERROR(VLOOKUP(C30,Restaurant!A:B,2,0),"") | E30: =IFERROR(VLOOKUP(D30&"Viet",Restaurant!C:D,2,0),"") | F30: =IFERROR(VLOOKUP(D30&"Eng",Restaurant!C:D,2,0),"")
A31: =IFERROR(IF(A30+1>$C$2,"",A30+1),"") | B31: =IF(A31="","",RANDBETWEEN($C$1,$C$2)) | C31: =IFERROR($C$1-1+_xlfn.RANK.EQ(B31,$B$4:$B$101)+COUNTIF(B$4:$B31,B31)-1,"") | D31: =IFERROR(VLOOKUP(C31,Restaurant!A:B,2,0),"") | E31: =IFERROR(VLOOKUP(D31&"Viet",Restaurant!C:D,2,0),"") | F31: =IFERROR(VLOOKUP(D31&"Eng",Restaurant!C:D,2,0),"")
A32: =IFERROR(IF(A31+1>$C$2,"",A31+1),"") | B32: =IF(A32="","",RANDBETWEEN($C$1,$C$2)) | C32: =IFERROR($C$1-1+_xlfn.RANK.EQ(B32,$B$4:$B$101)+COUNTIF(B$4:$B32,B32)-1,"") | D32: =IFERROR(VLOOKUP(C32,Restaurant!A:B,2,0),"") | E32: =IFERROR(VLOOKUP(D32&"Viet",Restaurant!C:D,2,0),"") | F32: =IFERROR(VLOOKUP(D32&"Eng",Restaurant!C:D,2,0),"")
A33: =IFERROR(IF(A32+1>$C$2,"",A32+1),"") | B33: =IF(A33="","",RANDBETWEEN($C$1,$C$2)) | C33: =IFERROR($C$1-1+_xlfn.RANK.EQ(B33,$B$4:$B$101)+COUNTIF(B$4:$B33,B33)-1,"") | D33: =IFERROR(VLOOKUP(C33,Restaurant!A:B,2,0),"") | E33: =IFERROR(VLOOKUP(D33&"Viet",Restaurant!C:D,2,0),"") | F33: =IFERROR(VLOOKUP(D33&"Eng",Restaurant!C:D,2,0),"")
... A72: =IFERROR(IF(A71+1>$C$2,"",A71+1),"") | B72: =IF(A72="","",RANDBETWEEN($C$1,$C$2)) | C72: =IFERROR($C$1-1+_xlfn.RANK.EQ(B72,$B$4:$B$101)+COUNTIF(B$4:$B72,B72)-1,"") | D72: =IFERROR(VLOOKUP(C72,Restaurant!A:B,2,0),"") | E72: =IFERROR(VLOOKUP(D72&"Viet",Restaurant!C:D,2,0),"") | F72: =IFERROR(VLOOKUP(D72&"Eng",Restaurant!C:D,2,0),"")
A73: =IFERROR(IF(A72+1>$C$2,"",A72+1),"") | B73: =IF(A73="","",RANDBETWEEN($C$1,$C$2)) | C73: =IFERROR($C$1-1+_xlfn.RANK.EQ(B73,$B$4:$B$101)+COUNTIF(B$4:$B73,B73)-1,"") | D73: =IFERROR(VLOOKUP(C73,Restaurant!A:B,2,0),"")
A74: =IFERROR(IF(A73+1>$C$2,"",A73+1),"") | B74: =IF(A74="","",RANDBETWEEN($C$1,$C$2)) | C74: =IFERROR($C$1-1+_xlfn.RANK.EQ(B74,$B$4:$B$101)+COUNTIF(B$4:$B74,B74)-1,"") | D74: =IFERROR(VLOOKUP(C74,Restaurant!A:B,2,0),"")
A75: =IFERROR(IF(A74+1>$C$2,"",A74+1),"") | B75: =IF(A75="","",RANDBETWEEN($C$1,$C$2)) | C75: =IFERROR($C$1-1+_xlfn.RANK.EQ(B75,$B$4:$B$101)+COUNTIF(B$4:$B75,B75)-1,"") | D75: =IFERROR(VLOOKUP(C75,Restaurant!A:B,2,0),"")
A76: =IFERROR(IF(A75+1>$C$2,"",A75+1),"") | B76: =IF(A76="","",RANDBETWEEN($C$1,$C$2)) | C76: =IFERROR($C$1-1+_xlfn.RANK.EQ(B76,$B$4:$B$101)+COUNTIF(B$4:$B76,B76)-1,"") | D76: =IFERROR(VLOOKUP(C76,Restaurant!A:B,2,0),"")
A77: =IFERROR(IF(A76+1>$C$2,"",A76+1),"") | B77: =IF(A77="","",RANDBETWEEN($C$1,$C$2)) | C77: =IFERROR($C$1-1+_xlfn.RANK.EQ(B77,$B$4:$B$101)+COUNTIF(B$4:$B77,B77)-1,"") | D77: =IFERROR(VLOOKUP(C77,Restaurant!A:B,2,0),"")
A78: =IFERROR(IF(A77+1>$C$2,"",A77+1),"") | B78: =IF(A78="","",RANDBETWEEN($C$1,$C$2)) | C78: =IFERROR($C$1-1+_xlfn.RANK.EQ(B78,$B$4:$B$101)+COUNTIF(B$4:$B78,B78)-1,"") | D78: =IFERROR(VLOOKUP(C78,Restaurant!A:B,2,0),"")
...

Sheet Sheet1
