Workbook

Sheet Shopping
A2: TOPIC: FROM MORNING TO NIGHT
A3: No | B3: No | C3: ID | D3: Sentence | E3: Type | F3: Link | G3: ID | H3: Copy Google drive to …
B4: 1 | C4: =B4&E4 -> 1Struc | D4: S + GOT + NOUN + WHOLESALE… /… mua giá sỉ/ | E4: Struc
B5: 1.1 | C5: =B5&E5 -> 1.1Viet | D5: Tôi đã mua tất giá sỉ. | E5: Viet | F5: =IF(G5="","","https://docs.google.com/uc?export=download&id="&G5) | G5: =IFERROR(LEFT(RIGHT(H5,LEN(H5)-32),LEN(RIGHT(H5,LEN(H5)-32))-17),"")
A6: 1 | B6: 1.1 | C6: =B6&E6 -> 1.1Eng | D6: I got my socks wholesale. | E6: Eng | F6: =IF(G6="","","https://docs.google.com/uc?export=download&id="&G6) -> https://docs.google.com/uc?export=download&id=1QvqycNx3JcG4G4TVHgXp1tDY_xL-WlxL | G6: =IFERROR(LEFT(RIGHT(H6,LEN(H6)-32),LEN(RIGHT(H6,LEN(H6)-32))-17),"") -> 1QvqycNx3JcG4G4TVHgXp1tDY_xL-WlxL | H6: https://drive.google.com/file/d/1QvqycNx3JcG4G4TVHgXp1tDY_xL-WlxL/view?usp=sharing
B7: 1.1 | C7: =B7&E7 -> 1.1Phon | D7: aɪ ga:t maɪ sa:ks ˈhoʊlseɪl | E7: Phon | F7: =IF(G7="","","https://docs.google.com/uc?export=download&id="&G7) | G7: =IFERROR(LEFT(RIGHT(H7,LEN(H7)-32),LEN(RIGHT(H7,LEN(H7)-32))-17),"")
B8: 1.2 | C8: =B8&E8 -> 1.2Viet | D8: Tôi đã mua quần áo giá sỉ. | E8: Viet | F8: =IF(G8="","","https://docs.google.com/uc?export=download&id="&G8) | G8: =IFERROR(LEFT(RIGHT(H8,LEN(H8)-32),LEN(RIGHT(H8,LEN(H8)-32))-17),"")
A9: =+A6+1 -> 2 | B9: =B8 -> 1.2 | C9: =B9&E9 -> 1.2Eng | D9: I got my clothes wholesale. | E9: Eng | F9: =IF(G9="","","https://docs.google.com/uc?export=download&id="&G9) -> https://docs.google.com/uc?export=download&id=1vasjBVqETqOl7bs3vQBOAzR4NiGpoxsF | G9: =IFERROR(LEFT(RIGHT(H9,LEN(H9)-32),LEN(RIGHT(H9,LEN(H9)-32))-17),"") -> 1vasjBVqETqOl7bs3vQBOAzR4NiGpoxsF | H9: https://drive.google.com/file/d/1vasjBVqETqOl7bs3vQBOAzR4NiGpoxsF/view?usp=sharing
B10: =B9 -> 1.2 | C10: =B10&E10 -> 1.2Phon | D10: aɪ ga:t maɪ kloʊðz ˈhoʊlseɪl | E10: Phon | F10: =IF(G10="","","https://docs.google.com/uc?export=download&id="&G10) | G10: =IFERROR(LEFT(RIGHT(H10,LEN(H10)-32),LEN(RIGHT(H10,LEN(H10)-32))-17),"")
B11: 1.3 | C11: =B11&E11 -> 1.3Viet | D11: Chị ấy mua bóng đèn trang trí với giá sỉ. | E11: Viet | F11: =IF(G11="","","https://docs.google.com/uc?export=download&id="&G11) | G11: =IFERROR(LEFT(RIGHT(H11,LEN(H11)-32),LEN(RIGHT(H11,LEN(H11)-32))-17),"")
A12: =+A9+1 -> 3 | B12: =B11 -> 1.3 | C12: =B12&E12 -> 1.3Eng | D12: She got decorative lights wholesale. | E12: Eng | F12: =IF(G12="","","https://docs.google.com/uc?export=download&id="&G12) -> https://docs.google.com/uc?export=download&id=1peXZA3soILfxKtdaD4T537d9LgVveBzE | G12: =IFERROR(LEFT(RIGHT(H12,LEN(H12)-32),LEN(RIGHT(H12,LEN(H12)-32))-17),"") -> 1peXZA3soILfxKtdaD4T537d9LgVveBzE | H12: https://drive.google.com/file/d/1peXZA3soILfxKtdaD4T537d9LgVveBzE/view?usp=sharing
B13: =B12 -> 1.3 | C13: =B13&E13 -> 1.3Phon | D13: ʃi: ga:t ˈdɛkrətɪv laɪts ˈhoʊlseɪl | E13: Phon | F13: =IF(G13="","","https://docs.google.com/uc?export=download&id="&G13) | G13: =IFERROR(LEFT(RIGHT(H13,LEN(H13)-32),LEN(RIGHT(H13,LEN(H13)-32))-17),"")
B14: 1.4 | C14: =B14&E14 -> 1.4Viet | D14: Anh ấy mua rượu với giá sỉ. | E14: Viet | F14: =IF(G14="","","https://docs.google.com/uc?export=download&id="&G14) | G14: =IFERROR(LEFT(RIGHT(H14,LEN(H14)-32),LEN(RIGHT(H14,LEN(H14)-32))-17),"")
A15: =+A12+1 -> 4 | B15: =B14 -> 1.4 | C15: =B15&E15 -> 1.4Eng | D15: He got wine wholesale. | E15: Eng | F15: =IF(G15="","","https://docs.google.com/uc?export=download&id="&G15) -> https://docs.google.com/uc?export=download&id=1lpbZ84Z9-7MbW-sErkcSGi88_7MjVpSa | G15: =IFERROR(LEFT(RIGHT(H15,LEN(H15)-32),LEN(RIGHT(H15,LEN(H15)-32))-17),"") -> 1lpbZ84Z9-7MbW-sErkcSGi88_7MjVpSa | H15: https://drive.google.com/file/d/1lpbZ84Z9-7MbW-sErkcSGi88_7MjVpSa/view?usp=sharing
B16: =B15 -> 1.4 | C16: =B16&E16 -> 1.4Phon | D16: hi: ga:t waɪn ˈhoʊlseɪl | E16: Phon | F16: =IF(G16="","","https://docs.google.com/uc?export=download&id="&G16) | G16: =IFERROR(LEFT(RIGHT(H16,LEN(H16)-32),LEN(RIGHT(H16,LEN(H16)-32))-17),"")
B17: 2 | C17: =B17&E17 -> 2Struc | D17: S + TO BE SOLD AT HALF PRICE… /Cái gì đó bán nửa giá…/ | E17: Struc | F17: =IF(G17="","","https://docs.google.com/uc?export=download&id="&G17) | G17: =IFERROR(LEFT(RIGHT(H17,LEN(H17)-32),LEN(RIGHT(H17,LEN(H17)-32))-17),"")
B18: 2.1 | C18: =B18&E18 -> 2.1Viet | D18: Hàng sản xuất dư được bán nửa giá. | E18: Viet | F18: =IF(G18="","","https://docs.google.com/uc?export=download&id="&G18) | G18: =IFERROR(LEFT(RIGHT(H18,LEN(H18)-32),LEN(RIGHT(H18,LEN(H18)-32))-17),"")
A19: =A15+1 -> 5 | B19: =B18 -> 2.1 | C19: =B19&E19 -> 2.1Eng | D19: Surplus goods are sold at half price. | E19: Eng | F19: =IF(G19="","","https://docs.google.com/uc?export=download&id="&G19) -> https://docs.google.com/uc?export=download&id=1dGzVe3ZtjEoDcPRMJotwSrA9aF9xdm3Z | G19: =IFERROR(LEFT(RIGHT(H19,LEN(H19)-32),LEN(RIGHT(H19,LEN(H19)-32))-17),"") -> 1dGzVe3ZtjEoDcPRMJotwSrA9aF9xdm3Z | H19: https://drive.google.com/file/d/1dGzVe3ZtjEoDcPRMJotwSrA9aF9xdm3Z/view?usp=sharing
B20: =B19 -> 2.1 | C20: =B20&E20 -> 2.1Phon | D20: ˈsɜ:rpləs gʊdz a:r soʊld æt hæf praɪs | E20: Phon | F20: =IF(G20="","","https://docs.google.com/uc?export=download&id="&G20) | G20: =IFERROR(LEFT(RIGHT(H20,LEN(H20)-32),LEN(RIGHT(H20,LEN(H20)-32))-17),"")
B21: 2.2 | C21: =B21&E21 -> 2.2Viet | D21: Cuốn sách này được bán với nửa giá. | E21: Viet | F21: =IF(G21="","","https://docs.google.com/uc?export=download&id="&G21) | G21: =IFERROR(LEFT(RIGHT(H21,LEN(H21)-32),LEN(RIGHT(H21,LEN(H21)-32))-17),"")
A22: =+A19+1 -> 6 | B22: =B21 -> 2.2 | C22: =B22&E22 -> 2.2Eng | D22: This book is sold at half price. | E22: Eng | F22: =IF(G22="","","https://docs.google.com/uc?export=download&id="&G22) -> https://docs.google.com/uc?export=download&id=1bE7kOP2RQNucQ7RbAkn0PeoO6yw_Dd_5 | G22: =IFERROR(LEFT(RIGHT(H22,LEN(H22)-32),LEN(RIGHT(H22,LEN(H22)-32))-17),"") -> 1bE7kOP2RQNucQ7RbAkn0PeoO6yw_Dd_5 | H22: https://drive.google.com/file/d/1bE7kOP2RQNucQ7RbAkn0PeoO6yw_Dd_5/view?usp=sharing
B23: =B22 -> 2.2 | C23: =B23&E23 -> 2.2Phon | D23: ðɪs bʊk ɪz soʊld æt hæf praɪs | E23: Phon | F23: =IF(G23="","","https://docs.google.com/uc?export=download&id="&G23) | G23: =IFERROR(LEFT(RIGHT(H23,LEN(H23)-32),LEN(RIGHT(H23,LEN(H23)-32))-17),"")
B24: 2.3 | C24: =B24&E24 -> 2.3Viet | D24: Mấy cái bánh pizza này được bán với nửa giá. | E24: Viet | F24: =IF(G24="","","https://docs.google.com/uc?export=download&id="&G24) | G24: =IFERROR(LEFT(RIGHT(H24,LEN(H24)-32),LEN(RIGHT(H24,LEN(H24)-32))-17),"")
A25: =+A22+1 -> 7 | B25: =B24 -> 2.3 | C25: =B25&E25 -> 2.3Eng | D25: These pizzas are sold at half price. | E25: Eng | F25: =IF(G25="","","https://docs.google.com/uc?export=download&id="&G25) -> https://docs.google.com/uc?export=download&id=1dj-mw8sQJcgFasY1pHP2zdirU8iZ-gOn | G25: =IFERROR(LEFT(RIGHT(H25,LEN(H25)-32),LEN(RIGHT(H25,LEN(H25)-32))-17),"") -> 1dj-mw8sQJcgFasY1pHP2zdirU8iZ-gOn | H25: https://drive.google.com/file/d/1dj-mw8sQJcgFasY1pHP2zdirU8iZ-gOn/view?usp=sharing
B26: =B25 -> 2.3 | C26: =B26&E26 -> 2.3Phon | D26: ði:z ˈpi:tsəz a:r soʊld æt hæf praɪs | E26: Phon | F26: =IF(G26="","","https://docs.google.com/uc?export=download&id="&G26) | G26: =IFERROR(LEFT(RIGHT(H26,LEN(H26)-32),LEN(RIGHT(H26,LEN(H26)-32))-17),"")
B27: 2.4 | C27: =B27&E27 -> 2.4Viet | D27: Mặt hàng này được bán nửa giá. | E27: Viet | F27: =IF(G27="","","https://docs.google.com/uc?export=download&id="&G27) | G27: =IFERROR(LEFT(RIGHT(H27,LEN(H27)-32),LEN(RIGHT(H27,LEN(H27)-32))-17),"")
A28: =+A25+1 -> 8 | B28: =B27 -> 2.4 | C28: =B28&E28 -> 2.4Eng | D28: This product/item is sold at half price. | E28: Eng | F28: =IF(G28="","","https://docs.google.com/uc?export=download&id="&G28) -> https://docs.google.com/uc?export=download&id=1Hp-h5XxwC5tGc8dxmnXl11DIn6a14Zcr | G28: =IFERROR(LEFT(RIGHT(H28,LEN(H28)-32),LEN(RIGHT(H28,LEN(H28)-32))-17),"") -> 1Hp-h5XxwC5tGc8dxmnXl11DIn6a14Zcr | H28: https://drive.google.com/file/d/1Hp-h5XxwC5tGc8dxmnXl11DIn6a14Zcr/view?usp=sharing
B29: =B28 -> 2.4 | C29: =B29&E29 -> 2.4Phon | D29: ðɪs ˈpra:dʌkt/ˈaɪtəm ɪz soʊld æt hæf praɪs | E29: Phon | F29: =IF(G29="","","https://docs.google.com/uc?export=download&id="&G29) | G29: =IFERROR(LEFT(RIGHT(H29,LEN(H29)-32),LEN(RIGHT(H29,LEN(H29)-32))-17),"")
B30: 3 | C30: =B30&E30 -> 3Struc | D30: S + ONLY BUY BRAND-NAME PRODUCTS… /Ai đó chỉ mua hàng có thương hiệu…/ | E30: Struc | F30: =IF(G30="","","https://docs.google.com/uc?export=download&id="&G30) | G30: =IFERROR(LEFT(RIGHT(H30,LEN(H30)-32),LEN(RIGHT(H30,LEN(H30)-32))-17),"")
B31: 3.1 | C31: =B31&E31 -> 3.1Viet | D31: Bố mình chỉ mua hàng có thương hiệu. | E31: Viet | F31: =IF(G31="","","https://docs.google.com/uc?export=download&id="&G31) | G31: =IFERROR(LEFT(RIGHT(H31,LEN(H31)-32),LEN(RIGHT(H31,LEN(H31)-32))-17),"")
A32: 9 | B32: =B31 -> 3.1 | C32: =B32&E32 -> 3.1Eng | D32: My dad only buys brand-name products. | E32: Eng | F32: =IF(G32="","","https://docs.google.com/uc?export=download&id="&G32) -> https://docs.google.com/uc?export=download&id=1-UhOlY1W8cuYL3nsSEckPWi4jEUoztWj | G32: =IFERROR(LEFT(RIGHT(H32,LEN(H32)-32),LEN(RIGHT(H32,LEN(H32)-32))-17),"") -> 1-UhOlY1W8cuYL3nsSEckPWi4jEUoztWj | H32: https://drive.google.com/file/d/1-UhOlY1W8cuYL3nsSEckPWi4jEUoztWj/view?usp=sharing
B33: =B32 -> 3.1 | C33: =B33&E33 -> 3.1Phon | D33: maɪ dæd ˈoʊnli baɪz brænd neɪm ˈpra:dʌkts | E33: Phon | F33: =IF(G33="","","https://docs.google.com/uc?export=download&id="&G33) | G33: =IFERROR(LEFT(RIGHT(H33,LEN(H33)-32),LEN(RIGHT(H33,LEN(H33)-32))-17),"")
B34: 3.2 | C34: =B34&E34 -> 3.2Viet | D34: Tôi chỉ mua giày có thương hiệu. | E34: Viet | F34: =IF(G34="","","https://docs.google.com/uc?export=download&id="&G34) | G34: =IFERROR(LEFT(RIGHT(H34,LEN(H34)-32),LEN(RIGHT(H34,LEN(H34)-32))-17),"")
A35: 10 | B35: =B34 -> 3.2 | C35: =B35&E35 -> 3.2Eng | D35: I only buy brand-name shoes. | E35: Eng | F35: =IF(G35="","","https://docs.google.com/uc?export=download&id="&G35) -> https://docs.google.com/uc?export=download&id=1sdtdrAYSm7wZwZPvc1IqZzv4wJifJfrW | G35: =IFERROR(LEFT(RIGHT(H35,LEN(H35)-32),LEN(RIGHT(H35,LEN(H35)-32))-17),"") -> 1sdtdrAYSm7wZwZPvc1IqZzv4wJifJfrW | H35: https://drive.google.com/file/d/1sdtdrAYSm7wZwZPvc1IqZzv4wJifJfrW/view?usp=sharing
B36: =B35 -> 3.2 | C36: =B36&E36 -> 3.2Phon | D36: aɪ ˈoʊnli baɪ brænd neɪm ʃu:z | E36: Phon | F36: =IF(G36="","","https://docs.google.com/uc?export=download&id="&G36) | G36: =IFERROR(LEFT(RIGHT(H36,LEN(H36)-32),LEN(RIGHT(H36,LEN(H36)-32))-17),"")
B37: 3.3 | C37: =B37&E37 -> 3.3Viet | D37: Mẹ tôi chỉ mua mắt kính có thương hiệu. | E37: Viet | F37: =IF(G37="","","https://docs.google.com/uc?export=download&id="&G37) | G37: =IFERROR(LEFT(RIGHT(H37,LEN(H37)-32),LEN(RIGHT(H37,LEN(H37)-32))-17),"")
A38: 11 | B38: =B37 -> 3.3 | C38: =B38&E38 -> 3.3Eng | D38: My mom only buys brand-name glasses. | E38: Eng | F38: =IF(G38="","","https://docs.google.com/uc?export=download&id="&G38) -> https://docs.google.com/uc?export=download&id=10u_HCX9arQY1jlRlG1z5K2HgwDSmOXSz | G38: =IFERROR(LEFT(RIGHT(H38,LEN(H38)-32),LEN(RIGHT(H38,LEN(H38)-32))-17),"") -> 10u_HCX9arQY1jlRlG1z5K2HgwDSmOXSz | H38: https://drive.google.com/file/d/10u_HCX9arQY1jlRlG1z5K2HgwDSmOXSz/view?usp=sharing
B39: =B38 -> 3.3 | C39: =B39&E39 -> 3.3Phon | D39: maɪ ma:m ˈoʊnli baɪz brænd neɪm ˈglæsəz | E39: Phon | F39: =IF(G39="","","https://docs.google.com/uc?export=download&id="&G39) | G39: =IFERROR(LEFT(RIGHT(H39,LEN(H39)-32),LEN(RIGHT(H39,LEN(H39)-32))-17),"")
B40: 3.4 | C40: =B40&E40 -> 3.4Viet | D40: Tôi chỉ mua giỏ xách có thương hiệu. | E40: Viet | F40: =IF(G40="","","https://docs.google.com/uc?export=download&id="&G40) | G40: =IFERROR(LEFT(RIGHT(H40,LEN(H40)-32),LEN(RIGHT(H40,LEN(H40)-32))-17),"")
A41: 12 | B41: =B40 -> 3.4 | C41: =B41&E41 -> 3.4Eng | D41: I only buy brand-name handbag. | E41: Eng | F41: =IF(G41="","","https://docs.google.com/uc?export=download&id="&G41) -> https://docs.google.com/uc?export=download&id=1DxwV84b1d-9Q1CeTOntziHsKh3lEtmJ1 | G41: =IFERROR(LEFT(RIGHT(H41,LEN(H41)-32),LEN(RIGHT(H41,LEN(H41)-32))-17),"") -> 1DxwV84b1d-9Q1CeTOntziHsKh3lEtmJ1 | H41: https://drive.google.com/file/d/1DxwV84b1d-9Q1CeTOntziHsKh3lEtmJ1/view?usp=sharing
...

Sheet Viet
B2: Sentence | C2: Link | D2: ID | E2: Copy Google drive to …
B3: 01-05 | C3: =IF(D3="","","https://docs.google.com/uc?export=download&id="&D3) -> https://docs.google.com/uc?export=download&id=16UItxbRFXQsHC6JqNryXRfu_CMxio5BD | D3: =IFERROR(LEFT(RIGHT(E3,LEN(E3)-32),LEN(RIGHT(E3,LEN(E3)-32))-17),"") -> 16UItxbRFXQsHC6JqNryXRfu_CMxio5BD | E3: https://drive.google.com/file/d/16UItxbRFXQsHC6JqNryXRfu_CMxio5BD/view?usp=sharing
B4: 06-10 | C4: =IF(D4="","","https://docs.google.com/uc?export=download&id="&D4) -> https://docs.google.com/uc?export=download&id=1tqASmv37J5zMRAaCyySLAl2omzPg-vbY | D4: =IFERROR(LEFT(RIGHT(E4,LEN(E4)-32),LEN(RIGHT(E4,LEN(E4)-32))-17),"") -> 1tqASmv37J5zMRAaCyySLAl2omzPg-vbY | E4: https://drive.google.com/file/d/1tqASmv37J5zMRAaCyySLAl2omzPg-vbY/view?usp=sharing
B5: 11-15 | C5: =IF(D5="","","https://docs.google.com/uc?export=download&id="&D5) -> https://docs.google.com/uc?export=download&id=1zu8BmU5AsbyFTurAxfEUJog2JD12PCcj | D5: =IFERROR(LEFT(RIGHT(E5,LEN(E5)-32),LEN(RIGHT(E5,LEN(E5)-32))-17),"") -> 1zu8BmU5AsbyFTurAxfEUJog2JD12PCcj | E5: https://drive.google.com/file/d/1zu8BmU5AsbyFTurAxfEUJog2JD12PCcj/view?usp=sharing
B6: 16-20 | C6: =IF(D6="","","https://docs.google.com/uc?export=download&id="&D6) -> https://docs.google.com/uc?export=download&id=19ReWTE3nbR5jjo8wYUX4QIpAZOw_rnNA | D6: =IFERROR(LEFT(RIGHT(E6,LEN(E6)-32),LEN(RIGHT(E6,LEN(E6)-32))-17),"") -> 19ReWTE3nbR5jjo8wYUX4QIpAZOw_rnNA | E6: https://drive.google.com/file/d/19ReWTE3nbR5jjo8wYUX4QIpAZOw_rnNA/view?usp=sharing
B7: 21-25 | C7: =IF(D7="","","https://docs.google.com/uc?export=download&id="&D7) -> https://docs.google.com/uc?export=download&id=1vZIwkXnA5xCUT3PRPjEXdiVcqQGsAEh8 | D7: =IFERROR(LEFT(RIGHT(E7,LEN(E7)-32),LEN(RIGHT(E7,LEN(E7)-32))-17),"") -> 1vZIwkXnA5xCUT3PRPjEXdiVcqQGsAEh8 | E7: https://drive.google.com/file/d/1vZIwkXnA5xCUT3PRPjEXdiVcqQGsAEh8/view?usp=sharing
B8: 26-30 | C8: =IF(D8="","","https://docs.google.com/uc?export=download&id="&D8) -> https://docs.google.com/uc?export=download&id=1Prr7EGqLz05h6XYDbwD3L2N6zUx-x7jO | D8: =IFERROR(LEFT(RIGHT(E8,LEN(E8)-32),LEN(RIGHT(E8,LEN(E8)-32))-17),"") -> 1Prr7EGqLz05h6XYDbwD3L2N6zUx-x7jO | E8: https://drive.google.com/file/d/1Prr7EGqLz05h6XYDbwD3L2N6zUx-x7jO/view?usp=sharing
B9: 31-34 | C9: =IF(D9="","","https://docs.google.com/uc?export=download&id="&D9) -> https://docs.google.com/uc?export=download&id=1DRzFbHlLN_HTeLrEHTYWI7X7-nsRDN9F | D9: =IFERROR(LEFT(RIGHT(E9,LEN(E9)-32),LEN(RIGHT(E9,LEN(E9)-32))-17),"") -> 1DRzFbHlLN_HTeLrEHTYWI7X7-nsRDN9F | E9: https://drive.google.com/file/d/1DRzFbHlLN_HTeLrEHTYWI7X7-nsRDN9F/view?usp=sharing
B10: 01-34 | C10: =IF(D10="","","https://docs.google.com/uc?export=download&id="&D10) -> https://docs.google.com/uc?export=download&id=1RHvj1ANg1BAYXqvKADUtV9HWVai_93Ex | D10: =IFERROR(LEFT(RIGHT(E10,LEN(E10)-32),LEN(RIGHT(E10,LEN(E10)-32))-17),"") -> 1RHvj1ANg1BAYXqvKADUtV9HWVai_93Ex | E10: https://drive.google.com/file/d/1RHvj1ANg1BAYXqvKADUtV9HWVai_93Ex/view?usp=sharing
C11: =IF(D11="","","https://docs.google.com/uc?export=download&id="&D11) | D11: =IFERROR(LEFT(RIGHT(E11,LEN(E11)-32),LEN(RIGHT(E11,LEN(E11)-32))-17),"")
C12: =IF(D12="","","https://docs.google.com/uc?export=download&id="&D12) | D12: =IFERROR(LEFT(RIGHT(E12,LEN(E12)-32),LEN(RIGHT(E12,LEN(E12)-32))-17),"")
C13: =IF(D13="","","https://docs.google.com/uc?export=download&id="&D13&"""") | D13: =IFERROR(LEFT(RIGHT(E13,LEN(E13)-32),LEN(RIGHT(E13,LEN(E13)-32))-17),"")

Sheet Sum
B2: Sentence | C2: Link | D2: ID | E2: Copy Google drive to …
B3: Woman | C3: =IF(D3="","","https://docs.google.com/uc?export=download&id="&D3) -> https://docs.google.com/uc?export=download&id=1Sxauxdmjchkj8TyASYJCj9mTOL5PSzWr | D3: =IFERROR(LEFT(RIGHT(E3,LEN(E3)-32),LEN(RIGHT(E3,LEN(E3)-32))-17),"") -> 1Sxauxdmjchkj8TyASYJCj9mTOL5PSzWr | E3: https://drive.google.com/file/d/1Sxauxdmjchkj8TyASYJCj9mTOL5PSzWr/view?usp=sharing
B4: Man | C4: =IF(D4="","","https://docs.google.com/uc?export=download&id="&D4) -> https://docs.google.com/uc?export=download&id=1TQKwAZuLCUmzvKorNgRFEptFrh9sF2Ko | D4: =IFERROR(LEFT(RIGHT(E4,LEN(E4)-32),LEN(RIGHT(E4,LEN(E4)-32))-17),"") -> 1TQKwAZuLCUmzvKorNgRFEptFrh9sF2Ko | E4: https://drive.google.com/file/d/1TQKwAZuLCUmzvKorNgRFEptFrh9sF2Ko/view?usp=sharing

Sheet Ramdom
B1: From | C1: 126
B2: To | C2: 139
C3: No | D3: No | E3: Viet | F3: Eng
A4: =C1 -> 126 | B4: =IF(A4="","",RANDBETWEEN($C$1,$C$2)) -> 138 | C4: =IFERROR($C$1-1+_xlfn.RANK.EQ(B4,$B$4:$B$142)+COUNTIF(B$4:$B4,B4)-1,"") -> 128 | D4: =IFERROR(VLOOKUP(C4,Shopping!A:B,2,0),"") -> 31.3 | E4: =IFERROR(VLOOKUP(D4&"Viet",Shopping!C:D,2,0),"") -> Tôi muốn mua 3 món. | F4: =IFERROR(VLOOKUP(D4&"Eng",Shopping!C:D,2,0),"") -> I would like to get three items.
A5: =IFERROR(IF(A4+1>$C$2,"",A4+1),"") -> 127 | B5: =IF(A5="","",RANDBETWEEN($C$1,$C$2)) -> 137 | C5: =IFERROR($C$1-1+_xlfn.RANK.EQ(B5,$B$4:$B$242)+COUNTIF(B$4:$B5,B5)-1,"") -> 129 | D5: =IFERROR(VLOOKUP(C5,Shopping!A:B,2,0),"") -> 31.4 | E5: =IFERROR(VLOOKUP(D5&"Viet",Shopping!C:D,2,0),"") -> Tôi muốn mua 1 túi 5 kí gạo. | F5: =IFERROR(VLOOKUP(D5&"Eng",Shopping!C:D,2,0),"") -> I would like a 5-kilogram bag of rice.
A6: =IFERROR(IF(A5+1>$C$2,"",A5+1),"") -> 128 | B6: =IF(A6="","",RANDBETWEEN($C$1,$C$2)) -> 133 | C6: =IFERROR($C$1-1+_xlfn.RANK.EQ(B6,$B$4:$B$242)+COUNTIF(B$4:$B6,B6)-1,"") -> 132 | D6: =IFERROR(VLOOKUP(C6,Shopping!A:B,2,0),"") -> 32.3 | E6: =IFERROR(VLOOKUP(D6&"Viet",Shopping!C:D,2,0),"") -> Khi nào thì kem chống nắng này hết hạn? | F6: =IFERROR(VLOOKUP(D6&"Eng",Shopping!C:D,2,0),"") -> When does this sunscreen expire?
A7: =IFERROR(IF(A6+1>$C$2,"",A6+1),"") -> 129 | B7: =IF(A7="","",RANDBETWEEN($C$1,$C$2)) -> 130 | C7: =IFERROR($C$1-1+_xlfn.RANK.EQ(B7,$B$4:$B$242)+COUNTIF(B$4:$B7,B7)-1,"") -> 135 | D7: =IFERROR(VLOOKUP(C7,Shopping!A:B,2,0),"") -> 33.2 | E7: =IFERROR(VLOOKUP(D7&"Viet",Shopping!C:D,2,0),"") -> Không biết cô có cái áo len này cùng kiểu mà chất liệu khác không? | F7: =IFERROR(VLOOKUP(D7&"Eng",Shopping!C:D,2,0),"") -> I was wondering if you had the same style of sweater made from another fabric.
A8: =IFERROR(IF(A7+1>$C$2,"",A7+1),"") -> 130 | B8: =IF(A8="","",RANDBETWEEN($C$1,$C$2)) -> 134 | C8: =IFERROR($C$1-1+_xlfn.RANK.EQ(B8,$B$4:$B$242)+COUNTIF(B$4:$B8,B8)-1,"") -> 130 | D8: =IFERROR(VLOOKUP(C8,Shopping!A:B,2,0),"") -> 32.1 | E8: =IFERROR(VLOOKUP(D8&"Viet",Shopping!C:D,2,0),"") -> Thịt heo này khi nào hết hạn? | F8: =IFERROR(VLOOKUP(D8&"Eng",Shopping!C:D,2,0),"") -> When does this pork expire?
A9: =IFERROR(IF(A8+1>$C$2,"",A8+1),"") -> 131 | B9: =IF(A9="","",RANDBETWEEN($C$1,$C$2)) -> 139 | C9: =IFERROR($C$1-1+_xlfn.RANK.EQ(B9,$B$4:$B$242)+COUNTIF(B$4:$B9,B9)-1,"") -> 126 | D9: =IFERROR(VLOOKUP(C9,Shopping!A:B,2,0),"") -> 31.1 | E9: =IFERROR(VLOOKUP(D9&"Viet",Shopping!C:D,2,0),"") -> Tôi muốn mua 1 lít sữa. | F9: =IFERROR(VLOOKUP(D9&"Eng",Shopping!C:D,2,0),"") -> I would like a liter of milk.
A10: =IFERROR(IF(A9+1>$C$2,"",A9+1),"") -> 132 | B10: =IF(A10="","",RANDBETWEEN($C$1,$C$2)) -> 128 | C10: =IFERROR($C$1-1+_xlfn.RANK.EQ(B10,$B$4:$B$242)+COUNTIF(B$4:$B10,B10)-1,"") -> 137 | D10: =IFERROR(VLOOKUP(C10,Shopping!A:B,2,0),"") -> 34.1 | E10: =IFERROR(VLOOKUP(D10&"Viet",Shopping!C:D,2,0),"") -> Tôi thích quần áo hơi rộng một chút. | F10: =IFERROR(VLOOKUP(D10&"Eng",Shopping!C:D,2,0),"") -> I prefer my clothes to be a little loose.
A11: =IFERROR(IF(A10+1>$C$2,"",A10+1),"") -> 133 | B11: =IF(A11="","",RANDBETWEEN($C$1,$C$2)) -> 134 | C11: =IFERROR($C$1-1+_xlfn.RANK.EQ(B11,$B$4:$B$242)+COUNTIF(B$4:$B11,B11)-1,"") -> 131 | D11: =IFERROR(VLOOKUP(C11,Shopping!A:B,2,0),"") -> 32.2 | E11: =IFERROR(VLOOKUP(D11&"Viet",Shopping!C:D,2,0),"") -> Khi nào sô cô la này hết hạn? | F11: =IFERROR(VLOOKUP(D11&"Eng",Shopping!C:D,2,0),"") -> When does this chocolate expire?
A12: =IFERROR(IF(A11+1>$C$2,"",A11+1),"") -> 134 | B12: =IF(A12="","",RANDBETWEEN($C$1,$C$2)) -> 139 | C12: =IFERROR($C$1-1+_xlfn.RANK.EQ(B12,$B$4:$B$242)+COUNTIF(B$4:$B12,B12)-1,"") -> 127 | D12: =IFERROR(VLOOKUP(C12,Shopping!A:B,2,0),"") -> 31.2 | E12: =IFERROR(VLOOKUP(D12&"Viet",Shopping!C:D,2,0),"") -> Tôi muốn mua 2 kí thịt bò. | F12: =IFERROR(VLOOKUP(D12&"Eng",Shopping!C:D,2,0),"") -> I would like 2 kilos of beef.
A13: =IFERROR(IF(A12+1>$C$2,"",A12+1),"") -> 135 | B13: =IF(A13="","",RANDBETWEEN($C$1,$C$2)) -> 128 | C13: =IFERROR($C$1-1+_xlfn.RANK.EQ(B13,$B$4:$B$242)+COUNTIF(B$4:$B13,B13)-1,"") -> 138 | D13: =IFERROR(VLOOKUP(C13,Shopping!A:B,2,0),"") -> 34.2 | E13: =IFERROR(VLOOKUP(D13&"Viet",Shopping!C:D,2,0),"") -> Tôi thích quần áo rộng rãi. | F13: =IFERROR(VLOOKUP(D13&"Eng",Shopping!C:D,2,0),"") -> I prefer my clothes to be baggy.
A14: =IFERROR(IF(A13+1>$C$2,"",A13+1),"") -> 136 | B14: =IF(A14="","",RANDBETWEEN($C$1,$C$2)) -> 133 | C14: =IFERROR($C$1-1+_xlfn.RANK.EQ(B14,$B$4:$B$242)+COUNTIF(B$4:$B14,B14)-1,"") -> 133 | D14: =IFERROR(VLOOKUP(C14,Shopping!A:B,2,0),"") -> 32.4 | E14: =IFERROR(VLOOKUP(D14&"Viet",Shopping!C:D,2,0),"") -> Khi nào mật ong này hết hạn? | F14: =IFERROR(VLOOKUP(D14&"Eng",Shopping!C:D,2,0),"") -> When does this honey expire?
A15: =IFERROR(IF(A14+1>$C$2,"",A14+1),"") -> 137 | B15: =IF(A15="","",RANDBETWEEN($C$1,$C$2)) -> 133 | C15: =IFERROR($C$1-1+_xlfn.RANK.EQ(B15,$B$4:$B$242)+COUNTIF(B$4:$B15,B15)-1,"") -> 134 | D15: =IFERROR(VLOOKUP(C15,Shopping!A:B,2,0),"") -> 33.1 | E15: =IFERROR(VLOOKUP(D15&"Viet",Shopping!C:D,2,0),"") -> Không biết cô có chiếc áo len này cỡ lớn hơn không? | F15: =IFERROR(VLOOKUP(D15&"Eng",Shopping!C:D,2,0),"") -> I was wondering if you had this sweater in a larger size.
A16: =IFERROR(IF(A15+1>$C$2,"",A15+1),"") -> 138 | B16: =IF(A16="","",RANDBETWEEN($C$1,$C$2)) -> 126 | C16: =IFERROR($C$1-1+_xlfn.RANK.EQ(B16,$B$4:$B$242)+COUNTIF(B$4:$B16,B16)-1,"") -> 139 | D16: =IFERROR(VLOOKUP(C16,Shopping!A:B,2,0),"") -> 34.3 | E16: =IFERROR(VLOOKUP(D16&"Viet",Shopping!C:D,2,0),"") -> Tôi thích quần áo thời trang xíu. | F16: =IFERROR(VLOOKUP(D16&"Eng",Shopping!C:D,2,0),"") -> I prefer my clothes to be fashionable. | J16: ll;
A17: =IFERROR(IF(A16+1>$C$2,"",A16+1),"") -> 139 | B17: =IF(A17="","",RANDBETWEEN($C$1,$C$2)) -> 129 | C17: =IFERROR($C$1-1+_xlfn.RANK.EQ(B17,$B$4:$B$242)+COUNTIF(B$4:$B17,B17)-1,"") -> 136 | D17: =IFERROR(VLOOKUP(C17,Shopping!A:B,2,0),"") -> 33.3 | E17: =IFERROR(VLOOKUP(D17&"Viet",Shopping!C:D,2,0),"") -> Không biết cô có cái nào khác mà không bị lỗi không? | F17: =IFERROR(VLOOKUP(D17&"Eng",Shopping!C:D,2,0),"") -> I was wondering if you had another one that is not damaged.
A18: =IFERROR(IF(A17+1>$C$2,"",A17+1),"") | B18: =IF(A18="","",RANDBETWEEN($C$1,$C$2)) | C18: =IFERROR($C$1-1+_xlfn.RANK.EQ(B18,$B$4:$B$242)+COUNTIF(B$4:$B18,B18)-1,"") | D18: =IFERROR(VLOOKUP(C18,Shopping!A:B,2,0),"") | E18: =IFERROR(VLOOKUP(D18&"Viet",Shopping!C:D,2,0),"") | F18: =IFERROR(VLOOKUP(D18&"Eng",Shopping!C:D,2,0),"")
A19: =IFERROR(IF(A18+1>$C$2,"",A18+1),"") | B19: =IF(A19="","",RANDBETWEEN($C$1,$C$2)) | C19: =IFERROR($C$1-1+_xlfn.RANK.EQ(B19,$B$4:$B$242)+COUNTIF(B$4:$B19,B19)-1,"") | D19: =IFERROR(VLOOKUP(C19,Shopping!A:B,2,0),"") | E19: =IFERROR(VLOOKUP(D19&"Viet",Shopping!C:D,2,0),"") | F19: =IFERROR(VLOOKUP(D19&"Eng",Shopping!C:D,2,0),"") | J19: 4
A20: =IFERROR(IF(A19+1>$C$2,"",A19+1),"") | B20: =IF(A20="","",RANDBETWEEN($C$1,$C$2)) | C20: =IFERROR($C$1-1+_xlfn.RANK.EQ(B20,$B$4:$B$242)+COUNTIF(B$4:$B20,B20)-1,"") | D20: =IFERROR(VLOOKUP(C20,Shopping!A:B,2,0),"") | E20: =IFERROR(VLOOKUP(D20&"Viet",Shopping!C:D,2,0),"") | F20: =IFERROR(VLOOKUP(D20&"Eng",Shopping!C:D,2,0),"")
A21: =IFERROR(IF(A20+1>$C$2,"",A20+1),"") | B21: =IF(A21="","",RANDBETWEEN($C$1,$C$2)) | C21: =IFERROR($C$1-1+_xlfn.RANK.EQ(B21,$B$4:$B$242)+COUNTIF(B$4:$B21,B21)-1,"") | D21: =IFERROR(VLOOKUP(C21,Shopping!A:B,2,0),"") | E21: =IFERROR(VLOOKUP(D21&"Viet",Shopping!C:D,2,0),"") | F21: =IFERROR(VLOOKUP(D21&"Eng",Shopping!C:D,2,0),"")
A22: =IFERROR(IF(A21+1>$C$2,"",A21+1),"") | B22: =IF(A22="","",RANDBETWEEN($C$1,$C$2)) | C22: =IFERROR($C$1-1+_xlfn.RANK.EQ(B22,$B$4:$B$242)+COUNTIF(B$4:$B22,B22)-1,"") | D22: =IFERROR(VLOOKUP(C22,Shopping!A:B,2,0),"") | E22: =IFERROR(VLOOKUP(D22&"Viet",Shopping!C:D,2,0),"") | F22: =IFERROR(VLOOKUP(D22&"Eng",Shopping!C:D,2,0),"")
A23: =IFERROR(IF(A22+1>$C$2,"",A22+1),"") | B23: =IF(A23="","",RANDBETWEEN($C$1,$C$2)) | C23: =IFERROR($C$1-1+_xlfn.RANK.EQ(B23,$B$4:$B$242)+COUNTIF(B$4:$B23,B23)-1,"") | D23: =IFERROR(VLOOKUP(C23,Shopping!A:B,2,0),"") | E23: =IFERROR(VLOOKUP(D23&"Viet",Shopping!C:D,2,0),"") | F23: =IFERROR(VLOOKUP(D23&"Eng",Shopping!C:D,2,0),"")
A24: =IFERROR(IF(A23+1>$C$2,"",A23+1),"") | B24: =IF(A24="","",RANDBETWEEN($C$1,$C$2)) | C24: =IFERROR($C$1-1+_xlfn.RANK.EQ(B24,$B$4:$B$242)+COUNTIF(B$4:$B24,B24)-1,"") | D24: =IFERROR(VLOOKUP(C24,Shopping!A:B,2,0),"") | E24: =IFERROR(VLOOKUP(D24&"Viet",Shopping!C:D,2,0),"") | F24: =IFERROR(VLOOKUP(D24&"Eng",Shopping!C:D,2,0),"")
A25: =IFERROR(IF(A24+1>$C$2,"",A24+1),"") | B25: =IF(A25="","",RANDBETWEEN($C$1,$C$2)) | C25: =IFERROR($C$1-1+_xlfn.RANK.EQ(B25,$B$4:$B$242)+COUNTIF(B$4:$B25,B25)-1,"") | D25: =IFERROR(VLOOKUP(C25,Shopping!A:B,2,0),"") | E25: =IFERROR(VLOOKUP(D25&"Viet",Shopping!C:D,2,0),"") | F25: =IFERROR(VLOOKUP(D25&"Eng",Shopping!C:D,2,0),"")
A26: =IFERROR(IF(A25+1>$C$2,"",A25+1),"") | B26: =IF(A26="","",RANDBETWEEN($C$1,$C$2)) | C26: =IFERROR($C$1-1+_xlfn.RANK.EQ(B26,$B$4:$B$242)+COUNTIF(B$4:$B26,B26)-1,"") | D26: =IFERROR(VLOOKUP(C26,Shopping!A:B,2,0),"") | E26: =IFERROR(VLOOKUP(D26&"Viet",Shopping!C:D,2,0),"") | F26: =IFERROR(VLOOKUP(D26&"Eng",Shopping!C:D,2,0),"")
A27: =IFERROR(IF(A26+1>$C$2,"",A26+1),"") | B27: =IF(A27="","",RANDBETWEEN($C$1,$C$2)) | C27: =IFERROR($C$1-1+_xlfn.RANK.EQ(B27,$B$4:$B$242)+COUNTIF(B$4:$B27,B27)-1,"") | D27: =IFERROR(VLOOKUP(C27,Shopping!A:B,2,0),"") | E27: =IFERROR(VLOOKUP(D27&"Viet",Shopping!C:D,2,0),"") | F27: =IFERROR(VLOOKUP(D27&"Eng",Shopping!C:D,2,0),"")
A28: =IFERROR(IF(A27+1>$C$2,"",A27+1),"") | B28: =IF(A28="","",RANDBETWEEN($C$1,$C$2)) | C28: =IFERROR($C$1-1+_xlfn.RANK.EQ(B28,$B$4:$B$242)+COUNTIF(B$4:$B28,B28)-1,"") | D28: =IFERROR(VLOOKUP(C28,Shopping!A:B,2,0),"") | E28: =IFERROR(VLOOKUP(D28&"Viet",Shopping!C:D,2,0),"") | F28: =IFERROR(VLOOKUP(D28&"Eng",Shopping!C:D,2,0),"")
A29: =IFERROR(IF(A28+1>$C$2,"",A28+1),"") | B29: =IF(A29="","",RANDBETWEEN($C$1,$C$2)) | C29: =IFERROR($C$1-1+_xlfn.RANK.EQ(B29,$B$4:$B$242)+COUNTIF(B$4:$B29,B29)-1,"") | D29: =IFERROR(VLOOKUP(C29,Shopping!A:B,2,0),"") | E29: =IFERROR(VLOOKUP(D29&"Viet",Shopping!C:D,2,0),"") | F29: =IFERROR(VLOOKUP(D29&"Eng",Shopping!C:D,2,0),"")
A30: =IFERROR(IF(A29+1>$C$2,"",A29+1),"") | B30: =IF(A30="","",RANDBETWEEN($C$1,$C$2)) | C30: =IFERROR($C$1-1+_xlfn.RANK.EQ(B30,$B$4:$B$242)+COUNTIF(B$4:$B30,B30)-1,"") | D30: =IFERROR(VLOOKUP(C30,Shopping!A:B,2,0),"") | E30: =IFERROR(VLOOKUP(D30&"Viet",Shopping!C:D,2,0),"") | F30: =IFERROR(VLOOKUP(D30&"Eng",Shopping!C:D,2,0),"")
A31: =IFERROR(IF(A30+1>$C$2,"",A30+1),"") | B31: =IF(A31="","",RANDBETWEEN($C$1,$C$2)) | C31: =IFERROR($C$1-1+_xlfn.RANK.EQ(B31,$B$4:$B$242)+COUNTIF(B$4:$B31,B31)-1,"") | D31: =IFERROR(VLOOKUP(C31,Shopping!A:B,2,0),"") | E31: =IFERROR(VLOOKUP(D31&"Viet",Shopping!C:D,2,0),"") | F31: =IFERROR(VLOOKUP(D31&"Eng",Shopping!C:D,2,0),"")
... A72: =IFERROR(IF(A71+1>$C$2,"",A71+1),"") | B72: =IF(A72="","",RANDBETWEEN($C$1,$C$2)) | C72: =IFERROR($C$1-1+_xlfn.RANK.EQ(B72,$B$4:$B$242)+COUNTIF(B$4:$B72,B72)-1,"") | D72: =IFERROR(VLOOKUP(C72,Shopping!A:B,2,0),"") | E72: =IFERROR(VLOOKUP(D72&"Viet",Shopping!C:D,2,0),"") | F72: =IFERROR(VLOOKUP(D72&"Eng",Shopping!C:D,2,0),"")
A73: =IFERROR(IF(A72+1>$C$2,"",A72+1),"") | B73: =IF(A73="","",RANDBETWEEN($C$1,$C$2)) | C73: =IFERROR($C$1-1+_xlfn.RANK.EQ(B73,$B$4:$B$242)+COUNTIF(B$4:$B73,B73)-1,"") | D73: =IFERROR(VLOOKUP(C73,Shopping!A:B,2,0),"")
A74: =IFERROR(IF(A73+1>$C$2,"",A73+1),"") | B74: =IF(A74="","",RANDBETWEEN($C$1,$C$2)) | C74: =IFERROR($C$1-1+_xlfn.RANK.EQ(B74,$B$4:$B$242)+COUNTIF(B$4:$B74,B74)-1,"") | D74: =IFERROR(VLOOKUP(C74,Shopping!A:B,2,0),"")
A75: =IFERROR(IF(A74+1>$C$2,"",A74+1),"") | B75: =IF(A75="","",RANDBETWEEN($C$1,$C$2)) | C75: =IFERROR($C$1-1+_xlfn.RANK.EQ(B75,$B$4:$B$242)+COUNTIF(B$4:$B75,B75)-1,"") | D75: =IFERROR(VLOOKUP(C75,Shopping!A:B,2,0),"")
A76: =IFERROR(IF(A75+1>$C$2,"",A75+1),"") | B76: =IF(A76="","",RANDBETWEEN($C$1,$C$2)) | C76: =IFERROR($C$1-1+_xlfn.RANK.EQ(B76,$B$4:$B$242)+COUNTIF(B$4:$B76,B76)-1,"") | D76: =IFERROR(VLOOKUP(C76,Shopping!A:B,2,0),"")
A77: =IFERROR(IF(A76+1>$C$2,"",A76+1),"") | B77: =IF(A77="","",RANDBETWEEN($C$1,$C$2)) | C77: =IFERROR($C$1-1+_xlfn.RANK.EQ(B77,$B$4:$B$242)+COUNTIF(B$4:$B77,B77)-1,"") | D77: =IFERROR(VLOOKUP(C77,Shopping!A:B,2,0),"")
A78: =IFERROR(IF(A77+1>$C$2,"",A77+1),"") | B78: =IF(A78="","",RANDBETWEEN($C$1,$C$2)) | C78: =IFERROR($C$1-1+_xlfn.RANK.EQ(B78,$B$4:$B$242)+COUNTIF(B$4:$B78,B78)-1,"") | D78: =IFERROR(VLOOKUP(C78,Shopping!A:B,2,0),"")
A79: =IFERROR(IF(A78+1>$C$2,"",A78+1),"") | B79: =IF(A79="","",RANDBETWEEN($C$1,$C$2)) | C79: =IFERROR($C$1-1+_xlfn.RANK.EQ(B79,$B$4:$B$242)+COUNTIF(B$4:$B79,B79)-1,"") | D79: =IFERROR(VLOOKUP(C79,Shopping!A:B,2,0),"")
A80: =IFERROR(IF(A79+1>$C$2,"",A79+1),"") | B80: =IF(A80="","",RANDBETWEEN($C$1,$C$2)) | C80: =IFERROR($C$1-1+_xlfn.RANK.EQ(B80,$B$4:$B$242)+COUNTIF(B$4:$B80,B80)-1,"") | D80: =IFERROR(VLOOKUP(C80,Shopping!A:B,2,0),"")
...

Sheet Sheet1
