Workbook

Sheet Travel
B2: TOPIC: TRAVEL
A3: No | B3: No | C3: ID | D3: Sentence | E3: Type | F3: Link | G3: ID | H3: Copy Google drive to …
B4: 1 | C4: 1Struc | D4: I’VE NEVER BEEN + TÊN NƠI ĐẾN / Tôi chưa bao giờ đi ... / | E4: Struc | F4: =IF(G4="","","https://docs.google.com/uc?export=download&id="&G4)
B5: 1.1 | C5: 1.1Viet | D5: Tôi chưa bao giờ đi nước ngoài. | E5: Viet | F5: =IF(G5="","","https://docs.google.com/uc?export=download&id="&G5) | G5: =IFERROR(LEFT(RIGHT(H5,LEN(H5)-32),LEN(RIGHT(H5,LEN(H5)-32))-17),"")
A6: 1 | B6: 1.1 | C6: 1.1Eng | D6: I’ve never been abroad. | E6: Eng | F6: =IF(G6="","","https://docs.google.com/uc?export=download&id="&G6) -> https://docs.google.com/uc?export=download&id=15tFxnGAiSrSez0jv3xL5BOCAQ4UmcL8_ | G6: =IFERROR(LEFT(RIGHT(H6,LEN(H6)-32),LEN(RIGHT(H6,LEN(H6)-32))-17),"") -> 15tFxnGAiSrSez0jv3xL5BOCAQ4UmcL8_ | H6: https://drive.google.com/file/d/15tFxnGAiSrSez0jv3xL5BOCAQ4UmcL8_/view?usp=sharing
B7: 1.1 | C7: 1.1Phon | D7: aɪv ˈnɛvər bɪn əˈbrɔd | E7: Phon | F7: =IF(G7="","","https://docs.google.com/uc?export=download&id="&G7) | G7: =IFERROR(LEFT(RIGHT(H7,LEN(H7)-32),LEN(RIGHT(H7,LEN(H7)-32))-17),"")
B8: 1.2 | C8: 1.2Viet | D8: Tôi chưa bao giờ đi Mỹ. | E8: Viet | F8: =IF(G8="","","https://docs.google.com/uc?export=download&id="&G8) | G8: =IFERROR(LEFT(RIGHT(H8,LEN(H8)-32),LEN(RIGHT(H8,LEN(H8)-32))-17),"")
A9: 2 | B9: 1.2 | C9: 1.2Eng | D9: I’ve never been to the USA. | E9: Eng | F9: =IF(G9="","","https://docs.google.com/uc?export=download&id="&G9) -> https://docs.google.com/uc?export=download&id=1v-zuEa8bbxlkOAdUsOJxpS4lpzfS5zE7 | G9: =IFERROR(LEFT(RIGHT(H9,LEN(H9)-32),LEN(RIGHT(H9,LEN(H9)-32))-17),"") -> 1v-zuEa8bbxlkOAdUsOJxpS4lpzfS5zE7 | H9: https://drive.google.com/file/d/1v-zuEa8bbxlkOAdUsOJxpS4lpzfS5zE7/view?usp=sharing
B10: 1.2 | C10: 1.2Phon | D10: aɪv ˈnɛvər bɪn tu ˈjuˈɛˈseɪ | E10: Phon | F10: =IF(G10="","","https://docs.google.com/uc?export=download&id="&G10) | G10: =IFERROR(LEFT(RIGHT(H10,LEN(H10)-32),LEN(RIGHT(H10,LEN(H10)-32))-17),"")
B11: 1.3 | C11: 1.3Viet | D11: Tôi chưa bao giờ đi Canada. | E11: Viet | F11: =IF(G11="","","https://docs.google.com/uc?export=download&id="&G11) | G11: =IFERROR(LEFT(RIGHT(H11,LEN(H11)-32),LEN(RIGHT(H11,LEN(H11)-32))-17),"")
A12: 3 | B12: 1.3 | C12: 1.3Eng | D12: I’ve never been to Canada. | E12: Eng | F12: =IF(G12="","","https://docs.google.com/uc?export=download&id="&G12) -> https://docs.google.com/uc?export=download&id=1dQO2K25TXe9vxbD6PzWRwD4xFb08mc6h | G12: =IFERROR(LEFT(RIGHT(H12,LEN(H12)-32),LEN(RIGHT(H12,LEN(H12)-32))-17),"") -> 1dQO2K25TXe9vxbD6PzWRwD4xFb08mc6h | H12: https://drive.google.com/file/d/1dQO2K25TXe9vxbD6PzWRwD4xFb08mc6h/view?usp=sharing
B13: 1.3 | C13: 1.3Phon | D13: aɪv ˈnɛvər bɪn tu ˈkænədə | E13: Phon | F13: =IF(G13="","","https://docs.google.com/uc?export=download&id="&G13) | G13: =IFERROR(LEFT(RIGHT(H13,LEN(H13)-32),LEN(RIGHT(H13,LEN(H13)-32))-17),"")
B14: 2 | C14: 2Struc | D14: I’M TAKING A PACKAGE TOUR OF + TÊN ĐỊA ĐIỂM / Tôi sẽ đi một chuyến trọn gói đến ... / | E14: Struc | F14: =IF(G14="","","https://docs.google.com/uc?export=download&id="&G14) | G14: =IFERROR(LEFT(RIGHT(H14,LEN(H14)-32),LEN(RIGHT(H14,LEN(H14)-32))-17),"")
B15: 2.1 | C15: 2.1Viet | D15: Tôi sẽ đi một chuyến trọn gói đến Nhật Bản. | E15: Viet | F15: =IF(G15="","","https://docs.google.com/uc?export=download&id="&G15) | G15: =IFERROR(LEFT(RIGHT(H15,LEN(H15)-32),LEN(RIGHT(H15,LEN(H15)-32))-17),"")
A16: 4 | B16: 2.1 | C16: 2.1Eng | D16: I’m taking a package tour of Japan. | E16: Eng | F16: =IF(G16="","","https://docs.google.com/uc?export=download&id="&G16) -> https://docs.google.com/uc?export=download&id=1sD_oQho_CjgEljOQrn6qmOtdCBQd4GtM | G16: =IFERROR(LEFT(RIGHT(H16,LEN(H16)-32),LEN(RIGHT(H16,LEN(H16)-32))-17),"") -> 1sD_oQho_CjgEljOQrn6qmOtdCBQd4GtM | H16: https://drive.google.com/file/d/1sD_oQho_CjgEljOQrn6qmOtdCBQd4GtM/view?usp=sharing
B17: 2.1 | C17: 2.1Phon | D17: aɪm ˈteɪkɪŋ ə ˈpækəʤ tʊr ʌv ʤəˈpæn | E17: Phon | F17: =IF(G17="","","https://docs.google.com/uc?export=download&id="&G17) | G17: =IFERROR(LEFT(RIGHT(H17,LEN(H17)-32),LEN(RIGHT(H17,LEN(H17)-32))-17),"")
B18: 2.2 | C18: 2.2Viet | D18: Tôi sẽ đi một chuyến trọn gói đến Thái Lan. | E18: Viet | F18: =IF(G18="","","https://docs.google.com/uc?export=download&id="&G18) | G18: =IFERROR(LEFT(RIGHT(H18,LEN(H18)-32),LEN(RIGHT(H18,LEN(H18)-32))-17),"")
A19: 5 | B19: 2.2 | C19: 2.2Eng | D19: I’m taking a package tour of Thailand. | E19: Eng | F19: =IF(G19="","","https://docs.google.com/uc?export=download&id="&G19) -> https://docs.google.com/uc?export=download&id=1PtarE1EztOHonKmZXYl8qrzsfA7PfRY2 | G19: =IFERROR(LEFT(RIGHT(H19,LEN(H19)-32),LEN(RIGHT(H19,LEN(H19)-32))-17),"") -> 1PtarE1EztOHonKmZXYl8qrzsfA7PfRY2 | H19: https://drive.google.com/file/d/1PtarE1EztOHonKmZXYl8qrzsfA7PfRY2/view?usp=sharing
B20: 2.2 | C20: 2.2Phon | D20: aɪm ˈteɪkɪŋ ə ˈpækəʤ tʊr ʌv ˈtaɪˌlænd | E20: Phon | F20: =IF(G20="","","https://docs.google.com/uc?export=download&id="&G20) | G20: =IFERROR(LEFT(RIGHT(H20,LEN(H20)-32),LEN(RIGHT(H20,LEN(H20)-32))-17),"")
B21: 2.3 | C21: 2.3Viet | D21: Tôi sẽ đi một chuyến trọn gói đến Đài Loan. | E21: Viet | F21: =IF(G21="","","https://docs.google.com/uc?export=download&id="&G21) | G21: =IFERROR(LEFT(RIGHT(H21,LEN(H21)-32),LEN(RIGHT(H21,LEN(H21)-32))-17),"")
A22: 6 | B22: 2.3 | C22: 2.3Eng | D22: I’m taking a package tour of Taiwan. | E22: Eng | F22: =IF(G22="","","https://docs.google.com/uc?export=download&id="&G22) -> https://docs.google.com/uc?export=download&id=1pfXg3PDQfVMBWM6FrX6n3wongj_Pmne2 | G22: =IFERROR(LEFT(RIGHT(H22,LEN(H22)-32),LEN(RIGHT(H22,LEN(H22)-32))-17),"") -> 1pfXg3PDQfVMBWM6FrX6n3wongj_Pmne2 | H22: https://drive.google.com/file/d/1pfXg3PDQfVMBWM6FrX6n3wongj_Pmne2/view?usp=sharing
B23: 2.3 | C23: 2.3Phon | D23: aɪm ˈteɪkɪŋ ə ˈpækəʤ tʊr ʌv ˈtaɪˈwɑn | E23: Phon | F23: =IF(G23="","","https://docs.google.com/uc?export=download&id="&G23) | G23: =IFERROR(LEFT(RIGHT(H23,LEN(H23)-32),LEN(RIGHT(H23,LEN(H23)-32))-17),"")
B24: 3 | C24: 3Struc | D24: ĐỊA ĐIỂM + WILL BE VERY EXPENSIVE DURING THE PEAK SEASON /…rất đắt vào mùa cao điểm/ | E24: Struc | F24: =IF(G24="","","https://docs.google.com/uc?export=download&id="&G24) | G24: =IFERROR(LEFT(RIGHT(H24,LEN(H24)-32),LEN(RIGHT(H24,LEN(H24)-32))-17),"")
B25: 3.1 | C25: 3.1Viet | D25: Paris rất đắt trong suốt mùa cao điểm. | E25: Viet | F25: =IF(G25="","","https://docs.google.com/uc?export=download&id="&G25) | G25: =IFERROR(LEFT(RIGHT(H25,LEN(H25)-32),LEN(RIGHT(H25,LEN(H25)-32))-17),"")
A26: 7 | B26: 3.1 | C26: 3.1Eng | D26: Paris will be very expensive during the peak season. | E26: Eng | F26: =IF(G26="","","https://docs.google.com/uc?export=download&id="&G26) -> https://docs.google.com/uc?export=download&id=1cYOze8ARxXNNd4lxdeh3zZl4jX4es0MU | G26: =IFERROR(LEFT(RIGHT(H26,LEN(H26)-32),LEN(RIGHT(H26,LEN(H26)-32))-17),"") -> 1cYOze8ARxXNNd4lxdeh3zZl4jX4es0MU | H26: https://drive.google.com/file/d/1cYOze8ARxXNNd4lxdeh3zZl4jX4es0MU/view?usp=sharing
B27: 3.1 | C27: 3.1Phon | D27: ˈpɛrɪs wɪl bi ˈvɛri ɪkˈspɛnsɪv ˈdʊrɪŋ ðə pik ˈsizən | E27: Phon | F27: =IF(G27="","","https://docs.google.com/uc?export=download&id="&G27) | G27: =IFERROR(LEFT(RIGHT(H27,LEN(H27)-32),LEN(RIGHT(H27,LEN(H27)-32))-17),"")
B28: 3.2 | C28: 3.2Viet | D28: Đà Lạt rất là đắc đỏ trong suốt mùa cao điểm. | E28: Viet | F28: =IF(G28="","","https://docs.google.com/uc?export=download&id="&G28) | G28: =IFERROR(LEFT(RIGHT(H28,LEN(H28)-32),LEN(RIGHT(H28,LEN(H28)-32))-17),"")
A29: 8 | B29: 3.2 | C29: 3.2Eng | D29: Dalat will be very expensive during the peak season. | E29: Eng | F29: =IF(G29="","","https://docs.google.com/uc?export=download&id="&G29) -> https://docs.google.com/uc?export=download&id=1j-8gFK4fv___qUY5bygc8p_D637pmhhk | G29: =IFERROR(LEFT(RIGHT(H29,LEN(H29)-32),LEN(RIGHT(H29,LEN(H29)-32))-17),"") -> 1j-8gFK4fv___qUY5bygc8p_D637pmhhk | H29: https://drive.google.com/file/d/1j-8gFK4fv___qUY5bygc8p_D637pmhhk/view?usp=sharing
B30: 3.2 | C30: 3.2Phon | D30: Dalat wɪl bi ˈvɛri ɪkˈspɛnsɪv ˈdʊrɪŋ ðə pik ˈsizən | E30: Phon | F30: =IF(G30="","","https://docs.google.com/uc?export=download&id="&G30) | G30: =IFERROR(LEFT(RIGHT(H30,LEN(H30)-32),LEN(RIGHT(H30,LEN(H30)-32))-17),"")
B31: 3.3 | C31: 3.3Viet | D31: Hong Kong rất đắc đỏ trong suốt mùa cao điểm. | E31: Viet | F31: =IF(G31="","","https://docs.google.com/uc?export=download&id="&G31) | G31: =IFERROR(LEFT(RIGHT(H31,LEN(H31)-32),LEN(RIGHT(H31,LEN(H31)-32))-17),"")
A32: 9 | B32: 3.3 | C32: 3.3Eng | D32: Hongkong will be very expensive during the peak season. | E32: Eng | F32: =IF(G32="","","https://docs.google.com/uc?export=download&id="&G32) -> https://docs.google.com/uc?export=download&id=1FzGKh-5qgJOQXF1H3hZNEUD7vH8ysYe1 | G32: =IFERROR(LEFT(RIGHT(H32,LEN(H32)-32),LEN(RIGHT(H32,LEN(H32)-32))-17),"") -> 1FzGKh-5qgJOQXF1H3hZNEUD7vH8ysYe1 | H32: https://drive.google.com/file/d/1FzGKh-5qgJOQXF1H3hZNEUD7vH8ysYe1/view?usp=sharing
B33: 3.3 | C33: 3.3Phon | D33: ˈhɔŋkɔŋ wɪl bi ˈvɛri ɪkˈspɛnsɪv ˈdʊrɪŋ ðə pik ˈsizən | E33: Phon | F33: =IF(G33="","","https://docs.google.com/uc?export=download&id="&G33) | G33: =IFERROR(LEFT(RIGHT(H33,LEN(H33)-32),LEN(RIGHT(H33,LEN(H33)-32))-17),"")
B34: 4 | C34: 4Struc | D34: S + CAN ONLY AFFORD TO STAY AT A + DẠNG KHÁCH SẠN/ NHÀ Ở /Chúng tôi chỉ đủ khả năng trả nổi tiền ở cho …/ | E34: Struc | F34: =IF(G34="","","https://docs.google.com/uc?export=download&id="&G34) | G34: =IFERROR(LEFT(RIGHT(H34,LEN(H34)-32),LEN(RIGHT(H34,LEN(H34)-32))-17),"")
B35: 4.1 | C35: 4.1Viet | D35: Chúng tôi chỉ đủ khả năng trả nổi tiền ở cho nhà nghỉ tập thể cho khách du lịch bụi thôi. | E35: Viet | F35: =IF(G35="","","https://docs.google.com/uc?export=download&id="&G35) | G35: =IFERROR(LEFT(RIGHT(H35,LEN(H35)-32),LEN(RIGHT(H35,LEN(H35)-32))-17),"")
A36: 10 | B36: 4.1 | C36: 4.1Eng | D36: We can only afford to stay at a backpacker hostel. | E36: Eng | F36: =IF(G36="","","https://docs.google.com/uc?export=download&id="&G36) -> https://docs.google.com/uc?export=download&id=1T9b1jv2cWlMTlwF6eljZdSm_9ko6SnUV | G36: =IFERROR(LEFT(RIGHT(H36,LEN(H36)-32),LEN(RIGHT(H36,LEN(H36)-32))-17),"") -> 1T9b1jv2cWlMTlwF6eljZdSm_9ko6SnUV | H36: https://drive.google.com/file/d/1T9b1jv2cWlMTlwF6eljZdSm_9ko6SnUV/view?usp=sharing
B37: 4.1 | C37: 4.1Phon | D37: wi kæn ˈoʊnli əˈfɔrd tu steɪ æt ə ˈbækˌpækər ˈhɑstəl | E37: Phon | F37: =IF(G37="","","https://docs.google.com/uc?export=download&id="&G37) | G37: =IFERROR(LEFT(RIGHT(H37,LEN(H37)-32),LEN(RIGHT(H37,LEN(H37)-32))-17),"")
B38: 4.2 | C38: 4.2Viet | D38: Chúng tôi chỉ đủ khả năng trả nổi tiền cho nhà khách thôi. | E38: Viet | F38: =IF(G38="","","https://docs.google.com/uc?export=download&id="&G38) | G38: =IFERROR(LEFT(RIGHT(H38,LEN(H38)-32),LEN(RIGHT(H38,LEN(H38)-32))-17),"")
A39: 11 | B39: 4.2 | C39: 4.2Eng | D39: We can only afford to stay at a guesthouse. | E39: Eng | F39: =IF(G39="","","https://docs.google.com/uc?export=download&id="&G39) -> https://docs.google.com/uc?export=download&id=1sz7MmE36Q7fPkQWGMPcx3rhmGVNwrBri | G39: =IFERROR(LEFT(RIGHT(H39,LEN(H39)-32),LEN(RIGHT(H39,LEN(H39)-32))-17),"") -> 1sz7MmE36Q7fPkQWGMPcx3rhmGVNwrBri | H39: https://drive.google.com/file/d/1sz7MmE36Q7fPkQWGMPcx3rhmGVNwrBri/view?usp=sharing
B40: 4.2 | C40: 4.2Phon | D40: wi kæn ˈoʊnli əˈfɔrd tu steɪ æt ə ˈgɛstˌhaʊs | E40: Phon | F40: =IF(G40="","","https://docs.google.com/uc?export=download&id="&G40) | G40: =IFERROR(LEFT(RIGHT(H40,LEN(H40)-32),LEN(RIGHT(H40,LEN(H40)-32))-17),"")
B41: 4.3 | C41: 4.3Viet | D41: Chúng tôi chỉ đủ khả năng ở trong căn hộ nhỏ thôi. | E41: Viet | F41: =IF(G41="","","https://docs.google.com/uc?export=download&id="&G41) | G41: =IFERROR(LEFT(RIGHT(H41,LEN(H41)-32),LEN(RIGHT(H41,LEN(H41)-32))-17),"")
...

Sheet Viet
B2: Sentence | C2: Link | D2: ID | E2: Copy Google drive to …
B3: 01-05 | C3: =IF(D3="","","https://docs.google.com/uc?export=download&id="&D3) -> https://docs.google.com/uc?export=download&id=1z-CK-LPThDVM8wVUsOVH1QcsU_B7s7n4 | D3: =IFERROR(LEFT(RIGHT(E3,LEN(E3)-32),LEN(RIGHT(E3,LEN(E3)-32))-17),"") -> 1z-CK-LPThDVM8wVUsOVH1QcsU_B7s7n4 | E3: https://drive.google.com/file/d/1z-CK-LPThDVM8wVUsOVH1QcsU_B7s7n4/view?usp=sharing
B4: 06-10 | C4: =IF(D4="","","https://docs.google.com/uc?export=download&id="&D4) -> https://docs.google.com/uc?export=download&id=136IuKU9AiM_ATjO6j9pn9t3hPxoRC9ah | D4: =IFERROR(LEFT(RIGHT(E4,LEN(E4)-32),LEN(RIGHT(E4,LEN(E4)-32))-17),"") -> 136IuKU9AiM_ATjO6j9pn9t3hPxoRC9ah | E4: https://drive.google.com/file/d/136IuKU9AiM_ATjO6j9pn9t3hPxoRC9ah/view?usp=sharing
B5: 11-15 | C5: =IF(D5="","","https://docs.google.com/uc?export=download&id="&D5) -> https://docs.google.com/uc?export=download&id=1VeoSpR_BnugwxUxk-9GrsriVybY-rPtU | D5: =IFERROR(LEFT(RIGHT(E5,LEN(E5)-32),LEN(RIGHT(E5,LEN(E5)-32))-17),"") -> 1VeoSpR_BnugwxUxk-9GrsriVybY-rPtU | E5: https://drive.google.com/file/d/1VeoSpR_BnugwxUxk-9GrsriVybY-rPtU/view?usp=sharing
B6: 16-20 | C6: =IF(D6="","","https://docs.google.com/uc?export=download&id="&D6) -> https://docs.google.com/uc?export=download&id=1mF8M7SBxeIJu26DMqCorS7r34UpRf0vG | D6: =IFERROR(LEFT(RIGHT(E6,LEN(E6)-32),LEN(RIGHT(E6,LEN(E6)-32))-17),"") -> 1mF8M7SBxeIJu26DMqCorS7r34UpRf0vG | E6: https://drive.google.com/file/d/1mF8M7SBxeIJu26DMqCorS7r34UpRf0vG/view?usp=sharing
B7: 21-28 | C7: =IF(D7="","","https://docs.google.com/uc?export=download&id="&D7) -> https://docs.google.com/uc?export=download&id=18Aka8AT1oIJvTXmS5NFPZKh9FFzAjw3k | D7: =IFERROR(LEFT(RIGHT(E7,LEN(E7)-32),LEN(RIGHT(E7,LEN(E7)-32))-17),"") -> 18Aka8AT1oIJvTXmS5NFPZKh9FFzAjw3k | E7: https://drive.google.com/file/d/18Aka8AT1oIJvTXmS5NFPZKh9FFzAjw3k/view?usp=sharing
B8: 01-28 | C8: =IF(D8="","","https://docs.google.com/uc?export=download&id="&D8) -> https://docs.google.com/uc?export=download&id=1kOT3642UsHN_ZYWCq7VjqkAXwBilZOJT | D8: =IFERROR(LEFT(RIGHT(E8,LEN(E8)-32),LEN(RIGHT(E8,LEN(E8)-32))-17),"") -> 1kOT3642UsHN_ZYWCq7VjqkAXwBilZOJT | E8: https://drive.google.com/file/d/1kOT3642UsHN_ZYWCq7VjqkAXwBilZOJT/view?usp=sharing

Sheet Sum
B2: Sentence | C2: Link | D2: ID | E2: Copy Google drive to …
B3: Woman | C3: =IF(D3="","","https://docs.google.com/uc?export=download&id="&D3) | D3: =IFERROR(LEFT(RIGHT(E3,LEN(E3)-32),LEN(RIGHT(E3,LEN(E3)-32))-17),"")
B4: Man | C4: =IF(D4="","","https://docs.google.com/uc?export=download&id="&D4) | D4: =IFERROR(LEFT(RIGHT(E4,LEN(E4)-32),LEN(RIGHT(E4,LEN(E4)-32))-17),"")

Sheet Ramdom
B1: From | C1: 85
B2: To | C2: 114
C3: No | D3: No | E3: Viet | F3: Eng
A4: =C1 -> 85 | B4: =IF(A4="","",RANDBETWEEN($C$1,$C$2)) -> 103 | C4: =IFERROR($C$1-1+_xlfn.RANK.EQ(B4,$B$4:$B$117)+COUNTIF(B$4:$B4,B4)-1,"") -> 98 | D4: =IFERROR(VLOOKUP(C4,Travel!A:B,2,0),"") -> 24.4 | E4: =IFERROR(VLOOKUP(D4&"Viet",Travel!C:D,2,0),"") -> Ở đây có dịch vụ gọi dậy sớm không ? | F4: =IFERROR(VLOOKUP(D4&"Eng",Travel!C:D,2,0),"") -> Is there a wake- up call service?
A5: =IFERROR(IF(A4+1>$C$2,"",A4+1),"") -> 86 | B5: =IF(A5="","",RANDBETWEEN($C$1,$C$2)) -> 95 | C5: =IFERROR($C$1-1+_xlfn.RANK.EQ(B5,$B$4:$B$117)+COUNTIF(B$4:$B5,B5)-1,"") -> 106 | D5: =IFERROR(VLOOKUP(C5,Travel!A:B,2,0),"") -> 26.3 | E5: =IFERROR(VLOOKUP(D5&"Viet",Travel!C:D,2,0),"") -> Cái điều khiển bị hỏng rồi. | F5: =IFERROR(VLOOKUP(D5&"Eng",Travel!C:D,2,0),"") -> The remote control doesn’t work.
A6: =IFERROR(IF(A5+1>$C$2,"",A5+1),"") -> 87 | B6: =IF(A6="","",RANDBETWEEN($C$1,$C$2)) -> 98 | C6: =IFERROR($C$1-1+_xlfn.RANK.EQ(B6,$B$4:$B$117)+COUNTIF(B$4:$B6,B6)-1,"") -> 104 | D6: =IFERROR(VLOOKUP(C6,Travel!A:B,2,0),"") -> 26.1 | E6: =IFERROR(VLOOKUP(D6&"Viet",Travel!C:D,2,0),"") -> Cái vòi sen bị hỏng rồi. | F6: =IFERROR(VLOOKUP(D6&"Eng",Travel!C:D,2,0),"") -> The shower doesn’t work.
A7: =IFERROR(IF(A6+1>$C$2,"",A6+1),"") -> 88 | B7: =IF(A7="","",RANDBETWEEN($C$1,$C$2)) -> 113 | C7: =IFERROR($C$1-1+_xlfn.RANK.EQ(B7,$B$4:$B$117)+COUNTIF(B$4:$B7,B7)-1,"") -> 85 | D7: =IFERROR(VLOOKUP(C7,Travel!A:B,2,0),"") -> 21.1 | E7: =IFERROR(VLOOKUP(D7&"Viet",Travel!C:D,2,0),"") -> Tôi định ở đây khoảng 3 ngày. | F7: =IFERROR(VLOOKUP(D7&"Eng",Travel!C:D,2,0),"") -> I plan to stay for 3 days.
A8: =IFERROR(IF(A7+1>$C$2,"",A7+1),"") -> 89 | B8: =IF(A8="","",RANDBETWEEN($C$1,$C$2)) -> 107 | C8: =IFERROR($C$1-1+_xlfn.RANK.EQ(B8,$B$4:$B$117)+COUNTIF(B$4:$B8,B8)-1,"") -> 93 | D8: =IFERROR(VLOOKUP(C8,Travel!A:B,2,0),"") -> 23.2 | E8: =IFERROR(VLOOKUP(D8&"Viet",Travel!C:D,2,0),"") -> Bạn có thể đưa tôi đến bến xe buýt được không? | F8: =IFERROR(VLOOKUP(D8&"Eng",Travel!C:D,2,0),"") -> Could you take me to the bus station?
A9: =IFERROR(IF(A8+1>$C$2,"",A8+1),"") -> 90 | B9: =IF(A9="","",RANDBETWEEN($C$1,$C$2)) -> 113 | C9: =IFERROR($C$1-1+_xlfn.RANK.EQ(B9,$B$4:$B$117)+COUNTIF(B$4:$B9,B9)-1,"") -> 86 | D9: =IFERROR(VLOOKUP(C9,Travel!A:B,2,0),"") -> 21.2 | E9: =IFERROR(VLOOKUP(D9&"Viet",Travel!C:D,2,0),"") -> Tôi định ở đây khoảng 1 tuần. | F9: =IFERROR(VLOOKUP(D9&"Eng",Travel!C:D,2,0),"") -> I plan to stay for a week.
A10: =IFERROR(IF(A9+1>$C$2,"",A9+1),"") -> 91 | B10: =IF(A10="","",RANDBETWEEN($C$1,$C$2)) -> 112 | C10: =IFERROR($C$1-1+_xlfn.RANK.EQ(B10,$B$4:$B$117)+COUNTIF(B$4:$B10,B10)-1,"") -> 87 | D10: =IFERROR(VLOOKUP(C10,Travel!A:B,2,0),"") -> 21.3 | E10: =IFERROR(VLOOKUP(D10&"Viet",Travel!C:D,2,0),"") -> Tôi định ở đây khoảng 1 tháng. | F10: =IFERROR(VLOOKUP(D10&"Eng",Travel!C:D,2,0),"") -> I plan to stay for a month.
A11: =IFERROR(IF(A10+1>$C$2,"",A10+1),"") -> 92 | B11: =IF(A11="","",RANDBETWEEN($C$1,$C$2)) -> 106 | C11: =IFERROR($C$1-1+_xlfn.RANK.EQ(B11,$B$4:$B$117)+COUNTIF(B$4:$B11,B11)-1,"") -> 96 | D11: =IFERROR(VLOOKUP(C11,Travel!A:B,2,0),"") -> 24.2 | E11: =IFERROR(VLOOKUP(D11&"Viet",Travel!C:D,2,0),"") -> Ở đây có dịch vụ phong không? | F11: =IFERROR(VLOOKUP(D11&"Eng",Travel!C:D,2,0),"") -> Is there room service?
A12: =IFERROR(IF(A11+1>$C$2,"",A11+1),"") -> 93 | B12: =IF(A12="","",RANDBETWEEN($C$1,$C$2)) -> 94 | C12: =IFERROR($C$1-1+_xlfn.RANK.EQ(B12,$B$4:$B$117)+COUNTIF(B$4:$B12,B12)-1,"") -> 107 | D12: =IFERROR(VLOOKUP(C12,Travel!A:B,2,0),"") -> 26.4 | E12: =IFERROR(VLOOKUP(D12&"Viet",Travel!C:D,2,0),"") -> Cái đèn bàn hỏng rồi. | F12: =IFERROR(VLOOKUP(D12&"Eng",Travel!C:D,2,0),"") -> The lamp doesn’t work.
A13: =IFERROR(IF(A12+1>$C$2,"",A12+1),"") -> 94 | B13: =IF(A13="","",RANDBETWEEN($C$1,$C$2)) -> 112 | C13: =IFERROR($C$1-1+_xlfn.RANK.EQ(B13,$B$4:$B$117)+COUNTIF(B$4:$B13,B13)-1,"") -> 88 | D13: =IFERROR(VLOOKUP(C13,Travel!A:B,2,0),"") -> 21.4 | E13: =IFERROR(VLOOKUP(D13&"Viet",Travel!C:D,2,0),"") -> Tôi định ở đây khoảng 10 ngày. | F13: =IFERROR(VLOOKUP(D13&"Eng",Travel!C:D,2,0),"") -> I plan to stay for ten days.
A14: =IFERROR(IF(A13+1>$C$2,"",A13+1),"") -> 95 | B14: =IF(A14="","",RANDBETWEEN($C$1,$C$2)) -> 86 | C14: =IFERROR($C$1-1+_xlfn.RANK.EQ(B14,$B$4:$B$117)+COUNTIF(B$4:$B14,B14)-1,"") -> 113 | D14: =IFERROR(VLOOKUP(C14,Travel!A:B,2,0),"") -> 28.3 | E14: =IFERROR(VLOOKUP(D14&"Viet",Travel!C:D,2,0),"") -> Tôi có thể ở lại thêm một đêm không? | F14: =IFERROR(VLOOKUP(D14&"Eng",Travel!C:D,2,0),"") -> Is it possible to stay one more night?
A15: =IFERROR(IF(A14+1>$C$2,"",A14+1),"") -> 96 | B15: =IF(A15="","",RANDBETWEEN($C$1,$C$2)) -> 93 | C15: =IFERROR($C$1-1+_xlfn.RANK.EQ(B15,$B$4:$B$117)+COUNTIF(B$4:$B15,B15)-1,"") -> 109 | D15: =IFERROR(VLOOKUP(C15,Travel!A:B,2,0),"") -> 27.2 | E15: =IFERROR(VLOOKUP(D15&"Viet",Travel!C:D,2,0),"") -> Ở đây không có máy sấy tóc. | F15: =IFERROR(VLOOKUP(D15&"Eng",Travel!C:D,2,0),"") -> There is no hairdryer.
A16: =IFERROR(IF(A15+1>$C$2,"",A15+1),"") -> 97 | B16: =IF(A16="","",RANDBETWEEN($C$1,$C$2)) -> 102 | C16: =IFERROR($C$1-1+_xlfn.RANK.EQ(B16,$B$4:$B$117)+COUNTIF(B$4:$B16,B16)-1,"") -> 100 | D16: =IFERROR(VLOOKUP(C16,Travel!A:B,2,0),"") -> 25.2 | E16: =IFERROR(VLOOKUP(D16&"Viet",Travel!C:D,2,0),"") -> Tôi muốn đặt một phòng đơn. | F16: =IFERROR(VLOOKUP(D16&"Eng",Travel!C:D,2,0),"") -> I would like to reserve a single room, please.
A17: =IFERROR(IF(A16+1>$C$2,"",A16+1),"") -> 98 | B17: =IF(A17="","",RANDBETWEEN($C$1,$C$2)) -> 100 | C17: =IFERROR($C$1-1+_xlfn.RANK.EQ(B17,$B$4:$B$117)+COUNTIF(B$4:$B17,B17)-1,"") -> 102 | D17: =IFERROR(VLOOKUP(C17,Travel!A:B,2,0),"") -> 25.4 | E17: =IFERROR(VLOOKUP(D17&"Viet",Travel!C:D,2,0),"") -> Tôi muốn đặt một phòng loại tốt. | F17: =IFERROR(VLOOKUP(D17&"Eng",Travel!C:D,2,0),"") -> I would like to reserve a deluxe room. | L17: 4
A18: =IFERROR(IF(A17+1>$C$2,"",A17+1),"") -> 99 | B18: =IF(A18="","",RANDBETWEEN($C$1,$C$2)) -> 97 | C18: =IFERROR($C$1-1+_xlfn.RANK.EQ(B18,$B$4:$B$117)+COUNTIF(B$4:$B18,B18)-1,"") -> 105 | D18: =IFERROR(VLOOKUP(C18,Travel!A:B,2,0),"") -> 26.2 | E18: =IFERROR(VLOOKUP(D18&"Viet",Travel!C:D,2,0),"") -> Cái tủ lạnh bị hỏng rồi. | F18: =IFERROR(VLOOKUP(D18&"Eng",Travel!C:D,2,0),"") -> The fridge doesn’t work.
A19: =IFERROR(IF(A18+1>$C$2,"",A18+1),"") -> 100 | B19: =IF(A19="","",RANDBETWEEN($C$1,$C$2)) -> 86 | C19: =IFERROR($C$1-1+_xlfn.RANK.EQ(B19,$B$4:$B$117)+COUNTIF(B$4:$B19,B19)-1,"") -> 114 | D19: =IFERROR(VLOOKUP(C19,Travel!A:B,2,0),"") -> 28.4 | E19: =IFERROR(VLOOKUP(D19&"Viet",Travel!C:D,2,0),"") -> Tôi có thể rời đi sớm hơn một ngày không ? | F19: =IFERROR(VLOOKUP(D19&"Eng",Travel!C:D,2,0),"") -> Is it possible to leave a day earlier? | L19: p
A20: =IFERROR(IF(A19+1>$C$2,"",A19+1),"") -> 101 | B20: =IF(A20="","",RANDBETWEEN($C$1,$C$2)) -> 107 | C20: =IFERROR($C$1-1+_xlfn.RANK.EQ(B20,$B$4:$B$117)+COUNTIF(B$4:$B20,B20)-1,"") -> 94 | D20: =IFERROR(VLOOKUP(C20,Travel!A:B,2,0),"") -> 23.3 | E20: =IFERROR(VLOOKUP(D20&"Viet",Travel!C:D,2,0),"") -> Bạn có thể đưa tôi đến trung tâm thành phố được không? | F20: =IFERROR(VLOOKUP(D20&"Eng",Travel!C:D,2,0),"") -> Could you take me to the city center?
A21: =IFERROR(IF(A20+1>$C$2,"",A20+1),"") -> 102 | B21: =IF(A21="","",RANDBETWEEN($C$1,$C$2)) -> 100 | C21: =IFERROR($C$1-1+_xlfn.RANK.EQ(B21,$B$4:$B$117)+COUNTIF(B$4:$B21,B21)-1,"") -> 103 | D21: =IFERROR(VLOOKUP(C21,Travel!A:B,2,0),"") -> 25.5 | E21: =IFERROR(VLOOKUP(D21&"Viet",Travel!C:D,2,0),"") -> Tôi muốn đặt một phòng tiêu chuẩn. | F21: =IFERROR(VLOOKUP(D21&"Eng",Travel!C:D,2,0),"") -> I would like to reserve a standard room.
A22: =IFERROR(IF(A21+1>$C$2,"",A21+1),"") -> 103 | B22: =IF(A22="","",RANDBETWEEN($C$1,$C$2)) -> 107 | C22: =IFERROR($C$1-1+_xlfn.RANK.EQ(B22,$B$4:$B$117)+COUNTIF(B$4:$B22,B22)-1,"") -> 95 | D22: =IFERROR(VLOOKUP(C22,Travel!A:B,2,0),"") -> 24.1 | E22: =IFERROR(VLOOKUP(D22&"Viet",Travel!C:D,2,0),"") -> Ở đây có dịch vụ giặt là không? | F22: =IFERROR(VLOOKUP(D22&"Eng",Travel!C:D,2,0),"") -> Is there a laundry service?
A23: =IFERROR(IF(A22+1>$C$2,"",A22+1),"") -> 104 | B23: =IF(A23="","",RANDBETWEEN($C$1,$C$2)) -> 110 | C23: =IFERROR($C$1-1+_xlfn.RANK.EQ(B23,$B$4:$B$117)+COUNTIF(B$4:$B23,B23)-1,"") -> 92 | D23: =IFERROR(VLOOKUP(C23,Travel!A:B,2,0),"") -> 23.1 | E23: =IFERROR(VLOOKUP(D23&"Viet",Travel!C:D,2,0),"") -> Bạn có thể đưa tôi đến địa chỉ này được không? | F23: =IFERROR(VLOOKUP(D23&"Eng",Travel!C:D,2,0),"") -> Could you take me to this address?
A24: =IFERROR(IF(A23+1>$C$2,"",A23+1),"") -> 105 | B24: =IF(A24="","",RANDBETWEEN($C$1,$C$2)) -> 101 | C24: =IFERROR($C$1-1+_xlfn.RANK.EQ(B24,$B$4:$B$117)+COUNTIF(B$4:$B24,B24)-1,"") -> 101 | D24: =IFERROR(VLOOKUP(C24,Travel!A:B,2,0),"") -> 25.3 | E24: =IFERROR(VLOOKUP(D24&"Viet",Travel!C:D,2,0),"") -> Cho tôi đặt một phòng cao cấp. | F24: =IFERROR(VLOOKUP(D24&"Eng",Travel!C:D,2,0),"") -> I would like to reserve a suite.
A25: =IFERROR(IF(A24+1>$C$2,"",A24+1),"") -> 106 | B25: =IF(A25="","",RANDBETWEEN($C$1,$C$2)) -> 111 | C25: =IFERROR($C$1-1+_xlfn.RANK.EQ(B25,$B$4:$B$117)+COUNTIF(B$4:$B25,B25)-1,"") -> 90 | D25: =IFERROR(VLOOKUP(C25,Travel!A:B,2,0),"") -> 22.2 | E25: =IFERROR(VLOOKUP(D25&"Viet",Travel!C:D,2,0),"") -> Xe buýt nào đi đến nhà ga? | F25: =IFERROR(VLOOKUP(D25&"Eng",Travel!C:D,2,0),"") -> Which bus goes to the station?
A26: =IFERROR(IF(A25+1>$C$2,"",A25+1),"") -> 107 | B26: =IF(A26="","",RANDBETWEEN($C$1,$C$2)) -> 88 | C26: =IFERROR($C$1-1+_xlfn.RANK.EQ(B26,$B$4:$B$117)+COUNTIF(B$4:$B26,B26)-1,"") -> 111 | D26: =IFERROR(VLOOKUP(C26,Travel!A:B,2,0),"") -> 28.1 | E26: =IFERROR(VLOOKUP(D26&"Viet",Travel!C:D,2,0),"") -> Tôi có thể làm thủ tục trả phòng muộn không? | F26: =IFERROR(VLOOKUP(D26&"Eng",Travel!C:D,2,0),"") -> Is it possible to check out late?
A27: =IFERROR(IF(A26+1>$C$2,"",A26+1),"") -> 108 | B27: =IF(A27="","",RANDBETWEEN($C$1,$C$2)) -> 87 | C27: =IFERROR($C$1-1+_xlfn.RANK.EQ(B27,$B$4:$B$117)+COUNTIF(B$4:$B27,B27)-1,"") -> 112 | D27: =IFERROR(VLOOKUP(C27,Travel!A:B,2,0),"") -> 28.2 | E27: =IFERROR(VLOOKUP(D27&"Viet",Travel!C:D,2,0),"") -> Tôi có thể gửi hành lí ở đây không? | F27: =IFERROR(VLOOKUP(D27&"Eng",Travel!C:D,2,0),"") -> Is it possible to leave my luggage here?
A28: =IFERROR(IF(A27+1>$C$2,"",A27+1),"") -> 109 | B28: =IF(A28="","",RANDBETWEEN($C$1,$C$2)) -> 89 | C28: =IFERROR($C$1-1+_xlfn.RANK.EQ(B28,$B$4:$B$117)+COUNTIF(B$4:$B28,B28)-1,"") -> 110 | D28: =IFERROR(VLOOKUP(C28,Travel!A:B,2,0),"") -> 27.3 | E28: =IFERROR(VLOOKUP(D28&"Viet",Travel!C:D,2,0),"") -> Ở đây không có kem đánh răng. | F28: =IFERROR(VLOOKUP(D28&"Eng",Travel!C:D,2,0),"") -> There is no toothpaste.
A29: =IFERROR(IF(A28+1>$C$2,"",A28+1),"") -> 110 | B29: =IF(A29="","",RANDBETWEEN($C$1,$C$2)) -> 112 | C29: =IFERROR($C$1-1+_xlfn.RANK.EQ(B29,$B$4:$B$117)+COUNTIF(B$4:$B29,B29)-1,"") -> 89 | D29: =IFERROR(VLOOKUP(C29,Travel!A:B,2,0),"") -> 22.1 | E29: =IFERROR(VLOOKUP(D29&"Viet",Travel!C:D,2,0),"") -> Xe buýt nào đi đến sân bay? | F29: =IFERROR(VLOOKUP(D29&"Eng",Travel!C:D,2,0),"") -> Which bus goes to the airport?
A30: =IFERROR(IF(A29+1>$C$2,"",A29+1),"") -> 111 | B30: =IF(A30="","",RANDBETWEEN($C$1,$C$2)) -> 104 | C30: =IFERROR($C$1-1+_xlfn.RANK.EQ(B30,$B$4:$B$117)+COUNTIF(B$4:$B30,B30)-1,"") -> 97 | D30: =IFERROR(VLOOKUP(C30,Travel!A:B,2,0),"") -> 24.3 | E30: =IFERROR(VLOOKUP(D30&"Viet",Travel!C:D,2,0),"") -> Ở đây có dịch vụ đỗ xe không? | F30: =IFERROR(VLOOKUP(D30&"Eng",Travel!C:D,2,0),"") -> Is there valet parking?
A31: =IFERROR(IF(A30+1>$C$2,"",A30+1),"") -> 112 | B31: =IF(A31="","",RANDBETWEEN($C$1,$C$2)) -> 103 | C31: =IFERROR($C$1-1+_xlfn.RANK.EQ(B31,$B$4:$B$117)+COUNTIF(B$4:$B31,B31)-1,"") -> 99 | D31: =IFERROR(VLOOKUP(C31,Travel!A:B,2,0),"") -> 25.1 | E31: =IFERROR(VLOOKUP(D31&"Viet",Travel!C:D,2,0),"") -> Tôi muốn đặt một phòng đôi. | F31: =IFERROR(VLOOKUP(D31&"Eng",Travel!C:D,2,0),"") -> I would like to reserve a double room, please.
... A72: =IFERROR(IF(A71+1>$C$2,"",A71+1),"") | B72: =IF(A72="","",RANDBETWEEN($C$1,$C$2)) | C72: =IFERROR($C$1-1+_xlfn.RANK.EQ(B72,$B$4:$B$117)+COUNTIF(B$4:$B72,B72)-1,"") | D72: =IFERROR(VLOOKUP(C72,Travel!A:B,2,0),"") | E72: =IFERROR(VLOOKUP(D72&"Viet",Travel!C:D,2,0),"") | F72: =IFERROR(VLOOKUP(D72&"Eng",Travel!C:D,2,0),"")
A73: =IFERROR(IF(A72+1>$C$2,"",A72+1),"") | B73: =IF(A73="","",RANDBETWEEN($C$1,$C$2)) | C73: =IFERROR($C$1-1+_xlfn.RANK.EQ(B73,$B$4:$B$117)+COUNTIF(B$4:$B73,B73)-1,"") | D73: =IFERROR(VLOOKUP(C73,Travel!A:B,2,0),"")
A74: =IFERROR(IF(A73+1>$C$2,"",A73+1),"") | B74: =IF(A74="","",RANDBETWEEN($C$1,$C$2)) | C74: =IFERROR($C$1-1+_xlfn.RANK.EQ(B74,$B$4:$B$117)+COUNTIF(B$4:$B74,B74)-1,"") | D74: =IFERROR(VLOOKUP(C74,Travel!A:B,2,0),"")
A75: =IFERROR(IF(A74+1>$C$2,"",A74+1),"") | B75: =IF(A75="","",RANDBETWEEN($C$1,$C$2)) | C75: =IFERROR($C$1-1+_xlfn.RANK.EQ(B75,$B$4:$B$117)+COUNTIF(B$4:$B75,B75)-1,"") | D75: =IFERROR(VLOOKUP(C75,Travel!A:B,2,0),"")
A76: =IFERROR(IF(A75+1>$C$2,"",A75+1),"") | B76: =IF(A76="","",RANDBETWEEN($C$1,$C$2)) | C76: =IFERROR($C$1-1+_xlfn.RANK.EQ(B76,$B$4:$B$117)+COUNTIF(B$4:$B76,B76)-1,"") | D76: =IFERROR(VLOOKUP(C76,Travel!A:B,2,0),"")
A77: =IFERROR(IF(A76+1>$C$2,"",A76+1),"") | B77: =IF(A77="","",RANDBETWEEN($C$1,$C$2)) | C77: =IFERROR($C$1-1+_xlfn.RANK.EQ(B77,$B$4:$B$117)+COUNTIF(B$4:$B77,B77)-1,"") | D77: =IFERROR(VLOOKUP(C77,Travel!A:B,2,0),"")
A78: =IFERROR(IF(A77+1>$C$2,"",A77+1),"") | B78: =IF(A78="","",RANDBETWEEN($C$1,$C$2)) | C78: =IFERROR($C$1-1+_xlfn.RANK.EQ(B78,$B$4:$B$117)+COUNTIF(B$4:$B78,B78)-1,"") | D78: =IFERROR(VLOOKUP(C78,Travel!A:B,2,0),"")
A79: =IFERROR(IF(A78+1>$C$2,"",A78+1),"") | B79: =IF(A79="","",RANDBETWEEN($C$1,$C$2)) | C79: =IFERROR($C$1-1+_xlfn.RANK.EQ(B79,$B$4:$B$117)+COUNTIF(B$4:$B79,B79)-1,"") | D79: =IFERROR(VLOOKUP(C79,Travel!A:B,2,0),"")
A80: =IFERROR(IF(A79+1>$C$2,"",A79+1),"") | B80: =IF(A80="","",RANDBETWEEN($C$1,$C$2)) | C80: =IFERROR($C$1-1+_xlfn.RANK.EQ(B80,$B$4:$B$117)+COUNTIF(B$4:$B80,B80)-1,"") | D80: =IFERROR(VLOOKUP(C80,Travel!A:B,2,0),"")
...

Sheet Sheet1

Sheet Sheet2

Sheet Sheet3
